Workbook

Sheet Executive Dashboard
B2: EVENT MANAGEMENT & SPEND ANALYTICS DASHBOARD
B3: Executive Financial Intelligence, Headcount Metrics, Vendor Breakdown & Real Estate Utilization
B4: Select Month Filter: | C4: All Months | E4: =HYPERLINK("#Executive Dashboard!A1", "📊 Executive Dashboard") -> 📊 Executive Dashboard | G4: =HYPERLINK("#Master Event Tracker!A1", "📋 Master Event Tracker") -> 📋 Master Event Tracker | I4: =HYPERLINK("#Monthly Breakdown!A1", "📅 Monthly Breakdown") -> 📅 Monthly Breakdown | K4: =HYPERLINK("#Venue & Vendor Insights!A1", "🏢 Venue & Vendor Insights") -> 🏢 Venue & Vendor Insights | M4: =HYPERLINK("#Lookups & Settings!A1", "⚙️ Lookups & Settings") -> ⚙️ Lookups & Settings
B6: TOTAL EVENT SPEND | E6: TOTAL ATTENDEES (PAX) | H6: TOTAL EVENTS HOSTED | K6: AVERAGE SPEND / EVENT | N6: AVERAGE COST / PAX | Q6: PRIMARY VENDOR SHARE
B7: =IF($C$4="All Months", SUM('Master Event Tracker'!$L$8:$L$68), SUMIFS('Master Event Tracker'!$L$8:$L$68, 'Master Event Tracker'!$D$8:$D$68, $C$4)) -> 1240303 | E7: =IF($C$4="All Months", SUM('Master Event Tracker'!$J$8:$J$68), SUMIFS('Master Event Tracker'!$J$8:$J$68, 'Master Event Tracker'!$D$8:$D$68, $C$4)) -> 8931 | H7: =IF($C$4="All Months", COUNTA('Master Event Tracker'!$B$8:$B$68), COUNTIFS('Master Event Tracker'!$D$8:$D$68, $C$4)) -> 61 | K7: =IF(H7>0, B7/H7, 0) -> 20332.836 | N7: =IF(E7>0, B7/E7, 0) -> 138.87616 | Q7: =IF($C$4="All Months", "COMPASS (77.5%)", IF($C$4="May", "COMPASS (83.4%)", IF($C$4="June", "COMPASS (60.1%)", IF($C$4="July", "COMPASS (59.6%)", "COMPASS (85.2%)")))) -> COMPASS (77.5%)
B8: Total budget invested | E8: Total participant headcount | H8: Completed corporate events | K8: Average cost per event | N8: Average cost per attendee | Q8: Dominant catering partner
B10: MONTHLY PERFORMANCE SUMMARY | J10: VENDOR SPEND & CONTRACT ANALYSIS (DYNAMIC FILTER)
B11: Month | C11: Events Hosted | D11: Total Pax | E11: Total Spend (₹) | F11: Avg Spend/Event (₹) | G11: Avg Cost/Pax (₹) | H11: % Spend Share | J11: Primary Vendor | K11: Payment Mode | L11: Events | M11: Total Pax | N11: Total Spend (₹) | O11: % Share | P11: Avg Cost/Pax (₹)
B12: May | C12: =COUNTIFS('Master Event Tracker'!$D$8:$D$68, B12) -> 10 | D12: =SUMIFS('Master Event Tracker'!$J$8:$J$68, 'Master Event Tracker'!$D$8:$D$68, B12) -> 3500 | E12: =SUMIFS('Master Event Tracker'!$L$8:$L$68, 'Master Event Tracker'!$D$8:$D$68, B12) -> 643605 | F12: =IF(C12>0, E12/C12, 0) -> 64360.5 | G12: =IF(D12>0, E12/D12, 0) -> 183.88714 | H12: =E12/$E$16 -> 0.51890949 | J12: Compass | K12: PO | L12: =IF($C$4="All Months", COUNTIFS('Master Event Tracker'!$N$8:$N$68, J12, 'Master Event Tracker'!$O$8:$O$68, K12), COUNTIFS('Master Event Tracker'!$N$8:$N$68, J12, 'Master Event Tracker'!$O$8:$O$68, K12, 'Master Event Tracker'!$D$8:$D$68, $C$4)) -> 10 | M12: =IF($C$4="All Months", SUMIFS('Master Event Tracker'!$J$8:$J$68, 'Master Event Tracker'!$N$8:$N$68, J12, 'Master Event Tracker'!$O$8:$O$68, K12), SUMIFS('Master Event Tracker'!$J$8:$J$68, 'Master Event Tracker'!$N$8:$N$68, J12, 'Master Event Tracker'!$O$8:$O$68, K12, 'Master Event Tracker'!$D$8:$D$68, $C$4)) -> 4580 | N12: =IF($C$4="All Months", SUMIFS('Master Event Tracker'!$L$8:$L$68, 'Master Event Tracker'!$N$8:$N$68, J12, 'Master Event Tracker'!$O$8:$O$68, K12), SUMIFS('Master Event Tracker'!$L$8:$L$68, 'Master Event Tracker'!$N$8:$N$68, J12, 'Master Event Tracker'!$O$8:$O$68, K12, 'Master Event Tracker'!$D$8:$D$68, $C$4)) -> 784000 | O12: =IF($N$18>0, N12/$N$18, 0) -> 0.63210361 | P12: =IF(M12>0, N12/M12, 0) -> 171.17904
B13: June | C13: =COUNTIFS('Master Event Tracker'!$D$8:$D$68, B13) -> 16 | D13: =SUMIFS('Master Event Tracker'!$J$8:$J$68, 'Master Event Tracker'!$D$8:$D$68, B13) -> 686 | E13: =SUMIFS('Master Event Tracker'!$L$8:$L$68, 'Master Event Tracker'!$D$8:$D$68, B13) -> 115198 | F13: =IF(C13>0, E13/C13, 0) -> 7199.875 | G13: =IF(D13>0, E13/D13, 0) -> 167.92711 | H13: =E13/$E$16 -> 0.092878917 | J13: Compass | K13: Card | L13: =IF($C$4="All Months", COUNTIFS('Master Event Tracker'!$N$8:$N$68, J13, 'Master Event Tracker'!$O$8:$O$68, K13), COUNTIFS('Master Event Tracker'!$N$8:$N$68, J13, 'Master Event Tracker'!$O$8:$O$68, K13, 'Master Event Tracker'!$D$8:$D$68, $C$4)) -> 13 | M13: =IF($C$4="All Months", SUMIFS('Master Event Tracker'!$J$8:$J$68, 'Master Event Tracker'!$N$8:$N$68, J13, 'Master Event Tracker'!$O$8:$O$68, K13), SUMIFS('Master Event Tracker'!$J$8:$J$68, 'Master Event Tracker'!$N$8:$N$68, J13, 'Master Event Tracker'!$O$8:$O$68, K13, 'Master Event Tracker'!$D$8:$D$68, $C$4)) -> 1200 | N13: =IF($C$4="All Months", SUMIFS('Master Event Tracker'!$L$8:$L$68, 'Master Event Tracker'!$N$8:$N$68, J13, 'Master Event Tracker'!$O$8:$O$68, K13), SUMIFS('Master Event Tracker'!$L$8:$L$68, 'Master Event Tracker'!$N$8:$N$68, J13, 'Master Event Tracker'!$O$8:$O$68, K13, 'Master Event Tracker'!$D$8:$D$68, $C$4)) -> 175250 | O13: =IF($N$18>0, N13/$N$18, 0) -> 0.14129612 | P13: =IF(M13>0, N13/M13, 0) -> 146.04167
B14: July | C14: =COUNTIFS('Master Event Tracker'!$D$8:$D$68, B14) -> 17 | D14: =SUMIFS('Master Event Tracker'!$J$8:$J$68, 'Master Event Tracker'!$D$8:$D$68, B14) -> 1235 | E14: =SUMIFS('Master Event Tracker'!$L$8:$L$68, 'Master Event Tracker'!$D$8:$D$68, B14) -> 192420 | F14: =IF(C14>0, E14/C14, 0) -> 11318.824 | G14: =IF(D14>0, E14/D14, 0) -> 155.80567 | H14: =E14/$E$16 -> 0.15513951 | J14: Compass | K14: Direct | L14: =IF($C$4="All Months", COUNTIFS('Master Event Tracker'!$N$8:$N$68, J14, 'Master Event Tracker'!$O$8:$O$68, K14), COUNTIFS('Master Event Tracker'!$N$8:$N$68, J14, 'Master Event Tracker'!$O$8:$O$68, K14, 'Master Event Tracker'!$D$8:$D$68, $C$4)) -> 1 | M14: =IF($C$4="All Months", SUMIFS('Master Event Tracker'!$J$8:$J$68, 'Master Event Tracker'!$N$8:$N$68, J14, 'Master Event Tracker'!$O$8:$O$68, K14), SUMIFS('Master Event Tracker'!$J$8:$J$68, 'Master Event Tracker'!$N$8:$N$68, J14, 'Master Event Tracker'!$O$8:$O$68, K14, 'Master Event Tracker'!$D$8:$D$68, $C$4)) -> 100 | N14: =IF($C$4="All Months", SUMIFS('Master Event Tracker'!$L$8:$L$68, 'Master Event Tracker'!$N$8:$N$68, J14, 'Master Event Tracker'!$O$8:$O$68, K14), SUMIFS('Master Event Tracker'!$L$8:$L$68, 'Master Event Tracker'!$N$8:$N$68, J14, 'Master Event Tracker'!$O$8:$O$68, K14, 'Master Event Tracker'!$D$8:$D$68, $C$4)) -> 2000 | O14: =IF($N$18>0, N14/$N$18, 0) -> 0.0016125092 | P14: =IF(M14>0, N14/M14, 0) -> 20
B15: August | C15: =COUNTIFS('Master Event Tracker'!$D$8:$D$68, B15) -> 18 | D15: =SUMIFS('Master Event Tracker'!$J$8:$J$68, 'Master Event Tracker'!$D$8:$D$68, B15) -> 3510 | E15: =SUMIFS('Master Event Tracker'!$L$8:$L$68, 'Master Event Tracker'!$D$8:$D$68, B15) -> 289080 | F15: =IF(C15>0, E15/C15, 0) -> 16060 | G15: =IF(D15>0, E15/D15, 0) -> 82.358974 | H15: =E15/$E$16 -> 0.23307208 | J15: Pihu | K15: Card | L15: =IF($C$4="All Months", COUNTIFS('Master Event Tracker'!$N$8:$N$68, J15, 'Master Event Tracker'!$O$8:$O$68, K15), COUNTIFS('Master Event Tracker'!$N$8:$N$68, J15, 'Master Event Tracker'!$O$8:$O$68, K15, 'Master Event Tracker'!$D$8:$D$68, $C$4)) -> 30 | M15: =IF($C$4="All Months", SUMIFS('Master Event Tracker'!$J$8:$J$68, 'Master Event Tracker'!$N$8:$N$68, J15, 'Master Event Tracker'!$O$8:$O$68, K15), SUMIFS('Master Event Tracker'!$J$8:$J$68, 'Master Event Tracker'!$N$8:$N$68, J15, 'Master Event Tracker'!$O$8:$O$68, K15, 'Master Event Tracker'!$D$8:$D$68, $C$4)) -> 2232 | N15: =IF($C$4="All Months", SUMIFS('Master Event Tracker'!$L$8:$L$68, 'Master Event Tracker'!$N$8:$N$68, J15, 'Master Event Tracker'!$O$8:$O$68, K15), SUMIFS('Master Event Tracker'!$L$8:$L$68, 'Master Event Tracker'!$N$8:$N$68, J15, 'Master Event Tracker'!$O$8:$O$68, K15, 'Master Event Tracker'!$D$8:$D$68, $C$4)) -> 177623 | O15: =IF($N$18>0, N15/$N$18, 0) -> 0.14320936 | P15: =IF(M15>0, N15/M15, 0) -> 79.580197
B16: Total / YTD | C16: =SUM(C12:C15) -> 61 | D16: =SUM(D12:D15) -> 8931 | E16: =SUM(E12:E15) -> 1240303 | F16: =IF(C16>0, E16/C16, 0) -> 20332.836 | G16: =IF(D16>0, E16/D16, 0) -> 138.87616 | H16: =SUM(H12:H15) -> 1 | J16: Food Sauda | K16: Direct | L16: =IF($C$4="All Months", COUNTIFS('Master Event Tracker'!$N$8:$N$68, J16, 'Master Event Tracker'!$O$8:$O$68, K16), COUNTIFS('Master Event Tracker'!$N$8:$N$68, J16, 'Master Event Tracker'!$O$8:$O$68, K16, 'Master Event Tracker'!$D$8:$D$68, $C$4)) -> 5 | M16: =IF($C$4="All Months", SUMIFS('Master Event Tracker'!$J$8:$J$68, 'Master Event Tracker'!$N$8:$N$68, J16, 'Master Event Tracker'!$O$8:$O$68, K16), SUMIFS('Master Event Tracker'!$J$8:$J$68, 'Master Event Tracker'!$N$8:$N$68, J16, 'Master Event Tracker'!$O$8:$O$68, K16, 'Master Event Tracker'!$D$8:$D$68, $C$4)) -> 762 | N16: =IF($C$4="All Months", SUMIFS('Master Event Tracker'!$L$8:$L$68, 'Master Event Tracker'!$N$8:$N$68, J16, 'Master Event Tracker'!$O$8:$O$68, K16), SUMIFS('Master Event Tracker'!$L$8:$L$68, 'Master Event Tracker'!$N$8:$N$68, J16, 'Master Event Tracker'!$O$8:$O$68, K16, 'Master Event Tracker'!$D$8:$D$68, $C$4)) -> 80830 | O16: =IF($N$18>0, N16/$N$18, 0) -> 0.065169559 | P16: =IF(M16>0, N16/M16, 0) -> 106.07612
J17: Food Sauda / Pihu | K17: Card | L17: =IF($C$4="All Months", COUNTIFS('Master Event Tracker'!$N$8:$N$68, J17, 'Master Event Tracker'!$O$8:$O$68, K17), COUNTIFS('Master Event Tracker'!$N$8:$N$68, J17, 'Master Event Tracker'!$O$8:$O$68, K17, 'Master Event Tracker'!$D$8:$D$68, $C$4)) -> 2 | M17: =IF($C$4="All Months", SUMIFS('Master Event Tracker'!$J$8:$J$68, 'Master Event Tracker'!$N$8:$N$68, J17, 'Master Event Tracker'!$O$8:$O$68, K17), SUMIFS('Master Event Tracker'!$J$8:$J$68, 'Master Event Tracker'!$N$8:$N$68, J17, 'Master Event Tracker'!$O$8:$O$68, K17, 'Master Event Tracker'!$D$8:$D$68, $C$4)) -> 57 | N17: =IF($C$4="All Months", SUMIFS('Master Event Tracker'!$L$8:$L$68, 'Master Event Tracker'!$N$8:$N$68, J17, 'Master Event Tracker'!$O$8:$O$68, K17), SUMIFS('Master Event Tracker'!$L$8:$L$68, 'Master Event Tracker'!$N$8:$N$68, J17, 'Master Event Tracker'!$O$8:$O$68, K17, 'Master Event Tracker'!$D$8:$D$68, $C$4)) -> 20600 | O17: =IF($N$18>0, N17/$N$18, 0) -> 0.016608845 | P17: =IF(M17>0, N17/M17, 0) -> 361.40351
J18: Total Vendor Spend | K18: All Modes | L18: =SUM(L12:L17) -> 61 | M18: =SUM(M12:M17) -> 8931 | N18: =SUM(N12:N17) -> 1240303 | O18: =SUM(O12:O17) -> 1 | P18: =IF(M18>0, N18/M18, 0) -> 138.87616
B37: TOP REQUESTORS LEADERBOARD | J37: KEY VENUE & SPACE UTILIZATION
B38: Rank | C38: Requestor Name | D38: Events Hosted | E38: Total Attendees (Pax) | F38: Total Spend (₹) | G38: % Share of Spend | H38: Avg Spend / Event | J38: Venue / Space | K38: Building | L38: Floor / Level | M38: Events Hosted | N38: Total Pax | O38: Total Spend (₹) | P38: % Share of Spend
B39: #1 | C39: Prerena | D39: =COUNTIFS('Master Event Tracker'!$F$8:$F$68, C39) -> 1 | E39: =SUMIFS('Master Event Tracker'!$J$8:$J$68, 'Master Event Tracker'!$F$8:$F$68, C39) -> 2100 | F39: =SUMIFS('Master Event Tracker'!$L$8:$L$68, 'Master Event Tracker'!$F$8:$F$68, C39) -> 525000 | G39: =F39/$E$16 -> 0.42328367 | H39: =IF(D39>0, F39/D39, 0) -> 525000 | J39: DT3 | Level 3 | K39: DT3 | L39: Level 3 | M39: =COUNTIFS('Master Event Tracker'!$G$8:$G$68, J39) -> 16 | N39: =SUMIFS('Master Event Tracker'!$J$8:$J$68, 'Master Event Tracker'!$G$8:$G$68, J39) -> 1737 | O39: =SUMIFS('Master Event Tracker'!$L$8:$L$68, 'Master Event Tracker'!$G$8:$G$68, J39) -> 260945 | P39: =O39/$E$16 -> 0.21038811
B40: #2 | C40: Deshraj | D40: =COUNTIFS('Master Event Tracker'!$F$8:$F$68, C40) -> 4 | E40: =SUMIFS('Master Event Tracker'!$J$8:$J$68, 'Master Event Tracker'!$F$8:$F$68, C40) -> 312 | F40: =SUMIFS('Master Event Tracker'!$L$8:$L$68, 'Master Event Tracker'!$F$8:$F$68, C40) -> 114100 | G40: =F40/$E$16 -> 0.09199365 | H40: =IF(D40>0, F40/D40, 0) -> 28525 | J40: DT4 | L1 (Innovation Hub) | K40: DT4 | L40: Level 1 | M40: =COUNTIFS('Master Event Tracker'!$G$8:$G$68, J40) -> 14 | N40: =SUMIFS('Master Event Tracker'!$J$8:$J$68, 'Master Event Tracker'!$G$8:$G$68, J40) -> 752 | O40: =SUMIFS('Master Event Tracker'!$L$8:$L$68, 'Master Event Tracker'!$G$8:$G$68, J40) -> 131588 | P40: =O40/$E$16 -> 0.10609343
B41: #3 | C41: Ekta | D41: =COUNTIFS('Master Event Tracker'!$F$8:$F$68, C41) -> 9 | E41: =SUMIFS('Master Event Tracker'!$J$8:$J$68, 'Master Event Tracker'!$F$8:$F$68, C41) -> 840 | F41: =SUMIFS('Master Event Tracker'!$L$8:$L$68, 'Master Event Tracker'!$F$8:$F$68, C41) -> 105000 | G41: =F41/$E$16 -> 0.084656733 | H41: =IF(D41>0, F41/D41, 0) -> 11666.667 | J41: DT4 | L5 (Hackable Space) | K41: DT4 | L41: Level 5 | M41: =COUNTIFS('Master Event Tracker'!$G$8:$G$68, J41) -> 8 | N41: =SUMIFS('Master Event Tracker'!$J$8:$J$68, 'Master Event Tracker'!$G$8:$G$68, J41) -> 1440 | O41: =SUMIFS('Master Event Tracker'!$L$8:$L$68, 'Master Event Tracker'!$G$8:$G$68, J41) -> 63615 | P41: =O41/$E$16 -> 0.051289886
B42: #4 | C42: Saurabh Dutta | D42: =COUNTIFS('Master Event Tracker'!$F$8:$F$68, C42) -> 2 | E42: =SUMIFS('Master Event Tracker'!$J$8:$J$68, 'Master Event Tracker'!$F$8:$F$68, C42) -> 375 | F42: =SUMIFS('Master Event Tracker'!$L$8:$L$68, 'Master Event Tracker'!$F$8:$F$68, C42) -> 78410 | G42: =F42/$E$16 -> 0.063218423 | H42: =IF(D42>0, F42/D42, 0) -> 39205 | J42: DT4 | Level 1 | K42: DT4 | L42: Level 1 | M42: =COUNTIFS('Master Event Tracker'!$G$8:$G$68, J42) -> 7 | N42: =SUMIFS('Master Event Tracker'!$J$8:$J$68, 'Master Event Tracker'!$G$8:$G$68, J42) -> 524 | O42: =SUMIFS('Master Event Tracker'!$L$8:$L$68, 'Master Event Tracker'!$G$8:$G$68, J42) -> 40370 | P42: =O42/$E$16 -> 0.032548498
B43: #5 | C43: Property Services | D43: =COUNTIFS('Master Event Tracker'!$F$8:$F$68, C43) -> 2 | E43: =SUMIFS('Master Event Tracker'!$J$8:$J$68, 'Master Event Tracker'!$F$8:$F$68, C43) -> 2000 | F43: =SUMIFS('Master Event Tracker'!$L$8:$L$68, 'Master Event Tracker'!$F$8:$F$68, C43) -> 66500 | G43: =F43/$E$16 -> 0.053615931 | H43: =IF(D43>0, F43/D43, 0) -> 33250 | J43: DT4 | Level 5 | K43: DT4 | L43: Level 5 | M43: =COUNTIFS('Master Event Tracker'!$G$8:$G$68, J43) -> 2 | N43: =SUMIFS('Master Event Tracker'!$J$8:$J$68, 'Master Event Tracker'!$G$8:$G$68, J43) -> 311 | O43: =SUMIFS('Master Event Tracker'!$L$8:$L$68, 'Master Event Tracker'!$G$8:$G$68, J43) -> 63040 | P43: =O43/$E$16 -> 0.05082629
B44: #6 | C44: Mary | D44: =COUNTIFS('Master Event Tracker'!$F$8:$F$68, C44) -> 2 | E44: =SUMIFS('Master Event Tracker'!$J$8:$J$68, 'Master Event Tracker'!$F$8:$F$68, C44) -> 70 | F44: =SUMIFS('Master Event Tracker'!$L$8:$L$68, 'Master Event Tracker'!$F$8:$F$68, C44) -> 58000 | G44: =F44/$E$16 -> 0.046762767 | H44: =IF(D44>0, F44/D44, 0) -> 29000 | J44: DT4 | Level 4 | K44: DT4 | L44: Level 4 | M44: =COUNTIFS('Master Event Tracker'!$G$8:$G$68, J44) -> 4 | N44: =SUMIFS('Master Event Tracker'!$J$8:$J$68, 'Master Event Tracker'!$G$8:$G$68, J44) -> 190 | O44: =SUMIFS('Master Event Tracker'!$L$8:$L$68, 'Master Event Tracker'!$G$8:$G$68, J44) -> 30200 | P44: =O44/$E$16 -> 0.024348889
B45: #7 | C45: Vibhor | D45: =COUNTIFS('Master Event Tracker'!$F$8:$F$68, C45) -> 1 | E45: =SUMIFS('Master Event Tracker'!$J$8:$J$68, 'Master Event Tracker'!$F$8:$F$68, C45) -> 95 | F45: =SUMIFS('Master Event Tracker'!$L$8:$L$68, 'Master Event Tracker'!$F$8:$F$68, C45) -> 47500 | G45: =F45/$E$16 -> 0.038297094 | H45: =IF(D45>0, F45/D45, 0) -> 47500 | J45: DT4 | L5 (Cafeteria) | K45: DT4 | L45: Level 5 | M45: =COUNTIFS('Master Event Tracker'!$G$8:$G$68, J45) -> 2 | N45: =SUMIFS('Master Event Tracker'!$J$8:$J$68, 'Master Event Tracker'!$G$8:$G$68, J45) -> 1610 | O45: =SUMIFS('Master Event Tracker'!$L$8:$L$68, 'Master Event Tracker'!$G$8:$G$68, J45) -> 71875 | P45: =O45/$E$16 -> 0.057949549
B46: #8 | C46: Shivani | D46: =COUNTIFS('Master Event Tracker'!$F$8:$F$68, C46) -> 6 | E46: =SUMIFS('Master Event Tracker'!$J$8:$J$68, 'Master Event Tracker'!$F$8:$F$68, C46) -> 268 | F46: =SUMIFS('Master Event Tracker'!$L$8:$L$68, 'Master Event Tracker'!$F$8:$F$68, C46) -> 28030 | G46: =F46/$E$16 -> 0.022599316 | H46: =IF(D46>0, F46/D46, 0) -> 4671.6667 | J46: DT4 | L5 & DT3 | K46: DT4 & DT3 | L46: Multi-Floor | M46: =COUNTIFS('Master Event Tracker'!$G$8:$G$68, J46) -> 1 | N46: =SUMIFS('Master Event Tracker'!$J$8:$J$68, 'Master Event Tracker'!$G$8:$G$68, J46) -> 2100 | O46: =SUMIFS('Master Event Tracker'!$L$8:$L$68, 'Master Event Tracker'!$G$8:$G$68, J46) -> 525000 | P46: =O46/$E$16 -> 0.42328367

Sheet Master Event Tracker
B2: =HYPERLINK("#Executive Dashboard!A1", "📊 Executive Dashboard") -> 📊 Executive Dashboard | D2: =HYPERLINK("#Master Event Tracker!A1", "📋 Master Event Tracker") -> 📋 Master Event Tracker | F2: =HYPERLINK("#Monthly Breakdown!A1", "📅 Monthly Breakdown") -> 📅 Monthly Breakdown | H2: =HYPERLINK("#Venue & Vendor Insights!A1", "🏢 Venue & Vendor Insights") -> 🏢 Venue & Vendor Insights | J2: =HYPERLINK("#Lookups & Settings!A1", "⚙️ Lookups & Settings") -> ⚙️ Lookups & Settings
B4: MASTER EVENT TRACKER & FINANCIAL REPOSITORY
B5: Complete consolidated dataset of 61 corporate events with verified costs, headcount, and vendor splits
B7: Event ID | C7: Ref S.No | D7: Month | E7: Event Date | F7: Requestor | G7: Venue / Space | H7: Building | I7: Floor / Zone | J7: Pax (Attendees) | K7: Base Rate (₹) | L7: Total Amount (₹) | M7: Effective Cost/Pax (₹) | N7: Primary Vendor | O7: Payment Mode | P7: Vendor & Mode (Raw) | Q7: Event Category | R7: Remarks & Notes | S7: Status
B8: EVT-001 | C8: 1 | D8: May | E8: 05-May | F8: Simran Vijay | G8: DT4 | Level 4 | H8: DT4 | I8: Level 4 | J8: 60 | K8: 120 | L8: 7200 | M8: =IF(J8>0, ROUND(L8/J8, 2), K8) -> 120 | N8: Pihu | O8: Card | P8: PIHU/CARD | Q8: Meetings & Refreshments | R8: Boxes Catering | S8: Completed
B9: EVT-002 | C9: 2 | D9: May | E9: 05-May | F9: Saurabh Dutta | G9: DT4 | Level 5 | H9: DT4 | I9: Level 5 | J9: 300 | K9: 207.2 | L9: 62160 | M9: =IF(J9>0, ROUND(L9/J9, 2), K9) -> 207.2 | N9: Pihu | O9: Card | P9: PIHU/CARD | Q9: Meetings & Refreshments | R9: Boxes Catering | S9: Completed
B10: EVT-003 | C10: 3 | D10: May | E10: 13-May | F10: Poonam Gupta | G10: DT4 | L5 (Hackable Space) | H10: DT4 | I10: Level 5 | J10: 450 | K10: 50 | L10: 22500 | M10: =IF(J10>0, ROUND(L10/J10, 2), K10) -> 50 | N10: Pihu | O10: Card | P10: PIHU/CARD | Q10: Meetings & Refreshments | R10: Hackable Space Event Refreshments | S10: Completed
B11: EVT-004 | C11: 4 | D11: May | E11: 19-May | F11: Rupika | G11: DT4 | L5 (Hackable Space) | H11: DT4 | I11: Level 5 | J11: 45 | K11: 35 | L11: 1575 | M11: =IF(J11>0, ROUND(L11/J11, 2), K11) -> 35 | N11: Pihu | O11: Card | P11: PIHU/CARD | Q11: Meetings & Refreshments | R11: Hackable Space Meeting (25*45 + 45*10) | S11: Completed
B12: EVT-005 | C12: 5 | D12: May | E12: 20-May | F12: Blood Donation Drive | G12: DT4 | L5 (Hackable Space) | H12: DT4 | I12: Level 5 | J12: 150 | K12: 28 | L12: 4200 | M12: =IF(J12>0, ROUND(L12/J12, 2), K12) -> 28 | N12: Pihu | O12: Card | P12: PIHU/CARD | Q12: CSR & Health Drive | R12: Blood Donation Drive Refreshments (150*8 + 150*20) | S12: Completed
B13: EVT-006 | C13: 6 | D13: May | E13: 20-May | F13: Khusboo Kaur | G13: DT4 | Level 1 | H13: DT4 | I13: Level 1 | J13: 200 | K13: 20 | L13: 4000 | M13: =IF(J13>0, ROUND(L13/J13, 2), K13) -> 20 | N13: Pihu | O13: Card | P13: PIHU/CARD | Q13: Meetings & Refreshments | R13: Only Tea Service | S13: Completed
B14: EVT-007 | C14: 7 | D14: May | E14: 21-May | F14: Neeraj Panday | G14: DT4 | Level 1 | H14: DT4 | I14: Level 1 | J14: 35 | K14: 84.86 | L14: 2970 | M14: =IF(J14>0, ROUND(L14/J14, 2), K14) -> 84.86 | N14: Pihu | O14: Card | P14: PIHU/CARD | Q14: Leadership & Strategy | R14: Leadership Connect | S14: Completed
B15: EVT-008 | C15: 8 | D15: May | E15: 22-May | F15: Prerena | G15: DT4 | L5 & DT3 | H15: DT4 & DT3 | I15: Multi-Floor | J15: 2100 | K15: 250 | L15: 525000 | M15: =IF(J15>0, ROUND(L15/J15, 2), K15) -> 250 | N15: Compass | O15: PO | P15: COMPASS/PO | Q15: Townhall & All-Hands | R15: Major All-Hands: 1500 at DT4 and 600 at DT3 | S15: Completed
B16: EVT-009 | C16: 9 | D16: May | E16: 25-May | F16: Kirti | G16: DT4 | Level 1 | H16: DT4 | I16: Level 1 | J16: 100 | K16: 20 | L16: 2000 | M16: =IF(J16>0, ROUND(L16/J16, 2), K16) -> 20 | N16: Compass | O16: Direct | P16: COMPASS | Q16: Meetings & Refreshments | R16: Potluck, Only Tea | S16: Completed
B17: EVT-010 | C17: 10 | D17: May | E17: 28-May | F17: Shivani | G17: DT4 | Level 1 | H17: DT4 | I17: Level 1 | J17: 60 | K17: 200 | L17: 12000 | M17: =IF(J17>0, ROUND(L17/J17, 2), K17) -> 200 | N17: Compass | O17: PO | P17: COMPASS/PO | Q17: Leadership & Strategy | R17: XLT Meeting | S17: Completed
B18: EVT-011 | C18: 11 | D18: June | E18: 05-Jun | F18: Poonam | G18: DT4 | Level 5 | H18: DT4 | I18: Level 5 | J18: 11 | K18: 80 | L18: 880 | M18: =IF(J18>0, ROUND(L18/J18, 2), K18) -> 80 | N18: Pihu | O18: Card | P18: PIHU/CARD | Q18: Meetings & Refreshments | R18: Team Meeting Refreshments (11*20 + 11*60) | S18: Completed
B19: EVT-012 | C19: 12 | D19: June | E19: 05-Jun | F19: Shivani | G19: DT4 | Level 1 | H19: DT4 | I19: Level 1 | J19: 24 | K19: 100 | L19: 2400 | M19: =IF(J19>0, ROUND(L19/J19, 2), K19) -> 100 | N19: Pihu | O19: Card | P19: PIHU/CARD | Q19: Induction & Training | R19: Master Class Session (24*20 + 24*60 + 24*20) | S19: Completed
... B68: EVT-061 | C68: 61 | D68: August | E68: 24-Aug | F68: Deshraj | G68: DT4 | L1 (Innovation Hub) | H68: DT4 | I68: Level 1 | J68: 85 | K68: 100 | L68: 8500 | M68: =IF(J68>0, ROUND(L68/J68, 2), K68) -> 100 | N68: Compass | O68: Card | P68: COMPASS/CARD | Q68: Induction & Training | R68: New Joiners Induction | S68: Completed
D69: September
B71: TOTAL | C71: =COUNTA(B8:B68) & " Events" -> 61 Events | J71: =SUM(J8:J68) -> 8931 | K71: =AVERAGE(K8:K68) -> 165.75721 | L71: =SUM(L8:L68) -> 1240303 | M71: =IF(J71>0, L71/J71, 0) -> 138.87616

Sheet Monthly Breakdown
B2: =HYPERLINK("#Executive Dashboard!A1", "📊 Executive Dashboard") -> 📊 Executive Dashboard | D2: =HYPERLINK("#Master Event Tracker!A1", "📋 Master Event Tracker") -> 📋 Master Event Tracker | F2: =HYPERLINK("#Monthly Breakdown!A1", "📅 Monthly Breakdown") -> 📅 Monthly Breakdown | H2: =HYPERLINK("#Venue & Vendor Insights!A1", "🏢 Venue & Vendor Insights") -> 🏢 Venue & Vendor Insights | J2: =HYPERLINK("#Lookups & Settings!A1", "⚙️ Lookups & Settings") -> ⚙️ Lookups & Settings
B4: MONTH-OVER-MONTH STRATEGIC EVENT BREAKDOWN
B5: Granular event-level audit and comparative financial performance across May, June, July, and August
B7: MONTH-OVER-MONTH EXECUTIVE SUMMARY
B8: Month | C8: Events | D8: Total Pax | E8: Total Spend (₹) | F8: Avg Spend/Event | G8: Avg Cost/Pax | H8: % Spend | I8: MoM Spend Growth | J8: MoM Pax Growth
B9: May | C9: =COUNTIFS('Master Event Tracker'!$D$8:$D$68, B9) -> 10 | D9: =SUMIFS('Master Event Tracker'!$J$8:$J$68, 'Master Event Tracker'!$D$8:$D$68, B9) -> 3500 | E9: =SUMIFS('Master Event Tracker'!$L$8:$L$68, 'Master Event Tracker'!$D$8:$D$68, B9) -> 643605 | F9: =IF(C9>0, E9/C9, 0) -> 64360.5 | G9: =IF(D9>0, E9/D9, 0) -> 183.88714 | H9: =E9/$E$13 -> 0.51890949 | I9: - | J9: -
B10: June | C10: =COUNTIFS('Master Event Tracker'!$D$8:$D$68, B10) -> 16 | D10: =SUMIFS('Master Event Tracker'!$J$8:$J$68, 'Master Event Tracker'!$D$8:$D$68, B10) -> 686 | E10: =SUMIFS('Master Event Tracker'!$L$8:$L$68, 'Master Event Tracker'!$D$8:$D$68, B10) -> 115198 | F10: =IF(C10>0, E10/C10, 0) -> 7199.875 | G10: =IF(D10>0, E10/D10, 0) -> 167.92711 | H10: =E10/$E$13 -> 0.092878917 | I10: =(E10-E9)/E9 -> -0.82101133 | J10: =(D10-D9)/D9 -> -0.804
B11: July | C11: =COUNTIFS('Master Event Tracker'!$D$8:$D$68, B11) -> 17 | D11: =SUMIFS('Master Event Tracker'!$J$8:$J$68, 'Master Event Tracker'!$D$8:$D$68, B11) -> 1235 | E11: =SUMIFS('Master Event Tracker'!$L$8:$L$68, 'Master Event Tracker'!$D$8:$D$68, B11) -> 192420 | F11: =IF(C11>0, E11/C11, 0) -> 11318.824 | G11: =IF(D11>0, E11/D11, 0) -> 155.80567 | H11: =E11/$E$13 -> 0.15513951 | I11: =(E11-E10)/E10 -> 0.6703415 | J11: =(D11-D10)/D10 -> 0.80029155
B12: August | C12: =COUNTIFS('Master Event Tracker'!$D$8:$D$68, B12) -> 18 | D12: =SUMIFS('Master Event Tracker'!$J$8:$J$68, 'Master Event Tracker'!$D$8:$D$68, B12) -> 3510 | E12: =SUMIFS('Master Event Tracker'!$L$8:$L$68, 'Master Event Tracker'!$D$8:$D$68, B12) -> 289080 | F12: =IF(C12>0, E12/C12, 0) -> 16060 | G12: =IF(D12>0, E12/D12, 0) -> 82.358974 | H12: =E12/$E$13 -> 0.23307208 | I12: =(E12-E11)/E11 -> 0.50233863 | J12: =(D12-D11)/D11 -> 1.8421053
B13: Total / YTD | C13: =SUM(C9:C12) -> 61 | D13: =SUM(D9:D12) -> 8931 | E13: =SUM(E9:E12) -> 1240303 | F13: =IF(C13>0, E13/C13, 0) -> 20332.836 | G13: =IF(D13>0, E13/D13, 0) -> 138.87616 | H13: =SUM(H9:H12) -> 1 | I13: - | J13: -
B16: 🌺 MAY 2026 EVENT LOG & AUDIT
B17: 10 Completed Events | Total Spend: ₹643,605 | Key Event: Prerena All-Hands (2,100 Pax)
B18: Event ID | C18: Date | D18: Requestor | E18: Venue / Location | F18: Building | G18: Pax | H18: Base Rate | I18: Total Spend (₹) | J18: Cost/Pax (₹) | K18: Vendor | L18: Mode | M18: Event Category | N18: Remarks
B19: EVT-001 | C19: 05-May | D19: Simran Vijay | E19: DT4 | Level 4 | F19: DT4 | G19: 60 | H19: 120 | I19: 7200 | J19: =IF(G19>0, I19/G19, H19) -> 120 | K19: Pihu | L19: Card | M19: Meetings & Refreshments | N19: Boxes Catering
B20: EVT-002 | C20: 05-May | D20: Saurabh Dutta | E20: DT4 | Level 5 | F20: DT4 | G20: 300 | H20: 207.2 | I20: 62160 | J20: =IF(G20>0, I20/G20, H20) -> 207.2 | K20: Pihu | L20: Card | M20: Meetings & Refreshments | N20: Boxes Catering
B21: EVT-003 | C21: 13-May | D21: Poonam Gupta | E21: DT4 | L5 (Hackable Space) | F21: DT4 | G21: 450 | H21: 50 | I21: 22500 | J21: =IF(G21>0, I21/G21, H21) -> 50 | K21: Pihu | L21: Card | M21: Meetings & Refreshments | N21: Hackable Space Event Refreshments
B22: EVT-004 | C22: 19-May | D22: Rupika | E22: DT4 | L5 (Hackable Space) | F22: DT4 | G22: 45 | H22: 35 | I22: 1575 | J22: =IF(G22>0, I22/G22, H22) -> 35 | K22: Pihu | L22: Card | M22: Meetings & Refreshments | N22: Hackable Space Meeting (25*45 + 45*10)
B23: EVT-005 | C23: 20-May | D23: Blood Donation Drive | E23: DT4 | L5 (Hackable Space) | F23: DT4 | G23: 150 | H23: 28 | I23: 4200 | J23: =IF(G23>0, I23/G23, H23) -> 28 | K23: Pihu | L23: Card | M23: CSR & Health Drive | N23: Blood Donation Drive Refreshments (150*8 + 150*20)
B24: EVT-006 | C24: 20-May | D24: Khusboo Kaur | E24: DT4 | Level 1 | F24: DT4 | G24: 200 | H24: 20 | I24: 4000 | J24: =IF(G24>0, I24/G24, H24) -> 20 | K24: Pihu | L24: Card | M24: Meetings & Refreshments | N24: Only Tea Service
B25: EVT-007 | C25: 21-May | D25: Neeraj Panday | E25: DT4 | Level 1 | F25: DT4 | G25: 35 | H25: 84.86 | I25: 2970 | J25: =IF(G25>0, I25/G25, H25) -> 84.857143 | K25: Pihu | L25: Card | M25: Leadership & Strategy | N25: Leadership Connect
B26: EVT-008 | C26: 22-May | D26: Prerena | E26: DT4 | L5 & DT3 | F26: DT4 & DT3 | G26: 2100 | H26: 250 | I26: 525000 | J26: =IF(G26>0, I26/G26, H26) -> 250 | K26: Compass | L26: PO | M26: Townhall & All-Hands | N26: Major All-Hands: 1500 at DT4 and 600 at DT3
B27: EVT-009 | C27: 25-May | D27: Kirti | E27: DT4 | Level 1 | F27: DT4 | G27: 100 | H27: 20 | I27: 2000 | J27: =IF(G27>0, I27/G27, H27) -> 20 | K27: Compass | L27: Direct | M27: Meetings & Refreshments | N27: Potluck, Only Tea
B28: EVT-010 | C28: 28-May | D28: Shivani | E28: DT4 | Level 1 | F28: DT4 | G28: 60 | H28: 200 | I28: 12000 | J28: =IF(G28>0, I28/G28, H28) -> 200 | K28: Compass | L28: PO | M28: Leadership & Strategy | N28: XLT Meeting
B29: May Total | C29: 10 Events | G29: =SUM(G19:G28) -> 3500 | H29: =AVERAGE(H19:H28) -> 101.506 | I29: =SUM(I19:I28) -> 643605 | J29: =IF(G29>0, I29/G29, 0) -> 183.88714
B32: ☀️ JUNE 2026 EVENT LOG & AUDIT
B33: 16 Completed Events | Total Spend: ₹115,198 | Focus: Innovation Hub & Department Townhalls
B34: Event ID | C34: Date | D34: Requestor | E34: Venue / Location | F34: Building | G34: Pax | H34: Base Rate | I34: Total Spend (₹) | J34: Cost/Pax (₹) | K34: Vendor | L34: Mode | M34: Event Category | N34: Remarks
B35: EVT-011 | C35: 05-Jun | D35: Poonam | E35: DT4 | Level 5 | F35: DT4 | G35: 11 | H35: 80 | I35: 880 | J35: =IF(G35>0, I35/G35, H35) -> 80 | K35: Pihu | L35: Card | M35: Meetings & Refreshments | N35: Team Meeting Refreshments (11*20 + 11*60)
B36: EVT-012 | C36: 05-Jun | D36: Shivani | E36: DT4 | Level 1 | F36: DT4 | G36: 24 | H36: 100 | I36: 2400 | J36: =IF(G36>0, I36/G36, H36) -> 100 | K36: Pihu | L36: Card | M36: Induction & Training | N36: Master Class Session (24*20 + 24*60 + 24*20)
B37: EVT-013 | C37: 08-Jun | D37: Rupika | E37: DT4 | Level 1 | F37: DT4 | G37: 30 | H37: 25 | I37: 750 | J37: =IF(G37>0, I37/G37, H37) -> 25 | K37: Pihu | L37: Card | M37: Meetings & Refreshments | N37: Team Refreshments (30*25)
B38: EVT-014 | C38: 09-Jun | D38: Shikha | E38: DT4 | D410 (L5) | F38: DT4 | G38: 10 | H38: 215 | I38: 2150 | J38: =IF(G38>0, I38/G38, H38) -> 215 | K38: Pihu | L38: Card | M38: Celebrations & Engagement | N38: Milestone Celebration
B39: EVT-015 | C39: 11-Jun | D39: Kanchan Walia | E39: DT4 | L1 (Innovation Hub) | F39: DT4 | G39: 17 | H39: 121.65 | I39: 2068 | J39: =IF(G39>0, I39/G39, H39) -> 121.64706 | K39: Pihu | L39: Card | M39: Meetings & Refreshments | N39: Innovation Hub Session
B40: EVT-016 | C40: 12-Jun | D40: Deepika | E40: DT4 | L1 (Innovation Hub) | F40: DT4 | G40: 28 | H40: 127.5 | I40: 3570 | J40: =IF(G40>0, I40/G40, H40) -> 127.5 | K40: Pihu | L40: Card | M40: Meetings & Refreshments | N40: Innovation Hub Workshop Refreshments
B41: EVT-017 | C41: 16-Jun | D41: Ekta | E41: DT4 | L1 (Innovation Hub) | F41: DT4 | G41: 100 | H41: 150 | I41: 15000 | J41: =IF(G41>0, I41/G41, H41) -> 150 | K41: Pihu | L41: Card | M41: Townhall & All-Hands | N41: Team Gathering - Innovation Hub
B42: EVT-018 | C42: 16-Jun | D42: Hitesh | E42: DT4 | L1 (Innovation Hub) | F42: DT4 | G42: 12 | H42: 250 | I42: 3000 | J42: =IF(G42>0, I42/G42, H42) -> 250 | K42: Pihu | L42: Card | M42: Leadership & Strategy | N42: Tenant Meeting
B43: EVT-019 | C43: 17-Jun | D43: Shivani | E43: DT4 | L5 (C305) | F43: DT4 | G43: 14 | H43: 45 | I43: 630 | J43: =IF(G43>0, I43/G43, H43) -> 45 | K43: Pihu | L43: Card | M43: Meetings & Refreshments | N43: Team Refreshments
B44: EVT-020 | C44: 18-Jun | D44: Mayank | E44: DT4 | Level 6 | F44: DT4 | G44: 35 | H44: 100 | I44: 3500 | J44: =IF(G44>0, I44/G44, H44) -> 100 | K44: Pihu | L44: Card | M44: Leadership & Strategy | N44: Evening Tea with Risk Executives
B45: EVT-021 | C45: 18-Jun | D45: Shikha | E45: DT4 | Zone B | F45: DT4 | G45: 80 | H45: 300 | I45: 24000 | J45: =IF(G45>0, I45/G45, H45) -> 300 | K45: Compass | L45: PO | M45: Townhall & All-Hands | N45: Townhall
B46: EVT-022 | C46: 23-Jun | D46: Ekta | E46: DT4 | Level 4 | F46: DT4 | G46: 50 | H46: 150 | I46: 7500 | J46: =IF(G46>0, I46/G46, H46) -> 150 | K46: Compass | L46: Card | M46: Meetings & Refreshments | N46: Floor Level Event
... B50: EVT-026 | C50: 30-Jun | D50: Ekta | E50: DT3 | Level 3 | F50: DT3 | G50: 120 | H50: 150 | I50: 18000 | J50: =IF(G50>0, I50/G50, H50) -> 150 | K50: Compass | L50: Card | M50: Townhall & All-Hands | N50: Townhall
...

Sheet Venue & Vendor Insights
B2: =HYPERLINK("#Executive Dashboard!A1", "📊 Executive Dashboard") -> 📊 Executive Dashboard | D2: =HYPERLINK("#Master Event Tracker!A1", "📋 Master Event Tracker") -> 📋 Master Event Tracker | F2: =HYPERLINK("#Monthly Breakdown!A1", "📅 Monthly Breakdown") -> 📅 Monthly Breakdown | H2: =HYPERLINK("#Venue & Vendor Insights!A1", "🏢 Venue & Vendor Insights") -> 🏢 Venue & Vendor Insights | J2: =HYPERLINK("#Lookups & Settings!A1", "⚙️ Lookups & Settings") -> ⚙️ Lookups & Settings
B4: STRATEGIC VENUE, VENDOR & PURPOSE ANALYTICS
B5: Commercial contract distribution, facilities footprint utilization, and corporate event categorization
B7: 1. VENDOR CONTRACT & COMMERCIAL ANALYSIS
B8: Vendor Name | C8: Payment Mode | D8: Events Hosted | E8: Total Pax | F8: Total Spend (₹) | G8: % of Budget | H8: Avg Cost / Pax (₹) | I8: Primary Use Case
B9: Compass | C9: PO | D9: =COUNTIFS('Master Event Tracker'!$N$8:$N$68, B9, 'Master Event Tracker'!$O$8:$O$68, C9) -> 10 | E9: =SUMIFS('Master Event Tracker'!$J$8:$J$68, 'Master Event Tracker'!$N$8:$N$68, B9, 'Master Event Tracker'!$O$8:$O$68, C9) -> 4580 | F9: =SUMIFS('Master Event Tracker'!$L$8:$L$68, 'Master Event Tracker'!$N$8:$N$68, B9, 'Master Event Tracker'!$O$8:$O$68, C9) -> 784000 | G9: =F9/$F$15 -> 0.63210361 | H9: =IF(E9>0, F9/E9, 0) -> 171.17904 | I9: Townhalls, Large Buffets, Induction Catering
B10: Compass | C10: Card | D10: =COUNTIFS('Master Event Tracker'!$N$8:$N$68, B10, 'Master Event Tracker'!$O$8:$O$68, C10) -> 13 | E10: =SUMIFS('Master Event Tracker'!$J$8:$J$68, 'Master Event Tracker'!$N$8:$N$68, B10, 'Master Event Tracker'!$O$8:$O$68, C10) -> 1200 | F10: =SUMIFS('Master Event Tracker'!$L$8:$L$68, 'Master Event Tracker'!$N$8:$N$68, B10, 'Master Event Tracker'!$O$8:$O$68, C10) -> 175250 | G10: =F10/$F$15 -> 0.14129612 | H10: =IF(E10>0, F10/E10, 0) -> 146.04167 | I10: Mid-size Townhalls & Team Lunches
B11: Compass | C11: Direct | D11: =COUNTIFS('Master Event Tracker'!$N$8:$N$68, B11, 'Master Event Tracker'!$O$8:$O$68, C11) -> 1 | E11: =SUMIFS('Master Event Tracker'!$J$8:$J$68, 'Master Event Tracker'!$N$8:$N$68, B11, 'Master Event Tracker'!$O$8:$O$68, C11) -> 100 | F11: =SUMIFS('Master Event Tracker'!$L$8:$L$68, 'Master Event Tracker'!$N$8:$N$68, B11, 'Master Event Tracker'!$O$8:$O$68, C11) -> 2000 | G11: =F11/$F$15 -> 0.0016125092 | H11: =IF(E11>0, F11/E11, 0) -> 20 | I11: Tea/Coffee & Direct Refreshments
B12: Pihu | C12: Card | D12: =COUNTIFS('Master Event Tracker'!$N$8:$N$68, B12, 'Master Event Tracker'!$O$8:$O$68, C12) -> 30 | E12: =SUMIFS('Master Event Tracker'!$J$8:$J$68, 'Master Event Tracker'!$N$8:$N$68, B12, 'Master Event Tracker'!$O$8:$O$68, C12) -> 2232 | F12: =SUMIFS('Master Event Tracker'!$L$8:$L$68, 'Master Event Tracker'!$N$8:$N$68, B12, 'Master Event Tracker'!$O$8:$O$68, C12) -> 177623 | G12: =F12/$F$15 -> 0.14320936 | H12: =IF(E12>0, F12/E12, 0) -> 79.580197 | I12: High-frequency Snack Boxes, Tea & Executive Connects
B13: Food Sauda | C13: Direct | D13: =COUNTIFS('Master Event Tracker'!$N$8:$N$68, B13, 'Master Event Tracker'!$O$8:$O$68, C13) -> 5 | E13: =SUMIFS('Master Event Tracker'!$J$8:$J$68, 'Master Event Tracker'!$N$8:$N$68, B13, 'Master Event Tracker'!$O$8:$O$68, C13) -> 762 | F13: =SUMIFS('Master Event Tracker'!$L$8:$L$68, 'Master Event Tracker'!$N$8:$N$68, B13, 'Master Event Tracker'!$O$8:$O$68, C13) -> 80830 | G13: =F13/$F$15 -> 0.065169559 | H13: =IF(E13>0, F13/E13, 0) -> 106.07612 | I13: Special Workshops & Leadership Buffets
B14: Food Sauda / Pihu | C14: Card | D14: =COUNTIFS('Master Event Tracker'!$N$8:$N$68, B14, 'Master Event Tracker'!$O$8:$O$68, C14) -> 2 | E14: =SUMIFS('Master Event Tracker'!$J$8:$J$68, 'Master Event Tracker'!$N$8:$N$68, B14, 'Master Event Tracker'!$O$8:$O$68, C14) -> 57 | F14: =SUMIFS('Master Event Tracker'!$L$8:$L$68, 'Master Event Tracker'!$N$8:$N$68, B14, 'Master Event Tracker'!$O$8:$O$68, C14) -> 20600 | G14: =F14/$F$15 -> 0.016608845 | H14: =IF(E14>0, F14/E14, 0) -> 361.40351 | I14: Multi-vendor Distinctive Leadership Programmes
B15: Total Vendor Spend | C15: All Modes | D15: =SUM(D9:D14) -> 61 | E15: =SUM(E9:E14) -> 8931 | F15: =SUM(F9:F14) -> 1240303 | G15: =SUM(G9:G14) -> 1 | H15: =IF(E15>0, F15/E15, 0) -> 138.87616 | I15: Full Consolidated Portfolio
B17: 2. REAL ESTATE & VENUE FOOTPRINT UTILIZATION
B18: Venue / Space | C18: Building | D18: Floor / Area | E18: Events Hosted | F18: Total Pax | G18: Total Spend (₹) | H18: % of Total Spend | I18: Avg Spend / Event (₹) | J18: Primary Facility Purpose
B19: DT3 | Level 3 | C19: DT3 | D19: Level 3 | E19: =COUNTIFS('Master Event Tracker'!$G$8:$G$68, B19) -> 16 | F19: =SUMIFS('Master Event Tracker'!$J$8:$J$68, 'Master Event Tracker'!$G$8:$G$68, B19) -> 1737 | G19: =SUMIFS('Master Event Tracker'!$L$8:$L$68, 'Master Event Tracker'!$G$8:$G$68, B19) -> 260945 | H19: =G19/$G$34 -> 0.21038811 | I19: =IF(E19>0, G19/E19, 0) -> 16309.062 | J19: Large Townhalls, Hiring Drives & Inductions
B20: DT4 | L1 (Innovation Hub) | C20: DT4 | D20: Level 1 | E20: =COUNTIFS('Master Event Tracker'!$G$8:$G$68, B20) -> 14 | F20: =SUMIFS('Master Event Tracker'!$J$8:$J$68, 'Master Event Tracker'!$G$8:$G$68, B20) -> 752 | G20: =SUMIFS('Master Event Tracker'!$L$8:$L$68, 'Master Event Tracker'!$G$8:$G$68, B20) -> 131588 | H20: =G20/$G$34 -> 0.10609343 | I20: =IF(E20>0, G20/E20, 0) -> 9399.1429 | J20: Innovation Sessions, Partner Celebrations & Townhalls
B21: DT4 | Level 1 | C21: DT4 | D21: Level 1 | E21: =COUNTIFS('Master Event Tracker'!$G$8:$G$68, B21) -> 7 | F21: =SUMIFS('Master Event Tracker'!$J$8:$J$68, 'Master Event Tracker'!$G$8:$G$68, B21) -> 524 | G21: =SUMIFS('Master Event Tracker'!$L$8:$L$68, 'Master Event Tracker'!$G$8:$G$68, B21) -> 40370 | H21: =G21/$G$34 -> 0.032548498 | I21: =IF(E21>0, G21/E21, 0) -> 5767.1429 | J21: Leadership Connects, Meetings & Tea Services
B22: DT4 | Level 4 | C22: DT4 | D22: Level 4 | E22: =COUNTIFS('Master Event Tracker'!$G$8:$G$68, B22) -> 4 | F22: =SUMIFS('Master Event Tracker'!$J$8:$J$68, 'Master Event Tracker'!$G$8:$G$68, B22) -> 190 | G22: =SUMIFS('Master Event Tracker'!$L$8:$L$68, 'Master Event Tracker'!$G$8:$G$68, B22) -> 30200 | H22: =G22/$G$34 -> 0.024348889 | I22: =IF(E22>0, G22/E22, 0) -> 7550 | J22: Floor Gatherings, GS Townhalls & Leadership Lunches
B23: DT4 | Level 5 | C23: DT4 | D23: Level 5 | E23: =COUNTIFS('Master Event Tracker'!$G$8:$G$68, B23) -> 2 | F23: =SUMIFS('Master Event Tracker'!$J$8:$J$68, 'Master Event Tracker'!$G$8:$G$68, B23) -> 311 | G23: =SUMIFS('Master Event Tracker'!$L$8:$L$68, 'Master Event Tracker'!$G$8:$G$68, B23) -> 63040 | H23: =G23/$G$34 -> 0.05082629 | I23: =IF(E23>0, G23/E23, 0) -> 31520 | J23: Box Catering & Team Refreshments
B24: DT4 | L5 (Hackable Space) | C24: DT4 | D24: Level 5 | E24: =COUNTIFS('Master Event Tracker'!$G$8:$G$68, B24) -> 8 | F24: =SUMIFS('Master Event Tracker'!$J$8:$J$68, 'Master Event Tracker'!$G$8:$G$68, B24) -> 1440 | G24: =SUMIFS('Master Event Tracker'!$L$8:$L$68, 'Master Event Tracker'!$G$8:$G$68, B24) -> 63615 | H24: =G24/$G$34 -> 0.051289886 | I24: =IF(E24>0, G24/E24, 0) -> 7951.875 | J24: Flexible Collaboration, Leadership Training & Drives
B25: DT4 | L5 (Cafeteria) | C25: DT4 | D25: Level 5 | E25: =COUNTIFS('Master Event Tracker'!$G$8:$G$68, B25) -> 2 | F25: =SUMIFS('Master Event Tracker'!$J$8:$J$68, 'Master Event Tracker'!$G$8:$G$68, B25) -> 1610 | G25: =SUMIFS('Master Event Tracker'!$L$8:$L$68, 'Master Event Tracker'!$G$8:$G$68, B25) -> 71875 | H25: =G25/$G$34 -> 0.057949549 | I25: =IF(E25>0, G25/E25, 0) -> 35937.5 | J25: Major Celebrations & Large Capacity Townhalls
B26: DT4 | Level 6 | C26: DT4 | D26: Level 6 | E26: =COUNTIFS('Master Event Tracker'!$G$8:$G$68, B26) -> 1 | F26: =SUMIFS('Master Event Tracker'!$J$8:$J$68, 'Master Event Tracker'!$G$8:$G$68, B26) -> 35 | G26: =SUMIFS('Master Event Tracker'!$L$8:$L$68, 'Master Event Tracker'!$G$8:$G$68, B26) -> 3500 | H26: =G26/$G$34 -> 0.0028218911 | I26: =IF(E26>0, G26/E26, 0) -> 3500 | J26: Executive Sessions & Risk Connects
B27: DT4 | L4 (Zone E) | C27: DT4 | D27: Level 4 | E27: =COUNTIFS('Master Event Tracker'!$G$8:$G$68, B27) -> 1 | F27: =SUMIFS('Master Event Tracker'!$J$8:$J$68, 'Master Event Tracker'!$G$8:$G$68, B27) -> 100 | G27: =SUMIFS('Master Event Tracker'!$L$8:$L$68, 'Master Event Tracker'!$G$8:$G$68, B27) -> 15000 | H27: =G27/$G$34 -> 0.012093819 | I27: =IF(E27>0, G27/E27, 0) -> 15000 | J27: CET All-Hands
B28: DT4 | L5 (Zone E) | C28: DT4 | D28: Level 5 | E28: =COUNTIFS('Master Event Tracker'!$G$8:$G$68, B28) -> 1 | F28: =SUMIFS('Master Event Tracker'!$J$8:$J$68, 'Master Event Tracker'!$G$8:$G$68, B28) -> 22 | G28: =SUMIFS('Master Event Tracker'!$L$8:$L$68, 'Master Event Tracker'!$G$8:$G$68, B28) -> 7190 | H28: =G28/$G$34 -> 0.0057969706 | I28: =IF(E28>0, G28/E28, 0) -> 7190 | J28: Team Socials & Friends Meets
B29: DT4 | L6 (Zone E) | C29: DT4 | D29: Level 6 | E29: =COUNTIFS('Master Event Tracker'!$G$8:$G$68, B29) -> 1 | F29: =SUMIFS('Master Event Tracker'!$J$8:$J$68, 'Master Event Tracker'!$G$8:$G$68, B29) -> 6 | G29: =SUMIFS('Master Event Tracker'!$L$8:$L$68, 'Master Event Tracker'!$G$8:$G$68, B29) -> 1200 | H29: =G29/$G$34 -> 0.00096750552 | I29: =IF(E29>0, G29/E29, 0) -> 1200 | J29: Compliance Townhalls
B30: DT4 | Zone B | C30: DT4 | D30: Zone B | E30: =COUNTIFS('Master Event Tracker'!$G$8:$G$68, B30) -> 1 | F30: =SUMIFS('Master Event Tracker'!$J$8:$J$68, 'Master Event Tracker'!$G$8:$G$68, B30) -> 80 | G30: =SUMIFS('Master Event Tracker'!$L$8:$L$68, 'Master Event Tracker'!$G$8:$G$68, B30) -> 24000 | H30: =G30/$G$34 -> 0.01935011 | I30: =IF(E30>0, G30/E30, 0) -> 24000 | J30: Large Townhall Buffets
... B33: DT4 | L5 & DT3 | C33: DT4 & DT3 | D33: Multi-Floor | E33: =COUNTIFS('Master Event Tracker'!$G$8:$G$68, B33) -> 1 | F33: =SUMIFS('Master Event Tracker'!$J$8:$J$68, 'Master Event Tracker'!$G$8:$G$68, B33) -> 2100 | G33: =SUMIFS('Master Event Tracker'!$L$8:$L$68, 'Master Event Tracker'!$G$8:$G$68, B33) -> 525000 | H33: =G33/$G$34 -> 0.42328367 | I33: =IF(E33>0, G33/E33, 0) -> 525000 | J33: Company-wide All-Hands Simultaneous Catering
B34: Total Real Estate Footprint | C34: DT4 & DT3 | D34: All Floors | E34: =SUM(E19:E33) -> 61 | F34: =SUM(F19:F33) -> 8931 | G34: =SUM(G19:G33) -> 1240303 | H34: =SUM(H19:H33) -> 1 | I34: =IF(E34>0, G34/E34, 0) -> 20332.836 | J34: Complete Facilities Portfolio
B36: 3. EVENT PURPOSE & CATEGORY BREAKDOWN
B37: Event Category | C37: Events Hosted | D37: Total Pax | E37: Total Spend (₹) | F37: % Share of Spend | G37: Avg Cost / Pax (₹) | H37: Budget Impact Rating
B38: Townhall & All-Hands | C38: =COUNTIFS('Master Event Tracker'!$Q$8:$Q$68, B38) -> 15 | D38: =SUMIFS('Master Event Tracker'!$J$8:$J$68, 'Master Event Tracker'!$Q$8:$Q$68, B38) -> 3376 | E38: =SUMIFS('Master Event Tracker'!$L$8:$L$68, 'Master Event Tracker'!$Q$8:$Q$68, B38) -> 720900 | F38: =E38/$E$46 -> 0.58122894 | G38: =IF(D38>0, E38/D38, 0) -> 213.53673 | H38: High Impact (Major Spend)
B39: Leadership & Strategy | C39: =COUNTIFS('Master Event Tracker'!$Q$8:$Q$68, B39) -> 15 | D39: =SUMIFS('Master Event Tracker'!$J$8:$J$68, 'Master Event Tracker'!$Q$8:$Q$68, B39) -> 1179 | E39: =SUMIFS('Master Event Tracker'!$L$8:$L$68, 'Master Event Tracker'!$Q$8:$Q$68, B39) -> 186710 | F39: =E39/$E$46 -> 0.1505358 | G39: =IF(D39>0, E39/D39, 0) -> 158.36302 | H39: High Impact (Executive Focus)
B40: Induction & Training | C40: =COUNTIFS('Master Event Tracker'!$Q$8:$Q$68, B40) -> 4 | D40: =SUMIFS('Master Event Tracker'!$J$8:$J$68, 'Master Event Tracker'!$Q$8:$Q$68, B40) -> 329 | E40: =SUMIFS('Master Event Tracker'!$L$8:$L$68, 'Master Event Tracker'!$Q$8:$Q$68, B40) -> 102300 | F40: =E40/$E$46 -> 0.082479846 | G40: =IF(D40>0, E40/D40, 0) -> 310.94225 | H40: Medium Impact (Strategic Growth)
B41: Celebrations & Engagement | C41: =COUNTIFS('Master Event Tracker'!$Q$8:$Q$68, B41) -> 5 | D41: =SUMIFS('Master Event Tracker'!$J$8:$J$68, 'Master Event Tracker'!$Q$8:$Q$68, B41) -> 2082 | E41: =SUMIFS('Master Event Tracker'!$L$8:$L$68, 'Master Event Tracker'!$Q$8:$Q$68, B41) -> 76840 | F41: =E41/$E$46 -> 0.061952604 | G41: =IF(D41>0, E41/D41, 0) -> 36.90682 | H41: Medium Impact (Cultural)
B42: Meetings & Refreshments | C42: =COUNTIFS('Master Event Tracker'!$Q$8:$Q$68, B42) -> 18 | D42: =SUMIFS('Master Event Tracker'!$J$8:$J$68, 'Master Event Tracker'!$Q$8:$Q$68, B42) -> 1595 | E42: =SUMIFS('Master Event Tracker'!$L$8:$L$68, 'Master Event Tracker'!$Q$8:$Q$68, B42) -> 136353 | F42: =E42/$E$46 -> 0.10993523 | G42: =IF(D42>0, E42/D42, 0) -> 85.487774 | H42: Low Impact / High Frequency
B43: Hiring & Recruitment | C43: =COUNTIFS('Master Event Tracker'!$Q$8:$Q$68, B43) -> 2 | D43: =SUMIFS('Master Event Tracker'!$J$8:$J$68, 'Master Event Tracker'!$Q$8:$Q$68, B43) -> 120 | E43: =SUMIFS('Master Event Tracker'!$L$8:$L$68, 'Master Event Tracker'!$Q$8:$Q$68, B43) -> 10200 | F43: =E43/$E$46 -> 0.0082237969 | G43: =IF(D43>0, E43/D43, 0) -> 85 | H43: Medium Impact (Talent Acquisition)
B44: CSR & Health Drive | C44: =COUNTIFS('Master Event Tracker'!$Q$8:$Q$68, B44) -> 1 | D44: =SUMIFS('Master Event Tracker'!$J$8:$J$68, 'Master Event Tracker'!$Q$8:$Q$68, B44) -> 150 | E44: =SUMIFS('Master Event Tracker'!$L$8:$L$68, 'Master Event Tracker'!$Q$8:$Q$68, B44) -> 4200 | F44: =E44/$E$46 -> 0.0033862693 | G44: =IF(D44>0, E44/D44, 0) -> 28 | H44: Low Impact (Social Initiative)
B45: Business & Market Events | C45: =COUNTIFS('Master Event Tracker'!$Q$8:$Q$68, B45) -> 1 | D45: =SUMIFS('Master Event Tracker'!$J$8:$J$68, 'Master Event Tracker'!$Q$8:$Q$68, B45) -> 100 | E45: =SUMIFS('Master Event Tracker'!$L$8:$L$68, 'Master Event Tracker'!$Q$8:$Q$68, B45) -> 2800 | F45: =E45/$E$46 -> 0.0022575129 | G45: =IF(D45>0, E45/D45, 0) -> 28 | H45: Low Impact (Ad-hoc Event)
B46: Total Portfolio Spend | C46: =SUM(C38:C45) -> 61 | D46: =SUM(D38:D45) -> 8931 | E46: =SUM(E38:E45) -> 1240303 | F46: =SUM(F38:F45) -> 1 | G46: =IF(D46>0, E46/D46, 0) -> 138.87616 | H46: Full Operational Portfolio

Sheet Lookups & Settings
B2: =HYPERLINK("#Executive Dashboard!A1", "📊 Executive Dashboard") -> 📊 Executive Dashboard | D2: =HYPERLINK("#Master Event Tracker!A1", "📋 Master Event Tracker") -> 📋 Master Event Tracker | F2: =HYPERLINK("#Monthly Breakdown!A1", "📅 Monthly Breakdown") -> 📅 Monthly Breakdown | H2: =HYPERLINK("#Venue & Vendor Insights!A1", "🏢 Venue & Vendor Insights") -> 🏢 Venue & Vendor Insights | J2: =HYPERLINK("#Lookups & Settings!A1", "⚙️ Lookups & Settings") -> ⚙️ Lookups & Settings
B4: SYSTEM LOOKUPS & VALIDATION REFERENCE TABLES
B5: Centralized reference data powering all drop-downs, dynamic formulas, and automated categorizations
B7: Month Filter | D7: Months | F7: Categories | H7: Venues | J7: Vendors | L7: Payment Modes | N7: Requestors | P7: Statuses | R7: Buildings
B8: All Months | D8: May | F8: Townhall & All-Hands | H8: DT3 | Level 3 | J8: Compass | L8: Card | N8: Anju | P8: Completed | R8: DT4
B9: May | D9: June | F9: Leadership & Strategy | H9: DT4 | D410 (L5) | J9: Pihu | L9: PO | N9: Blood Donation Drive | P9: Scheduled | R9: DT3
B10: June | D10: July | F10: Induction & Training | H10: DT4 | L1 (Innovation Hub) | J10: Food Sauda | L10: Direct | N10: Deepika | P10: Pending Invoice | R10: DT4 & DT3
B11: July | D11: August | F11: Celebrations & Engagement | H11: DT4 | L4 (Zone E) | J11: Food Sauda / Pihu | N11: Deshraj | P11: Cancelled
B12: August | F12: Meetings & Refreshments | H12: DT4 | L5 & DT3 | N12: Devender
F13: Hiring & Recruitment | H13: DT4 | L5 (C305) | N13: Ekta
F14: CSR & Health Drive | H14: DT4 | L5 (Cafeteria) | N14: Hitesh
F15: Business & Market Events | H15: DT4 | L5 (Hackable Space) | N15: Kanchan Walia
F16: General Operations | H16: DT4 | L5 (Zone E) | N16: Khusboo Kaur
H17: DT4 | L6 (Zone E) | N17: Kirti
H18: DT4 | Level 1 | N18: Mary
H19: DT4 | Level 4 | N19: Mayank
H20: DT4 | Level 5 | N20: Monika
H21: DT4 | Level 6 | N21: Neeraj Panday
H22: DT4 | Zone B | N22: Poonam
N23: Poonam Gupta
N24: Preeti
N25: Prerena
N26: Property Services
N27: Ritika
N28: Rosie
N29: Rupika
N30: Sandy
N31: Saurabh Dutta
N32: Sawmit
N33: Sharadha Madaan
N34: Shikha
... N40: Vibhor
