Workbook

Sheet Dashboard
A1: 🏢 CBRE | YEARLY EVENT OPERATIONS DASHBOARD
A2: Downtown-3 & Downtown-4 Facilities • 2026 Event Planning, Capacity Analytics & Operations Management
A4: OPERATIONS CALENDAR BOOKING POLICY & STATUS GUIDE:
B5: 🟢 GREEN: Calendar Booking Done / Completed | G5: 🟡 YELLOW: Booking Pending (Upcoming / Action Required) | M5: 🔴 RED: Event Canceled by Organizer | R5: 📑 Open Master Tracker ↗
B7: TOTAL EVENTS (2026) | D7: EVENTS CONDUCTED (DONE) | F7: 🌟 BIG EVENTS (100+) | H7: 👥 SMALL EVENTS (<100) | J7: TOTAL ATTENDEES | L7: DOWNTOWN-3 EVENTS | N7: DOWNTOWN-4 EVENTS | P7: 📨 TOTAL FEEDBACK SENT | R7: ⚪ FEEDBACK NOT REQUIRED
B8: =B25+I28 -> 1786 | D8: =C25+J28 -> 1298 | F8: =P25 -> 148 | H8: =Q25 -> 1709 | J8: =F25+M28 -> 63482.333 | L8: =B25 -> 605 | N8: =I28 -> 1181 | P8: =R25+S25 -> 77 | R8: =COUNTIF(Master_Event_Tracker_2026!$T$3:$T$5000, "Not Required") -> 1808
B9: DT-3 & DT-4 combined | D9: 🟢 Done / Confirmed | F9: 100+ Pax (Feedback Applicable) | H9: < 100 Pax (Routine Events) | J9: 👥 Expected Pax | L9: 🏢 DT-3 Facility | N9: 🏢 DT-4 Facility | P9: DT-3: 12 | DT-4: 37 | R9: Routine Events / NA
A11: 🏢 DOWNTOWN-3 (DT-3) MONTHLY EVENT TRACKER & NAVIGATION | H11: 🏢 DOWNTOWN-4 (DT-4) MONTHLY EVENT TRACKER & NAVIGATION | O11: 📋 MONTHWISE EVENT SCALE & DT-3 / DT-4 FEEDBACK TRACKER
A12: Month (Click to Open) | B12: Total Events | C12: 🟢 Confirmed | D12: 🟡 Pending | E12: 🔴 Canceled | F12: Total Pax | H12: Month (Click to Open) | I12: Total Events | J12: 🟢 Confirmed | K12: 🟡 Pending | L12: 🔴 Canceled | M12: Total Pax | O12: Month | P12: 🌟 Big (100+) | Q12: 👥 Small (<100) | R12: 📨 DT-3 FB Sent | S12: 📨 DT-4 FB Sent
A13: Jan 2026 ↗ | B13: =COUNTIF('DT-3 Jan26'!$O$3:$O$500, "<>") -> 48 | C13: =COUNTIF('DT-3 Jan26'!$O$3:$O$500, "Confirmed (Done)") -> 45 | D13: =COUNTIF('DT-3 Jan26'!$O$3:$O$500, "Pending Calendar Booking") -> 0 | E13: =COUNTIF('DT-3 Jan26'!$O$3:$O$500, "Canceled") -> 3 | F13: =SUM('DT-3 Jan26'!$F$3:$F$500) -> 1190 | H13: Jan 2026 ↗ | I13: =COUNTIF('DT-4 Jan26'!$P$3:$P$500, "<>") -> 61 | J13: =COUNTIF('DT-4 Jan26'!$P$3:$P$500, "Confirmed (Done)") -> 54 | K13: =COUNTIF('DT-4 Jan26'!$P$3:$P$500, "Pending Calendar Booking") -> 0 | L13: =COUNTIF('DT-4 Jan26'!$P$3:$P$500, "Canceled") -> 7 | M13: =SUM('DT-4 Jan26'!$G$3:$G$500) -> 2851.3333 | O13: Jan 2026 | P13: =COUNTIFS(Master_Event_Tracker_2026!$C$3:$C$5000, "Jan", Master_Event_Tracker_2026!$L$3:$L$5000, "Big Event") -> 7 | Q13: =COUNTIFS(Master_Event_Tracker_2026!$C$3:$C$5000, "Jan", Master_Event_Tracker_2026!$L$3:$L$5000, "Small Event") -> 140 | R13: =COUNTIF('DT-3 Jan26'!$P$3:$P$500, "Form sent") -> 0 | S13: =COUNTIF('DT-4 Jan26'!$Q$3:$Q$500, "Form sent") -> 0
A14: Feb 2026 ↗ | B14: =COUNTIF('DT-3 Feb26'!$O$3:$O$500, "<>") -> 48 | C14: =COUNTIF('DT-3 Feb26'!$O$3:$O$500, "Confirmed (Done)") -> 44 | D14: =COUNTIF('DT-3 Feb26'!$O$3:$O$500, "Pending Calendar Booking") -> 0 | E14: =COUNTIF('DT-3 Feb26'!$O$3:$O$500, "Canceled") -> 4 | F14: =SUM('DT-3 Feb26'!$F$3:$F$500) -> 1497 | H14: Feb 2026 ↗ | I14: =COUNTIF('DT-4 Feb26'!$P$3:$P$500, "<>") -> 119 | J14: =COUNTIF('DT-4 Feb26'!$P$3:$P$500, "Confirmed (Done)") -> 107 | K14: =COUNTIF('DT-4 Feb26'!$P$3:$P$500, "Pending Calendar Booking") -> 0 | L14: =COUNTIF('DT-4 Feb26'!$P$3:$P$500, "Canceled") -> 12 | M14: =SUM('DT-4 Feb26'!$G$3:$G$500) -> 4731 | O14: Feb 2026 | P14: =COUNTIFS(Master_Event_Tracker_2026!$C$3:$C$5000, "Feb", Master_Event_Tracker_2026!$L$3:$L$5000, "Big Event") -> 22 | Q14: =COUNTIFS(Master_Event_Tracker_2026!$C$3:$C$5000, "Feb", Master_Event_Tracker_2026!$L$3:$L$5000, "Small Event") -> 183 | R14: =COUNTIF('DT-3 Feb26'!$P$3:$P$500, "Form sent") -> 0 | S14: =COUNTIF('DT-4 Feb26'!$Q$3:$Q$500, "Form sent") -> 0
A15: Mar 2026 ↗ | B15: =COUNTIF('DT-3 Mar26'!$O$3:$O$500, "<>") -> 59 | C15: =COUNTIF('DT-3 Mar26'!$O$3:$O$500, "Confirmed (Done)") -> 58 | D15: =COUNTIF('DT-3 Mar26'!$O$3:$O$500, "Pending Calendar Booking") -> 0 | E15: =COUNTIF('DT-3 Mar26'!$O$3:$O$500, "Canceled") -> 1 | F15: =SUM('DT-3 Mar26'!$F$3:$F$500) -> 1910 | H15: Mar 2026 ↗ | I15: =COUNTIF('DT-4 Mar26'!$P$3:$P$500, "<>") -> 118 | J15: =COUNTIF('DT-4 Mar26'!$P$3:$P$500, "Confirmed (Done)") -> 112 | K15: =COUNTIF('DT-4 Mar26'!$P$3:$P$500, "Pending Calendar Booking") -> 0 | L15: =COUNTIF('DT-4 Mar26'!$P$3:$P$500, "Canceled") -> 6 | M15: =SUM('DT-4 Mar26'!$G$3:$G$500) -> 4180 | O15: Mar 2026 | P15: =COUNTIFS(Master_Event_Tracker_2026!$C$3:$C$5000, "Mar", Master_Event_Tracker_2026!$L$3:$L$5000, "Big Event") -> 19 | Q15: =COUNTIFS(Master_Event_Tracker_2026!$C$3:$C$5000, "Mar", Master_Event_Tracker_2026!$L$3:$L$5000, "Small Event") -> 196 | R15: =COUNTIF('DT-3 Mar26'!$P$3:$P$500, "Form sent") -> 0 | S15: =COUNTIF('DT-4 Mar26'!$Q$3:$Q$500, "Form sent") -> 0
A16: Apr 2026 ↗ | B16: =COUNTIF('DT-3 Apr26'!$O$3:$O$500, "<>") -> 53 | C16: =COUNTIF('DT-3 Apr26'!$O$3:$O$500, "Confirmed (Done)") -> 51 | D16: =COUNTIF('DT-3 Apr26'!$O$3:$O$500, "Pending Calendar Booking") -> 0 | E16: =COUNTIF('DT-3 Apr26'!$O$3:$O$500, "Canceled") -> 2 | F16: =SUM('DT-3 Apr26'!$F$3:$F$500) -> 1713 | H16: Apr 2026 ↗ | I16: =COUNTIF('DT-4 Apr26'!$P$3:$P$500, "<>") -> 68 | J16: =COUNTIF('DT-4 Apr26'!$P$3:$P$500, "Confirmed (Done)") -> 61 | K16: =COUNTIF('DT-4 Apr26'!$P$3:$P$500, "Pending Calendar Booking") -> 0 | L16: =COUNTIF('DT-4 Apr26'!$P$3:$P$500, "Canceled") -> 7 | M16: =SUM('DT-4 Apr26'!$G$3:$G$500) -> 3063 | O16: Apr 2026 | P16: =COUNTIFS(Master_Event_Tracker_2026!$C$3:$C$5000, "Apr", Master_Event_Tracker_2026!$L$3:$L$5000, "Big Event") -> 13 | Q16: =COUNTIFS(Master_Event_Tracker_2026!$C$3:$C$5000, "Apr", Master_Event_Tracker_2026!$L$3:$L$5000, "Small Event") -> 108 | R16: =COUNTIF('DT-3 Apr26'!$P$3:$P$500, "Form sent") -> 0 | S16: =COUNTIF('DT-4 Apr26'!$Q$3:$Q$500, "Form sent") -> 0
A17: May 2026 ↗ | B17: =COUNTIF('DT-3 May26'!$O$3:$O$500, "<>") -> 48 | C17: =COUNTIF('DT-3 May26'!$O$3:$O$500, "Confirmed (Done)") -> 45 | D17: =COUNTIF('DT-3 May26'!$O$3:$O$500, "Pending Calendar Booking") -> 0 | E17: =COUNTIF('DT-3 May26'!$O$3:$O$500, "Canceled") -> 3 | F17: =SUM('DT-3 May26'!$F$3:$F$500) -> 1200 | H17: May 2026 ↗ | I17: =COUNTIF('DT-4 May26'!$P$3:$P$500, "<>") -> 92 | J17: =COUNTIF('DT-4 May26'!$P$3:$P$500, "Confirmed (Done)") -> 89 | K17: =COUNTIF('DT-4 May26'!$P$3:$P$500, "Pending Calendar Booking") -> 0 | L17: =COUNTIF('DT-4 May26'!$P$3:$P$500, "Canceled") -> 3 | M17: =SUM('DT-4 May26'!$G$3:$G$500) -> 4474 | O17: May 2026 | P17: =COUNTIFS(Master_Event_Tracker_2026!$C$3:$C$5000, "May", Master_Event_Tracker_2026!$L$3:$L$5000, "Big Event") -> 16 | Q17: =COUNTIFS(Master_Event_Tracker_2026!$C$3:$C$5000, "May", Master_Event_Tracker_2026!$L$3:$L$5000, "Small Event") -> 124 | R17: =COUNTIF('DT-3 May26'!$P$3:$P$500, "Form sent") -> 0 | S17: =COUNTIF('DT-4 May26'!$Q$3:$Q$500, "Form sent") -> 0
A18: Jun 2026 ↗ | B18: =COUNTIF('DT-3 Jun26'!$O$3:$O$500, "<>") -> 48 | C18: =COUNTIF('DT-3 Jun26'!$O$3:$O$500, "Confirmed (Done)") -> 45 | D18: =COUNTIF('DT-3 Jun26'!$O$3:$O$500, "Pending Calendar Booking") -> 0 | E18: =COUNTIF('DT-3 Jun26'!$O$3:$O$500, "Canceled") -> 3 | F18: =SUM('DT-3 Jun26'!$F$3:$F$500) -> 1217 | H18: Jun 2026 ↗ | I18: =COUNTIF('DT-4 Jun26'!$P$3:$P$500, "<>") -> 118 | J18: =COUNTIF('DT-4 Jun26'!$P$3:$P$500, "Confirmed (Done)") -> 109 | K18: =COUNTIF('DT-4 Jun26'!$P$3:$P$500, "Pending Calendar Booking") -> 0 | L18: =COUNTIF('DT-4 Jun26'!$P$3:$P$500, "Canceled") -> 9 | M18: =SUM('DT-4 Jun26'!$G$3:$G$500) -> 4958 | O18: Jun 2026 | P18: =COUNTIFS(Master_Event_Tracker_2026!$C$3:$C$5000, "Jun", Master_Event_Tracker_2026!$L$3:$L$5000, "Big Event") -> 14 | Q18: =COUNTIFS(Master_Event_Tracker_2026!$C$3:$C$5000, "Jun", Master_Event_Tracker_2026!$L$3:$L$5000, "Small Event") -> 152 | R18: =COUNTIF('DT-3 Jun26'!$P$3:$P$500, "Form sent") -> 0 | S18: =COUNTIF('DT-4 Jun26'!$Q$3:$Q$500, "Form sent") -> 0
A19: Jul 2026 ↗ | B19: =COUNTIF('DT-3 Jul26'!$O$3:$O$500, "<>") -> 64 | C19: =COUNTIF('DT-3 Jul26'!$O$3:$O$500, "Confirmed (Done)") -> 59 | D19: =COUNTIF('DT-3 Jul26'!$O$3:$O$500, "Pending Calendar Booking") -> 0 | E19: =COUNTIF('DT-3 Jul26'!$O$3:$O$500, "Canceled") -> 5 | F19: =SUM('DT-3 Jul26'!$F$3:$F$500) -> 1682 | H19: Jul 2026 ↗ | I19: =COUNTIF('DT-4 Jul26'!$P$3:$P$500, "<>") -> 177 | J19: =COUNTIF('DT-4 Jul26'!$P$3:$P$500, "Confirmed (Done)") -> 147 | K19: =COUNTIF('DT-4 Jul26'!$P$3:$P$500, "Pending Calendar Booking") -> 0 | L19: =COUNTIF('DT-4 Jul26'!$P$3:$P$500, "Canceled") -> 30 | M19: =SUM('DT-4 Jul26'!$G$3:$G$500) -> 7266 | O19: Jul 2026 | P19: =COUNTIFS(Master_Event_Tracker_2026!$C$3:$C$5000, "Jul", Master_Event_Tracker_2026!$L$3:$L$5000, "Big Event") -> 25 | Q19: =COUNTIFS(Master_Event_Tracker_2026!$C$3:$C$5000, "Jul", Master_Event_Tracker_2026!$L$3:$L$5000, "Small Event") -> 216 | R19: =COUNTIF('DT-3 Jul26'!$P$3:$P$500, "Form sent") -> 0 | S19: =COUNTIF('DT-4 Jul26'!$Q$3:$Q$500, "Form sent") -> 0
A20: Aug 2026 ↗ | B20: =COUNTIF('DT-3 Aug26'!$O$3:$O$501, "<>") -> 51 | C20: =COUNTIF('DT-3 Aug26'!$O$3:$O$501, "Confirmed (Done)") -> 38 | D20: =COUNTIF('DT-3 Aug26'!$O$3:$O$501, "Pending Calendar Booking") -> 3 | E20: =COUNTIF('DT-3 Aug26'!$O$3:$O$501, "Canceled") -> 10 | F20: =SUM('DT-3 Aug26'!$F$3:$F$501) -> 1868 | H20: Aug 2026 ↗ | I20: =COUNTIF('DT-4 Aug26'!$P$3:$P$505, "<>") -> 133 | J20: =COUNTIF('DT-4 Aug26'!$P$3:$P$505, "Confirmed (Done)") -> 109 | K20: =COUNTIF('DT-4 Aug26'!$P$3:$P$505, "Pending Calendar Booking") -> 0 | L20: =COUNTIF('DT-4 Aug26'!$P$3:$P$505, "Canceled") -> 24 | M20: =SUM('DT-4 Aug26'!$G$3:$G$505) -> 6113 | O20: Aug 2026 | P20: =COUNTIFS(Master_Event_Tracker_2026!$C$3:$C$5000, "Aug", Master_Event_Tracker_2026!$L$3:$L$5000, "Big Event") -> 21 | Q20: =COUNTIFS(Master_Event_Tracker_2026!$C$3:$C$5000, "Aug", Master_Event_Tracker_2026!$L$3:$L$5000, "Small Event") -> 162 | R20: =COUNTIF('DT-3 Aug26'!$P$3:$P$501, "Form sent") -> 12 | S20: =COUNTIF('DT-4 Aug26'!$Q$3:$Q$505, "Form sent") -> 65
A21: Sep 2026 ↗ | B21: =COUNTIF('DT-3 Sep26'!$O$3:$O$505, "<>") -> 42 | C21: =COUNTIF('DT-3 Sep26'!$O$3:$O$505, "Confirmed (Done)") -> 22 | D21: =COUNTIF('DT-3 Sep26'!$O$3:$O$505, "Pending Calendar Booking") -> 20 | E21: =COUNTIF('DT-3 Sep26'!$O$3:$O$505, "Canceled") -> 0 | F21: =SUM('DT-3 Sep26'!$F$3:$F$505) -> 1174 | H21: Sep 2026 ↗ | I21: =COUNTIF('DT-4 Sep26'!$P$3:$P$554, "<>") -> 136 | J21: =COUNTIF('DT-4 Sep26'!$P$3:$P$554, "Confirmed (Done)") -> 101 | K21: =COUNTIF('DT-4 Sep26'!$P$3:$P$554, "Pending Calendar Booking") -> 33 | L21: =COUNTIF('DT-4 Sep26'!$P$3:$P$554, "Canceled") -> 2 | M21: =SUM('DT-4 Sep26'!$G$3:$G$554) -> 5687 | O21: Sep 2026 | P21: =COUNTIFS(Master_Event_Tracker_2026!$C$3:$C$5000, "Sep", Master_Event_Tracker_2026!$L$3:$L$5000, "Big Event") -> 8 | Q21: =COUNTIFS(Master_Event_Tracker_2026!$C$3:$C$5000, "Sep", Master_Event_Tracker_2026!$L$3:$L$5000, "Small Event") -> 143 | R21: =COUNTIF('DT-3 Sep26'!$P$3:$P$505, "Form sent") -> 0 | S21: =COUNTIF('DT-4 Sep26'!$Q$3:$Q$554, "Form sent") -> 0
A22: Oct 2026 ↗ | B22: =COUNTIF('DT-3 Oct26'!$O$3:$O$500, "<>") -> 48 | C22: =COUNTIF('DT-3 Oct26'!$O$3:$O$500, "Confirmed (Done)") -> 0 | D22: =COUNTIF('DT-3 Oct26'!$O$3:$O$500, "Pending Calendar Booking") -> 48 | E22: =COUNTIF('DT-3 Oct26'!$O$3:$O$500, "Canceled") -> 0 | F22: =SUM('DT-3 Oct26'!$F$3:$F$500) -> 85 | H22: Oct 2026 ↗ | I22: =COUNTIF('DT-4 Oct26'!$P$3:$P$507, "<>") -> 55 | J22: =COUNTIF('DT-4 Oct26'!$P$3:$P$507, "Confirmed (Done)") -> 2 | K22: =COUNTIF('DT-4 Oct26'!$P$3:$P$507, "Pending Calendar Booking") -> 53 | L22: =COUNTIF('DT-4 Oct26'!$P$3:$P$507, "Canceled") -> 0 | M22: =SUM('DT-4 Oct26'!$G$3:$G$507) -> 1398 | O22: Oct 2026 | P22: =COUNTIFS(Master_Event_Tracker_2026!$C$3:$C$5000, "Oct", Master_Event_Tracker_2026!$L$3:$L$5000, "Big Event") -> 0 | Q22: =COUNTIFS(Master_Event_Tracker_2026!$C$3:$C$5000, "Oct", Master_Event_Tracker_2026!$L$3:$L$5000, "Small Event") -> 96 | R22: =COUNTIF('DT-3 Oct26'!$P$3:$P$500, "Form sent") -> 0 | S22: =COUNTIF('DT-4 Oct26'!$Q$3:$Q$507, "Form sent") -> 0
A23: Nov 2026 ↗ | B23: =COUNTIF('DT-3 Nov26'!$O$3:$O$500, "<>") -> 48 | C23: =COUNTIF('DT-3 Nov26'!$O$3:$O$500, "Confirmed (Done)") -> 0 | D23: =COUNTIF('DT-3 Nov26'!$O$3:$O$500, "Pending Calendar Booking") -> 48 | E23: =COUNTIF('DT-3 Nov26'!$O$3:$O$500, "Canceled") -> 0 | F23: =SUM('DT-3 Nov26'!$F$3:$F$500) -> 200 | H23: Nov 2026 ↗ | I23: =COUNTIF('DT-4 Nov26'!$P$3:$P$505, "<>") -> 53 | J23: =COUNTIF('DT-4 Nov26'!$P$3:$P$505, "Confirmed (Done)") -> 0 | K23: =COUNTIF('DT-4 Nov26'!$P$3:$P$505, "Pending Calendar Booking") -> 53 | L23: =COUNTIF('DT-4 Nov26'!$P$3:$P$505, "Canceled") -> 0 | M23: =SUM('DT-4 Nov26'!$G$3:$G$505) -> 1365 | O23: Nov 2026 | P23: =COUNTIFS(Master_Event_Tracker_2026!$C$3:$C$5000, "Nov", Master_Event_Tracker_2026!$L$3:$L$5000, "Big Event") -> 3 | Q23: =COUNTIFS(Master_Event_Tracker_2026!$C$3:$C$5000, "Nov", Master_Event_Tracker_2026!$L$3:$L$5000, "Small Event") -> 93 | R23: =COUNTIF('DT-3 Nov26'!$P$3:$P$500, "Form sent") -> 0 | S23: =COUNTIF('DT-4 Nov26'!$Q$3:$Q$505, "Form sent") -> 0
A24: Dec 2026 ↗ | B24: =COUNTIF('DT-3 Dec26'!$O$3:$O$500, "<>") -> 48 | C24: =COUNTIF('DT-3 Dec26'!$O$3:$O$500, "Confirmed (Done)") -> 0 | D24: =COUNTIF('DT-3 Dec26'!$O$3:$O$500, "Pending Calendar Booking") -> 48 | E24: =COUNTIF('DT-3 Dec26'!$O$3:$O$500, "Canceled") -> 0 | F24: =SUM('DT-3 Dec26'!$F$3:$F$500) -> 50 | H24: Dec 2026 ↗ | I24: =COUNTIF('DT-4 Dec26'!$P$3:$P$503, "<>") -> 51 | J24: =COUNTIF('DT-4 Dec26'!$P$3:$P$503, "Confirmed (Done)") -> 0 | K24: =COUNTIF('DT-4 Dec26'!$P$3:$P$503, "Pending Calendar Booking") -> 51 | L24: =COUNTIF('DT-4 Dec26'!$P$3:$P$503, "Canceled") -> 0 | M24: =SUM('DT-4 Dec26'!$G$3:$G$503) -> 1010 | O24: Dec 2026 | P24: =COUNTIFS(Master_Event_Tracker_2026!$C$3:$C$5000, "Dec", Master_Event_Tracker_2026!$L$3:$L$5000, "Big Event") -> 0 | Q24: =COUNTIFS(Master_Event_Tracker_2026!$C$3:$C$5000, "Dec", Master_Event_Tracker_2026!$L$3:$L$5000, "Small Event") -> 96 | R24: =COUNTIF('DT-3 Dec26'!$P$3:$P$500, "Form sent") -> 0 | S24: =COUNTIF('DT-4 Dec26'!$Q$3:$Q$503, "Form sent") -> 0
A25: DT-3 Full Year Total | B25: =SUM(B13:B24) -> 605 | C25: =SUM(C13:C24) -> 407 | D25: =SUM(D13:D24) -> 167 | E25: =SUM(E13:E24) -> 31 | F25: =SUM(F13:F24) -> 13786 | H25: Jan '27 ↗ | I25: =COUNTIF('DT-4 Jan27'!$P$3:$P$503, "<>") -> 41 | J25: =COUNTIF('DT-4 Jan27'!$P$3:$P$503, "Confirmed (Done)") -> 8 | K25: =COUNTIF('DT-4 Jan27'!$P$3:$P$503, "Pending Calendar Booking") -> 33 | L25: =COUNTIF('DT-4 Jan27'!$P$3:$P$503, "Canceled") -> 0 | M25: =SUM('DT-4 Jan27'!$G$3:$G$503) -> 800 | O25: Full Year Total | P25: =SUM(P13:P24) -> 148 | Q25: =SUM(Q13:Q24) -> 1709 | R25: =SUM(R13:R24) -> 12 | S25: =SUM(S13:S24) -> 65
H26: Feb '27 ↗ | I26: =COUNTIF('DT-4 Feb27'!$P$3:$P$504, "<>") -> 42 | J26: =COUNTIF('DT-4 Feb27'!$P$3:$P$504, "Confirmed (Done)") -> 8 | K26: =COUNTIF('DT-4 Feb27'!$P$3:$P$504, "Pending Calendar Booking") -> 34 | L26: =COUNTIF('DT-4 Feb27'!$P$3:$P$504, "Canceled") -> 0 | M26: =SUM('DT-4 Feb27'!$G$3:$G$504) -> 850
H27: Mar '27 ↗ | I27: =COUNTIF('DT-4 Mar27'!$P$3:$P$503, "<>") -> 41 | J27: =COUNTIF('DT-4 Mar27'!$P$3:$P$503, "Confirmed (Done)") -> 8 | K27: =COUNTIF('DT-4 Mar27'!$P$3:$P$503, "Pending Calendar Booking") -> 33 | L27: =COUNTIF('DT-4 Mar27'!$P$3:$P$503, "Canceled") -> 0 | M27: =SUM('DT-4 Mar27'!$G$3:$G$503) -> 950 | O27: Event Scale Metric | P27: Summary | R27: Feedback Breakdown | S27: Count
H28: DT-4 2026 Subtotal | I28: =SUM(I13:I24) -> 1181 | J28: =SUM(J13:J24) -> 891 | K28: =SUM(K13:K24) -> 190 | L28: =SUM(L13:L24) -> 100 | M28: =SUM(M13:M27) -> 49696.333 | O28: 🏆 Events Conducted | P28: =E45 -> 1298 | R28: 🏢 DT-3 Feedback Sent | S28: =R25 -> 12
O29: 🌟 Big Events (100+) | P29: =P25 -> 148 | R29: 🏢 DT-4 Feedback Sent | S29: =S25 -> 65
O30: 👥 Small Events (<100) | P30: =Q25 -> 1709 | R30: 📨 Total Feedback Sent | S30: =R25+S25 -> 77
A31: 📊 2026 COMBINED MONTHLY EVENTS SUMMARY | K31: 🔍 INTERACTIVE MONTH SELECTION & DEEP DIVE
A32: Month | B32: DT-3 Events | C32: DT-4 Events | D32: Total Events | E32: 🟢 Confirmed | F32: 🟡 Pending | G32: 🔴 Canceled | H32: Confirmed % | I32: Total Pax | K32: 📅 SELECT MONTH: | M32: Jan | P32: 🟢 Live Auto-Calculated Drilldown
A33: Jan | B33: =B13 -> 48 | C33: =I13 -> 61 | D33: =B33+C33 -> 109 | E33: =C13+J13 -> 99 | F33: =D13+K13 -> 0 | G33: =E13+L13 -> 10 | H33: =IFERROR(E33/(E33+F33), 0) -> 1 | I33: =F13+M13 -> 4041.3333 | K33: TOTAL EVENTS | M33: CONFIRMED (DONE) | P33: PENDING BOOKING | S33: CANCELED
A34: Feb | B34: =B14 -> 48 | C34: =I14 -> 119 | D34: =B34+C34 -> 167 | E34: =C14+J14 -> 151 | F34: =D14+K14 -> 0 | G34: =E14+L14 -> 16 | H34: =IFERROR(E34/(E34+F34), 0) -> 1 | I34: =F14+M14 -> 6228 | K34: =IF($M$32="Full Year 2026", D45, IFERROR(INDEX($D$33:$D$44, MATCH($M$32, $A$33:$A$44, 0)), 0)) -> 109 | M34: =IF($M$32="Full Year 2026", E45, IFERROR(INDEX($E$33:$E$44, MATCH($M$32, $A$33:$A$44, 0)), 0)) -> 99 | P34: =IF($M$32="Full Year 2026", F45, IFERROR(INDEX($F$33:$F$44, MATCH($M$32, $A$33:$A$44, 0)), 0)) -> 0 | S34: =IF($M$32="Full Year 2026", G45, IFERROR(INDEX($G$33:$G$44, MATCH($M$32, $A$33:$A$44, 0)), 0)) -> 10
A35: Mar | B35: =B15 -> 59 | C35: =I15 -> 118 | D35: =B35+C35 -> 177 | E35: =C15+J15 -> 170 | F35: =D15+K15 -> 0 | G35: =E15+L15 -> 7 | H35: =IFERROR(E35/(E35+F35), 0) -> 1 | I35: =F15+M15 -> 6090 | K35: CONFIRMED % RATE | M35: TOTAL ATTENDEES (PAX) | P35: DT-3 EVENTS | R35: DT-4 EVENTS
A36: Apr | B36: =B16 -> 53 | C36: =I16 -> 68 | D36: =B36+C36 -> 121 | E36: =C16+J16 -> 112 | F36: =D16+K16 -> 0 | G36: =E16+L16 -> 9 | H36: =IFERROR(E36/(E36+F36), 0) -> 1 | I36: =F16+M16 -> 4776 | K36: =IF($M$32="Full Year 2026", H45, IFERROR(INDEX($H$33:$H$44, MATCH($M$32, $A$33:$A$44, 0)), 0)) -> 1 | M36: =IF($M$32="Full Year 2026", I45, IFERROR(INDEX($I$33:$I$44, MATCH($M$32, $A$33:$A$44, 0)), 0)) -> 4041.3333 | P36: =IF($M$32="Full Year 2026", B45, IFERROR(INDEX($B$33:$B$44, MATCH($M$32, $A$33:$A$44, 0)), 0)) -> 48 | R36: =IF($M$32="Full Year 2026", C45, IFERROR(INDEX($C$33:$C$44, MATCH($M$32, $A$33:$A$44, 0)), 0)) -> 61
A37: May | B37: =B17 -> 48 | C37: =I17 -> 92 | D37: =B37+C37 -> 140 | E37: =C17+J17 -> 134 | F37: =D17+K17 -> 0 | G37: =E17+L17 -> 6 | H37: =IFERROR(E37/(E37+F37), 0) -> 1 | I37: =F17+M17 -> 5674 | K37: 🌟 BIG (100+): | M37: =IF($M$32="Full Year 2026", P25, IFERROR(INDEX($P$13:$P$24, MATCH($M$32, $A$33:$A$44, 0)), 0)) -> 7 | N37: 👥 SMALL (<100): | P37: =IF($M$32="Full Year 2026", Q25, IFERROR(INDEX($Q$13:$Q$24, MATCH($M$32, $A$33:$A$44, 0)), 0)) -> 140 | Q37: 📨 DT3 / DT4 FB: | S37: =IF($M$32="Full Year 2026", R25&"/"&S25, IFERROR(INDEX($R$13:$R$24, MATCH($M$32, $A$33:$A$44, 0))&"/"&INDEX($S$13:$S$24, MATCH($M$32, $A$33:$A$44, 0)), "0/0")) -> 0/0
A38: Jun | B38: =B18 -> 48 | C38: =I18 -> 118 | D38: =B38+C38 -> 166 | E38: =C18+J18 -> 154 | F38: =D18+K18 -> 0 | G38: =E18+L18 -> 12 | H38: =IFERROR(E38/(E38+F38), 0) -> 1 | I38: =F18+M18 -> 6175 | K38: 🚀 QUICK NAVIGATION TO MONTHLY TRACKERS
A39: Jul | B39: =B19 -> 64 | C39: =I19 -> 177 | D39: =B39+C39 -> 241 | E39: =C19+J19 -> 206 | F39: =D19+K19 -> 0 | G39: =E19+L19 -> 35 | H39: =IFERROR(E39/(E39+F39), 0) -> 1 | I39: =F19+M19 -> 8948 | K39: 💡 HOW TO USE THIS DASHBOARD: 1. Change the Month dropdown above (M32) to instantly update the Monthly Deep Dive KPIs. 2. Click any Month in the DT-3 / DT-4 tables (Rows 13-27) to jump directly to that month's sheet. 3. In any monthly sheet, click '🏠 ⮌ RETURN TO DASHBOARD' (A1) to return back here. 4. Event Scale: Big Event (100+ pax) vs Small Event (<100 pax). Feedback forms recorded for previous entries are preserved; routine events are marked 'Not Required'.
A40: Aug | B40: =B20 -> 51 | C40: =I20 -> 133 | D40: =B40+C40 -> 184 | E40: =C20+J20 -> 147 | F40: =D20+K20 -> 3 | G40: =E20+L20 -> 34 | H40: =IFERROR(E40/(E40+F40), 0) -> 0.98 | I40: =F20+M20 -> 7981
A41: Sep | B41: =B21 -> 42 | C41: =I21 -> 136 | D41: =B41+C41 -> 178 | E41: =C21+J21 -> 123 | F41: =D21+K21 -> 53 | G41: =E21+L21 -> 2 | H41: =IFERROR(E41/(E41+F41), 0) -> 0.69886364 | I41: =F21+M21 -> 6861
A42: Oct | B42: =B22 -> 48 | C42: =I22 -> 55 | D42: =B42+C42 -> 103 | E42: =C22+J22 -> 2 | F42: =D22+K22 -> 101 | G42: =E22+L22 -> 0 | H42: =IFERROR(E42/(E42+F42), 0) -> 0.019417476 | I42: =F22+M22 -> 1483
A43: Nov | B43: =B23 -> 48 | C43: =I23 -> 53 | D43: =B43+C43 -> 101 | E43: =C23+J23 -> 0 | F43: =D23+K23 -> 101 | G43: =E23+L23 -> 0 | H43: =IFERROR(E43/(E43+F43), 0) -> 0 | I43: =F23+M23 -> 1565
...

Sheet Master_Event_Tracker_2026
A1: 🏠 ⮌ BACK TO DASHBOARD | D1: MASTER EVENT OPERATIONS DATABASE • FULL YEAR 2026 (DOWNTOWN-3 & DOWNTOWN-4) | Q1: 🟢 Green: Confirmed | 🟡 Yellow: Pending | 🔴 Red: Canceled
A2: Event ID | B2: Year | C2: Month | D2: Event Date | E2: Day | F2: Building | G2: Floor | H2: Location | I2: Event Title / Purpose | J2: Category | K2: Capacity / Pax | L2: Event Scale | M2: Start Time | N2: End Time | O2: F&B Support | P2: Logistic Support | Q2: Booked By | R2: Requester Email | S2: Calendar Booking Status | T2: Feedback Form | U2: Booking Date | V2: Remarks | W2: Booking Taken By
A3: =IF(OR(D3<>"",H3<>"",I3<>"",Q3<>"",S3<>""), "EVT-" & TEXT(B3, "0000") & "-" & TEXT(COUNTIF(OFFSET($A$1, 1, 0, ROW()-2, 1), "EVT*") + 1, "0000"), "") -> EVT-2026-0001 | B3: 2026 | C3: Jan | D3: 46023 | E3: Thu | F3: Downtown-3 | G3: General | J3: Team Meeting & Workshop | K3: 0 | L3: Small Event | S3: Confirmed (Done) | T3: Not Required
A4: =IF(OR(D4<>"",H4<>"",I4<>"",Q4<>"",S4<>""), "EVT-" & TEXT(B4, "0000") & "-" & TEXT(COUNTIF(OFFSET($A$1, 1, 0, ROW()-2, 1), "EVT*") + 1, "0000"), "") -> EVT-2026-0002 | B4: 2026 | C4: Jan | D4: 46024 | E4: Fri | F4: Downtown-3 | G4: General | J4: Team Meeting & Workshop | K4: 0 | L4: Small Event | S4: Confirmed (Done) | T4: Not Required
A5: =IF(OR(D5<>"",H5<>"",I5<>"",Q5<>"",S5<>""), "EVT-" & TEXT(B5, "0000") & "-" & TEXT(COUNTIF(OFFSET($A$1, 1, 0, ROW()-2, 1), "EVT*") + 1, "0000"), "") -> EVT-2026-0003 | B5: 2026 | C5: Jan | D5: 46025 | E5: Sat | F5: Downtown-3 | G5: General | J5: Team Meeting & Workshop | K5: 0 | L5: Small Event | S5: Confirmed (Done) | T5: Not Required
A6: =IF(OR(D6<>"",H6<>"",I6<>"",Q6<>"",S6<>""), "EVT-" & TEXT(B6, "0000") & "-" & TEXT(COUNTIF(OFFSET($A$1, 1, 0, ROW()-2, 1), "EVT*") + 1, "0000"), "") -> EVT-2026-0004 | B6: 2026 | C6: Jan | D6: 46026 | E6: Sun | F6: Downtown-3 | G6: General | J6: Team Meeting & Workshop | K6: 0 | L6: Small Event | S6: Confirmed (Done) | T6: Not Required
A7: =IF(OR(D7<>"",H7<>"",I7<>"",Q7<>"",S7<>""), "EVT-" & TEXT(B7, "0000") & "-" & TEXT(COUNTIF(OFFSET($A$1, 1, 0, ROW()-2, 1), "EVT*") + 1, "0000"), "") -> EVT-2026-0005 | B7: 2026 | C7: Jan | D7: 46027 | E7: Mon | F7: Downtown-3 | G7: L-5 | H7: MR-305 & 306 | I7: Induction Session | J7: Induction & Onboarding | K7: 35 | L7: Small Event | M7: 08:00 AM | N7: 05:00 PM | O7: Lunch | Q7: Deshraj | S7: Confirmed (Done) | T7: Not Required | U7: 46001 | V7: Classroom set up with power extension-
A8: =IF(OR(D8<>"",H8<>"",I8<>"",Q8<>"",S8<>""), "EVT-" & TEXT(B8, "0000") & "-" & TEXT(COUNTIF(OFFSET($A$1, 1, 0, ROW()-2, 1), "EVT*") + 1, "0000"), "") -> EVT-2026-0006 | B8: 2026 | C8: Jan | D8: 46027 | E8: Mon | F8: Downtown-3 | G8: General | H8: Breakout Area | I8: Induction Session | J8: Induction & Onboarding | K8: 35 | L8: Small Event | M8: 08:00 AM | N8: 05:00 PM | O8: Lunch | Q8: Deshraj | S8: Confirmed (Done) | T8: Not Required | V8: Classroom set up with power extension-
A9: =IF(OR(D9<>"",H9<>"",I9<>"",Q9<>"",S9<>""), "EVT-" & TEXT(B9, "0000") & "-" & TEXT(COUNTIF(OFFSET($A$1, 1, 0, ROW()-2, 1), "EVT*") + 1, "0000"), "") -> EVT-2026-0007 | B9: 2026 | C9: Jan | D9: 46028 | E9: Tue | F9: Downtown-3 | G9: General | J9: Team Meeting & Workshop | K9: 0 | L9: Small Event | S9: Confirmed (Done) | T9: Not Required
A10: =IF(OR(D10<>"",H10<>"",I10<>"",Q10<>"",S10<>""), "EVT-" & TEXT(B10, "0000") & "-" & TEXT(COUNTIF(OFFSET($A$1, 1, 0, ROW()-2, 1), "EVT*") + 1, "0000"), "") -> EVT-2026-0008 | B10: 2026 | C10: Jan | D10: 46029 | E10: Wed | F10: Downtown-3 | G10: General | J10: Team Meeting & Workshop | K10: 0 | L10: Small Event | S10: Confirmed (Done) | T10: Not Required
A11: =IF(OR(D11<>"",H11<>"",I11<>"",Q11<>"",S11<>""), "EVT-" & TEXT(B11, "0000") & "-" & TEXT(COUNTIF(OFFSET($A$1, 1, 0, ROW()-2, 1), "EVT*") + 1, "0000"), "") -> EVT-2026-0009 | B11: 2026 | C11: Jan | D11: 46030 | E11: Thu | F11: Downtown-3 | G11: General | J11: Team Meeting & Workshop | K11: 0 | L11: Small Event | S11: Confirmed (Done) | T11: Not Required
A12: =IF(OR(D12<>"",H12<>"",I12<>"",Q12<>"",S12<>""), "EVT-" & TEXT(B12, "0000") & "-" & TEXT(COUNTIF(OFFSET($A$1, 1, 0, ROW()-2, 1), "EVT*") + 1, "0000"), "") -> EVT-2026-0010 | B12: 2026 | C12: Jan | D12: 46031 | E12: Fri | F12: Downtown-3 | G12: General | J12: Team Meeting & Workshop | K12: 0 | L12: Small Event | S12: Confirmed (Done) | T12: Not Required
A13: =IF(OR(D13<>"",H13<>"",I13<>"",Q13<>"",S13<>""), "EVT-" & TEXT(B13, "0000") & "-" & TEXT(COUNTIF(OFFSET($A$1, 1, 0, ROW()-2, 1), "EVT*") + 1, "0000"), "") -> EVT-2026-0011 | B13: 2026 | C13: Jan | D13: 46032 | E13: Sat | F13: Downtown-3 | G13: L-5 | H13: MR-305 & 306 | I13: Driver's Training | J13: Training & Enablement | K13: 20 | L13: Small Event | M13: 10:00 AM | N13: 01:00 PM | O13: Snacks | Q13: Prem Chaudhary | S13: Confirmed (Done) | T13: Not Required | V13: Arranged the snacks- Cup Cakes, Samosa and tea
A14: =IF(OR(D14<>"",H14<>"",I14<>"",Q14<>"",S14<>""), "EVT-" & TEXT(B14, "0000") & "-" & TEXT(COUNTIF(OFFSET($A$1, 1, 0, ROW()-2, 1), "EVT*") + 1, "0000"), "") -> EVT-2026-0012 | B14: 2026 | C14: Jan | D14: 46032 | E14: Sat | F14: Downtown-3 | G14: General | H14: Hiring drive | I14: ZONE C, D and E | J14: Assessment & Hiring | K14: 0 | L14: Small Event | M14: 08:30 AM | N14: 05:00 PM | Q14: Manoj Thakral | S14: Confirmed (Done) | T14: Not Required | V14: List will be shared shortly.
A15: =IF(OR(D15<>"",H15<>"",I15<>"",Q15<>"",S15<>""), "EVT-" & TEXT(B15, "0000") & "-" & TEXT(COUNTIF(OFFSET($A$1, 1, 0, ROW()-2, 1), "EVT*") + 1, "0000"), "") -> EVT-2026-0013 | B15: 2026 | C15: Jan | D15: 46033 | E15: Sun | F15: Downtown-3 | G15: General | J15: Team Meeting & Workshop | K15: 0 | L15: Small Event | S15: Confirmed (Done) | T15: Not Required
A16: =IF(OR(D16<>"",H16<>"",I16<>"",Q16<>"",S16<>""), "EVT-" & TEXT(B16, "0000") & "-" & TEXT(COUNTIF(OFFSET($A$1, 1, 0, ROW()-2, 1), "EVT*") + 1, "0000"), "") -> EVT-2026-0014 | B16: 2026 | C16: Jan | D16: 46034 | E16: Mon | F16: Downtown-3 | G16: L-5 | H16: MR-305 & 306 | I16: Inductin Session | J16: Team Meeting & Workshop | K16: 40 | L16: Small Event | M16: 08:00 AM | N16: 05:00 PM | O16: Lunch | Q16: Deshraj | S16: Confirmed (Done) | T16: Not Required | V16: Classroom set up with power extension
A17: =IF(OR(D17<>"",H17<>"",I17<>"",Q17<>"",S17<>""), "EVT-" & TEXT(B17, "0000") & "-" & TEXT(COUNTIF(OFFSET($A$1, 1, 0, ROW()-2, 1), "EVT*") + 1, "0000"), "") -> EVT-2026-0015 | B17: 2026 | C17: Jan | D17: 46034 | E17: Mon | F17: Downtown-3 | G17: General | H17: Breakout Area | I17: Inductin Session | J17: Team Meeting & Workshop | K17: 20 | L17: Small Event | M17: 08:00 AM | N17: 05:00 PM | O17: Lunch | Q17: Deshraj | S17: Confirmed (Done) | T17: Not Required | V17: Classroom set up and require one table and one chair for the facilitator
A18: =IF(OR(D18<>"",H18<>"",I18<>"",Q18<>"",S18<>""), "EVT-" & TEXT(B18, "0000") & "-" & TEXT(COUNTIF(OFFSET($A$1, 1, 0, ROW()-2, 1), "EVT*") + 1, "0000"), "") -> EVT-2026-0016 | B18: 2026 | C18: Jan | D18: 46035 | E18: Tue | F18: Downtown-3 | G18: General | J18: Team Meeting & Workshop | K18: 0 | L18: Small Event | S18: Confirmed (Done) | T18: Not Required | V18: TBC
A19: =IF(OR(D19<>"",H19<>"",I19<>"",Q19<>"",S19<>""), "EVT-" & TEXT(B19, "0000") & "-" & TEXT(COUNTIF(OFFSET($A$1, 1, 0, ROW()-2, 1), "EVT*") + 1, "0000"), "") -> EVT-2026-0017 | B19: 2026 | C19: Jan | D19: 46036 | E19: Wed | F19: Downtown-3 | G19: L-5 | H19: MR-305 & 306 | I19: Inductin Session | J19: Team Meeting & Workshop | K19: 25 | L19: Small Event | M19: 08:00 AM | N19: 05:00 PM | O19: Lunch | Q19: Deshraj | S19: Confirmed (Done) | T19: Not Required
A20: =IF(OR(D20<>"",H20<>"",I20<>"",Q20<>"",S20<>""), "EVT-" & TEXT(B20, "0000") & "-" & TEXT(COUNTIF(OFFSET($A$1, 1, 0, ROW()-2, 1), "EVT*") + 1, "0000"), "") -> EVT-2026-0018 | B20: 2026 | C20: Jan | D20: 46036 | E20: Wed | F20: Downtown-3 | G20: General | H20: Breakout Area | J20: Team Meeting & Workshop | K20: 0 | L20: Small Event | S20: Confirmed (Done) | T20: Not Required
A21: =IF(OR(D21<>"",H21<>"",I21<>"",Q21<>"",S21<>""), "EVT-" & TEXT(B21, "0000") & "-" & TEXT(COUNTIF(OFFSET($A$1, 1, 0, ROW()-2, 1), "EVT*") + 1, "0000"), "") -> EVT-2026-0019 | B21: 2026 | C21: Jan | D21: 46037 | E21: Thu | F21: Downtown-3 | G21: L-5 | H21: MR-305 & 306 | I21: Communicating with Impact (FCO + Nom) | J21: Team Meeting & Workshop | K21: 25 | L21: Small Event | M21: 02:30 PM | N21: 04:30 PM | Q21: Deshraj | S21: Confirmed (Done) | T21: Not Required | V21: Cluster Set up- add onlyone chair and one chair+table for the facilitator
A22: =IF(OR(D22<>"",H22<>"",I22<>"",Q22<>"",S22<>""), "EVT-" & TEXT(B22, "0000") & "-" & TEXT(COUNTIF(OFFSET($A$1, 1, 0, ROW()-2, 1), "EVT*") + 1, "0000"), "") -> EVT-2026-0020 | B22: 2026 | C22: Jan | D22: 46037 | E22: Thu | F22: Downtown-3 | G22: General | H22: Cafeteria + Breakout Area | I22: Risk Awareness session for Enterprise Data team | J22: Team Meeting & Workshop | K22: 200 | L22: Big Event | M22: 03:00 PM | N22: 04:00 PM | Q22: Maanshu Chugh | S22: Confirmed (Done) | T22: Not Required | U22: 46028 | V22: Theater style
A23: =IF(OR(D23<>"",H23<>"",I23<>"",Q23<>"",S23<>""), "EVT-" & TEXT(B23, "0000") & "-" & TEXT(COUNTIF(OFFSET($A$1, 1, 0, ROW()-2, 1), "EVT*") + 1, "0000"), "") -> EVT-2026-0021 | B23: 2026 | C23: Jan | D23: 46038 | E23: Fri | F23: Downtown-3 | G23: General | H23: Cafeteria | I23: Culture Immersion NH + Nominations | J23: Team Meeting & Workshop | K23: 50 | L23: Small Event | M23: 03:00 PM | N23: 04:30 PM | Q23: Deshraj | S23: Confirmed (Done) | T23: Not Required | V23: Theater style
A24: =IF(OR(D24<>"",H24<>"",I24<>"",Q24<>"",S24<>""), "EVT-" & TEXT(B24, "0000") & "-" & TEXT(COUNTIF(OFFSET($A$1, 1, 0, ROW()-2, 1), "EVT*") + 1, "0000"), "") -> EVT-2026-0022 | B24: 2026 | C24: Jan | D24: 46039 | E24: Sat | F24: Downtown-3 | G24: General | I24: Hiring Drive | J24: Assessment & Hiring | K24: 0 | L24: Small Event | M24: 08:00 AM | N24: 05:00 PM | Q24: Mohit Mishra/ Monika Nigam | S24: Confirmed (Done) | T24: Not Required
A25: =IF(OR(D25<>"",H25<>"",I25<>"",Q25<>"",S25<>""), "EVT-" & TEXT(B25, "0000") & "-" & TEXT(COUNTIF(OFFSET($A$1, 1, 0, ROW()-2, 1), "EVT*") + 1, "0000"), "") -> EVT-2026-0023 | B25: 2026 | C25: Jan | D25: 46040 | E25: Sun | F25: Downtown-3 | G25: General | J25: Team Meeting & Workshop | K25: 0 | L25: Small Event | S25: Confirmed (Done) | T25: Not Required
A26: =IF(OR(D26<>"",H26<>"",I26<>"",Q26<>"",S26<>""), "EVT-" & TEXT(B26, "0000") & "-" & TEXT(COUNTIF(OFFSET($A$1, 1, 0, ROW()-2, 1), "EVT*") + 1, "0000"), "") -> EVT-2026-0024 | B26: 2026 | C26: Jan | D26: 46041 | E26: Mon | F26: Downtown-3 | G26: L-5 | H26: MR-305 & 306 | I26: Induction Session (perm -305 and 306) contractors- (breakout area) | J26: Induction & Onboarding | K26: 70 | L26: Small Event | M26: 08:00 AM | N26: 05:00 PM | O26: Lunch | Q26: Deshraj | S26: Confirmed (Done) | T26: Not Required | U26: 46001 | V26: Classroom set up
A27: =IF(OR(D27<>"",H27<>"",I27<>"",Q27<>"",S27<>""), "EVT-" & TEXT(B27, "0000") & "-" & TEXT(COUNTIF(OFFSET($A$1, 1, 0, ROW()-2, 1), "EVT*") + 1, "0000"), "") -> EVT-2026-0025 | B27: 2026 | C27: Jan | D27: 46041 | E27: Mon | F27: Downtown-3 | G27: General | H27: Breakout Area | J27: Team Meeting & Workshop | K27: 0 | L27: Small Event | Q27: Deshraj | S27: Confirmed (Done) | T27: Not Required | V27: Classroom set up
A28: =IF(OR(D28<>"",H28<>"",I28<>"",Q28<>"",S28<>""), "EVT-" & TEXT(B28, "0000") & "-" & TEXT(COUNTIF(OFFSET($A$1, 1, 0, ROW()-2, 1), "EVT*") + 1, "0000"), "") -> EVT-2026-0026 | B28: 2026 | C28: Jan | D28: 46042 | E28: Tue | F28: Downtown-3 | G28: L-5 | H28: MR-305 & 306 | I28: ALT Workshop 2 | J28: Team Meeting & Workshop | K28: 0 | L28: Small Event | M28: 08:30 AM | N28: 04:30 PM | O28: Tea, cookies and Food Arrnagement | Q28: Deshraj | S28: Confirmed (Done) | T28: Not Required | U28: 46364 | V28: Cluster Set Up- Two white boards required
A29: =IF(OR(D29<>"",H29<>"",I29<>"",Q29<>"",S29<>""), "EVT-" & TEXT(B29, "0000") & "-" & TEXT(COUNTIF(OFFSET($A$1, 1, 0, ROW()-2, 1), "EVT*") + 1, "0000"), "") -> EVT-2026-0027 | B29: 2026 | C29: Jan | D29: 46042 | E29: Tue | F29: Downtown-3 | G29: General | J29: Team Meeting & Workshop | K29: 0 | L29: Small Event | S29: Confirmed (Done) | T29: Not Required | V29: Cluster set up
A30: =IF(OR(D30<>"",H30<>"",I30<>"",Q30<>"",S30<>""), "EVT-" & TEXT(B30, "0000") & "-" & TEXT(COUNTIF(OFFSET($A$1, 1, 0, ROW()-2, 1), "EVT*") + 1, "0000"), "") -> EVT-2026-0028 | B30: 2026 | C30: Jan | D30: 46042 | E30: Tue | F30: Downtown-3 | G30: General | H30: Breakout Area | I30: Internal Sourcing Training | J30: Training & Enablement | K30: 30 | L30: Small Event | M30: 02:00 PM | N30: 04:00 PM | Q30: Tushar Mudgil | S30: Confirmed (Done) | T30: Not Required | U30: 46035 | V30: Theater set up
A31: =IF(OR(D31<>"",H31<>"",I31<>"",Q31<>"",S31<>""), "EVT-" & TEXT(B31, "0000") & "-" & TEXT(COUNTIF(OFFSET($A$1, 1, 0, ROW()-2, 1), "EVT*") + 1, "0000"), "") -> EVT-2026-0029 | B31: 2026 | C31: Jan | D31: 46043 | E31: Wed | F31: Downtown-3 | G31: General | H31: Breakout Area | I31: Internal Sourcing Training | J31: Training & Enablement | K31: 30 | L31: Small Event | M31: 02:00 PM | N31: 04:00 PM | Q31: Tushar Mudgil | S31: Canceled | T31: Not Required | U31: 46035 | V31: Theater set up
A32: =IF(OR(D32<>"",H32<>"",I32<>"",Q32<>"",S32<>""), "EVT-" & TEXT(B32, "0000") & "-" & TEXT(COUNTIF(OFFSET($A$1, 1, 0, ROW()-2, 1), "EVT*") + 1, "0000"), "") -> EVT-2026-0030 | B32: 2026 | C32: Jan | D32: 46044 | E32: Thu | F32: Downtown-3 | G32: General | H32: Breakou Area | I32: Q1 R&R Ceremony (Business Lending) | J32: Team Meeting & Workshop | K32: 70 | L32: Small Event | M32: 09:30 AM | N32: 10:15 AM | Q32: Jackie Jose | S32: Canceled | T32: Not Required | U32: 46035 | V32: Theater style | W32: Moved to DT-4 Hackable space
A33: =IF(OR(D33<>"",H33<>"",I33<>"",Q33<>"",S33<>""), "EVT-" & TEXT(B33, "0000") & "-" & TEXT(COUNTIF(OFFSET($A$1, 1, 0, ROW()-2, 1), "EVT*") + 1, "0000"), "") -> EVT-2026-0031 | B33: 2026 | C33: Jan | D33: 46044 | E33: Thu | F33: Downtown-3 | G33: General | J33: Team Meeting & Workshop | K33: 0 | L33: Small Event | S33: Confirmed (Done) | T33: Not Required | V33: Theater style
A34: =IF(OR(D34<>"",H34<>"",I34<>"",Q34<>"",S34<>""), "EVT-" & TEXT(B34, "0000") & "-" & TEXT(COUNTIF(OFFSET($A$1, 1, 0, ROW()-2, 1), "EVT*") + 1, "0000"), "") -> EVT-2026-0032 | B34: 2026 | C34: Jan | D34: 46044 | E34: Thu | F34: Downtown-3 | G34: General | H34: Breakou Area | I34: DCO Fun Crew – Republic Day Event” | J34: Team Meeting & Workshop | K34: 60 | L34: Small Event | M34: 03:00 PM | N34: 04:30 PM | Q34: Arpan Relan | S34: Confirmed (Done) | T34: Not Required | U34: 46027 | V34: Theater Style
A35: =IF(OR(D35<>"",H35<>"",I35<>"",Q35<>"",S35<>""), "EVT-" & TEXT(B35, "0000") & "-" & TEXT(COUNTIF(OFFSET($A$1, 1, 0, ROW()-2, 1), "EVT*") + 1, "0000"), "") -> EVT-2026-0033 | B35: 2026 | C35: Jan | D35: 46045 | E35: Fri | F35: Downtown-3 | G35: General | H35: Social Hub 2 | I35: Lunch | J35: Social & Team Connect | K35: 0 | L35: Small Event | Q35: Sameer Duttta | S35: Confirmed (Done) | T35: Not Required | U35: 46044 | V35: Sameer will share the details /
A36: =IF(OR(D36<>"",H36<>"",I36<>"",Q36<>"",S36<>""), "EVT-" & TEXT(B36, "0000") & "-" & TEXT(COUNTIF(OFFSET($A$1, 1, 0, ROW()-2, 1), "EVT*") + 1, "0000"), "") -> EVT-2026-0034 | B36: 2026 | C36: Jan | D36: 46046 | E36: Sat | F36: Downtown-3 | G36: General | I36: Hiring Drive | J36: Assessment & Hiring | K36: 0 | L36: Small Event | M36: 08:00 AM | N36: 05:00 PM | Q36: Eisha Mittal | S36: Confirmed (Done) | T36: Not Required | U36: 46031
A37: =IF(OR(D37<>"",H37<>"",I37<>"",Q37<>"",S37<>""), "EVT-" & TEXT(B37, "0000") & "-" & TEXT(COUNTIF(OFFSET($A$1, 1, 0, ROW()-2, 1), "EVT*") + 1, "0000"), "") -> EVT-2026-0035 | B37: 2026 | C37: Jan | D37: 46047 | E37: Sun | F37: Downtown-3 | G37: General | J37: Team Meeting & Workshop | K37: 0 | L37: Small Event | S37: Confirmed (Done) | T37: Not Required
A38: =IF(OR(D38<>"",H38<>"",I38<>"",Q38<>"",S38<>""), "EVT-" & TEXT(B38, "0000") & "-" & TEXT(COUNTIF(OFFSET($A$1, 1, 0, ROW()-2, 1), "EVT*") + 1, "0000"), "") -> EVT-2026-0036 | B38: 2026 | C38: Jan | D38: 46049 | E38: Tue | F38: Downtown-3 | G38: L-5 | H38: MR-305 and 306 | I38: Induction Session (perm -305 and 306) contractors- (breakout area) | J38: Induction & Onboarding | K38: 0 | L38: Small Event | M38: 08:00 AM | N38: 05:00 PM | O38: Lunch | Q38: Deshraj | S38: Confirmed (Done) | T38: Not Required | V38: Classroom set up
A39: =IF(OR(D39<>"",H39<>"",I39<>"",Q39<>"",S39<>""), "EVT-" & TEXT(B39, "0000") & "-" & TEXT(COUNTIF(OFFSET($A$1, 1, 0, ROW()-2, 1), "EVT*") + 1, "0000"), "") -> EVT-2026-0037 | B39: 2026 | C39: Jan | D39: 46049 | E39: Tue | F39: Downtown-3 | G39: General | H39: Breakout Area | I39: DL Workshop | J39: Team Meeting & Workshop | K39: 0 | L39: Small Event | M39: 08:00 AM | N39: 05:00 PM | O39: Snacks+Lunch | Q39: Deshraj | S39: Confirmed (Done) | T39: Not Required | V39: Classroom set up
A40: =IF(OR(D40<>"",H40<>"",I40<>"",Q40<>"",S40<>""), "EVT-" & TEXT(B40, "0000") & "-" & TEXT(COUNTIF(OFFSET($A$1, 1, 0, ROW()-2, 1), "EVT*") + 1, "0000"), "") -> EVT-2026-0038 | B40: 2026 | C40: Jan | D40: 46050 | E40: Wed | F40: Downtown-3 | G40: L-5 | H40: MR-305 and 306 | I40: DL Workshop | J40: Team Meeting & Workshop | K40: 0 | L40: Small Event | M40: 08:00 AM | N40: 05:00 PM | O40: Snacks+Lunch | Q40: Deshraj | S40: Confirmed (Done) | T40: Not Required | V40: Classroom set up
...

Sheet DT-3 Jan26
A1: 🏠 ⮌ RETURN TO DASHBOARD | D1: DOWNTOWN-3 EVENT OPERATIONS TRACKER • JAN26 | N1: 🟢 Green: Confirmed | 🟡 Yellow: Pending | 🔴 Red: Canceled
A2: Event ID | B2: Event Date | C2: Day | D2: Location | E2: Event Type / Title | F2: Capacity | G2: Event Scale | H2: Event Start Time | I2: Event End Time | J2: F& B | K2: Logistic Support | L2: Booked By | M2: Requester Email | N2: Booking Date | O2: Status | P2: Feedback Form | Q2: Remarks | R2: Booking Taken By
A3: =IF(OR(D3<>"", E3<>"", K3<>"", N3<>""), "EVT-2026-" & TEXT(COUNTIF(OFFSET($A$1, 1, 0, ROW()-2, 1), "EVT*") + 1, "0000"), "") | B3: 46023 | C3: Thu | G3: Small Event | O3: Confirmed (Done) | P3: Not Required
A4: =IF(OR(D4<>"", E4<>"", K4<>"", N4<>""), "EVT-2026-" & TEXT(COUNTIF(OFFSET($A$1, 1, 0, ROW()-2, 1), "EVT*") + 1, "0000"), "") | B4: 46024 | C4: Fri | G4: Small Event | O4: Confirmed (Done) | P4: Not Required
A5: =IF(OR(D5<>"", E5<>"", K5<>"", N5<>""), "EVT-2026-" & TEXT(COUNTIF(OFFSET($A$1, 1, 0, ROW()-2, 1), "EVT*") + 1, "0000"), "") | B5: 46025 | C5: Sat | G5: Small Event | O5: Confirmed (Done) | P5: Not Required
A6: =IF(OR(D6<>"", E6<>"", K6<>"", N6<>""), "EVT-2026-" & TEXT(COUNTIF(OFFSET($A$1, 1, 0, ROW()-2, 1), "EVT*") + 1, "0000"), "") | B6: 46026 | C6: Sun | G6: Small Event | O6: Confirmed (Done) | P6: Not Required
A7: =IF(OR(D7<>"", E7<>"", K7<>"", N7<>""), "EVT-2026-" & TEXT(COUNTIF(OFFSET($A$1, 1, 0, ROW()-2, 1), "EVT*") + 1, "0000"), "") -> EVT-2026-0001 | B7: 46027 | C7: Mon | D7: MR-305 & 306 | E7: Induction Session | F7: 35 | G7: Small Event | H7: 08:00 AM | I7: 05:00 PM | J7: Lunch | L7: Deshraj | N7: 46001 | O7: Confirmed (Done) | P7: Not Required | Q7: Classroom set up with power extension-
A8: =IF(OR(D8<>"", E8<>"", K8<>"", N8<>""), "EVT-2026-" & TEXT(COUNTIF(OFFSET($A$1, 1, 0, ROW()-2, 1), "EVT*") + 1, "0000"), "") -> EVT-2026-0002 | B8: 46027 | C8: Mon | D8: Breakout Area | E8: Induction Session | F8: 35 | G8: Small Event | H8: 08:00 AM | I8: 05:00 PM | J8: Lunch | L8: Deshraj | O8: Confirmed (Done) | P8: Not Required | Q8: Classroom set up with power extension-
A9: =IF(OR(D9<>"", E9<>"", K9<>"", N9<>""), "EVT-2026-" & TEXT(COUNTIF(OFFSET($A$1, 1, 0, ROW()-2, 1), "EVT*") + 1, "0000"), "") | B9: 46028 | C9: Tue | G9: Small Event | O9: Confirmed (Done) | P9: Not Required
A10: =IF(OR(D10<>"", E10<>"", K10<>"", N10<>""), "EVT-2026-" & TEXT(COUNTIF(OFFSET($A$1, 1, 0, ROW()-2, 1), "EVT*") + 1, "0000"), "") | B10: 46029 | C10: Wed | G10: Small Event | O10: Confirmed (Done) | P10: Not Required
A11: =IF(OR(D11<>"", E11<>"", K11<>"", N11<>""), "EVT-2026-" & TEXT(COUNTIF(OFFSET($A$1, 1, 0, ROW()-2, 1), "EVT*") + 1, "0000"), "") | B11: 46030 | C11: Thu | G11: Small Event | O11: Confirmed (Done) | P11: Not Required
A12: =IF(OR(D12<>"", E12<>"", K12<>"", N12<>""), "EVT-2026-" & TEXT(COUNTIF(OFFSET($A$1, 1, 0, ROW()-2, 1), "EVT*") + 1, "0000"), "") | B12: 46031 | C12: Fri | G12: Small Event | O12: Confirmed (Done) | P12: Not Required
A13: =IF(OR(D13<>"", E13<>"", K13<>"", N13<>""), "EVT-2026-" & TEXT(COUNTIF(OFFSET($A$1, 1, 0, ROW()-2, 1), "EVT*") + 1, "0000"), "") -> EVT-2026-0003 | B13: 46032 | C13: Sat | D13: MR-305 & 306 | E13: Driver's Training | F13: 20 | G13: Small Event | H13: 10:00 AM | I13: 01:00 PM | J13: Snacks | L13: Prem Chaudhary | O13: Confirmed (Done) | P13: Not Required | Q13: Arranged the snacks- Cup Cakes, Samosa and tea
A14: =IF(OR(D14<>"", E14<>"", K14<>"", N14<>""), "EVT-2026-" & TEXT(COUNTIF(OFFSET($A$1, 1, 0, ROW()-2, 1), "EVT*") + 1, "0000"), "") -> EVT-2026-0004 | B14: 46032 | C14: Sat | D14: Hiring drive | E14: ZONE C, D and E | G14: Small Event | H14: 08:30 AM | I14: 05:00 PM | L14: Manoj Thakral | O14: Confirmed (Done) | P14: Not Required | Q14: List will be shared shortly.
A15: =IF(OR(D15<>"", E15<>"", K15<>"", N15<>""), "EVT-2026-" & TEXT(COUNTIF(OFFSET($A$1, 1, 0, ROW()-2, 1), "EVT*") + 1, "0000"), "") | B15: 46033 | C15: Sun | G15: Small Event | O15: Confirmed (Done) | P15: Not Required
A16: =IF(OR(D16<>"", E16<>"", K16<>"", N16<>""), "EVT-2026-" & TEXT(COUNTIF(OFFSET($A$1, 1, 0, ROW()-2, 1), "EVT*") + 1, "0000"), "") -> EVT-2026-0005 | B16: 46034 | C16: Mon | D16: MR-305 & 306 | E16: Inductin Session | F16: 40 | G16: Small Event | H16: 08:00 AM | I16: 05:00 PM | J16: Lunch | L16: Deshraj | O16: Confirmed (Done) | P16: Not Required | Q16: Classroom set up with power extension
A17: =IF(OR(D17<>"", E17<>"", K17<>"", N17<>""), "EVT-2026-" & TEXT(COUNTIF(OFFSET($A$1, 1, 0, ROW()-2, 1), "EVT*") + 1, "0000"), "") -> EVT-2026-0006 | B17: 46034 | C17: Mon | D17: Breakout Area | E17: Inductin Session | F17: 20 | G17: Small Event | H17: 08:00 AM | I17: 05:00 PM | J17: Lunch | L17: Deshraj | O17: Confirmed (Done) | P17: Not Required | Q17: Classroom set up and require one table and one chair for the facilitator
A18: =IF(OR(D18<>"", E18<>"", K18<>"", N18<>""), "EVT-2026-" & TEXT(COUNTIF(OFFSET($A$1, 1, 0, ROW()-2, 1), "EVT*") + 1, "0000"), "") | B18: 46035 | C18: Tue | G18: Small Event | O18: Confirmed (Done) | P18: Not Required | Q18: TBC
A19: =IF(OR(D19<>"", E19<>"", K19<>"", N19<>""), "EVT-2026-" & TEXT(COUNTIF(OFFSET($A$1, 1, 0, ROW()-2, 1), "EVT*") + 1, "0000"), "") -> EVT-2026-0007 | B19: 46036 | C19: Wed | D19: MR-305 & 306 | E19: Inductin Session | F19: 25 | G19: Small Event | H19: 08:00 AM | I19: 05:00 PM | J19: Lunch | L19: Deshraj | O19: Confirmed (Done) | P19: Not Required
A20: =IF(OR(D20<>"", E20<>"", K20<>"", N20<>""), "EVT-2026-" & TEXT(COUNTIF(OFFSET($A$1, 1, 0, ROW()-2, 1), "EVT*") + 1, "0000"), "") -> EVT-2026-0008 | B20: 46036 | C20: Wed | D20: Breakout Area | G20: Small Event | O20: Confirmed (Done) | P20: Not Required
A21: =IF(OR(D21<>"", E21<>"", K21<>"", N21<>""), "EVT-2026-" & TEXT(COUNTIF(OFFSET($A$1, 1, 0, ROW()-2, 1), "EVT*") + 1, "0000"), "") -> EVT-2026-0009 | B21: 46037 | C21: Thu | D21: MR-305 & 306 | E21: Communicating with Impact (FCO + Nom) | F21: 25 | G21: Small Event | H21: 02:30 PM | I21: 04:30 PM | L21: Deshraj | O21: Confirmed (Done) | P21: Not Required | Q21: Cluster Set up- add onlyone chair and one chair+table for the facilitator
A22: =IF(OR(D22<>"", E22<>"", K22<>"", N22<>""), "EVT-2026-" & TEXT(COUNTIF(OFFSET($A$1, 1, 0, ROW()-2, 1), "EVT*") + 1, "0000"), "") -> EVT-2026-0010 | B22: 46037 | C22: Thu | D22: Cafeteria + Breakout Area | E22: Risk Awareness session for Enterprise Data team | F22: 200 | G22: Big Event | H22: 03:00 PM | I22: 04:00 PM | L22: Maanshu Chugh | N22: 6th Jan'26 | O22: Confirmed (Done) | P22: Not Required | Q22: Theater style
A23: =IF(OR(D23<>"", E23<>"", K23<>"", N23<>""), "EVT-2026-" & TEXT(COUNTIF(OFFSET($A$1, 1, 0, ROW()-2, 1), "EVT*") + 1, "0000"), "") -> EVT-2026-0011 | B23: 46038 | C23: Fri | D23: Cafeteria | E23: Culture Immersion NH + Nominations | F23: 50 | G23: Small Event | H23: 03:00 PM | I23: 04:30 PM | L23: Deshraj | O23: Confirmed (Done) | P23: Not Required | Q23: Theater style
A24: =IF(OR(D24<>"", E24<>"", K24<>"", N24<>""), "EVT-2026-" & TEXT(COUNTIF(OFFSET($A$1, 1, 0, ROW()-2, 1), "EVT*") + 1, "0000"), "") -> EVT-2026-0012 | B24: 46039 | C24: Sat | E24: Hiring Drive | G24: Small Event | H24: 08:00 AM | I24: 05:00 PM | L24: Mohit Mishra/ Monika Nigam | O24: Confirmed (Done) | P24: Not Required
A25: =IF(OR(D25<>"", E25<>"", K25<>"", N25<>""), "EVT-2026-" & TEXT(COUNTIF(OFFSET($A$1, 1, 0, ROW()-2, 1), "EVT*") + 1, "0000"), "") | B25: 46040 | C25: Sun | G25: Small Event | O25: Confirmed (Done) | P25: Not Required
A26: =IF(OR(D26<>"", E26<>"", K26<>"", N26<>""), "EVT-2026-" & TEXT(COUNTIF(OFFSET($A$1, 1, 0, ROW()-2, 1), "EVT*") + 1, "0000"), "") -> EVT-2026-0013 | B26: 46041 | C26: Mon | D26: MR-305 & 306 | E26: Induction Session (perm -305 and 306) contractors- (breakout area) | F26: 70 | G26: Small Event | H26: 08:00 AM | I26: 05:00 PM | J26: Lunch | L26: Deshraj | N26: 46001 | O26: Confirmed (Done) | P26: Not Required | Q26: Classroom set up
A27: =IF(OR(D27<>"", E27<>"", K27<>"", N27<>""), "EVT-2026-" & TEXT(COUNTIF(OFFSET($A$1, 1, 0, ROW()-2, 1), "EVT*") + 1, "0000"), "") -> EVT-2026-0014 | B27: 46041 | C27: Mon | D27: Breakout Area | G27: Small Event | L27: Deshraj | O27: Confirmed (Done) | P27: Not Required | Q27: Classroom set up
A28: =IF(OR(D28<>"", E28<>"", K28<>"", N28<>""), "EVT-2026-" & TEXT(COUNTIF(OFFSET($A$1, 1, 0, ROW()-2, 1), "EVT*") + 1, "0000"), "") -> EVT-2026-0015 | B28: 46042 | C28: Tue | D28: MR-305 & 306 | E28: ALT Workshop 2 | G28: Small Event | H28: 08:30 AM | I28: 04:30 PM | J28: Tea, cookies and Food Arrnagement | L28: Deshraj | N28: 46364 | O28: Confirmed (Done) | P28: Not Required | Q28: Cluster Set Up- Two white boards required
A29: =IF(OR(D29<>"", E29<>"", K29<>"", N29<>""), "EVT-2026-" & TEXT(COUNTIF(OFFSET($A$1, 1, 0, ROW()-2, 1), "EVT*") + 1, "0000"), "") | B29: 46042 | C29: Tue | G29: Small Event | O29: Confirmed (Done) | P29: Not Required | Q29: Cluster set up
A30: =IF(OR(D30<>"", E30<>"", K30<>"", N30<>""), "EVT-2026-" & TEXT(COUNTIF(OFFSET($A$1, 1, 0, ROW()-2, 1), "EVT*") + 1, "0000"), "") -> EVT-2026-0016 | B30: 46042 | C30: Tue | D30: Breakout Area | E30: Internal Sourcing Training | F30: 30 | G30: Small Event | H30: 02:00 PM | I30: 04:00 PM | L30: Tushar Mudgil | N30: 13th Jan'26 | O30: Confirmed (Done) | P30: Not Required | Q30: Theater set up
A31: =IF(OR(D31<>"", E31<>"", K31<>"", N31<>""), "EVT-2026-" & TEXT(COUNTIF(OFFSET($A$1, 1, 0, ROW()-2, 1), "EVT*") + 1, "0000"), "") -> EVT-2026-0017 | B31: 46043 | C31: Wed | D31: Breakout Area | E31: Internal Sourcing Training | F31: 30 | G31: Small Event | H31: 02:00 PM | I31: 04:00 PM | L31: Tushar Mudgil | N31: 13th Jan'26 | O31: Canceled | P31: Not Required | Q31: Theater set up
A32: =IF(OR(D32<>"", E32<>"", K32<>"", N32<>""), "EVT-2026-" & TEXT(COUNTIF(OFFSET($A$1, 1, 0, ROW()-2, 1), "EVT*") + 1, "0000"), "") -> EVT-2026-0018 | B32: 46044 | C32: Thu | D32: Breakou Area | E32: Q1 R&R Ceremony (Business Lending) | F32: 70 | G32: Small Event | H32: 09:30 AM | I32: 10:15 AM | L32: Jackie Jose | N32: 46035 | O32: Canceled | P32: Not Required | Q32: Theater style | R32: Moved to DT-4 Hackable space
A33: =IF(OR(D33<>"", E33<>"", K33<>"", N33<>""), "EVT-2026-" & TEXT(COUNTIF(OFFSET($A$1, 1, 0, ROW()-2, 1), "EVT*") + 1, "0000"), "") | B33: 46044 | C33: Thu | G33: Small Event | O33: Confirmed (Done) | P33: Not Required | Q33: Theater style
A34: =IF(OR(D34<>"", E34<>"", K34<>"", N34<>""), "EVT-2026-" & TEXT(COUNTIF(OFFSET($A$1, 1, 0, ROW()-2, 1), "EVT*") + 1, "0000"), "") -> EVT-2026-0019 | B34: 46044 | C34: Thu | D34: Breakou Area | E34: DCO Fun Crew – Republic Day Event” | F34: 60 | G34: Small Event | H34: 03:00 PM | I34: 04:30 PM | L34: Arpan Relan | N34: 5th Jan'26 | O34: Confirmed (Done) | P34: Not Required | Q34: Theater Style
A35: =IF(OR(D35<>"", E35<>"", K35<>"", N35<>""), "EVT-2026-" & TEXT(COUNTIF(OFFSET($A$1, 1, 0, ROW()-2, 1), "EVT*") + 1, "0000"), "") -> EVT-2026-0020 | B35: 46045 | C35: Fri | D35: Social Hub 2 | E35: Lunch | G35: Small Event | L35: Sameer Duttta | N35: 46044 | O35: Confirmed (Done) | P35: Not Required | Q35: Sameer will share the details /
A36: =IF(OR(D36<>"", E36<>"", K36<>"", N36<>""), "EVT-2026-" & TEXT(COUNTIF(OFFSET($A$1, 1, 0, ROW()-2, 1), "EVT*") + 1, "0000"), "") -> EVT-2026-0021 | B36: 46046 | C36: Sat | E36: Hiring Drive | G36: Small Event | H36: 08:00 AM | I36: 05:00 PM | L36: Eisha Mittal | N36: 46031 | O36: Confirmed (Done) | P36: Not Required
A37: =IF(OR(D37<>"", E37<>"", K37<>"", N37<>""), "EVT-2026-" & TEXT(COUNTIF(OFFSET($A$1, 1, 0, ROW()-2, 1), "EVT*") + 1, "0000"), "") | B37: 46047 | C37: Sun | G37: Small Event | O37: Confirmed (Done) | P37: Not Required
A38: =IF(OR(D38<>"", E38<>"", K38<>"", N38<>""), "EVT-2026-" & TEXT(COUNTIF(OFFSET($A$1, 1, 0, ROW()-2, 1), "EVT*") + 1, "0000"), "") -> EVT-2026-0022 | B38: 46049 | C38: Tue | D38: MR-305 and 306 | E38: Induction Session (perm -305 and 306) contractors- (breakout area) | G38: Small Event | H38: 08:00 AM | I38: 05:00 PM | J38: Lunch | L38: Deshraj | O38: Confirmed (Done) | P38: Not Required | Q38: Classroom set up
A39: =IF(OR(D39<>"", E39<>"", K39<>"", N39<>""), "EVT-2026-" & TEXT(COUNTIF(OFFSET($A$1, 1, 0, ROW()-2, 1), "EVT*") + 1, "0000"), "") -> EVT-2026-0023 | B39: 46049 | C39: Tue | D39: Breakout Area | E39: DL Workshop | G39: Small Event | H39: 08:00 AM | I39: 05:00 PM | J39: Snacks+Lunch | L39: Deshraj | O39: Confirmed (Done) | P39: Not Required | Q39: Classroom set up
A40: =IF(OR(D40<>"", E40<>"", K40<>"", N40<>""), "EVT-2026-" & TEXT(COUNTIF(OFFSET($A$1, 1, 0, ROW()-2, 1), "EVT*") + 1, "0000"), "") -> EVT-2026-0024 | B40: 46050 | C40: Wed | D40: MR-305 and 306 | E40: DL Workshop | G40: Small Event | H40: 08:00 AM | I40: 05:00 PM | J40: Snacks+Lunch | L40: Deshraj | O40: Confirmed (Done) | P40: Not Required | Q40: Classroom set up
...

Sheet DT-4 Jan26
A1: 🏠 ⮌ RETURN TO DASHBOARD | D1: DOWNTOWN-4 EVENT OPERATIONS TRACKER • JAN26 | O1: 🟢 Green: Confirmed | 🟡 Yellow: Pending | 🔴 Red: Canceled
A2: Event ID | B2: Event Date | C2: Day | D2: Location | E2: Floor | F2: Event Type / Title | G2: Capacity | H2: Event Scale | I2: Event Start Time | J2: Event End Time | K2: F& B | L2: Logistic Support | M2: Booked By | N2: Requester Email | O2: Booking Date | P2: Status | Q2: Feedback Form | R2: Remarks | S2: Booking Taken By
A3: =IF(OR(D3<>"", F3<>"", L3<>"", O3<>""), "EVT-2026-" & TEXT(COUNTIF('DT-3 Jan26'!$A$3:$A$500, "EVT*") + COUNTIF(OFFSET($A$1, 1, 0, ROW()-2, 1), "EVT*") + 1, "0000"), "") -> EVT-2026-0031 | B3: 01/01/2026- 30th Jan'26 | C3: Thur | D3: Hackable Area | E3: 5th Floor | F3: Training | G3: 35 | H3: Small Event | I3: 08:00 AM | J3: 05:00 PM | L3: nO | M3: Binu | O3: 45992 | P3: Confirmed (Done) | Q3: Not Required | R3: Classroom set up and require the Power extension
A4: =IF(OR(D4<>"", F4<>"", L4<>"", O4<>""), "EVT-2026-" & TEXT(COUNTIF('DT-3 Jan26'!$A$3:$A$500, "EVT*") + COUNTIF(OFFSET($A$1, 1, 0, ROW()-2, 1), "EVT*") + 1, "0000"), "") -> EVT-2026-0032 | B4: 01/01/2026- 30th Jan'26 | C4: Thur | D4: Zone E Breakout Area | E4: 5th Floor | F4: Training | G4: 35 | H4: Small Event | I4: 08:00 AM | J4: 05:00 PM | L4: nO | M4: Binu | O4: 45992 | P4: Confirmed (Done) | Q4: Not Required | R4: Classroom set up and require the Power extension
A5: =IF(OR(D5<>"", F5<>"", L5<>"", O5<>""), "EVT-2026-" & TEXT(COUNTIF('DT-3 Jan26'!$A$3:$A$500, "EVT*") + COUNTIF(OFFSET($A$1, 1, 0, ROW()-2, 1), "EVT*") + 1, "0000"), "") | B5: 46024 | C5: Fri | H5: Small Event | P5: Confirmed (Done) | Q5: Not Required
A6: =IF(OR(D6<>"", F6<>"", L6<>"", O6<>""), "EVT-2026-" & TEXT(COUNTIF('DT-3 Jan26'!$A$3:$A$500, "EVT*") + COUNTIF(OFFSET($A$1, 1, 0, ROW()-2, 1), "EVT*") + 1, "0000"), "") | B6: 46025 | C6: Sat | H6: Small Event | P6: Confirmed (Done) | Q6: Not Required
A7: =IF(OR(D7<>"", F7<>"", L7<>"", O7<>""), "EVT-2026-" & TEXT(COUNTIF('DT-3 Jan26'!$A$3:$A$500, "EVT*") + COUNTIF(OFFSET($A$1, 1, 0, ROW()-2, 1), "EVT*") + 1, "0000"), "") | B7: 46026 | C7: Sun | H7: Small Event | P7: Confirmed (Done) | Q7: Not Required
A8: =IF(OR(D8<>"", F8<>"", L8<>"", O8<>""), "EVT-2026-" & TEXT(COUNTIF('DT-3 Jan26'!$A$3:$A$500, "EVT*") + COUNTIF(OFFSET($A$1, 1, 0, ROW()-2, 1), "EVT*") + 1, "0000"), "") | B8: 46027 | C8: Mon | H8: Small Event | P8: Confirmed (Done) | Q8: Not Required
A9: =IF(OR(D9<>"", F9<>"", L9<>"", O9<>""), "EVT-2026-" & TEXT(COUNTIF('DT-3 Jan26'!$A$3:$A$500, "EVT*") + COUNTIF(OFFSET($A$1, 1, 0, ROW()-2, 1), "EVT*") + 1, "0000"), "") -> EVT-2026-0033 | B9: 46028 | C9: Tue | D9: Zone E Breakout Area | E9: L-4 | F9: Codility | G9: 50 | H9: Small Event | I9: 01:30 PM | J9: 04:00 PM | M9: Parul Wadhera | O9: 46008 | P9: Confirmed (Done) | Q9: Not Required | R9: Classroom set up
A10: =IF(OR(D10<>"", F10<>"", L10<>"", O10<>""), "EVT-2026-" & TEXT(COUNTIF('DT-3 Jan26'!$A$3:$A$500, "EVT*") + COUNTIF(OFFSET($A$1, 1, 0, ROW()-2, 1), "EVT*") + 1, "0000"), "") | B10: 46029 | C10: Wed | H10: Small Event | P10: Confirmed (Done) | Q10: Not Required
A11: =IF(OR(D11<>"", F11<>"", L11<>"", O11<>""), "EVT-2026-" & TEXT(COUNTIF('DT-3 Jan26'!$A$3:$A$500, "EVT*") + COUNTIF(OFFSET($A$1, 1, 0, ROW()-2, 1), "EVT*") + 1, "0000"), "") | B11: 46030 | C11: Thu | H11: Small Event | P11: Confirmed (Done) | Q11: Not Required
A12: =IF(OR(D12<>"", F12<>"", L12<>"", O12<>""), "EVT-2026-" & TEXT(COUNTIF('DT-3 Jan26'!$A$3:$A$500, "EVT*") + COUNTIF(OFFSET($A$1, 1, 0, ROW()-2, 1), "EVT*") + 1, "0000"), "") | B12: 46031 | C12: Fri | H12: Small Event | P12: Confirmed (Done) | Q12: Not Required
A13: =IF(OR(D13<>"", F13<>"", L13<>"", O13<>""), "EVT-2026-" & TEXT(COUNTIF('DT-3 Jan26'!$A$3:$A$500, "EVT*") + COUNTIF(OFFSET($A$1, 1, 0, ROW()-2, 1), "EVT*") + 1, "0000"), "") | B13: 46032 | C13: Sat | H13: Small Event | P13: Confirmed (Done) | Q13: Not Required
A14: =IF(OR(D14<>"", F14<>"", L14<>"", O14<>""), "EVT-2026-" & TEXT(COUNTIF('DT-3 Jan26'!$A$3:$A$500, "EVT*") + COUNTIF(OFFSET($A$1, 1, 0, ROW()-2, 1), "EVT*") + 1, "0000"), "") | B14: 46033 | C14: Sun | H14: Small Event | P14: Confirmed (Done) | Q14: Not Required
A15: =IF(OR(D15<>"", F15<>"", L15<>"", O15<>""), "EVT-2026-" & TEXT(COUNTIF('DT-3 Jan26'!$A$3:$A$500, "EVT*") + COUNTIF(OFFSET($A$1, 1, 0, ROW()-2, 1), "EVT*") + 1, "0000"), "") | B15: 46034 | C15: Mon | H15: Small Event | P15: Confirmed (Done) | Q15: Not Required
A16: =IF(OR(D16<>"", F16<>"", L16<>"", O16<>""), "EVT-2026-" & TEXT(COUNTIF('DT-3 Jan26'!$A$3:$A$500, "EVT*") + COUNTIF(OFFSET($A$1, 1, 0, ROW()-2, 1), "EVT*") + 1, "0000"), "") -> EVT-2026-0034 | B16: 46035 | C16: Tue | D16: Zone E Breakout Area | E16: L-4 | F16: Codility | G16: 50 | H16: Small Event | I16: 01:30 PM | J16: 04:00 PM | M16: Parul Wadhera | O16: 46008 | P16: Confirmed (Done) | Q16: Not Required | R16: Classroom set up
A17: =IF(OR(D17<>"", F17<>"", L17<>"", O17<>""), "EVT-2026-" & TEXT(COUNTIF('DT-3 Jan26'!$A$3:$A$500, "EVT*") + COUNTIF(OFFSET($A$1, 1, 0, ROW()-2, 1), "EVT*") + 1, "0000"), "") -> EVT-2026-0035 | B17: 46037 | C17: Thu | D17: Zone E Breakout Area | E17: L-4 | F17: Codility | G17: 50 | H17: Small Event | I17: 01:30 PM | J17: 04:00 PM | M17: Parul Wadhera | P17: Confirmed (Done) | Q17: Not Required
A18: =IF(OR(D18<>"", F18<>"", L18<>"", O18<>""), "EVT-2026-" & TEXT(COUNTIF('DT-3 Jan26'!$A$3:$A$500, "EVT*") + COUNTIF(OFFSET($A$1, 1, 0, ROW()-2, 1), "EVT*") + 1, "0000"), "") -> EVT-2026-0036 | B18: 46037 | C18: Thu | D18: Innovation ARea | E18: L-1 | F18: Townhall | G18: 200 | H18: Big Event | I18: 11:00 AM | J18: 12:30 PM | M18: Kriti Kapoor | O18: 14th Jan'26 | P18: Confirmed (Done) | Q18: Not Required | R18: Theater Style
A19: =IF(OR(D19<>"", F19<>"", L19<>"", O19<>""), "EVT-2026-" & TEXT(COUNTIF('DT-3 Jan26'!$A$3:$A$500, "EVT*") + COUNTIF(OFFSET($A$1, 1, 0, ROW()-2, 1), "EVT*") + 1, "0000"), "") -> EVT-2026-0037 | B19: 46037 | C19: Thu | D19: Zone E Breakout Area | E19: L-4 | F19: Codility | G19: 50 | H19: Small Event | I19: 02:00 PM | J19: 04:00 PM | M19: Parul Wadhera | P19: Confirmed (Done) | Q19: Not Required
A20: =IF(OR(D20<>"", F20<>"", L20<>"", O20<>""), "EVT-2026-" & TEXT(COUNTIF('DT-3 Jan26'!$A$3:$A$500, "EVT*") + COUNTIF(OFFSET($A$1, 1, 0, ROW()-2, 1), "EVT*") + 1, "0000"), "") -> EVT-2026-0038 | B20: 46038 | C20: Fri | D20: Cafeteria | E20: L-5 | F20: Department Townhall | G20: 60 | H20: Small Event | I20: 04:00 PM | J20: 05:00 PM | M20: Prateek Gupta | O20: 7th Jan'26 | P20: Confirmed (Done) | Q20: Not Required | R20: Theater style
A21: =IF(OR(D21<>"", F21<>"", L21<>"", O21<>""), "EVT-2026-" & TEXT(COUNTIF('DT-3 Jan26'!$A$3:$A$500, "EVT*") + COUNTIF(OFFSET($A$1, 1, 0, ROW()-2, 1), "EVT*") + 1, "0000"), "") -> EVT-2026-0039 | B21: 46038 | C21: Fri | D21: Zone E Breakout Area | E21: L-4 | F21: Smart Bytes | G21: 30 | H21: Small Event | I21: 03:00 PM | J21: 03:30 PM | M21: Somaya | O21: 7th Jan'26 | P21: Confirmed (Done) | Q21: Not Required | R21: Theater Style
A22: =IF(OR(D22<>"", F22<>"", L22<>"", O22<>""), "EVT-2026-" & TEXT(COUNTIF('DT-3 Jan26'!$A$3:$A$500, "EVT*") + COUNTIF(OFFSET($A$1, 1, 0, ROW()-2, 1), "EVT*") + 1, "0000"), "") -> EVT-2026-0040 | B22: 46039 | C22: Sat | E22: Hiring Drive | G22: 0.33333333 | H22: Small Event | I22: 05:00 PM | L22: Eisha Mittal- | M22: 2026-01-09 00:00:00 | O22: waiting for the final number of the candidates from Mohit, if numbers are increased then we can keep Eisha hiring drive in Dt-4 | P22: Confirmed (Done) | Q22: Not Required
A23: =IF(OR(D23<>"", F23<>"", L23<>"", O23<>""), "EVT-2026-" & TEXT(COUNTIF('DT-3 Jan26'!$A$3:$A$500, "EVT*") + COUNTIF(OFFSET($A$1, 1, 0, ROW()-2, 1), "EVT*") + 1, "0000"), "") | B23: 46040 | C23: Sun | H23: Small Event | P23: Confirmed (Done) | Q23: Not Required
A24: =IF(OR(D24<>"", F24<>"", L24<>"", O24<>""), "EVT-2026-" & TEXT(COUNTIF('DT-3 Jan26'!$A$3:$A$500, "EVT*") + COUNTIF(OFFSET($A$1, 1, 0, ROW()-2, 1), "EVT*") + 1, "0000"), "") -> EVT-2026-0041 | B24: 46041 | C24: Mon | D24: Hackable Area | E24: L-5 | F24: Fraud Operations- Internal Meeting | G24: 16 | H24: Small Event | I24: 11:00 AM | J24: 12:00 PM | M24: Manu Singh | P24: Confirmed (Done) | Q24: Not Required | R24: Theater style
A25: =IF(OR(D25<>"", F25<>"", L25<>"", O25<>""), "EVT-2026-" & TEXT(COUNTIF('DT-3 Jan26'!$A$3:$A$500, "EVT*") + COUNTIF(OFFSET($A$1, 1, 0, ROW()-2, 1), "EVT*") + 1, "0000"), "") -> EVT-2026-0042 | B25: 46041 | C25: Mon | D25: Hackable Area | E25: L-5 | F25: Introduction sesion Paul cookie- Tech | G25: 70 | H25: Small Event | I25: 02:30 PM | J25: 03:30 PM | M25: Rupika Nagpal | P25: Confirmed (Done) | Q25: Not Required | R25: Theater Style
A26: =IF(OR(D26<>"", F26<>"", L26<>"", O26<>""), "EVT-2026-" & TEXT(COUNTIF('DT-3 Jan26'!$A$3:$A$500, "EVT*") + COUNTIF(OFFSET($A$1, 1, 0, ROW()-2, 1), "EVT*") + 1, "0000"), "") -> EVT-2026-0043 | B26: 46041 | C26: Mon | D26: Zone E Breakout Area | E26: L-4 | F26: Tech Onboarding - | G26: 30 | H26: Small Event | I26: 02:00 PM | J26: 05:00 PM | L26: No | M26: Soamya | O26: 46008 | P26: Confirmed (Done) | Q26: Not Required | R26: Theater style
