Workbook

Sheet Dashboard
A1: CBRE | CONTRACTUAL STAFF MANAGEMENT DASHBOARD
A2: =" Real-Time Workforce Analytics • Automated Duplicate Tracking • Live As Of: " & TEXT(TODAY(), "DD-MMM-YYYY") -> 0
B4: TOTAL HEADCOUNT | D4: ACTIVE STAFF | F4: IN-ACTIVE STAFF | H4: PERMANENT | J4: RELIEVER | L4: BGV COMPLIANT
B5: =C20 -> 0 | D5: =D20 -> 0 | F5: =E20 -> 0 | H5: =F20 -> 0 | J5: =G20 -> 0 | L5: =J20 -> 0
B9: 🏢 AGENCY-WISE STAFF BREAKDOWN (AUTOMATED SUMMARY TABLE)
B10: Click any Agency Navigation Switch below to filter & view staff details:
B13: Agency Name | C13: Total Staff | D13: Active | E13: In-Active | F13: Permanent | G13: Reliever | H13: DT3 Loc | I13: DT4 Loc | J13: BGV Done | K13: ID Issued | L13: Active %
B14: CBRE | C14: =COUNTIF('Contractual Staff Details'!$C$3:$C$5000, "CBRE") -> 0 | D14: =COUNTIFS('Contractual Staff Details'!$C$3:$C$5000, "CBRE", 'Contractual Staff Details'!$S$3:$S$5000, "Active") -> 0 | E14: =COUNTIFS('Contractual Staff Details'!$C$3:$C$5000, "CBRE", 'Contractual Staff Details'!$S$3:$S$5000, "In-Active") + COUNTIFS('Contractual Staff Details'!$C$3:$C$5000, "CBRE", 'Contractual Staff Details'!$S$3:$S$5000, "Inactive") -> 0 | F14: =COUNTIFS('Contractual Staff Details'!$C$3:$C$5000, "CBRE", 'Contractual Staff Details'!$X$3:$X$5000, "Permanent*") -> 0 | G14: =COUNTIFS('Contractual Staff Details'!$C$3:$C$5000, "CBRE", 'Contractual Staff Details'!$X$3:$X$5000, "Relie*") + COUNTIFS('Contractual Staff Details'!$C$3:$C$5000, "CBRE", 'Contractual Staff Details'!$X$3:$X$5000, "Reliv*") -> 0 | H14: =COUNTIFS('Contractual Staff Details'!$C$3:$C$5000, "CBRE", 'Contractual Staff Details'!$J$3:$J$5000, "*DT*3*") -> 0 | I14: =COUNTIFS('Contractual Staff Details'!$C$3:$C$5000, "CBRE", 'Contractual Staff Details'!$J$3:$J$5000, "*DT*4*") -> 0 | J14: =COUNTIFS('Contractual Staff Details'!$C$3:$C$5000, "CBRE", 'Contractual Staff Details'!$T$3:$T$5000, "Yes*") + COUNTIFS('Contractual Staff Details'!$C$3:$C$5000, "CBRE", 'Contractual Staff Details'!$T$3:$T$5000, "Shared*") -> 0 | K14: =COUNTIFS('Contractual Staff Details'!$C$3:$C$5000, "CBRE", 'Contractual Staff Details'!$U$3:$U$5000, "Yes*") + COUNTIFS('Contractual Staff Details'!$C$3:$C$5000, "CBRE", 'Contractual Staff Details'!$U$3:$U$5000, "Available*") -> 0 | L14: =IF(C14>0, D14/C14, 0) -> 0
B15: EHK | C15: =COUNTIF('Contractual Staff Details'!$C$3:$C$5000, "EHK") + COUNTIF('Contractual Staff Details'!$C$3:$C$5000, "*Express*") -> 0 | D15: =COUNTIFS('Contractual Staff Details'!$C$3:$C$5000, "EHK", 'Contractual Staff Details'!$S$3:$S$5000, "Active") + COUNTIFS('Contractual Staff Details'!$C$3:$C$5000, "*Express*", 'Contractual Staff Details'!$S$3:$S$5000, "Active") -> 0 | E15: =COUNTIFS('Contractual Staff Details'!$C$3:$C$5000, "EHK", 'Contractual Staff Details'!$S$3:$S$5000, "In-Active") + COUNTIFS('Contractual Staff Details'!$C$3:$C$5000, "EHK", 'Contractual Staff Details'!$S$3:$S$5000, "Inactive") + COUNTIFS('Contractual Staff Details'!$C$3:$C$5000, "*Express*", 'Contractual Staff Details'!$S$3:$S$5000, "In-Active") + COUNTIFS('Contractual Staff Details'!$C$3:$C$5000, "*Express*", 'Contractual Staff Details'!$S$3:$S$5000, "Inactive") -> 0 | F15: =COUNTIFS('Contractual Staff Details'!$C$3:$C$5000, "EHK", 'Contractual Staff Details'!$X$3:$X$5000, "Permanent*") + COUNTIFS('Contractual Staff Details'!$C$3:$C$5000, "*Express*", 'Contractual Staff Details'!$X$3:$X$5000, "Permanent*") -> 0 | G15: =COUNTIFS('Contractual Staff Details'!$C$3:$C$5000, "EHK", 'Contractual Staff Details'!$X$3:$X$5000, "Relie*") + COUNTIFS('Contractual Staff Details'!$C$3:$C$5000, "EHK", 'Contractual Staff Details'!$X$3:$X$5000, "Reliv*") + COUNTIFS('Contractual Staff Details'!$C$3:$C$5000, "*Express*", 'Contractual Staff Details'!$X$3:$X$5000, "Relie*") + COUNTIFS('Contractual Staff Details'!$C$3:$C$5000, "*Express*", 'Contractual Staff Details'!$X$3:$X$5000, "Reliv*") -> 0 | H15: =COUNTIFS('Contractual Staff Details'!$C$3:$C$5000, "EHK", 'Contractual Staff Details'!$J$3:$J$5000, "*DT*3*") + COUNTIFS('Contractual Staff Details'!$C$3:$C$5000, "*Express*", 'Contractual Staff Details'!$J$3:$J$5000, "*DT*3*") -> 0 | I15: =COUNTIFS('Contractual Staff Details'!$C$3:$C$5000, "EHK", 'Contractual Staff Details'!$J$3:$J$5000, "*DT*4*") + COUNTIFS('Contractual Staff Details'!$C$3:$C$5000, "*Express*", 'Contractual Staff Details'!$J$3:$J$5000, "*DT*4*") -> 0 | J15: =COUNTIFS('Contractual Staff Details'!$C$3:$C$5000, "EHK", 'Contractual Staff Details'!$T$3:$T$5000, "Yes*") + COUNTIFS('Contractual Staff Details'!$C$3:$C$5000, "EHK", 'Contractual Staff Details'!$T$3:$T$5000, "Shared*") + COUNTIFS('Contractual Staff Details'!$C$3:$C$5000, "*Express*", 'Contractual Staff Details'!$T$3:$T$5000, "Yes*") + COUNTIFS('Contractual Staff Details'!$C$3:$C$5000, "*Express*", 'Contractual Staff Details'!$T$3:$T$5000, "Shared*") -> 0 | K15: =COUNTIFS('Contractual Staff Details'!$C$3:$C$5000, "EHK", 'Contractual Staff Details'!$U$3:$U$5000, "Yes*") + COUNTIFS('Contractual Staff Details'!$C$3:$C$5000, "EHK", 'Contractual Staff Details'!$U$3:$U$5000, "Available*") + COUNTIFS('Contractual Staff Details'!$C$3:$C$5000, "*Express*", 'Contractual Staff Details'!$U$3:$U$5000, "Yes*") + COUNTIFS('Contractual Staff Details'!$C$3:$C$5000, "*Express*", 'Contractual Staff Details'!$U$3:$U$5000, "Available*") -> 0 | L15: =IF(C15>0, D15/C15, 0) -> 0
B16: SKFM | C16: =COUNTIF('Contractual Staff Details'!$C$3:$C$5000, "SKFM") + COUNTIF('Contractual Staff Details'!$C$3:$C$5000, "*SK Facility*") -> 0 | D16: =COUNTIFS('Contractual Staff Details'!$C$3:$C$5000, "SKFM", 'Contractual Staff Details'!$S$3:$S$5000, "Active") + COUNTIFS('Contractual Staff Details'!$C$3:$C$5000, "*SK Facility*", 'Contractual Staff Details'!$S$3:$S$5000, "Active") -> 0 | E16: =COUNTIFS('Contractual Staff Details'!$C$3:$C$5000, "SKFM", 'Contractual Staff Details'!$S$3:$S$5000, "In-Active") + COUNTIFS('Contractual Staff Details'!$C$3:$C$5000, "SKFM", 'Contractual Staff Details'!$S$3:$S$5000, "Inactive") + COUNTIFS('Contractual Staff Details'!$C$3:$C$5000, "*SK Facility*", 'Contractual Staff Details'!$S$3:$S$5000, "In-Active") + COUNTIFS('Contractual Staff Details'!$C$3:$C$5000, "*SK Facility*", 'Contractual Staff Details'!$S$3:$S$5000, "Inactive") -> 0 | F16: =COUNTIFS('Contractual Staff Details'!$C$3:$C$5000, "SKFM", 'Contractual Staff Details'!$X$3:$X$5000, "Permanent*") + COUNTIFS('Contractual Staff Details'!$C$3:$C$5000, "*SK Facility*", 'Contractual Staff Details'!$X$3:$X$5000, "Permanent*") -> 0 | G16: =COUNTIFS('Contractual Staff Details'!$C$3:$C$5000, "SKFM", 'Contractual Staff Details'!$X$3:$X$5000, "Relie*") + COUNTIFS('Contractual Staff Details'!$C$3:$C$5000, "SKFM", 'Contractual Staff Details'!$X$3:$X$5000, "Reliv*") + COUNTIFS('Contractual Staff Details'!$C$3:$C$5000, "*SK Facility*", 'Contractual Staff Details'!$X$3:$X$5000, "Relie*") + COUNTIFS('Contractual Staff Details'!$C$3:$C$5000, "*SK Facility*", 'Contractual Staff Details'!$X$3:$X$5000, "Reliv*") -> 0 | H16: =COUNTIFS('Contractual Staff Details'!$C$3:$C$5000, "SKFM", 'Contractual Staff Details'!$J$3:$J$5000, "*DT*3*") + COUNTIFS('Contractual Staff Details'!$C$3:$C$5000, "*SK Facility*", 'Contractual Staff Details'!$J$3:$J$5000, "*DT*3*") -> 0 | I16: =COUNTIFS('Contractual Staff Details'!$C$3:$C$5000, "SKFM", 'Contractual Staff Details'!$J$3:$J$5000, "*DT*4*") + COUNTIFS('Contractual Staff Details'!$C$3:$C$5000, "*SK Facility*", 'Contractual Staff Details'!$J$3:$J$5000, "*DT*4*") -> 0 | J16: =COUNTIFS('Contractual Staff Details'!$C$3:$C$5000, "SKFM", 'Contractual Staff Details'!$T$3:$T$5000, "Yes*") + COUNTIFS('Contractual Staff Details'!$C$3:$C$5000, "SKFM", 'Contractual Staff Details'!$T$3:$T$5000, "Shared*") + COUNTIFS('Contractual Staff Details'!$C$3:$C$5000, "*SK Facility*", 'Contractual Staff Details'!$T$3:$T$5000, "Yes*") + COUNTIFS('Contractual Staff Details'!$C$3:$C$5000, "*SK Facility*", 'Contractual Staff Details'!$T$3:$T$5000, "Shared*") -> 0 | K16: =COUNTIFS('Contractual Staff Details'!$C$3:$C$5000, "SKFM", 'Contractual Staff Details'!$U$3:$U$5000, "Yes*") + COUNTIFS('Contractual Staff Details'!$C$3:$C$5000, "SKFM", 'Contractual Staff Details'!$U$3:$U$5000, "Available*") + COUNTIFS('Contractual Staff Details'!$C$3:$C$5000, "*SK Facility*", 'Contractual Staff Details'!$U$3:$U$5000, "Yes*") + COUNTIFS('Contractual Staff Details'!$C$3:$C$5000, "*SK Facility*", 'Contractual Staff Details'!$U$3:$U$5000, "Available*") -> 0 | L16: =IF(C16>0, D16/C16, 0) -> 0
B17: COMPASS | C17: =COUNTIF('Contractual Staff Details'!$C$3:$C$5000, "COMPASS") -> 0 | D17: =COUNTIFS('Contractual Staff Details'!$C$3:$C$5000, "COMPASS", 'Contractual Staff Details'!$S$3:$S$5000, "Active") -> 0 | E17: =COUNTIFS('Contractual Staff Details'!$C$3:$C$5000, "COMPASS", 'Contractual Staff Details'!$S$3:$S$5000, "In-Active") + COUNTIFS('Contractual Staff Details'!$C$3:$C$5000, "COMPASS", 'Contractual Staff Details'!$S$3:$S$5000, "Inactive") -> 0 | F17: =COUNTIFS('Contractual Staff Details'!$C$3:$C$5000, "COMPASS", 'Contractual Staff Details'!$X$3:$X$5000, "Permanent*") -> 0 | G17: =COUNTIFS('Contractual Staff Details'!$C$3:$C$5000, "COMPASS", 'Contractual Staff Details'!$X$3:$X$5000, "Relie*") + COUNTIFS('Contractual Staff Details'!$C$3:$C$5000, "COMPASS", 'Contractual Staff Details'!$X$3:$X$5000, "Reliv*") -> 0 | H17: =COUNTIFS('Contractual Staff Details'!$C$3:$C$5000, "COMPASS", 'Contractual Staff Details'!$J$3:$J$5000, "*DT*3*") -> 0 | I17: =COUNTIFS('Contractual Staff Details'!$C$3:$C$5000, "COMPASS", 'Contractual Staff Details'!$J$3:$J$5000, "*DT*4*") -> 0 | J17: =COUNTIFS('Contractual Staff Details'!$C$3:$C$5000, "COMPASS", 'Contractual Staff Details'!$T$3:$T$5000, "Yes*") + COUNTIFS('Contractual Staff Details'!$C$3:$C$5000, "COMPASS", 'Contractual Staff Details'!$T$3:$T$5000, "Shared*") -> 0 | K17: =COUNTIFS('Contractual Staff Details'!$C$3:$C$5000, "COMPASS", 'Contractual Staff Details'!$U$3:$U$5000, "Yes*") + COUNTIFS('Contractual Staff Details'!$C$3:$C$5000, "COMPASS", 'Contractual Staff Details'!$U$3:$U$5000, "Available*") -> 0 | L17: =IF(C17>0, D17/C17, 0) -> 0
B18: PIHU FOODS | C18: =COUNTIF('Contractual Staff Details'!$C$3:$C$5000, "PIHU FOODS") -> 0 | D18: =COUNTIFS('Contractual Staff Details'!$C$3:$C$5000, "PIHU FOODS", 'Contractual Staff Details'!$S$3:$S$5000, "Active") -> 0 | E18: =COUNTIFS('Contractual Staff Details'!$C$3:$C$5000, "PIHU FOODS", 'Contractual Staff Details'!$S$3:$S$5000, "In-Active") + COUNTIFS('Contractual Staff Details'!$C$3:$C$5000, "PIHU FOODS", 'Contractual Staff Details'!$S$3:$S$5000, "Inactive") -> 0 | F18: =COUNTIFS('Contractual Staff Details'!$C$3:$C$5000, "PIHU FOODS", 'Contractual Staff Details'!$X$3:$X$5000, "Permanent*") -> 0 | G18: =COUNTIFS('Contractual Staff Details'!$C$3:$C$5000, "PIHU FOODS", 'Contractual Staff Details'!$X$3:$X$5000, "Relie*") + COUNTIFS('Contractual Staff Details'!$C$3:$C$5000, "PIHU FOODS", 'Contractual Staff Details'!$X$3:$X$5000, "Reliv*") -> 0 | H18: =COUNTIFS('Contractual Staff Details'!$C$3:$C$5000, "PIHU FOODS", 'Contractual Staff Details'!$J$3:$J$5000, "*DT*3*") -> 0 | I18: =COUNTIFS('Contractual Staff Details'!$C$3:$C$5000, "PIHU FOODS", 'Contractual Staff Details'!$J$3:$J$5000, "*DT*4*") -> 0 | J18: =COUNTIFS('Contractual Staff Details'!$C$3:$C$5000, "PIHU FOODS", 'Contractual Staff Details'!$T$3:$T$5000, "Yes*") + COUNTIFS('Contractual Staff Details'!$C$3:$C$5000, "PIHU FOODS", 'Contractual Staff Details'!$T$3:$T$5000, "Shared*") -> 0 | K18: =COUNTIFS('Contractual Staff Details'!$C$3:$C$5000, "PIHU FOODS", 'Contractual Staff Details'!$U$3:$U$5000, "Yes*") + COUNTIFS('Contractual Staff Details'!$C$3:$C$5000, "PIHU FOODS", 'Contractual Staff Details'!$U$3:$U$5000, "Available*") -> 0 | L18: =IF(C18>0, D18/C18, 0) -> 0
B19: I-con | C19: =COUNTIF('Contractual Staff Details'!$C$3:$C$5000, "I-con") -> 0 | D19: =COUNTIFS('Contractual Staff Details'!$C$3:$C$5000, "I-con", 'Contractual Staff Details'!$S$3:$S$5000, "Active") -> 0 | E19: =COUNTIFS('Contractual Staff Details'!$C$3:$C$5000, "I-con", 'Contractual Staff Details'!$S$3:$S$5000, "In-Active") + COUNTIFS('Contractual Staff Details'!$C$3:$C$5000, "I-con", 'Contractual Staff Details'!$S$3:$S$5000, "Inactive") -> 0 | F19: =COUNTIFS('Contractual Staff Details'!$C$3:$C$5000, "I-con", 'Contractual Staff Details'!$X$3:$X$5000, "Permanent*") -> 0 | G19: =COUNTIFS('Contractual Staff Details'!$C$3:$C$5000, "I-con", 'Contractual Staff Details'!$X$3:$X$5000, "Relie*") + COUNTIFS('Contractual Staff Details'!$C$3:$C$5000, "I-con", 'Contractual Staff Details'!$X$3:$X$5000, "Reliv*") -> 0 | H19: =COUNTIFS('Contractual Staff Details'!$C$3:$C$5000, "I-con", 'Contractual Staff Details'!$J$3:$J$5000, "*DT*3*") -> 0 | I19: =COUNTIFS('Contractual Staff Details'!$C$3:$C$5000, "I-con", 'Contractual Staff Details'!$J$3:$J$5000, "*DT*4*") -> 0 | J19: =COUNTIFS('Contractual Staff Details'!$C$3:$C$5000, "I-con", 'Contractual Staff Details'!$T$3:$T$5000, "Yes*") + COUNTIFS('Contractual Staff Details'!$C$3:$C$5000, "I-con", 'Contractual Staff Details'!$T$3:$T$5000, "Shared*") -> 0 | K19: =COUNTIFS('Contractual Staff Details'!$C$3:$C$5000, "I-con", 'Contractual Staff Details'!$U$3:$U$5000, "Yes*") + COUNTIFS('Contractual Staff Details'!$C$3:$C$5000, "I-con", 'Contractual Staff Details'!$U$3:$U$5000, "Available*") -> 0 | L19: =IF(C19>0, D19/C19, 0) -> 0
B20: TOTAL / ALL AGENCIES | C20: =SUM(C14:C19) -> 0 | D20: =SUM(D14:D19) -> 0 | E20: =SUM(E14:E19) -> 0 | F20: =SUM(F14:F19) -> 0 | G20: =SUM(G14:G19) -> 0 | H20: =SUM(H14:H19) -> 0 | I20: =SUM(I14:I19) -> 0 | J20: =SUM(J14:J19) -> 0 | K20: =SUM(K14:K19) -> 0 | L20: =IF(C20>0, D20/C20, 0) -> 0
B22: 📍 LOCATION-WISE DISTRIBUTION | H22: 🛡️ COMPLIANCE & VERIFICATION STATUS
B23: Location | C23: Headcount | D23: Active | E23: In-Active | F23: Share % | H23: Compliance Item | I23: Target | J23: Completed | K23: Pending | L23: Compliance %
B24: NAB DT 3 | C24: =COUNTIFS('Contractual Staff Details'!$J$3:$J$5000, "*DT*3*", 'Contractual Staff Details'!$J$3:$J$5000, "<>*DT4*") -> 0 | D24: =COUNTIFS('Contractual Staff Details'!$J$3:$J$5000, "*DT*3*", 'Contractual Staff Details'!$J$3:$J$5000, "<>*DT4*", 'Contractual Staff Details'!$S$3:$S$5000, "Active") -> 0 | E24: =COUNTIFS('Contractual Staff Details'!$J$3:$J$5000, "*DT*3*", 'Contractual Staff Details'!$J$3:$J$5000, "<>*DT4*", 'Contractual Staff Details'!$S$3:$S$5000, "In-Active") + COUNTIFS('Contractual Staff Details'!$J$3:$J$5000, "*DT*3*", 'Contractual Staff Details'!$J$3:$J$5000, "<>*DT4*", 'Contractual Staff Details'!$S$3:$S$5000, "Inactive") -> 0 | F24: =IF($C$20>0, C24/$C$20, 0) -> 0 | H24: BGV Verification | I24: =$C$20 -> 0 | J24: =J20 -> 0 | K24: =I24-J24 -> 0 | L24: =IF(I24>0, J24/I24, 0) -> 0
B25: NAB DT 4 | C25: =COUNTIFS('Contractual Staff Details'!$J$3:$J$5000, "*DT*4*", 'Contractual Staff Details'!$J$3:$J$5000, "<>*DT3*") -> 0 | D25: =COUNTIFS('Contractual Staff Details'!$J$3:$J$5000, "*DT*4*", 'Contractual Staff Details'!$J$3:$J$5000, "<>*DT3*", 'Contractual Staff Details'!$S$3:$S$5000, "Active") -> 0 | E25: =COUNTIFS('Contractual Staff Details'!$J$3:$J$5000, "*DT*4*", 'Contractual Staff Details'!$J$3:$J$5000, "<>*DT3*", 'Contractual Staff Details'!$S$3:$S$5000, "In-Active") + COUNTIFS('Contractual Staff Details'!$J$3:$J$5000, "*DT*4*", 'Contractual Staff Details'!$J$3:$J$5000, "<>*DT3*", 'Contractual Staff Details'!$S$3:$S$5000, "Inactive") -> 0 | F25: =IF($C$20>0, C25/$C$20, 0) -> 0 | H25: Vendor ID Card | I25: =$C$20 -> 0 | J25: =K20 -> 0 | K25: =I25-J25 -> 0 | L25: =IF(I25>0, J25/I25, 0) -> 0
B26: DT4/DT3 & Dual | C26: =COUNTIFS('Contractual Staff Details'!$J$3:$J$5000, "*DT*4*", 'Contractual Staff Details'!$J$3:$J$5000, "*DT*3*") -> 0 | D26: =COUNTIFS('Contractual Staff Details'!$J$3:$J$5000, "*DT*4*", 'Contractual Staff Details'!$J$3:$J$5000, "*DT*3*", 'Contractual Staff Details'!$S$3:$S$5000, "Active") -> 0 | E26: =COUNTIFS('Contractual Staff Details'!$J$3:$J$5000, "*DT*4*", 'Contractual Staff Details'!$J$3:$J$5000, "*DT*3*", 'Contractual Staff Details'!$S$3:$S$5000, "In-Active") + COUNTIFS('Contractual Staff Details'!$J$3:$J$5000, "*DT*4*", 'Contractual Staff Details'!$J$3:$J$5000, "*DT*3*", 'Contractual Staff Details'!$S$3:$S$5000, "Inactive") -> 0 | F26: =IF($C$20>0, C26/$C$20, 0) -> 0 | H26: PF / UAN Available | I26: =$C$20 -> 0 | J26: =COUNTIFS('Contractual Staff Details'!$V$3:$V$5000, "<>", 'Contractual Staff Details'!$V$3:$V$5000, "<>NA", 'Contractual Staff Details'!$V$3:$V$5000, "<>N/A", 'Contractual Staff Details'!$V$3:$V$5000, "<>-") -> 0 | K26: =I26-J26 -> 0 | L26: =IF(I26>0, J26/I26, 0) -> 0
B27: Other / Unassigned | C27: =C20 - SUM(C24:C26) -> 0 | D27: =D20 - SUM(D24:D26) -> 0 | E27: =E20 - SUM(E24:E26) -> 0 | F27: =IF($C$20>0, C27/$C$20, 0) -> 0 | H27: ESIC No Available | I27: =$C$20 -> 0 | J27: =COUNTIFS('Contractual Staff Details'!$W$3:$W$5000, "<>", 'Contractual Staff Details'!$W$3:$W$5000, "<>NA", 'Contractual Staff Details'!$W$3:$W$5000, "<>N/A", 'Contractual Staff Details'!$W$3:$W$5000, "<>-") -> 0 | K27: =I27-J27 -> 0 | L27: =IF(I27>0, J27/I27, 0) -> 0
B28: Total | C28: =SUM(C24:C27) -> 0 | D28: =SUM(D24:D27) -> 0 | E28: =SUM(E24:E27) -> 0 | F28: =IF(C28>0, SUM(F24:F27), 0) -> 0

Sheet Contractual Staff Details
A1: =COUNTIF(D3:D5000, "<>") -> 0
A2: S. No. | B2: IPC Partner Name | C2: Agency Name | D2: Emp ID | E2: Name | F2: Father Name | G2: Contact Number | H2: Address | I2: Gender | J2: NAB Location | K2: DOJ | L2: Aging As Of Today | M2: Designation | N2: NAB ID | O2: NAB Line Manager | P2: NAB Manager Email ID | Q2: LM ID | R2: Line Manager Name | S2: Status | T2: BGV Status | U2: Vendor ID Card | V2: PF -UAN No | W2: ESIC No | X2: Permanent / Reliever | Y2: DOE
A3: 1 | B3: CBRE | C3: CBRE | D3: 2070412 | E3: Shishir Tiwari | F3: Mr. KS Tiwari | G3: 9871768697 | H3: 849b, I Block, Palam Vihar, Gurgaon | I3: Male | J3: DT4 | K3: 04-Oct-2025 | L3: =IF(K3="","",IFERROR(ROUND((TODAY()-IF(ISNUMBER(K3),K3,DATEVALUE(K3)))/365.25, 1),"")) -> 0 | M3: AGM | N3: 40027440 | O3: Hitesh Kumar | P3: Hitesh.Kumar2@nab.com.au | Q3: N/A | R3: Shishir | S3: Active | T3: shared | U3: Yes | V3: 100351167375 | W3: N/A | X3: Permanent
A4: 2 | B4: CBRE | C4: CBRE | D4: 1756544 | E4: Naveen Rai | F4: Late Balmiki Rai | G4: 8010743686 | H4: We-95, Second Floor, Mohan Gardan, Uttam Nagar, New Delhi | I4: Male | J4: DT3 | K4: 01-Oct-2025 | L4: =IF(K4="","",IFERROR(ROUND((TODAY()-IF(ISNUMBER(K4),K4,DATEVALUE(K4)))/365.25, 1),"")) -> 0 | M4: AFM-Soft | N4: 40027449 | O4: Hitesh Kumar | P4: Hitesh.Kumar2@nab.com.au | Q4: N/A | R4: Shishir | S4: Active | T4: shared | U4: Yes | V4: 100262850880 | W4: N/A | X4: Permanent
A5: 3 | B5: CBRE | C5: CBRE | D5: 2059197 | E5: Aditya Kumar | F5: Mr.Shiv Shankar Prasad | G5: 7503345712 | H5: A-8 Gali Number 01, Siddhantri Enclave Bhagwati Garden Uttam Nagar New Delhi-110059 | I5: Male | J5: DT4 | K5: 02-Sep-2025 | L5: =IF(K5="","",IFERROR(ROUND((TODAY()-IF(ISNUMBER(K5),K5,DATEVALUE(K5)))/365.25, 1),"")) -> 0 | M5: AFM-Soft | N5: 40027441 | O5: Hitesh Kumar | P5: Hitesh.Kumar2@nab.com.au | Q5: N/A | R5: Shishir | S5: Active | T5: shared | U5: Yes | V5: 101136770356 | W5: N/A | X5: Permanent
A6: 4 | B6: CBRE | C6: CBRE | D6: 2064661 | E6: Sunil Yadav | F6: Mr. Attar Singh Yadav | G6: 9873609474 | H6: H.No. 83, Village -Silokhra, Yadav Street, Gurgaon Haryana-122001 | I6: Male | J6: DT3 | K6: 01-Oct-2025 | L6: =IF(K6="","",IFERROR(ROUND((TODAY()-IF(ISNUMBER(K6),K6,DATEVALUE(K6)))/365.25, 1),"")) -> 0 | M6: Sr. Executive | N6: N/A | O6: Latika Chauhan | P6: Latika.Chauhan1@nab.com.au | Q6: N/A | R6: Shishir | S6: In-Active | T6: Shared | U6: Yes | V6: 100371400244 | W6: N/A | X6: Permanent
A7: 5 | B7: CBRE | C7: CBRE | D7: 1944108 | E7: Arjun Grewal | F7: Mr Sundeep Grewal | G7: 7982567412 | H7: H.No 5 Shivani Enclave Phase 3 Kakrola New Delhi-110078 | I7: Male | J7: DT3 | K7: 01-Oct-2025 | L7: =IF(K7="","",IFERROR(ROUND((TODAY()-IF(ISNUMBER(K7),K7,DATEVALUE(K7)))/365.25, 1),"")) -> 0 | M7: Executive | N7: N/A | O7: Latika Chauhan | P7: Latika.Chauhan1@nab.com.au | Q7: N/A | R7: Shishir | S7: In-Active | T7: Under Process | U7: Yes | V7: 101789388453 | W7: N/A | X7: Permanent
A8: 6 | B8: CBRE | C8: CBRE | D8: 1645923 | E8: Diksha Chhabra | F8: Mr.Ashok Kumar Malik | G8: 9999693534 | H8: Flat No. 903 Tower C9 The Pranayam Sector 82 Neharpar Faridabad | I8: Female | J8: DT4 | K8: 08-Aug-2025 | L8: =IF(K8="","",IFERROR(ROUND((TODAY()-IF(ISNUMBER(K8),K8,DATEVALUE(K8)))/365.25, 1),"")) -> 0 | M8: Executive | N8: 40027418 | O8: Hitesh Kumar | P8: Hitesh.Kumar2@nab.com.au | Q8: N/A | R8: Shishir | S8: Active | T8: shared | U8: Yes | V8: 100540211551 | W8: N/A | X8: Permanent
A9: 7 | B9: CBRE | C9: CBRE | D9: 1882295 | E9: Shashank Tripathi | F9: Narendra Mani Tripathi | G9: 9999153888 | H9: H No. 54, Swaroop Garden, Rajendra Park, Gurugram Haryana. | I9: Male | J9: DT4 | K9: 08-Aug-2025 | L9: =IF(K9="","",IFERROR(ROUND((TODAY()-IF(ISNUMBER(K9),K9,DATEVALUE(K9)))/365.25, 1),"")) -> 0 | M9: Executive | N9: N/A | O9: Hitesh Kumar | P9: Hitesh.Kumar2@nab.com.au | Q9: N/A | R9: Shishir | S9: In-Active | T9: shared | U9: Yes | V9: 100472064203 | W9: N/A | X9: Permanent
A10: 8 | B10: CBRE | C10: CBRE | D10: 1940878 | E10: Santosh | F10: Ramjee Mishra | G10: 8595293708 | H10: H.No 23, Gali No 4, Sheetla Colony Ashok Vihar Phase 3 Near Global Hospital Sector-5, Gurgaon Haryana-122001 | I10: Male | J10: DT4 | K10: 30-Oct-2025 | L10: =IF(K10="","",IFERROR(ROUND((TODAY()-IF(ISNUMBER(K10),K10,DATEVALUE(K10)))/365.25, 1),"")) -> 0 | M10: Executive | N10: N/A | O10: Hitesh Kumar | P10: Hitesh.Kumar2@nab.com.au | Q10: N/A | R10: Shishir | S10: In-Active | T10: shared | U10: Yes | V10: 100952459430 | W10: N/A | X10: Permanent
A11: 9 | B11: CBRE | C11: CBRE | D11: 1933589 | E11: Ayush | F11: Pawan Kumar | G11: 7018492048 | H11: Vill Garoru, Tehsil Joginder Nagar, Distt Mandi Himachal-175015 | I11: Male | J11: DT4 | K11: 20-Nov-2025 | L11: =IF(K11="","",IFERROR(ROUND((TODAY()-IF(ISNUMBER(K11),K11,DATEVALUE(K11)))/365.25, 1),"")) -> 0 | M11: Executive | N11: 40027448 | O11: Hitesh Kumar | P11: Hitesh.Kumar2@nab.com.au | Q11: N/A | R11: Shishir | S11: Active | T11: shared | U11: Yes | V11: 101896315616 | W11: N/A | X11: Permanent
A12: 10 | B12: CBRE | C12: CBRE | D12: 2064660 | E12: Satyabrata Mohanty | F12: Ramesh Chandra Mohanty | G12: 7008952166 | H12: Sec 21, Sonarwali Gali, Dundahera, Gurgaon | I12: Male | J12: DT3 | K12: 01-Oct-2025 | L12: =IF(K12="","",IFERROR(ROUND((TODAY()-IF(ISNUMBER(K12),K12,DATEVALUE(K12)))/365.25, 1),"")) -> 0 | M12: Sr. Executive | N12: 40027445 | O12: Latika Chauhan | P12: Latika.Chauhan1@nab.com.au | Q12: N/A | R12: Shishir | S12: Active | T12: Shared | U12: Yes | V12: 101199207916 | W12: N/A | X12: Permanent
A13: 11 | B13: CBRE | C13: CBRE | D13: 1894401 | E13: Raman | F13: Mr.Ram Mehar | G13: 9992299747 | H13: Pyramid Elite, Sector 86, Gurgaon | I13: Male | J13: DT4 | K13: 08-Aug-2025 | L13: =IF(K13="","",IFERROR(ROUND((TODAY()-IF(ISNUMBER(K13),K13,DATEVALUE(K13)))/365.25, 1),"")) -> 0 | M13: Executive | N13: 40027438 | O13: Hitesh Kumar | P13: Hitesh.Kumar2@nab.com.au | Q13: N/A | R13: Shishir | S13: Active | T13: shared | U13: Yes | V13: 100458160803 | W13: N/A | X13: Permanent
A14: 12 | B14: CBRE | C14: CBRE | D14: 2056224 | E14: Sunil Kumar | F14: Mr. Ram Garib | G14: 8821860330 | H14: Village -Purkhipur Post- Kurebhar Dist-Sultanpur(Up) 228151 | I14: Male | J14: DT4 | K14: 08-Aug-2025 | L14: =IF(K14="","",IFERROR(ROUND((TODAY()-IF(ISNUMBER(K14),K14,DATEVALUE(K14)))/365.25, 1),"")) -> 0 | M14: Executive | N14: 40027419 | O14: Hitesh Kumar | P14: Hitesh.Kumar2@nab.com.au | Q14: N/A | R14: Shishir | S14: Active | T14: shared | U14: Yes | V14: 101181082596 | W14: N/A | X14: Permanent
... A96: 94 | B96: CBRE | C96: EHK | D96: 52837 | E96: Muktar Ali | F96: Basiruddin | G96: 9958736491 | H96: Village- Islampur Murshidabad West Bengal-742202 | I96: Male | J96: DT4 | K96: 08-Aug-2025 | L96: =IF(K96="","",IFERROR(ROUND((TODAY()-IF(ISNUMBER(K96),K96,DATEVALUE(K96)))/365.25, 1),"")) -> 0 | M96: Steward | N96: N/A | O96: Hitesh Kumar | P96: Hitesh.Kumar2@nab.com.au | Q96: N/A | R96: Naveen Rai | S96: Active | T96: Shared | U96: Yes | V96: 101263425783 | W96: 6936399255 | X96: Permanent
A97: 95 | B97: CBRE | C97: EHK | D97: 47697 | E97: Sunil Bayen | F97: Ananda Bayen | G97: 7003526921 | H97: Sanakpur Mayureswar -I Birbhum West Bengal-731245 | I97: Male | J97: DT4 | K97: 08-Aug-2025 | L97: =IF(K97="","",IFERROR(ROUND((TODAY()-IF(ISNUMBER(K97),K97,DATEVALUE(K97)))/365.25, 1),"")) -> 0 | M97: House Boy | N97: N/A | O97: Hitesh Kumar | P97: Hitesh.Kumar2@nab.com.au | Q97: N/A | R97: Naveen Rai | S97: In-Active | T97: Shared | U97: Yes | V97: 102169089743 | W97: 6935727175 | X97: Reliever | Y97: 01-Jul-2026
A98: 96 | B98: CBRE | C98: EHK | D98: 48838 | E98: Gobinda Bayen | F98: Sadai Bayen | G98: 9883223561 | H98: Mahishgram Murshidabad West Bengal -742168 | I98: Male | J98: DT4 | K98: 08-Aug-2025 | L98: =IF(K98="","",IFERROR(ROUND((TODAY()-IF(ISNUMBER(K98),K98,DATEVALUE(K98)))/365.25, 1),"")) -> 0 | M98: House Boy | N98: N/A | O98: Hitesh Kumar | P98: Hitesh.Kumar2@nab.com.au | Q98: N/A | R98: Naveen Rai | S98: In-Active | T98: Shared | U98: Yes | V98: 101263472322 | W98: 6927596790 | X98: Permanent
A99: 97 | B99: CBRE | C99: EHK | D99: 49215 | E99: Rabijit Das | F99: Bikash Das | G99: 6295101698 | H99: Pakhuria Birhum West Bengal-731245 | I99: Male | J99: DT4 | K99: 08-Aug-2025 | L99: =IF(K99="","",IFERROR(ROUND((TODAY()-IF(ISNUMBER(K99),K99,DATEVALUE(K99)))/365.25, 1),"")) -> 0 | M99: House Boy | N99: N/A | O99: Hitesh Kumar | P99: Hitesh.Kumar2@nab.com.au | Q99: N/A | R99: Naveen Rai | S99: In-Active | T99: Shared | U99: Yes | V99: 101815194725 | W99: 6931930916 | X99: Permanent
A100: 98 | B100: CBRE | C100: EHK | D100: 50205 | E100: Netai Das | F100: Ramkumar Das | G100: 8145500867 | H100: Punchthupi Bharwan Murshidabad West Bengal-742161 | I100: Male | J100: DT4 | K100: 08-Aug-2025 | L100: =IF(K100="","",IFERROR(ROUND((TODAY()-IF(ISNUMBER(K100),K100,DATEVALUE(K100)))/365.25, 1),"")) -> 0 | M100: House Boy | N100: N/A | O100: Hitesh Kumar | P100: Hitesh.Kumar2@nab.com.au | Q100: N/A | R100: Naveen Rai | S100: In-Active | T100: Shared | U100: Yes | V100: 101826772934 | W100: 6932044595 | X100: Permanent
A101: 99 | B101: CBRE | C101: EHK | D101: 52293 | E101: Biswajit Das | F101: Uttam Das | G101: 7047739644 | H101: Hno 127 ,Chakkar Pur ,Gurgoan, Haryana,,122001 | I101: Male | J101: DT4 | K101: 08-Aug-2025 | L101: =IF(K101="","",IFERROR(ROUND((TODAY()-IF(ISNUMBER(K101),K101,DATEVALUE(K101)))/365.25, 1),"")) -> 0 | M101: House Boy | N101: N/A | O101: Hitesh Kumar | P101: Hitesh.Kumar2@nab.com.au | Q101: N/A | R101: Naveen Rai | S101: Active | T101: Shared | U101: Yes | V101: 102226051472 | W101: 6936211162 | X101: Permanent
A102: 100 | B102: CBRE | C102: EHK | D102: 53849 | E102: Krishna Das | F102: Goutam Das | G102: 9510350772 | H102: Vill-Burwan, Po-Burwan,Murshidabad ,West Bengal,,742132 | I102: Male | J102: DT4 | K102: 08-Aug-2025 | L102: =IF(K102="","",IFERROR(ROUND((TODAY()-IF(ISNUMBER(K102),K102,DATEVALUE(K102)))/365.25, 1),"")) -> 0 | M102: House Boy | N102: N/A | O102: Hitesh Kumar | P102: Hitesh.Kumar2@nab.com.au | Q102: N/A | R102: Naveen Rai | S102: In-Active | T102: Shared | U102: Yes | V102: 102251232401 | W102: 6936506753 | X102: Permanent
A103: 101 | B103: CBRE | C103: EHK | D103: 48836 | E103: Bapun Das | F103: Babulal Das | G103: 9560490147 | H103: Barakulberiya Purba Hindu Musalman Kaliganj Po-Kaliganj Nadia West Bengal-741150 | I103: Male | J103: DT4 | K103: 08-Aug-2025 | L103: =IF(K103="","",IFERROR(ROUND((TODAY()-IF(ISNUMBER(K103),K103,DATEVALUE(K103)))/365.25, 1),"")) -> 0 | M103: House Boy | N103: N/A | O103: Hitesh Kumar | P103: Hitesh.Kumar2@nab.com.au | Q103: N/A | R103: Naveen Rai | S103: In-Active | T103: Shared | U103: Yes | V103: 101599214472 | W103: 6935789730 | X103: Permanent
A104: 102 | B104: CBRE | C104: EHK | D104: 48845 | E104: Shambhu Sant | F104: Nanigopal Sant | G104: 8597689751 | H104: Jarisaui Jarisai Paschim Medinipur Baita Bazar West Bengal-721420 | I104: Male | J104: DT4 | K104: 08-Aug-2025 | L104: =IF(K104="","",IFERROR(ROUND((TODAY()-IF(ISNUMBER(K104),K104,DATEVALUE(K104)))/365.25, 1),"")) -> 0 | M104: House Boy | N104: N/A | O104: Hitesh Kumar | P104: Hitesh.Kumar2@nab.com.au | Q104: N/A | R104: Naveen Rai | S104: In-Active | T104: Shared | U104: Yes | V104: 102143872775 | W104: 6724136666 | X104: Permanent
A105: 103 | B105: CBRE | C105: EHK | D105: 50117 | E105: Subhankar Bayen | F105: Ganesh Bayen | G105: 8097781843 | H105: Mahishgram Murshidabad West Bengal-742168 | I105: Male | J105: DT4 | K105: 08-Aug-2025 | L105: =IF(K105="","",IFERROR(ROUND((TODAY()-IF(ISNUMBER(K105),K105,DATEVALUE(K105)))/365.25, 1),"")) -> 0 | M105: House Boy | N105: N/A | O105: Hitesh Kumar | P105: Hitesh.Kumar2@nab.com.au | Q105: N/A | R105: Naveen Rai | S105: In-Active | T105: Shared | U105: Yes | V105: 102196667560 | W105: 6936051490 | X105: Permanent
A106: 104 | B106: CBRE | C106: EHK | D106: 33591 | E106: Pintu Shil | F106: Cheraku Shil | G106: 9547393559 | H106: Chakrashail Safa Nagar Dakshin Dinajpur West Bengal-733141 | I106: Male | J106: DT4 | K106: 08-Aug-2025 | L106: =IF(K106="","",IFERROR(ROUND((TODAY()-IF(ISNUMBER(K106),K106,DATEVALUE(K106)))/365.25, 1),"")) -> 0 | M106: House Boy | N106: N/A | O106: Hitesh Kumar | P106: Hitesh.Kumar2@nab.com.au | Q106: N/A | R106: Naveen Rai | S106: In-Active | T106: Shared | U106: Yes | V106: 101916390444 | W106: 6933137354 | X106: Permanent
A107: 105 | B107: CBRE | C107: EHK | D107: 52292 | E107: Goutam Das | F107: Mohan Das | G107: 9732836132 | H107: Hno 127 ,Chakkar Pur ,Gurgoan, Haryana,,122001 | I107: Male | J107: DT4 | K107: 08-Aug-2025 | L107: =IF(K107="","",IFERROR(ROUND((TODAY()-IF(ISNUMBER(K107),K107,DATEVALUE(K107)))/365.25, 1),"")) -> 0 | M107: House Boy | N107: N/A | O107: Hitesh Kumar | P107: Hitesh.Kumar2@nab.com.au | Q107: N/A | R107: Naveen Rai | S107: In-Active | T107: Shared | U107: Yes | V107: 101832936339 | W107: 6724466758 | X107: Permanent
A108: 106 | B108: CBRE | C108: EHK | D108: 48841 | E108: Sukdeb Bayen | F108: Jamini Bayen | G108: 7319244360 | H108: Kurunnarun Kunnarun Murshidabad West Bengal-742161 | I108: Male | J108: DT4 | K108: 08-Aug-2025 | L108: =IF(K108="","",IFERROR(ROUND((TODAY()-IF(ISNUMBER(K108),K108,DATEVALUE(K108)))/365.25, 1),"")) -> 0 | M108: House Boy | N108: N/A | O108: Hitesh Kumar | P108: Hitesh.Kumar2@nab.com.au | Q108: N/A | R108: Naveen Rai | S108: In-Active | T108: Shared | U108: Yes | V108: 102172507975 | W108: 6935838385 | X108: Permanent
A109: 107 | B109: CBRE | C109: EHK | D109: 50115 | E109: Subhash Das | F109: Dinu Das | G109: 8927163496 | H109: Bhrulia Nadia West Bengal-741157 | I109: Male | J109: DT4 | K109: 08-Aug-2025 | L109: =IF(K109="","",IFERROR(ROUND((TODAY()-IF(ISNUMBER(K109),K109,DATEVALUE(K109)))/365.25, 1),"")) -> 0 | M109: House Boy | N109: N/A | O109: Hitesh Kumar | P109: Hitesh.Kumar2@nab.com.au | Q109: N/A | R109: Naveen Rai | S109: In-Active | T109: Shared | U109: Yes | V109: 101804641186 | W109: 6932449139 | X109: Permanent
... A115: 113 | B115: CBRE | C115: EHK | D115: 54982 | E115: Rajib Das | F115: Sukhen Das | G115: 7029418376 | H115: Mahishgram Murshidabad West Benga-742168 | I115: Male | J115: DT4 | K115: 02-Sep-2025 | L115: =IF(K115="","",IFERROR(ROUND((TODAY()-IF(ISNUMBER(K115),K115,DATEVALUE(K115)))/365.25, 1),"")) -> 0 | M115: House Boy | N115: N/A | O115: Hitesh Kumar | P115: Hitesh.Kumar2@nab.com.au | Q115: N/A | R115: Naveen Rai | S115: In-Active | T115: Shared | U115: Yes | V115: 102265881865 | W115: 6936576928 | X115: Permanent
A116: 114 | B116: CBRE | C116: EHK | D116: 53847 | E116: Bishnu Das | F116: Labai Das | G116: 9910357442 | H116: Marjatpur, Birbhum, Beliakuricha,West Bengal,,731234 | I116: Male | J116: DT4 | K116: 20-Aug-2025 | L116: =IF(K116="","",IFERROR(ROUND((TODAY()-IF(ISNUMBER(K116),K116,DATEVALUE(K116)))/365.25, 1),"")) -> 0 | M116: House Boy | N116: N/A | O116: Hitesh Kumar | P116: Hitesh.Kumar2@nab.com.au | Q116: N/A | R116: Naveen Rai | S116: In-Active | T116: Shared | U116: Yes | V116: 102251237218 | W116: 6936506722 | X116: Reliever | Y116: 25-Jun-2026
A117: 115 | B117: CBRE | C117: EHK | D117: 55787 | E117: Satyaban Mondal | F117: Biswanath Mondal | G117: 9038876969 | H117: Haripur Howrah West Bengal-711315 | I117: Male | J117: DT4 | K117: 01-Oct-2025 | L117: =IF(K117="","",IFERROR(ROUND((TODAY()-IF(ISNUMBER(K117),K117,DATEVALUE(K117)))/365.25, 1),"")) -> 0 | M117: House Boy | N117: N/A | O117: Hitesh Kumar | P117: Hitesh.Kumar2@nab.com.au | Q117: N/A | R117: Naveen Rai | S117: In-Active | T117: Shared | U117: Yes | V117: 102267904759 | W117: 6936627195 | X117: Permanent
A118: 116 | B118: CBRE | C118: EHK | D118: 55392 | E118: Santosh Kumar Sharma | F118: Mishrilal Sharma | G118: 7654151620 | H118: Ward -04 Bishanpur Panchayat Paharpur Manahar Chamra Har Vaishali Bihar-844504 | I118: Male | J118: DT3 | K118: 01-Oct-2025 | L118: =IF(K118="","",IFERROR(ROUND((TODAY()-IF(ISNUMBER(K118),K118,DATEVALUE(K118)))/365.25, 1),"")) -> 0 | M118: Hk Supervisor | N118: N/A | O118: Latika Chauhan | P118: Latika.Chauhan1@nab.com.au | Q118: N/A | R118: Naveen Rai | S118: Active | T118: Shared | U118: Yes | V118: 101818188784 | W118: 6932318448 | X118: Permanent
A119: 117 | B119: CBRE | C119: EHK | D119: 55330 | E119: Adittya | F119: BRAJ KISHOR DUAWEDI | G119: 9835749632 | H119: Purani Sahebganj Sahebganj Jharkhand-816109 | I119: Male | J119: DT3 | K119: 01-Oct-2025 | L119: =IF(K119="","",IFERROR(ROUND((TODAY()-IF(ISNUMBER(K119),K119,DATEVALUE(K119)))/365.25, 1),"")) -> 0 | M119: Hk Supervisor | N119: N/A | O119: Latika Chauhan | P119: Latika.Chauhan1@nab.com.au | Q119: N/A | R119: Naveen Rai | S119: Active | T119: Shared | U119: Yes | V119: 102010478638 | W119: 6934100380 | X119: Permanent
A120: 118 | B120: CBRE | C120: EHK | D120: 56291 | E120: Pankaj Kumar | F120: Rakesh Kumar | G120: 98216 59754 | H120: Manipur Rae Bareli Utter Pradesh Manipur Rae Bareli Utter Pradesh-229316 | I120: Male | J120: DT3 | K120: 29-Oct-2025 | L120: =IF(K120="","",IFERROR(ROUND((TODAY()-IF(ISNUMBER(K120),K120,DATEVALUE(K120)))/365.25, 1),"")) -> 0 | M120: Hk Supervisor | N120: N/A | O120: Latika Chauhan | P120: Latika.Chauhan1@nab.com.au | Q120: N/A | R120: Naveen Rai | S120: In-Active | T120: Shared | U120: Yes | V120: 101116460950 | W120: 1115100564 | X120: Permanent
A121: 119 | B121: CBRE | C121: EHK | D121: 56540 | E121: Archana Kumari | F121: Saurav Kumar | G121: 9582875392 | H121: House No -697 Gali No-06 C Chuttan Nagar Bijwasan South West Delhi-110061 | I121: Female | J121: DT3 | K121: 17-Nov-2025 | L121: =IF(K121="","",IFERROR(ROUND((TODAY()-IF(ISNUMBER(K121),K121,DATEVALUE(K121)))/365.25, 1),"")) -> 0 | M121: Hk Supervisor | N121: N/A | O121: Latika Chauhan | P121: Latika.Chauhan1@nab.com.au | Q121: N/A | R121: Naveen Rai | S121: Active | T121: Shared | U121: Yes | V121: 100926794591 | W121: 6929250003 | X121: Permanent
A122: 120 | B122: CBRE | C122: EHK | D122: 55387 | E122: Golap Mostufa | F122: Sajahan Ali | G122: 9395518716 | H122: Vill -Uttar Safakamar Po- Gobardhana Gobardhana Barpeta Assam-781315 | I122: Male | J122: DT3 | K122: 01-Oct-2025 | L122: =IF(K122="","",IFERROR(ROUND((TODAY()-IF(ISNUMBER(K122),K122,DATEVALUE(K122)))/365.25, 1),"")) -> 0 | M122: House Boy | N122: N/A | O122: Latika Chauhan | P122: Latika.Chauhan1@nab.com.au | Q122: N/A | R122: Naveen Rai | S122: In-Active | T122: Shared | U122: Yes | V122: 102110554081 | W122: 4709266476 | X122: Permanent
A123: 121 | B123: CBRE | C123: EHK | D123: 55653 | E123: Rana Saha | F123: Late Nepal Saha | G123: 96438 27197 | H123: Nazirpur Post -Nazir Pur Nadia West Bengal-741165 | I123: Male | J123: DT3 | K123: 01-Oct-2025 | L123: =IF(K123="","",IFERROR(ROUND((TODAY()-IF(ISNUMBER(K123),K123,DATEVALUE(K123)))/365.25, 1),"")) -> 0 | M123: House Boy | N123: N/A | O123: Latika Chauhan | P123: Latika.Chauhan1@nab.com.au | Q123: N/A | R123: Naveen Rai | S123: In-Active | T123: Shared | U123: Yes | V123: 101803310747 | W123: 6932127484 | X123: Permanent
A124: 122 | B124: CBRE | C124: EHK | D124: 56539 | E124: Santosh Kumar | F124: Ramketar | G124: 7275561194 | H124: Pure Diktan Kotva Mohmmadbad Rai Bareli Uttar Pradesh-229126 | I124: Male | J124: DT3 | K124: 01-Nov-2025 | L124: =IF(K124="","",IFERROR(ROUND((TODAY()-IF(ISNUMBER(K124),K124,DATEVALUE(K124)))/365.25, 1),"")) -> 0 | M124: House Boy | N124: N/A | O124: Latika Chauhan | P124: Latika.Chauhan1@nab.com.au | Q124: N/A | R124: Naveen Rai | S124: In-Active | T124: Shared | U124: Yes | V124: 101901556001 | W124: 6934145748 | X124: Permanent
A125: 123 | B125: CBRE | C125: EHK | D125: 55390 | E125: Mosharof Ali | F125: Noor Islam | G125: 9864702535 | H125: Vill- Safakamar Gobardhana Barpeta Assam-781315 | I125: Male | J125: DT3 | K125: 01-Oct-2025 | L125: =IF(K125="","",IFERROR(ROUND((TODAY()-IF(ISNUMBER(K125),K125,DATEVALUE(K125)))/365.25, 1),"")) -> 0 | M125: House Boy | N125: N/A | O125: Latika Chauhan | P125: Latika.Chauhan1@nab.com.au | Q125: N/A | R125: Naveen Rai | S125: In-Active | T125: Shared | U125: Yes | V125: 101698258496 | W125: 5610380792 | X125: Permanent
A126: 124 | B126: CBRE | C126: EHK | D126: 55667 | E126: Sunil Paswan | F126: Mahendra Paswan | G126: 8287320107 | H126: Manjira Post -Manjira Baka Bihar-813102 | I126: Male | J126: DT3 | K126: 11-Oct-2025 | L126: =IF(K126="","",IFERROR(ROUND((TODAY()-IF(ISNUMBER(K126),K126,DATEVALUE(K126)))/365.25, 1),"")) -> 0 | M126: House Boy | N126: N/A | O126: Latika Chauhan | P126: Latika.Chauhan1@nab.com.au | Q126: N/A | R126: Naveen Rai | S126: Active | T126: Shared | U126: Yes | V126: 101354577280 | W126: 6935199211 | X126: Permanent
...
