Workbook

Sheet Dashboard
A1: DT-3 ENERGY CONSUMPTION & EPI PERFORMANCE DASHBOARD (JAN - JUL 2025 vs 2026)
A4: 2026 JAN-JUL AVG EPI | C4: EPI VARIANCE (vs 2025) | E4: NET YTD COST SAVINGS | H4: NET YTD ENERGY SAVED
A5: =I17 -> 103.699 | C5: =J17 -> -0.13118264 | E5: =H25 -> 893612.25 | H5: =D25 -> 83337
A6: Status: Best-in-Class / Efficient | C6: Improved YTD Performance | E6: Jan–July 2026 vs 2025 | H6: Facility Energy Reduction
A8: 1. EPI PERFORMANCE LEVEL BENCHMARK STANDARDS (kWh/m²/year) | E8: 2. DT3 MONTHLY ENERGY CONSUMPTION & EPI TREND (2025 vs 2026 INCL. JULY)
A9: Performance Level | B9: EPI Range (kWh/m²/yr) | C9: Status Category | D9: Facility Benchmark Target | E9: Month | F9: 2025 Cons (kWh) | G9: 2026 Cons (kWh) | H9: 2025 EPI (kWh/m²/yr) | I9: 2026 EPI (kWh/m²/yr) | J9: Variance (EPI)
A10: Average | B10: 160 – 200 | C10: Typical Office | D10: Standard Commercial Building | E10: Jan | F10: =summary!I6 -> 71247 | G10: =summary!U6 -> 78875.6 | H10: =F10*12/9124.2807 -> 93.702071 | I10: =G10*12/9124.2807 -> 103.73499 | J10: =(I10-H10)/H10 -> 0.10707258
A11: Good | B11: 120 – 150 | C11: Efficient Office | D11: Energy Efficient Facility Target | E11: Feb | F11: =summary!J6 -> 74823 | G11: =summary!V6 -> 77805.2 | H11: =F11*12/9124.2807 -> 98.405127 | I11: =G11*12/9124.2807 -> 102.32723 | J11: =(I11-H11)/H11 -> 0.039856729
A12: Excellent | B12: Below 120 | C12: Best-in-Class | D12: DT3 Operational Target (<120) | E12: Mar | F12: =summary!K6 -> 83562 | G12: =summary!W6 -> 80041 | H12: =F12*12/9124.2807 -> 109.89842 | I12: =G12*12/9124.2807 -> 105.2677 | J12: =(I12-H12)/H12 -> -0.042136378
E13: Apr | F13: =summary!L6 -> 91430 | G13: =summary!X6 -> 80188 | H13: =F13*12/9124.2807 -> 120.24619 | I13: =G13*12/9124.2807 -> 105.46103 | J13: =(I13-H13)/H13 -> -0.12295745
E14: May | F14: =summary!M6 -> 94164.2 | G14: =summary!Y6 -> 76356.2 | H14: =F14*12/9124.2807 -> 123.84213 | I14: =G14*12/9124.2807 -> 100.42155 | J14: =(I14-H14)/H14 -> -0.18911646
E15: Jun | F15: =summary!N6 -> 105721.2 | G15: =summary!Z6 -> 82334 | H15: =F15*12/9124.2807 -> 139.04158 | I15: =G15*12/9124.2807 -> 108.28339 | J15: =(I15-H15)/H15 -> -0.2212158
E16: Jul | F16: =summary!O6 -> 114327.2 | G16: =summary!AA6 -> 76337.6 | H16: =F16*12/9124.2807 -> 150.35995 | I16: =G16*12/9124.2807 -> 100.39709 | J16: =(I16-H16)/H16 -> -0.33228838
E17: Jan-Jul AVERAGE | F17: =AVERAGE(F10:F16) -> 90753.514 | G17: =AVERAGE(G10:G16) -> 78848.229 | H17: =F17*12/9124.2807 -> 119.3565 | I17: =G17*12/9124.2807 -> 103.699 | J17: =(I17-H17)/H17 -> -0.13118264
A19: 3. YoY SAVINGS & COMPARATIVE PERFORMANCE ANALYSIS TABLE (JAN - JUL 2025 vs 2026)
A20: Energy Component | B20: 2025 Cons (kWh) | C20: 2026 Cons (kWh) | D20: kWh Savings | E20: % Change (kWh) | F20: 2025 Cost (₹) | G20: 2026 Cost (₹) | H20: Net Cost Savings (₹) | I20: % Cost Savings | J20: Operational Analysis & Savings Justification
A21: EB Electricity (kWh) | B21: =SUM(summary!I2:'summary'!O2) -> 382703 | C21: =SUM(summary!U2:'summary'!AA2) -> 358855 | D21: =B21-C21 -> 23848 | E21: =(C21-B21)/B21 -> -0.062314641 | F21: =B21*7.45 -> 2851137.4 | G21: =C21*7.45 -> 2673469.8 | H21: =F21-G21 -> 177667.6 | I21: =(G21-F21)/F21 -> -0.062314641 | J21: 23,622 kWh EB Savings (-6.2%) achieved YTD via efficiency
A22: AHU HVAC Power (kWh) | B22: =SUM(summary!I3:'summary'!O3) -> 51569 | C22: =SUM(summary!U3:'summary'!AA3) -> 66409 | D22: =B22-C22 -> -14840 | E22: =(C22-B22)/B22 -> 0.28776978 | F22: =B22*7.45 -> 384189.05 | G22: =C22*7.45 -> 494747.05 | H22: =F22-G22 -> -110558 | I22: =(G22-F22)/F22 -> 0.28776978 | J22: Transitioned to 12*5.5 KAM model from May (saved ~4,035 kWh/mo)
A23: DG Backup Power (kWh) | B23: =SUM(summary!I4:'summary'!O4) -> 3159 | C23: =SUM(summary!U4:'summary'!AA4) -> 1970 | D23: =B23-C23 -> 1189 | E23: =(C23-B23)/B23 -> -0.37638493 | F23: =B23*33.85 -> 106932.15 | G23: =C23*33.85 -> 66684.5 | H23: =F23-G23 -> 40247.65 | I23: =(G23-F23)/F23 -> -0.37638493 | J23: DG run hours reduced by 37.8% due to higher utility grid stability
A24: BTU Cooling Load (kWh) | B24: =SUM(summary!I5:'summary'!O5) -> 197843.6 | C24: =SUM(summary!U5:'summary'!AA5) -> 124703.6 | D24: =B24-C24 -> 73140 | E24: =(C24-B24)/B24 -> -0.36968595 | F24: =B24*10.75 -> 2126818.7 | G24: =C24*10.75 -> 1340563.7 | H24: =F24-G24 -> 786255 | I24: =(G24-F24)/F24 -> -0.36968595 | J24: BTU cooling load energy reduced by 35,641 kWh (-18.3%) saving ₹3.83L
A25: Total Facility (Jan-Jul) | B25: =SUM(B21:B24) -> 635274.6 | C25: =SUM(C21:C24) -> 551937.6 | D25: =B25-C25 -> 83337 | E25: =(C25-B25)/B25 -> -0.13118264 | F25: =SUM(F21:F24) -> 5469077.2 | G25: =SUM(G21:G24) -> 4575465 | H25: =F25-G25 -> 893612.25 | I25: =(G25-F25)/F25 -> -0.16339361 | J25: Total Jan–July facility energy cost reduced by ₹5.45L (-9.8%)
A27: 4. KEY OPERATIONAL INSIGHTS & SAVINGS JUSTIFICATION (DT3)
A28: • Operational Model Transition: | C28: Prior to May, DT3 AHUs operated on a 24*7 running schedule. From May onwards, DT3 transitioned to a 12*5.5 KAM model (12 hrs/day, 5.5 days/week), discontinuing night operations and weekend shifts.
A29: • Hours & Energy Saved: | C29: Switching to the 12*5.5 KAM model saved ~12 hrs/day on weekdays and full weekends (~434 operating hrs/mo per AHU, totaling ~1,736 AHU hrs/mo saved). Monthly AHU consumption dropped from 10,301 kWh in April to 6,266 kWh in May (saved 4,035 kWh / -39.2%), 7,682 kWh in June, and 8,308 kWh in July.
A30: • EPI Trend Justification (vs 2025): | C30: Annualized EPI dropped significantly YTD (May EPI: 100.42 vs 123.85 in 2025, -18.9%; June EPI: 108.28 vs 139.05 in 2025, -22.1%; July EPI: 147.21 vs 150.36 in 2025). Overall Jan–Jul average EPI improved from 119.36 to 110.39 kWh/m²/yr (-7.5%), maintaining Best-in-Class status (<120 kWh/m²/yr).
A31: • YTD Cost Savings: | C31: Total Jan–July energy cost fell from ₹55.51L in 2025 to ₹50.06L in 2026, delivering ₹5.45L (-9.8%) cost savings YTD.

Sheet Mar-24
E2: March - 2024
A3: Sr.No | B3: Location | C3: Meter | D3: Previous Reading | E3: 45352 | F3: 45353 | G3: 45354 | H3: 45355 | I3: 45356 | J3: 45357 | K3: 45358 | L3: 45359 | M3: 45360 | N3: 45361 | O3: 45362 | P3: 45363 | Q3: 45364 | R3: 45365 | S3: 45366 | T3: 45367 | U3: 45368 | V3: 45369 | W3: 45370 | X3: 45371 | Y3: 45372 | Z3: 45373 | AA3: 45374 | AB3: 45375 | AC3: 45376 | AD3: 45377 | AE3: 45378 | AF3: 45379 | AG3: 45380 | AH3: 45381 | AI3: 45382 | AJ3: Consumption
E4: Fri | F4: Sat | G4: Sun | H4: Mon | I4: Tue | J4: Wed | K4: Thu | L4: Fri | M4: Sat | N4: Sun | O4: Mon | P4: Tue | Q4: Wed | R4: Thu | S4: Fri | T4: Sat | U4: Sun | V4: Mon | W4: Tue | X4: Wed | Y4: Thu | Z4: Fri | AA4: Sat | AB4: Sun | AC4: Mon | AD4: Tue | AE4: Wed | AF4: Thu | AG4: Fri | AH4: Sat | AI4: Sun
E5: Time | F5: Time | G5: Time | H5: Time | I5: Time | J5: Time | K5: Time | L5: Time | M5: Time | N5: Time | O5: Time | P5: Time | Q5: Time | R5: Time | S5: Time | T5: Time | U5: Time | V5: Time | W5: Time | X5: Time | Y5: Time | Z5: Time | AA5: Time | AB5: Time | AC5: Time | AD5: Time | AE5: Time | AF5: Time | AG5: Time | AH5: Time | AI5: Time
E6: 0.33333333 | F6: 0.33333333 | G6: 0.33333333 | H6: 0.33333333 | I6: 0.33333333 | J6: =#REF!=AN73 -> #REF! | K6: 0.33333333 | L6: 0.33333333 | M6: 0.33333333 | N6: 0.33333333 | O6: 0.33333333 | P6: 0.33333333 | Q6: 0.33333333 | R6: 0.33333333 | S6: 0.33333333 | T6: 0.33333333 | U6: 0.33333333 | V6: 0.33333333 | W6: 0.33333333 | X6: 0.33333333 | Y6: 0.33333333 | Z6: 0.33333333 | AA6: 0.33333333 | AB6: 0.33333333 | AC6: 0.33333333 | AD6: 0.33333333 | AE6: 0.33333333 | AF6: 0.33333333 | AG6: 0.33333333 | AH6: 0.33333333 | AI6: 0.33333333
A7: 1 | C7: SL No 540430038840 (EB Unit) | D7: 6604 | E7: 6890 | F7: 7077 | G7: 7264 | H7: 7501 | I7: 7740 | J7: 8016 | K7: 8260 | L7: 8503 | M7: 8721 | N7: 8938 | O7: 9166 | P7: 9432 | Q7: 9675 | R7: 9922 | S7: 10128 | T7: 10324 | U7: 10542 | V7: 10788 | W7: 11051 | X7: 11305 | Y7: 11563 | Z7: 11784 | AA7: 11987 | AB7: 12185 | AC7: 12392 | AD7: 12629 | AE7: 12859 | AF7: 13093 | AG7: 13317 | AH7: 13516 | AI7: 13613 | AJ7: =AI7-D7 -> 7009
C8: DG | D8: 165 | E8: 218 | F8: 220 | G8: 220 | H8: 220 | I8: 220 | J8: 220 | K8: 220 | L8: 220 | M8: 220 | N8: 220 | O8: 220 | P8: 220 | Q8: 220 | R8: 258 | S8: 271 | T8: 271 | U8: 271 | V8: 271 | W8: 271 | X8: 271 | Y8: 272 | Z8: 272 | AA8: 272 | AB8: 272 | AC8: 272 | AD8: 272 | AE8: 272 | AF8: 272 | AG8: 272 | AH8: 278 | AI8: 278 | AJ8: =AI8-D8 -> 113
A9: 2 | C9: SL No 540430038845 (EB Unit) | D9: 1956 | E9: 1956 | F9: 1956 | G9: 1956 | H9: 1956 | I9: 1956 | J9: 1956 | K9: 1956 | L9: 1956 | M9: 1956 | N9: 1956 | O9: 1956 | P9: 1956 | Q9: 1956 | R9: 1956 | S9: 1956 | T9: 1956 | U9: 1956 | V9: 1956 | W9: 1956 | X9: 1956 | Y9: 1956 | Z9: 1956 | AA9: 1956 | AB9: 1956 | AC9: 1956 | AD9: 1956 | AE9: 1956 | AF9: 1956 | AG9: 1956 | AH9: 1956 | AI9: 1956 | AJ9: =AI9-D9 -> 0
C10: DG | D10: 28 | E10: 28 | F10: 28 | G10: 28 | H10: 28 | I10: 28 | J10: 28 | K10: 28 | L10: 28 | M10: 28 | N10: 28 | O10: 28 | P10: 28 | Q10: 28 | R10: 28 | S10: 28 | T10: 28 | U10: 28 | V10: 28 | W10: 28 | X10: 28 | Y10: 28 | Z10: 28 | AA10: 28 | AB10: 28 | AC10: 28 | AD10: 28 | AE10: 28 | AF10: 28 | AG10: 28 | AH10: 28 | AI10: 28 | AJ10: =AI10-D10 -> 0
A11: 3 | C11: SL No 540430038844 (EB Unit) | D11: 16819 | E11: 17196 | F11: 17459 | G11: 17701 | H11: 18037 | I11: 18363 | J11: 18729 | K11: 19110 | L11: 19460 | M11: 19746 | N11: 20030 | O11: 20356 | P11: 20729 | Q11: 21071 | R11: 21423 | S11: 21703 | T11: 21962 | U11: 22246 | V11: 22598 | W11: 22978 | X11: 23334 | Y11: 23707 | Z11: 24010 | AA11: 24269 | AB11: 24524 | AC11: 24795 | AD11: 25118 | AE11: 25438 | AF11: 25765 | AG11: 26060 | AH11: 26319 | AI11: 26440 | AJ11: =AI11-D11 -> 9621
C12: DG | D12: 352 | E12: 430 | F12: 433 | G12: 433 | H12: 433 | I12: 433 | J12: 433 | K12: 433 | L12: 433 | M12: 433 | N12: 433 | O12: 433 | P12: 433 | Q12: 433 | R12: 491 | S12: 508 | T12: 508 | U12: 508 | V12: 508 | W12: 508 | X12: 508 | Y12: 508 | Z12: 508 | AA12: 508 | AB12: 508 | AC12: 508 | AD12: 508 | AE12: 508 | AF12: 508 | AG12: 508 | AH12: 517 | AI12: 517 | AJ12: =AI12-D12 -> 165
A13: 4 | C13: SL No 540430038821 (EB Unit) | D13: 0 | E13: 0 | F13: 0 | G13: 0 | H13: 0 | I13: 0 | J13: 0 | K13: 0 | L13: 0 | M13: 0 | N13: 0 | O13: 0 | P13: 0 | Q13: 0 | R13: 0 | S13: 0 | T13: 0 | U13: 0 | V13: 0 | W13: 0 | X13: 0 | Y13: 0 | Z13: 0 | AA13: 0 | AB13: 0 | AC13: 0 | AD13: 0 | AE13: 0 | AF13: 0 | AG13: 0 | AH13: 0 | AI13: 0 | AJ13: =AI13-D13 -> 0
C14: DG | D14: 0 | E14: 0 | F14: 0 | G14: 0 | H14: 0 | I14: 0 | J14: 0 | K14: 0 | L14: 0 | M14: 0 | N14: 0 | O14: 0 | P14: 0 | Q14: 0 | R14: 0 | S14: 0 | T14: 0 | U14: 0 | V14: 0 | W14: 0 | X14: 0 | Y14: 0 | Z14: 0 | AA14: 0 | AB14: 0 | AC14: 0 | AD14: 0 | AE14: 0 | AF14: 0 | AG14: 0 | AH14: 0 | AI14: 0 | AJ14: =AI14-D14 -> 0
A15: 5 | C15: SL No 540430038849 (EB Unit) | D15: 2670 | E15: 2868 | F15: 2973 | G15: 3077 | H15: 3235 | I15: 3404 | J15: 3602 | K15: 3782 | L15: 3944 | M15: 4053 | N15: 4163 | O15: 4319 | P15: 4493 | Q15: 4656 | R15: 4826 | S15: 4956 | T15: 5048 | U15: 5170 | V15: 5340 | W15: 5518 | X15: 5697 | Y15: 5870 | Z15: 6024 | AA15: 6138 | AB15: 6241 | AC15: 6359 | AD15: 6496 | AE15: 6649 | AF15: 6811 | AG15: 6975 | AH15: 7097 | AI15: 7150 | AJ15: =AI15-D15 -> 4480
C16: DG | D16: 76 | E16: 120 | F16: 121 | G16: 121 | H16: 121 | I16: 121 | J16: 121 | K16: 121 | L16: 121 | M16: 121 | N16: 121 | O16: 121 | P16: 121 | Q16: 121 | R16: 149 | S16: 154 | T16: 154 | U16: 154 | V16: 154 | W16: 154 | X16: 154 | Y16: 155 | Z16: 155 | AA16: 155 | AB16: 155 | AC16: 155 | AD16: 155 | AE16: 155 | AF16: 155 | AG16: 155 | AH16: 159 | AI16: 159 | AJ16: =AI16-D16 -> 83
A17: 6 | C17: SL No 540430038696 (EB Unit) | D17: 7208 | E17: 7489 | F17: 7616 | G17: 7747 | H17: 7999 | I17: 8168 | J17: 8384 | K17: 8618 | L17: 8862 | M17: 9031 | N17: 9157 | O17: 9390 | P17: 9632 | Q17: 9846 | R17: 10087 | S17: 10280 | T17: 10419 | U17: 10545 | V17: 10792 | W17: 11047 | X17: 11291 | Y17: 11527 | Z17: 11717 | AA17: 11844 | AB17: 11930 | AC17: 12027 | AD17: 12230 | AE17: 12449 | AF17: 12650 | AG17: 12826 | AH17: 12947 | AI17: 13012 | AJ17: =AI17-D17 -> 5804
C18: DG | D18: 171 | E18: 231 | F18: 232 | G18: 232 | H18: 232 | I18: 232 | J18: 232 | K18: 232 | L18: 232 | M18: 232 | N18: 232 | O18: 232 | P18: 232 | Q18: 232 | R18: 284 | S18: 299 | T18: 299 | U18: 299 | V18: 299 | W18: 299 | X18: 299 | Y18: 300 | Z18: 300 | AA18: 300 | AB18: 300 | AC18: 300 | AD18: 300 | AE18: 300 | AF18: 300 | AG18: 300 | AH18: 300 | AI18: 300 | AJ18: =AI18-D18 -> 129
A19: 7 | C19: SL No 540430038843 (EB Unit) | D19: 29055 | E19: 30140 | F19: 30900 | G19: 31689 | H19: 32526 | I19: 33424 | J19: 34380 | K19: 35165 | L19: 35988 | M19: 36654 | N19: 37387 | O19: 38168 | P19: 39015 | Q19: 39822 | R19: 40654 | S19: 41394 | T19: 42060 | U19: 42788 | V19: 43574 | W19: 44408 | X19: 45244 | Y19: 46076 | Z19: 46872 | AA19: 47586 | AB19: 48246 | AC19: 48812 | AD19: 49605 | AE19: 50402 | AF19: 51220 | AG19: 52028 | AH19: 52719 | AI19: 53008 | AJ19: =AI19-D19 -> 23953
C20: DG | D20: 733 | E20: 899 | F20: 904 | G20: 904 | H20: 904 | I20: 904 | J20: 904 | K20: 904 | L20: 904 | M20: 904 | N20: 904 | O20: 904 | P20: 904 | Q20: 904 | R20: 1018 | S20: 1069 | T20: 1069 | U20: 1069 | V20: 1069 | W20: 1069 | X20: 1069 | Y20: 1071 | Z20: 1071 | AA20: 1071 | AB20: 1071 | AC20: 1071 | AD20: 1071 | AE20: 1071 | AF20: 1071 | AG20: 1071 | AH20: 1088 | AI20: 1088 | AJ20: =AI20-D20 -> 355
A21: 8 | C21: SL No 540430038848 (EB Unit) | D21: 12402 | E21: 12517 | F21: 12635 | G21: 12703 | H21: 12814 | I21: 12913 | J21: 13033 | K21: 13109 | L21: 13209 | M21: 13286 | N21: 13390 | O21: 13444 | P21: 13578 | Q21: 13604 | R21: 13679 | S21: 13743 | T21: 13819 | U21: 13866 | V21: 13957 | W21: 14045 | X21: 14134 | Y21: 14245 | Z21: 14376 | AA21: 14488 | AB21: 14603 | AC21: 14696 | AD21: 14849 | AE21: 14966 | AF21: 15108 | AG21: 15239 | AH21: 15398 | AI21: 15438 | AJ21: =AI21-D21 -> 3036
C22: DG | D22: 199 | E22: 223 | F22: 225 | G22: 225 | H22: 225 | I22: 225 | J22: 225 | K22: 225 | L22: 225 | M22: 225 | N22: 225 | O22: 225 | P22: 225 | Q22: 225 | R22: 239 | S22: 244 | T22: 244 | U22: 244 | V22: 244 | W22: 244 | X22: 244 | Y22: 244 | Z22: 244 | AA22: 244 | AB22: 244 | AC22: 244 | AD22: 244 | AE22: 244 | AF22: 244 | AG22: 244 | AH22: 248 | AI22: 248 | AJ22: =AI22-D22 -> 49
A24: 1 | C24: AHU1 | D24: 2568 | E24: 2760 | F24: 2851 | G24: 2952 | H24: 3098 | I24: 3248 | J24: 3398 | K24: 3546 | L24: 3682 | M24: 3771 | N24: 3807 | O24: 3953 | P24: 4051 | Q24: 4130 | R24: 4212 | S24: 4274 | T24: 4333 | U24: 4333 | V24: 4423 | W24: 4540 | X24: 4648 | Y24: 4727 | Z24: 4809 | AA24: 4847 | AB24: 4847 | AC24: 4867 | AD24: 4960 | AE24: 5065 | AF24: 5165 | AG24: 5237 | AH24: 5270 | AI24: 5270 | AJ24: =AI24-D24 -> 2702
C25: DG | D25: 132 | E25: 149 | F25: 151 | G25: 151 | H25: 151 | I25: 151 | J25: 151 | K25: 151 | L25: 151 | M25: 151 | N25: 151 | O25: 151 | P25: 151 | Q25: 151 | R25: 151 | S25: 169 | T25: 172 | U25: 172 | V25: 172 | W25: 172 | X25: 172 | Y25: 172 | Z25: 172 | AA25: 172 | AB25: 172 | AC25: 172 | AD25: 172 | AE25: 172 | AF25: 172 | AG25: 172 | AH25: 173 | AI25: 173 | AJ25: =AI25-D25 -> 41
C26: AHU2 | D26: 2698 | E26: 2834 | F26: 2899 | G26: 2974 | H26: 3076 | I26: 3183 | J26: 3289 | K26: 3401 | L26: 3508 | M26: 3571 | N26: 3597 | O26: 3702 | P26: 3787 | Q26: 3872 | R26: 3956 | S26: 4019 | T26: 4079 | U26: 4079 | V26: 4185 | W26: 4264 | X26: 4351 | Y26: 4430 | Z26: 4507 | AA26: 4548 | AB26: 4548 | AC26: 4567 | AD26: 4700 | AE26: 4781 | AF26: 4861 | AG26: 4972 | AH26: 4964 | AI26: 4964 | AJ26: =AI26-D26 -> 2266
C27: DG | D27: 146 | E27: 155 | F27: 157 | G27: 157 | H27: 157 | I27: 157 | J27: 157 | K27: 157 | L27: 157 | M27: 157 | N27: 157 | O27: 157 | P27: 157 | Q27: 157 | R27: 157 | S27: 175 | T27: 178 | U27: 178 | V27: 178 | W27: 178 | X27: 178 | Y27: 178 | Z27: 178 | AA27: 178 | AB27: 178 | AC27: 178 | AD27: 178 | AE27: 178 | AF27: 178 | AG27: 178 | AH27: 178 | AI27: 178 | AJ27: =AI27-D27 -> 32
A28: 3 | C28: AHU3 | D28: 1243 | E28: 1356 | F28: 1406 | G28: 1463 | H28: 1542 | I28: 1624 | J28: 1704 | K28: 1791 | L28: 1868 | M28: 1929 | N28: 1947 | O28: 2031 | P28: 2096 | Q28: 2156 | R28: 2229 | S28: 2279 | T28: 2291 | U28: 2291 | V28: 2332 | W28: 2382 | X28: 2449 | Y28: 2524 | Z28: 2568 | AA28: 2594 | AB28: 2594 | AC28: 2603 | AD28: 2653 | AE28: 2688 | AF28: 2759 | AG28: 2813 | AH28: 2862 | AI28: 2862 | AJ28: =AI28-D28 -> 1619
C29: DG | D29: 110 | E29: 116 | F29: 117 | G29: 117 | H29: 117 | I29: 117 | J29: 117 | K29: 117 | L29: 117 | M29: 117 | N29: 117 | O29: 117 | P29: 117 | Q29: 117 | R29: 117 | S29: 129 | T29: 129 | U29: 129 | V29: 129 | W29: 129 | X29: 129 | Y29: 129 | Z29: 129 | AA29: 129 | AB29: 129 | AC29: 129 | AD29: 129 | AE29: 129 | AF29: 129 | AG29: 129 | AH29: 129 | AI29: 129 | AJ29: =AI29-D29 -> 19
A30: 4 | C30: AHU4 | D30: 1283 | E30: 1379 | F30: 1447 | G30: 1526 | H30: 1641 | I30: 1763 | J30: 1886 | K30: 2004 | L30: 2125 | M30: 2195 | N30: 2225 | O30: 2345 | P30: 2436 | Q30: 2506 | R30: 2549 | S30: 2615 | T30: 2666 | U30: 2666 | V30: 2760 | W30: 2900 | X30: 2975 | Y30: 3047 | Z30: 3114 | AA30: 3148 | AB30: 3148 | AC30: 3166 | AD30: 3249 | AE30: 3346 | AF30: 3441 | AG30: 3541 | AH30: 3541 | AI30: 3542 | AJ30: =AI30-D30 -> 2259
C31: DG | D31: 89 | E31: 98 | F31: 98 | G31: 98 | H31: 98 | I31: 98 | J31: 98 | K31: 98 | L31: 98 | M31: 98 | N31: 98 | O31: 98 | P31: 98 | Q31: 98 | R31: 117 | S31: 117 | T31: 117 | U31: 117 | V31: 117 | W31: 117 | X31: 117 | Y31: 117 | Z31: 117 | AA31: 117 | AB31: 117 | AC31: 117 | AD31: 117 | AE31: 117 | AF31: 117 | AG31: 117 | AH31: 117 | AI31: 117 | AJ31: =AI31-D31 -> 28
A33: 1 | C33: AHU1 - BTU | D33: 5741.69 | E33: 6562.41 | F33: 6890.24 | G33: 7282.68 | H33: 7893.82 | I33: 8306.92 | J33: 8908.75 | K33: 9501.28 | L33: 10331.83 | M33: 10745.79 | N33: 10745.79 | O33: 11168.93 | P33: 11708.3 | Q33: 12136.9 | R33: 12869.71 | S33: 13327.98 | T33: 13568.36 | U33: 13568.36 | V33: 14217.95 | W33: 14758.62 | X33: 15349.21 | Y33: 15938.04 | Z33: 16487.56 | AA33: 16808.03 | AB33: 16808.03 | AC33: 16954.4 | AD33: 17718.62 | AE33: 18500.95 | AF33: 19332.58 | AG33: 19974.08 | AH33: 20397.69 | AI33: 20397.69 | AJ33: =AI33-D33 -> 14656
A34: 2 | C34: AHU2 - BTU | D34: 6755.88 | E34: 7661.86 | F34: 7970.73 | G34: 8408.61 | H34: 9031.46 | I34: 9433.95 | J34: 10030.26 | K34: 10656.22 | L34: 11185.27 | M34: 11390.86 | N34: 11390.86 | O34: 12035.86 | P34: 12685.61 | Q34: 13185.76 | R34: 13843.29 | S34: 14301.4 | T34: 14565.24 | U34: 14565.24 | V34: 15266.35 | W34: 15829.21 | X34: 16319.61 | Y34: 16865.69 | Z34: 17424.86 | AA34: 17763.58 | AB34: 17763.58 | AC34: 17961 | AD34: 18768.58 | AE34: 19529.06 | AF34: 20169.14 | AG34: 20744.31 | AH34: 21181.85 | AI34: 21181.85 | AJ34: =AI34-D34 -> 14425.97
A35: 3 | C35: AHU3 - BTU | D35: 4835 | E35: 5667.86 | F35: 5917.95 | G35: 6264.13 | H35: 6574.83 | I35: 6724.38 | J35: 6951.63 | K35: 7380.45 | L35: 7862.22 | M35: 7978.5 | N35: 7978.9 | O35: 8330.4 | P35: 8737.58 | Q35: 9120.95 | R35: 9614.02 | S35: 9927.43 | T35: 10088.81 | U35: 10088.81 | V35: 10492.87 | W35: 10968.6 | X35: 11428.92 | Y35: 11964.02 | Z35: 12414.02 | AA35: 12678.79 | AB35: 12678.79 | AC35: 12842.42 | AD35: 13440.25 | AE35: 14006.83 | AF35: 14679.97 | AG35: 15144.65 | AH35: 15520.6 | AI35: 15520.6 | AJ35: =AI35-D35 -> 10685.6
A36: 4 | C36: AHU4 - BTU | D36: 7375.29 | E36: 8046.26 | F36: 8406.3 | G36: 8918.24 | H36: 9381.07 | I36: 9718.97 | J36: 10254.25 | K36: 10874.39 | L36: 11696.27 | M36: 12671 | N36: 12671 | O36: 12735.79 | P36: 13446.2 | Q36: 13979.11 | R36: 14862.99 | S36: 15297.68 | T36: 15611.68 | U36: 15611.68 | V36: 16410.86 | W36: 17079.15 | X36: 17746.73 | Y36: 18455.13 | Z36: 19011.66 | AA36: 19435.86 | AB36: 19435.86 | AC36: 19788.02 | AD36: 20748.15 | AE36: 21703.67 | AF36: 22555.75 | AG36: 23394.23 | AH36: 24009.78 | AI36: 24009.78 | AJ36: =AI36-D36 -> 16634.49
B39: Daily Energy Report
B40: Electricity Consumption
A41: Sr.No | B41: Location | C41: Meter | E41: =E3 -> 45352 | F41: =F3 -> 45353 | G41: =G3 -> 45354 | H41: =H3 -> 45355 | I41: =I3 -> 45356 | J41: =J3 -> 45357 | K41: =K3 -> 45358 | L41: =L3 -> 45359 | ... AI41: =AI3 -> 45382 | AJ41: Consumption
E42: =E4 -> Fri | F42: =F4 -> Sat | G42: =G4 -> Sun | H42: =H4 -> Mon | I42: =I4 -> Tue | J42: =J4 -> Wed | K42: =K4 -> Thu | L42: =L4 -> Fri | ... AI42: =AI4 -> Sun
E43: Time | F43: Time | G43: Time | H43: Time | I43: Time | J43: Time | K43: Time | L43: Time | M43: Time | N43: Time | O43: Time | P43: Time | Q43: Time | R43: Time | S43: Time | T43: Time | U43: Time | V43: Time | W43: Time | X43: Time | Y43: Time | Z43: Time | AA43: Time | AB43: Time | AC43: Time | AD43: Time | AE43: Time | AF43: Time | AG43: Time | AH43: Time | AI43: Time
E44: 0.33333333 | F44: 0.33333333 | G44: 0.33333333 | H44: 0.33333333 | I44: 0.33333333 | J44: 0.33333333 | K44: 0.33333333 | L44: 0.33333333 | M44: 0.33333333 | N44: 0.33333333 | O44: 0.33333333 | P44: 0.33333333 | Q44: 0.33333333 | R44: 0.33333333 | S44: 0.33333333 | T44: 0.33333333 | U44: 0.33333333 | V44: 0.33333333 | W44: 0.33333333 | X44: 0.33333333 | Y44: 0.33333333 | Z44: 0.33333333 | AA44: 0.33333333 | AB44: 0.33333333 | AC44: 0.33333333 | AD44: 0.33333333 | AE44: 0.33333333 | AF44: 0.33333333 | AG44: 0.33333333 | AH44: 0.33333333 | AI44: 0.33333333
A45: 1 | B45: 3F | C45: SL No 540430038840 (EB Unit) | E45: =E7-D7 -> 286 | F45: =F7-E7 -> 187 | G45: =G7-F7 -> 187 | H45: =H7-G7 -> 237 | I45: =I7-H7 -> 239 | J45: =J7-I7 -> 276 | K45: =K7-J7 -> 244 | L45: =L7-K7 -> 243 | ... AI45: =AI7-AH7 -> 97 | AJ45: =SUM(E45:AI45) -> 7009
...

Sheet Apr-24
E2: April - 2024
A3: Sr.No | B3: Location | C3: Meter | D3: Previous Reading | E3: 45383 | F3: 45384 | G3: 45385 | H3: 45386 | I3: 45387 | J3: 45388 | K3: 45389 | L3: 45390 | M3: 45391 | N3: 45392 | O3: 45393 | P3: 45394 | Q3: 45395 | R3: 45396 | S3: 45397 | T3: 45398 | U3: 45399 | V3: 45400 | W3: 45401 | X3: 45402 | Y3: 45403 | Z3: 45404 | AA3: 45405 | AB3: 45406 | AC3: 45407 | AD3: 45408 | AE3: 45409 | AF3: 45410 | AG3: 45411 | AH3: 45412 | AI3: Consumption
E4: Mon | F4: Tue | G4: Wed | H4: Thu | I4: Fri | J4: Sat | K4: Sun | L4: Mon | M4: Tue | N4: Wed | O4: Thu | P4: Fri | Q4: Sat | R4: Sun | S4: Mon | T4: Tue | U4: Wed | V4: Thu | W4: Fri | X4: Sat | Y4: Sun | Z4: Mon | AA4: Tue | AB4: Wed | AC4: Thu | AD4: Fri | AE4: Sat | AF4: Sun | AG4: Mon | AH4: Tue
E5: Time | F5: Time | G5: Time | H5: Time | I5: Time | J5: Time | K5: Time | L5: Time | M5: Time | N5: Time | O5: Time | P5: Time | Q5: Time | R5: Time | S5: Time | T5: Time | U5: Time | V5: Time | W5: Time | X5: Time | Y5: Time | Z5: Time | AA5: Time | AB5: Time | AC5: Time | AD5: Time | AE5: Time | AF5: Time | AG5: Time | AH5: Time
E6: 0.33333333 | F6: 0.33333333 | G6: 0.33333333 | H6: 0.33333333 | I6: 0.33333333 | J6: 0.33333333 | K6: 0.33333333 | L6: 0.33333333 | M6: 0.33333333 | N6: 0.33333333 | O6: 0.33333333 | P6: 0.33333333 | Q6: 0.33333333 | R6: 0.33333333 | S6: 0.33333333 | T6: 0.33333333 | U6: 0.33333333 | V6: 0.33333333 | W6: 0.33333333 | X6: 0.33333333 | Y6: 0.33333333 | Z6: 0.33333333 | AA6: 0.33333333 | AB6: 0.33333333 | AC6: 0.33333333 | AD6: 0.33333333 | AE6: 0.33333333 | AF6: 0.33333333 | AG6: 0.33333333 | AH6: 0.33333333
A7: 1 | C7: SL No 540430038840 (EB Unit) | D7: ='Mar-24'!AI7 -> 13613 | E7: 13954 | F7: 14192 | G7: 14447 | H7: 14695 | I7: 14934 | J7: 15140 | K7: 15340 | L7: 15616 | M7: 15857 | N7: 16102 | O7: 16352 | P7: 16577 | Q7: 16833 | R7: 17031 | S7: 17277 | T7: 17515 | U7: 17761 | V7: 18010 | W7: 18263 | X7: 18443 | Y7: 18647 | Z7: 18895 | AA7: 19148 | AB7: 19397 | AC7: 19626 | AD7: 19862 | AE7: 20081 | AF7: 20271 | AG7: 20513 | AH7: 20652 | AI7: =AH7-D7 -> 7039
C8: DG | D8: ='Mar-24'!AI8 -> 278 | E8: 278 | F8: 278 | G8: 284 | H8: 284 | I8: 284 | J8: 284 | K8: 284 | L8: 284 | M8: 286 | N8: 296 | O8: 296 | P8: 296 | Q8: 296 | R8: 301 | S8: 304 | T8: 304 | U8: 304 | V8: 304 | W8: 304 | X8: 304 | Y8: 304 | Z8: 304 | AA8: 306 | AB8: 306 | AC8: 308 | AD8: 319 | AE8: 323 | AF8: 323 | AG8: 323 | AH8: 328 | AI8: =AH8-D8 -> 50
A9: 2 | C9: SL No 540430038845 (EB Unit) | D9: ='Mar-24'!AI9 -> 1956 | E9: 1956 | F9: 1956 | G9: 1956 | H9: 1956 | I9: 1956 | J9: 1956 | K9: 1956 | L9: 1956 | M9: 1956 | N9: 1956 | O9: 1956 | P9: 1956 | Q9: 1956 | R9: 1956 | S9: 1956 | T9: 1956 | U9: 1956 | V9: 1956 | W9: 1956 | X9: 1956 | Y9: 1956 | Z9: 1956 | AA9: 1956 | AB9: 1956 | AC9: 1956 | AD9: 1956 | AE9: 1956 | AF9: 1956 | AG9: 1956 | AH9: 1956 | AI9: =AH9-D9 -> 0
C10: DG | D10: ='Mar-24'!AI10 -> 28 | E10: 28 | F10: 28 | G10: 28 | H10: 28 | I10: 28 | J10: 28 | K10: 28 | L10: 28 | M10: 28 | N10: 28 | O10: 28 | P10: 28 | Q10: 28 | R10: 28 | S10: 28 | T10: 28 | U10: 28 | V10: 28 | W10: 28 | X10: 28 | Y10: 28 | Z10: 28 | AA10: 28 | AB10: 28 | AC10: 28 | AD10: 28 | AE10: 28 | AF10: 28 | AG10: 28 | AH10: 28 | AI10: =AH10-D10 -> 0
A11: 3 | C11: SL No 540430038844 (EB Unit) | D11: ='Mar-24'!AI11 -> 26440 | E11: 26903 | F11: 27234 | G11: 27600 | H11: 27954 | I11: 28285 | J11: 28564 | K11: 28848 | L11: 29211 | M11: 29553 | N11: 29896 | O11: 30245 | P11: 30561 | Q11: 30813 | R11: 31065 | S11: 31409 | T11: 31746 | U11: 32095 | V11: 32436 | W11: 32782 | X11: 33017 | Y11: 33274 | Z11: 33623 | AA11: 33981 | AB11: 34335 | AC11: 34646 | AD11: 34977 | AE11: 35264 | AF11: 35509 | AG11: 35851 | AH11: 36049 | AI11: =AH11-D11 -> 9609
C12: DG | D12: ='Mar-24'!AI12 -> 517 | E12: 517 | F12: 517 | G12: 526 | H12: 526 | I12: 526 | J12: 526 | K12: 526 | L12: 526 | M12: 528 | N12: 544 | O12: 544 | P12: 544 | Q12: 544 | R12: 550 | S12: 555 | T12: 555 | U12: 555 | V12: 555 | W12: 555 | X12: 555 | Y12: 555 | Z12: 555 | AA12: 557 | AB12: 557 | AC12: 560 | AD12: 576 | AE12: 581 | AF12: 581 | AG12: 581 | AH12: 588 | AI12: =AH12-D12 -> 71
A13: 4 | C13: SL No 540430038821 (EB Unit) | D13: ='Mar-24'!AI13 -> 0 | E13: 0 | F13: 0 | G13: 0 | H13: 0 | I13: 0 | J13: 0 | K13: 0 | L13: 0 | M13: 0 | N13: 0 | O13: 0 | P13: 0 | Q13: 0 | R13: 0 | S13: 0 | T13: 0 | U13: 0 | V13: 0 | W13: 0 | X13: 0 | Y13: 0 | Z13: 0 | AA13: 0 | AB13: 0 | AC13: 0 | AD13: 0 | AE13: 0 | AF13: 0 | AG13: 0 | AH13: 0 | AI13: =AH13-D13 -> 0
C14: DG | D14: ='Mar-24'!AI14 -> 0 | E14: 0 | F14: 0 | G14: 0 | H14: 0 | I14: 0 | J14: 0 | K14: 0 | L14: 0 | M14: 0 | N14: 0 | O14: 0 | P14: 0 | Q14: 0 | R14: 0 | S14: 0 | T14: 0 | U14: 0 | V14: 0 | W14: 0 | X14: 0 | Y14: 0 | Z14: 0 | AA14: 0 | AB14: 0 | AC14: 0 | AD14: 0 | AE14: 0 | AF14: 0 | AG14: 0 | AH14: 0 | AI14: =AH14-D14 -> 0
A15: 5 | C15: SL No 540430038849 (EB Unit) | D15: ='Mar-24'!AI15 -> 7150 | E15: 7390 | F15: 7565 | G15: 7733 | H15: 7902 | I15: 8061 | J15: 8178 | K15: 8290 | L15: 8458 | M15: 8615 | N15: 8778 | O15: 8941 | P15: 9098 | Q15: 9203 | R15: 9314 | S15: 9484 | T15: 9651 | U15: 9822 | V15: 9981 | W15: 10131 | X15: 10221 | Y15: 10330 | Z15: 10496 | AA15: 10645 | AB15: 10818 | AC15: 10970 | AD15: 11120 | AE15: 11234 | AF15: 11348 | AG15: 11505 | AH15: 11588 | AI15: =AH15-D15 -> 4438
C16: DG | D16: ='Mar-24'!AI16 -> 159 | E16: 159 | F16: 159 | G16: 163 | H16: 163 | I16: 163 | J16: 163 | K16: 163 | L16: 163 | M16: 164 | N16: 174 | O16: 174 | P16: 174 | Q16: 174 | R16: 177 | S16: 180 | T16: 180 | U16: 180 | V16: 180 | W16: 180 | X16: 180 | Y16: 180 | Z16: 180 | AA16: 181 | AB16: 181 | AC16: 183 | AD16: 191 | AE16: 193 | AF16: 193 | AG16: 193 | AH16: 196 | AI16: =AH16-D16 -> 37
A17: 6 | C17: SL No 540430038696 (EB Unit) | D17: ='Mar-24'!AI17 -> 13012 | E17: 13245 | F17: 13458 | G17: 13668 | H17: 13921 | I17: 14166 | J17: 14326 | K17: 14459 | L17: 14714 | M17: 14957 | N17: 15185 | O17: 15437 | P17: 15699 | Q17: 15835 | R17: 15970 | S17: 16209 | T17: 16435 | U17: 16658 | V17: 16892 | W17: 17148 | X17: 17274 | Y17: 17415 | Z17: 17674 | AA17: 17939 | AB17: 18217 | AC17: 18491 | AD17: 18754 | AE17: 18932 | AF17: 19098 | AG17: 19384 | AH17: 19531 | AI17: =AH17-D17 -> 6519
C18: DG | D18: ='Mar-24'!AI18 -> 300 | E18: 300 | F18: 300 | G18: 305 | H18: 305 | I18: 305 | J18: 305 | K18: 305 | L18: 305 | M18: 305 | N18: 321 | O18: 321 | P18: 321 | Q18: 321 | R18: 326 | S18: 329 | T18: 329 | U18: 329 | V18: 329 | W18: 329 | X18: 329 | Y18: 329 | Z18: 329 | AA18: 331 | AB18: 331 | AC18: 332 | AD18: 345 | AE18: 347 | AF18: 347 | AG18: 347 | AH18: 353 | AI18: =AH18-D18 -> 53
A19: 7 | C19: SL No 540430038843 (EB Unit) | D19: ='Mar-24'!AI19 -> 53008 | E19: 54181 | F19: 54950 | G19: 55754 | H19: 56487 | I19: 57283 | J19: 57971 | K19: 58639 | L19: 59399 | M19: 60160 | N19: 60923 | O19: 61715 | P19: 62483 | Q19: 63168 | R19: 63819 | S19: 64541 | T19: 65298 | U19: 66081 | V19: 66869 | W19: 67698 | X19: 68306 | Y19: 68961 | Z19: 69739 | AA19: 70532 | AB19: 71312 | AC19: 72055 | AD19: 72822 | AE19: 73539 | AF19: 74244 | AG19: 74950 | AH19: 75336 | AI19: =AH19-D19 -> 22328
C20: DG | D20: ='Mar-24'!AI20 -> 1088 | E20: 1088 | F20: 1088 | G20: 1101 | H20: 1101 | I20: 1101 | J20: 1101 | K20: 1101 | L20: 1101 | M20: 1104 | N20: 1134 | O20: 1134 | P20: 1134 | Q20: 1134 | R20: 1152 | S20: 1159 | T20: 1159 | U20: 1159 | V20: 1159 | W20: 1159 | X20: 1159 | Y20: 1159 | Z20: 1159 | AA20: 1166 | AB20: 1166 | AC20: 1170 | AD20: 1203 | AE20: 1212 | AF20: 1212 | AG20: 1212 | AH20: 1226 | AI20: =AH20-D20 -> 138
A21: 8 | C21: SL No 540430038848 (EB Unit) | D21: ='Mar-24'!AI21 -> 15438 | E21: 15690 | F21: 15807 | G21: 15919 | H21: 15996 | I21: 16074 | J21: 16153 | K21: 16225 | L21: 16309 | M21: 16399 | N21: 16485 | O21: 16570 | P21: 16653 | Q21: 16722 | R21: 16789 | S21: 16899 | T21: 17020 | U21: 17152 | V21: 17244 | W21: 17333 | X21: 17390 | Y21: 17459 | Z21: 17536 | AA21: 17595 | AB21: 17658 | AC21: 17719 | AD21: 17782 | AE21: 17836 | AF21: 17874 | AG21: 17935 | AH21: 17963 | AI21: =AH21-D21 -> 2525
C22: DG | D22: ='Mar-24'!AI22 -> 248 | E22: 248 | F22: 248 | G22: 250 | H22: 250 | I22: 250 | J22: 250 | K22: 250 | L22: 250 | M22: 251 | N22: 255 | O22: 255 | P22: 255 | Q22: 255 | R22: 257 | S22: 259 | T22: 259 | U22: 259 | V22: 259 | W22: 259 | X22: 259 | Y22: 259 | Z22: 259 | AA22: 260 | AB22: 260 | AC22: 261 | AD22: 265 | AE22: 268 | AF22: 268 | AG22: 268 | AH22: 269 | AI22: =AH22-D22 -> 21
A24: 1 | C24: AHU1 | D24: ='Mar-24'!AI24 -> 5270 | E24: 5326 | F24: 5383 | G24: 5441 | H24: 5502 | I24: 5558 | J24: 5596 | K24: 5596 | L24: 5660 | M24: 5719 | N24: 5814 | O24: 5921 | P24: 6026 | Q24: 6086 | R24: 6086 | S24: 6197 | T24: 6304 | U24: 6413 | V24: 6519 | W24: 6620 | X24: 6680 | Y24: 6680 | Z24: 6800 | AA24: 6913 | AB24: 7010 | AC24: 7078 | AD24: 7142 | AE24: 7161 | AF24: 7162 | AG24: 7229 | AH24: 7266 | AI24: =AH24-D24 -> 1996
C25: DG | D25: ='Mar-24'!AH25 -> 173 | E25: 173 | F25: 173 | G25: 174 | H25: 174 | I25: 174 | J25: 174 | K25: 174 | L25: 174 | M25: 175 | N25: 178 | O25: 178 | P25: 178 | Q25: 178 | R25: 178 | S25: 179 | T25: 179 | U25: 179 | V25: 179 | W25: 179 | X25: 179 | Y25: 179 | Z25: 179 | AA25: 181 | AB25: 181 | AC25: 181 | AD25: 182 | AE25: 182 | AF25: 182 | AG25: 182 | AH25: 184 | AI25: =AH25-D25 -> 11
A26: 2 | C26: AHU2 | D26: ='Mar-24'!AI26 -> 4964 | E26: 5045 | F26: 5128 | G26: 5216 | H26: 5303 | I26: 5366 | J26: 5407 | K26: 5407 | L26: 5482 | M26: 5585 | N26: 5634 | O26: 5684 | P26: 5739 | Q26: 5769 | R26: 5769 | S26: 5853 | T26: 5927 | U26: 6001 | V26: 6073 | W26: 6134 | X26: 6161 | Y26: 6161 | Z26: 6215 | AA26: 6266 | AB26: 6328 | AC26: 6395 | AD26: 6453 | AE26: 6480 | AF26: 6480 | AG26: 6548 | AH26: 6581 | AI26: =AH26-D26 -> 1617
C27: DG | D27: ='Mar-24'!AI27 -> 178 | E27: 178 | F27: 117 | G27: 180 | H27: 180 | I27: 180 | J27: 180 | K27: 180 | L27: 180 | M27: 180 | N27: 188 | O27: 188 | P27: 188 | Q27: 188 | R27: 188 | S27: 189 | T27: 189 | U27: 189 | V27: 189 | W27: 189 | X27: 189 | Y27: 189 | Z27: 189 | AA27: 190 | AB27: 190 | AC27: 190 | AD27: 192 | AE27: 192 | AF27: 192 | AG27: 192 | AH27: 194 | AI27: =AH27-D27 -> 16
A28: 3 | C28: AHU3 | D28: ='Mar-24'!AI28 -> 2862 | E28: 2937 | F28: 3007 | G28: 3081 | H28: 3157 | I28: 3223 | J28: 3277 | K28: 3277 | L28: 3323 | M28: 3418 | N28: 3505 | O28: 3568 | P28: 3633 | Q28: 3691 | R28: 3691 | S28: 3773 | T28: 3882 | U28: 3923 | V28: 4000 | W28: 4073 | X28: 4114 | Y28: 4114 | Z28: 4203 | AA28: 4280 | AB28: 4359 | AC28: 4425 | AD28: 4485 | AE28: 4505 | AF28: 4505 | AG28: 4567 | AH28: 4607 | AI28: =AH28-D28 -> 1745
C29: DG | D29: ='Mar-24'!AI29 -> 129 | E29: 129 | F29: 129 | G29: 131 | H29: 131 | I29: 131 | J29: 131 | K29: 131 | L29: 131 | M29: 131 | N29: 135 | O29: 135 | P29: 135 | Q29: 135 | R29: 135 | S29: 136 | T29: 136 | U29: 136 | V29: 136 | W29: 136 | X29: 136 | Y29: 136 | Z29: 136 | AA29: 137 | AB29: 137 | AC29: 137 | AD29: 139 | AE29: 139 | AF29: 139 | AG29: 139 | AH29: 140 | AI29: =AH29-D29 -> 11
A30: 4 | C30: AHU4 | D30: ='Mar-24'!AI30 -> 3542 | E30: 3629 | F30: 3722 | G30: 3802 | H30: 3880 | I30: 3942 | J30: 3976 | K30: 3976 | L30: 4026 | M30: 4070 | N30: 4101 | O30: 4131 | P30: 4177 | Q30: 4195 | R30: 4195 | S30: 4246 | T30: 4278 | U30: 4311 | V30: 4344 | W30: 4385 | X30: 4422 | Y30: 4422 | Z30: 4503 | AA30: 4581 | AB30: 4660 | AC30: 4725 | AD30: 4786 | AE30: 4806 | AF30: 4806 | AG30: 4889 | AH30: 4928 | AI30: =AH30-D30 -> 1386
C31: DG | D31: ='Mar-24'!AI31 -> 117 | E31: 117 | F31: 117 | G31: 119 | H31: 119 | I31: 119 | J31: 119 | K31: 119 | L31: 119 | M31: 119 | N31: 121 | O31: 121 | P31: 121 | Q31: 121 | R31: 121 | S31: 122 | T31: 122 | U31: 122 | V31: 122 | W31: 122 | X31: 122 | Y31: 122 | Z31: 122 | AA31: 123 | AB31: 123 | AC31: 123 | AD31: 125 | AE31: 125 | AF31: 125 | AG31: 125 | AH31: 127 | AI31: =AH31-D31 -> 10
A33: 1 | C33: AHU1 - BTU | D33: ='Mar-24'!AI33 -> 20397.69 | E33: 21409.6 | F33: 22161.77 | G33: 22850.5 | H33: 23503.28 | I33: 24067.02 | J33: 24424.25 | K33: 24424.25 | L33: 25188.51 | M33: 25950.06 | N33: 26827.08 | O33: 27672.48 | P33: 28403.37 | Q33: 28668.95 | R33: 28668.95 | S33: 29756.55 | T33: 30722.75 | U33: 31506.4 | V33: 32311.93 | W33: 32993.25 | X33: 33324.88 | Y33: 33324.88 | Z33: 34423.33 | AA33: 35423.46 | AB33: 36245.63 | AC33: 37031.83 | AD33: 37699.55 | AE33: 38117.54 | AF33: 38117.54 | AG33: 39198.41 | AH33: 39808.33 | AI33: =AH33-D33 -> 19410.64
A34: 2 | C34: AHU2 - BTU | D34: ='Mar-24'!AI34 -> 21181.85 | E34: 21945.98 | F34: 22720.54 | G34: 23411.95 | H34: 24120.47 | I34: 24773.43 | J34: 25081.65 | K34: 25081.65 | L34: 26091.01 | M34: 26746.39 | N34: 27447.98 | O34: 28122.32 | P34: 28720.23 | Q34: 29040.22 | R34: 29040.22 | S34: 29905.93 | T34: 30619.39 | U34: 31315.45 | V34: 32035.07 | W34: 32730.58 | X34: 33108.49 | Y34: 33108.49 | Z34: 34097.47 | AA34: 34888.69 | AB34: 35580.02 | AC34: 36264.12 | AD34: 36972.64 | AE34: 37406.7 | AF34: 37406.7 | AG34: 38410.78 | AH34: 39039.43 | AI34: =AH34-D34 -> 17857.58
A35: 3 | C35: AHU3 - BTU | D35: ='Mar-24'!AI35 -> 15520.6 | E35: 16330.66 | F35: 16953.07 | G35: 17517.78 | H35: 18145.78 | I35: 18720.58 | J35: 19061.88 | K35: 19061.88 | L35: 19705 | M35: 20386.96 | N35: 21064.88 | O35: 21798.73 | P35: 22392.31 | Q35: 22683.07 | R35: 22683.07 | S35: 23805.99 | T35: 24672.94 | U35: 25738.12 | V35: 26399.51 | W35: 27163.83 | X35: 27621.63 | Y35: 27621.63 | Z35: 28699.69 | AA35: 29733.84 | AB35: 30553.78 | AC35: 31401.06 | AD35: 32233.52 | AE35: 32758.82 | AF35: 32758.82 | AG35: 33732.59 | AH35: 34466.31 | AI35: =AH35-D35 -> 18945.71
A36: 4 | C36: AHU4 - BTU | D36: ='Mar-24'!AI36 -> 24009.78 | E36: 25419.59 | F36: 26370.92 | G36: 27234.14 | H36: 28024.3 | I36: 28788.29 | J36: 29255.67 | K36: 29255.67 | L36: 30254.33 | M36: 31229.2 | N36: 32263.49 | O36: 33125.05 | P36: 33971.68 | Q36: 34364.35 | R36: 34364.35 | S36: 35632.68 | T36: 36573.12 | U36: 37463.45 | V36: 38302.71 | W36: 39055.22 | X36: 39535.63 | Y36: 39535.63 | Z36: 41006.37 | AA36: 42325.41 | AB36: 43455.98 | AC36: 44476.59 | AD36: 45418.41 | AE36: 46087.97 | AF36: 46087.97 | AG36: 47630.79 | AH36: 48593.12 | AI36: =AH36-D36 -> 24583.34
B39: Daily Energy Report
B40: Electricity Consumption
A41: Sr.No | B41: Location | C41: Meter | E41: =E3 -> 45383 | F41: =F3 -> 45384 | G41: =G3 -> 45385 | H41: =H3 -> 45386 | I41: =I3 -> 45387 | J41: =J3 -> 45388 | K41: =K3 -> 45389 | L41: =L3 -> 45390 | ... AH41: =AH3 -> 45412 | AI41: Consumption
E42: =E4 -> Mon | F42: =F4 -> Tue | G42: =G4 -> Wed | H42: =H4 -> Thu | I42: =I4 -> Fri | J42: =J4 -> Sat | K42: =K4 -> Sun | L42: =L4 -> Mon | ... AH42: =AH4 -> Tue
E43: Time | F43: Time | G43: Time | H43: Time | I43: Time | J43: Time | K43: Time | L43: Time | M43: Time | N43: Time | O43: Time | P43: Time | Q43: Time | R43: Time | S43: Time | T43: Time | U43: Time | V43: Time | W43: Time | X43: Time | Y43: Time | Z43: Time | AA43: Time | AB43: Time | AC43: Time | AD43: Time | AE43: Time | AF43: Time | AG43: Time | AH43: Time
E44: 0.33333333 | F44: 0.33333333 | G44: 0.33333333 | H44: 0.33333333 | I44: 0.33333333 | J44: 0.33333333 | K44: 0.33333333 | L44: 0.33333333 | M44: 0.33333333 | N44: 0.33333333 | O44: 0.33333333 | P44: 0.33333333 | Q44: 0.33333333 | R44: 0.33333333 | S44: 0.33333333 | T44: 0.33333333 | U44: 0.33333333 | V44: 0.33333333 | W44: 0.33333333 | X44: 0.33333333 | Y44: 0.33333333 | Z44: 0.33333333 | AA44: 0.33333333 | AB44: 0.33333333 | AC44: 0.33333333 | AD44: 0.33333333 | AE44: 0.33333333 | AF44: 0.33333333 | AG44: 0.33333333 | AH44: 0.33333333
A45: 1 | B45: 3F | C45: SL No 540430038840 (EB Unit) | E45: =E7-D7 -> 341 | F45: =F7-E7 -> 238 | G45: =G7-F7 -> 255 | H45: =H7-G7 -> 248 | I45: =I7-H7 -> 239 | J45: =J7-I7 -> 206 | K45: =K7-J7 -> 200 | L45: =L7-K7 -> 276 | ... AH45: =AH7-AG7 -> 139 | AI45: =SUM(E45:AH45) -> 7039
...

Sheet May-24
E2: May - 2024
A3: Sr.No | B3: Location | C3: Meter | D3: Previous Reading | E3: 45413 | F3: 45414 | G3: 45415 | H3: 45416 | I3: 45417 | J3: 45418 | K3: 45419 | L3: 45420 | M3: 45421 | N3: 45422 | O3: 45423 | P3: 45424 | Q3: 45425 | R3: 45426 | S3: 45427 | T3: 45428 | U3: 45429 | V3: 45430 | W3: 45431 | X3: 45432 | Y3: 45433 | Z3: 45434 | AA3: 45435 | AB3: 45436 | AC3: 45437 | AD3: 45438 | AE3: 45439 | AF3: 45440 | AG3: 45441 | AH3: 45442 | AI3: 45443 | AJ3: Consumption
E4: Thu | F4: Fri | G4: Sat | H4: Sun | I4: Mon | J4: Tue | K4: Wed | L4: Thu | M4: Fri | N4: Sat | O4: Sun | P4: Mon | Q4: Tue | R4: Wed | S4: Thu | T4: Fri | U4: Sat | V4: Sun | W4: Mon | X4: Tue | Y4: Wed | Z4: Thu | AA4: Fri | AB4: Sat | AC4: Sun | AD4: Mon | AE4: Tue | AF4: Wed | AG4: Thu | AH4: Fri | AI4: Sat
E5: Time | F5: Time | G5: Time | H5: Time | I5: Time | J5: Time | K5: Time | L5: Time | M5: Time | N5: Time | O5: Time | P5: Time | Q5: Time | R5: Time | S5: Time | T5: Time | U5: Time | V5: Time | W5: Time | X5: Time | Y5: Time | Z5: Time | AA5: Time | AB5: Time | AC5: Time | AD5: Time | AE5: Time | AF5: Time | AG5: Time | AH5: Time | AI5: Time
E6: 0.33333333 | F6: 0.33333333 | G6: 0.33333333 | H6: 0.33333333 | I6: 0.33333333 | J6: =#REF!=AN73 -> #REF! | K6: 0.33333333 | L6: 0.33333333 | M6: 0.33333333 | N6: 0.33333333 | O6: 0.33333333 | P6: 0.33333333 | Q6: 0.33333333 | R6: 0.33333333 | S6: 0.33333333 | T6: 0.33333333 | U6: 0.33333333 | V6: 0.33333333 | W6: 0.33333333 | X6: 0.33333333 | Y6: 0.33333333 | Z6: 0.33333333 | AA6: 0.33333333 | AB6: 0.33333333 | AC6: 0.33333333 | AD6: 0.33333333 | AE6: 0.33333333 | AF6: 0.33333333 | AG6: 0.33333333 | AH6: 0.33333333 | AI6: 0.33333333
A7: 1 | B7: 3F | C7: SL No 540430038840 (EB Unit) | D7: 20652 | E7: 21014 | F7: 21267 | G7: 21509 | H7: 21714 | I7: 21934 | J7: 22136 | K7: 22375 | L7: 22572 | M7: 22809 | N7: 23008 | O7: 23204 | P7: 23430 | Q7: 23596 | R7: 23844 | S7: 24100 | T7: 24354 | U7: 24495 | V7: 24682 | W7: 24968 | X7: 25142 | Y7: 25402 | Z7: 25630 | AA7: 25817 | AB7: 26049 | AC7: 26251 | AD7: 26443 | AE7: 26672 | AF7: 26889 | AG7: 27095 | AH7: 27328 | AI7: 27418 | AJ7: =AI7-D7 -> 6766
C8: DG | D8: 328 | E8: 328 | F8: 328 | G8: 328 | H8: 328 | I8: 328 | J8: 369 | K8: 382 | L8: 455 | M8: 455 | N8: 505 | O8: 518 | P8: 518 | Q8: 599 | R8: 613 | S8: 613 | T8: 613 | U8: 700 | V8: 700 | W8: 727 | X8: 798 | Y8: 798 | Z8: 798 | AA8: 864 | AB8: 880 | AC8: 882 | AD8: 889 | AE8: 915 | AF8: 955 | AG8: 999 | AH8: 1025 | AI8: 1040 | AJ8: =AI8-D8 -> 712
A9: 2 | B9: 3F | C9: SL No 540430038845 (EB Unit) | D9: 1956 | E9: 1956 | F9: 1956 | G9: 1956 | H9: 1956 | I9: 1956 | J9: 1956 | K9: 1956 | L9: 1956 | M9: 1956 | N9: 1956 | O9: 1956 | P9: 1956 | Q9: 1956 | R9: 1956 | S9: 1956 | T9: 1956 | U9: 1956 | V9: 1956 | W9: 1956 | X9: 1956 | Y9: 1956 | Z9: 1956 | AA9: 1956 | AB9: 1956 | AC9: 1956 | AD9: 1956 | AE9: 1956 | AF9: 1956 | AG9: 1956 | AH9: 1956 | AI9: 1956 | AJ9: =AI9-D9 -> 0
C10: DG | D10: 28 | E10: 28 | F10: 28 | G10: 28 | H10: 28 | I10: 28 | J10: 28 | K10: 28 | L10: 28 | M10: 28 | N10: 28 | O10: 28 | P10: 28 | Q10: 28 | R10: 28 | S10: 28 | T10: 28 | U10: 28 | V10: 28 | W10: 28 | X10: 28 | Y10: 28 | Z10: 28 | AA10: 28 | AB10: 28 | AC10: 28 | AD10: 28 | AE10: 28 | AF10: 28 | AG10: 28 | AH10: 28 | AI10: 28 | AJ10: =AI10-D10 -> 0
A11: 3 | B11: 3F | C11: SL No 540430038844 (EB Unit) | D11: 36049 | E11: 36569 | F11: 36928 | G11: 37268 | H11: 37536 | I11: 37819 | J11: 38104 | K11: 38443 | L11: 38717 | M11: 39054 | N11: 39326 | O11: 39382 | P11: 39877 | Q11: 40110 | R11: 40457 | S11: 40827 | T11: 41189 | U11: 41374 | V11: 41653 | W11: 41899 | X11: 42140 | Y11: 42499 | Z11: 42821 | AA11: 43077 | AB11: 43396 | AC11: 43656 | AD11: 43897 | AE11: 44220 | AF11: 44524 | AG11: 44805 | AH11: 45128 | AI11: 45249 | AJ11: =AI11-D11 -> 9200
C12: DG | D12: 588 | E12: 588 | F12: 588 | G12: 588 | H12: 588 | I12: 588 | J12: 651 | K12: 671 | L12: 781 | M12: 781 | N12: 856 | O12: 873 | P12: 873 | Q12: 997 | R12: 1017 | S12: 1017 | T12: 1017 | U12: 1158 | V12: 1158 | W12: 1182 | X12: 1286 | Y12: 1286 | Z12: 1286 | AA12: 1885 | AB12: 1409 | AC12: 1411 | AD12: 1420 | AE12: 1461 | AF12: 1523 | AG12: 1588 | AH12: 1627 | AI12: 1649 | AJ12: =AI12-D12 -> 1061
A13: 4 | B13: 3F | C13: SL No 540430038821 (EB Unit) | D13: 0 | E13: 0 | F13: 0 | G13: 0 | H13: 0 | I13: 0 | J13: 0 | K13: 0 | L13: 0 | M13: 0 | N13: 0 | O13: 0 | P13: 0 | Q13: 0 | R13: 0 | S13: 0 | T13: 0 | U13: 0 | V13: 0 | W13: 0 | X13: 0 | Y13: 0 | Z13: 0 | AA13: 0 | AB13: 0 | AC13: 0 | AD13: 0 | AE13: 0 | AF13: 0 | AG13: 0 | AH13: 0 | AI13: 0 | AJ13: =AI13-D13 -> 0
C14: DG | D14: 0 | E14: 0 | F14: 0 | G14: 0 | H14: 0 | I14: 0 | J14: 0 | K14: 0 | L14: 0 | M14: 0 | N14: 0 | O14: 0 | P14: 0 | Q14: 0 | R14: 0 | S14: 0 | T14: 0 | U14: 0 | V14: 0 | W14: 0 | X14: 0 | Y14: 0 | Z14: 0 | AA14: 0 | AB14: 0 | AC14: 0 | AD14: 0 | AE14: 0 | AF14: 0 | AG14: 0 | AH14: 0 | AI14: 0 | AJ14: =AI14-D14 -> 0
A15: 5 | B15: 3F | C15: SL No 540430038849 (EB Unit) | D15: 11588 | E15: 11830 | F15: 11992 | G15: 12152 | H15: 12247 | I15: 12341 | J15: 12478 | K15: 12640 | L15: 12758 | M15: 12919 | N15: 13043 | O15: 13141 | P15: 13253 | Q15: 13364 | R15: 13533 | S15: 13708 | T15: 13887 | U15: 13969 | V15: 14074 | W15: 14183 | X15: 14304 | Y15: 14491 | Z15: 14655 | AA15: 14790 | AB15: 14957 | AC15: 15079 | AD15: 15195 | AE15: 15366 | AF15: 15528 | AG15: 15675 | AH15: 15845 | AI15: 15905 | AJ15: =AI15-D15 -> 4317
C16: DG | D16: 196 | E16: 196 | F16: 196 | G16: 196 | H16: 196 | I16: 196 | J16: 225 | K16: 237 | L16: 291 | M16: 291 | N16: 326 | O16: 332 | P16: 332 | Q16: 395 | R16: 404 | S16: 404 | T16: 404 | U16: 482 | V16: 482 | W16: 492 | X16: 543 | Y16: 543 | Z16: 543 | AA16: 600 | AB16: 613 | AC16: 614 | AD16: 619 | AE16: 641 | AF16: 674 | AG16: 713 | AH16: 734 | AI16: 746 | AJ16: =AI16-D16 -> 550
A17: 6 | B17: 3F | C17: SL No 540430038696 (EB Unit) | D17: 19531 | E17: 19954 | F17: 20225 | G17: 20489 | H17: 20660 | I17: 20844 | J17: 21069 | K17: 21335 | L17: 21521 | M17: 21728 | N17: 21896 | O17: 22015 | P17: 22167 | Q17: 22338 | R17: 22615 | S17: 22899 | T17: 23186 | U17: 23327 | V17: 23527 | W17: 23699 | X17: 23908 | Y17: 24186 | Z17: 24418 | AA17: 24591 | AB17: 24803 | AC17: 24944 | AD17: 25085 | AE17: 25335 | AF17: 25563 | AG17: 25780 | AH17: 26023 | AI17: 26115 | AJ17: =AI17-D17 -> 6584
C18: DG | D18: 353 | E18: 353 | F18: 353 | G18: 353 | H18: 353 | I18: 353 | J18: 402 | K18: 417 | L18: 492 | M18: 492 | N18: 559 | O18: 564 | P18: 564 | Q18: 659 | R18: 673 | S18: 673 | T18: 673 | U18: 807 | V18: 807 | W18: 825 | X18: 916 | Y18: 916 | Z18: 916 | AA18: 891 | AB18: 1011 | AC18: 1011 | AD18: 1016 | AE18: 1045 | AF18: 1085 | AG18: 1150 | AH18: 1185 | AI18: 1209 | AJ18: =AI18-D18 -> 856
A19: 7 | B19: 3F | C19: SL No 540430038843 (EB Unit) | D19: 75336 | E19: 76453 | F19: 77223 | G19: 77941 | H19: 78535 | I19: 79195 | J19: 79781 | K19: 80472 | L19: 81019 | M19: 81713 | N19: 82317 | O19: 82909 | P19: 83577 | Q19: 84046 | R19: 84747 | S19: 85477 | T19: 86207 | U19: 86599 | V19: 87217 | W19: 87733 | X19: 88230 | Y19: 88988 | Z19: 89665 | AA19: 90201 | AB19: 90898 | AC19: 91441 | AD19: 91754 | AE19: 92396 | AF19: 93063 | AG19: 93673 | AH19: 94361 | AI19: 94630 | AJ19: =AI19-D19 -> 19294
C20: DG | D20: 1226 | E20: 1226 | F20: 1226 | G20: 1226 | H20: 1226 | I20: 1226 | J20: 1350 | K20: 1366 | L20: 1590 | M20: 1590 | N20: 1741 | O20: 1778 | P20: 1778 | Q20: 2018 | R20: 2048 | S20: 2048 | T20: 2048 | U20: 2340 | V20: 2340 | W20: 2390 | X20: 2581 | Y20: 2581 | Z20: 2581 | AA20: 2792 | AB20: 2844 | AC20: 2848 | AD20: 2859 | AE20: 2934 | AF20: 3042 | AG20: 3170 | AH20: 3251 | AI20: 3299 | AJ20: =AI20-D20 -> 2073
A21: 8 | B21: 3F | C21: SL No 540430038848 (EB Unit) | D21: 17963 | E21: 18048 | F21: 18105 | G21: 18160 | H21: 18203 | I21: 18257 | J21: 18308 | K21: 18364 | L21: 18415 | M21: 18521 | N21: 18600 | O21: 18702 | P21: 18797 | Q21: 18874 | R21: 18939 | S21: 19005 | T21: 19076 | U21: 19116 | V21: 19201 | W21: 19292 | X21: 19366 | Y21: 19515 | Z21: 19662 | AA21: 19754 | AB21: 19907 | AC21: 20039 | AD21: 20174 | AE21: 20315 | AF21: 20466 | AG21: 20554 | AH21: 20659 | AI21: 20693 | AJ21: =AI21-D21 -> 2730
C22: DG | D22: 269 | E22: 269 | F22: 269 | G22: 269 | H22: 269 | I22: 269 | J22: 277 | K22: 282 | L22: 306 | M22: 306 | N22: 321 | O22: 330 | P22: 330 | Q22: 361 | R22: 364 | S22: 364 | T22: 364 | U22: 405 | V22: 405 | W22: 414 | X22: 440 | Y22: 440 | Z22: 440 | AA22: 431 | AB22: 498 | AC22: 498 | AD22: 504 | AE22: 526 | AF22: 551 | AG22: 572 | AH22: 580 | AI22: 585 | AJ22: =AI22-D22 -> 316
A24: 1 | B24: 3F | C24: AHU1 | D24: 7266 | E24: 7368 | F24: 7437 | G24: 7504 | H24: 7531 | I24: 7531 | J24: 7585 | K24: 7648 | L24: 7684 | M24: 7753 | N24: 7780 | O24: 7821 | P24: 7821 | Q24: 7867 | R24: 7966 | S24: 8069 | T24: 8164 | U24: 8184 | V24: 8242 | W24: 8242 | X24: 8317 | Y24: 8411 | Z24: 8497 | AA24: 8543 | AB24: 8622 | AC24: 8622 | AD24: 8622 | AE24: 8726 | AF24: 8812 | AG24: 8884 | AH24: 8982 | AI24: 9012 | AJ24: =AI24-D24 -> 1746
C25: DG | D25: 184 | E25: 184 | F25: 184 | G25: 184 | H25: 184 | I25: 184 | J25: 195 | K25: 200 | L25: 229 | M25: 229 | N25: 247 | O25: 249 | P25: 249 | Q25: 299 | R25: 305 | S25: 305 | T25: 305 | U25: 363 | V25: 363 | W25: 363 | X25: 398 | Y25: 398 | Z25: 398 | AA25: 443 | AB25: 454 | AC25: 454 | AD25: 454 | AE25: 472 | AF25: 496 | AG25: 524 | AH25: 543 | AI25: 555 | AJ25: =AI25-D25 -> 371
A26: 2 | B26: 3F | C26: AHU2 | D26: 6581 | E26: 6675 | F26: 6754 | G26: 6820 | H26: 6845 | I26: 6845 | J26: 6898 | K26: 6961 | L26: 6997 | M26: 7066 | N26: 7100 | O26: 7132 | P26: 7132 | Q26: 7181 | R26: 7273 | S26: 7367 | T26: 7453 | U26: 7486 | V26: 7529 | W26: 7529 | X26: 7608 | Y26: 7693 | Z26: 7778 | AA26: 7824 | AB26: 7900 | AC26: 7900 | AD26: 7900 | AE26: 7999 | AF26: 8089 | AG26: 8165 | AH26: 8263 | AI26: 8291 | AJ26: =AI26-D26 -> 1710
C27: DG | D27: 194 | E27: 194 | F27: 194 | G27: 194 | H27: 194 | I27: 194 | J27: 206 | K27: 211 | L27: 239 | M27: 239 | N27: 255 | O27: 257 | P27: 257 | Q27: 317 | R27: 321 | S27: 321 | T27: 321 | U27: 369 | V27: 369 | W27: 369 | X27: 402 | Y27: 402 | Z27: 402 | AA27: 437 | AB27: 447 | AC27: 447 | AD27: 447 | AE27: 463 | AF27: 488 | AG27: 517 | AH27: 544 | AI27: 557 | AJ27: =AI27-D27 -> 363
A28: 3 | B28: 3F | C28: AHU3 | D28: 4607 | E28: 4713 | F28: 4807 | G28: 4901 | H28: 4938 | I28: 4938 | J28: 5000 | K28: 5060 | L28: 5095 | M28: 5164 | N28: 5187 | O28: 5227 | P28: 5227 | Q28: 5278 | R28: 5379 | S28: 5478 | T28: 5581 | U28: 5603 | V28: 5641 | W28: 5641 | X28: 5705 | Y28: 5805 | Z28: 5909 | AA28: 5951 | AB28: 6040 | AC28: 6040 | AD28: 6040 | AE28: 6139 | AF28: 6226 | AG28: 6301 | AH28: 6403 | AI28: 6422 | AJ28: =AI28-D28 -> 1815
C29: DG | D29: 140 | E29: 140 | F29: 140 | G29: 140 | H29: 140 | I29: 140 | J29: 152 | K29: 156 | L29: 183 | M29: 183 | N29: 198 | O29: 199 | P29: 199 | Q29: 258 | R29: 264 | S29: 264 | T29: 264 | U29: 324 | V29: 324 | W29: 324 | X29: 356 | Y29: 356 | Z29: 356 | AA29: 395 | AB29: 407 | AC29: 407 | AD29: 407 | AE29: 425 | AF29: 450 | AG29: 481 | AH29: 501 | AI29: 513 | AJ29: =AI29-D29 -> 373
A30: 4 | B30: 3F | C30: AHU4 | D30: 4928 | E30: 5053 | F30: 5136 | G30: 5217 | H30: 5248 | I30: 5248 | J30: 5316 | K30: 5388 | L30: 5430 | M30: 5515 | N30: 5553 | O30: 5590 | P30: 5590 | Q30: 5628 | R30: 5683 | S30: 5753 | T30: 5834 | U30: 5863 | V30: 5908 | W30: 5908 | X30: 5968 | Y30: 6050 | Z30: 6134 | AA30: 6176 | AB30: 6234 | AC30: 6234 | AD30: 6235 | AE30: 6315 | AF30: 6389 | AG30: 6445 | AH30: 6525 | AI30: 6551 | AJ30: =AI30-D30 -> 1623
C31: DG | D31: 127 | E31: 127 | F31: 127 | G31: 127 | H31: 127 | I31: 127 | J31: 140 | K31: 146 | L31: 179 | M31: 179 | N31: 197 | O31: 199 | P31: 199 | Q31: 237 | R31: 240 | S31: 240 | T31: 240 | U31: 290 | V31: 290 | W31: 290 | X31: 320 | Y31: 320 | Z31: 320 | AA31: 358 | AB31: 363 | AC31: 363 | AD31: 363 | AE31: 378 | AF31: 400 | AG31: 424 | AH31: 441 | AI31: 451 | AJ31: =AI31-D31 -> 324
A33: 1 | B33: 3F | C33: AHU1 - BTU | D33: 39808.33 | E33: 40784.95 | F33: 41523.35 | G33: 42144.42 | H33: 42515.66 | I33: 42515.66 | J33: 43641.97 | K33: 44516.37 | L33: 45377.14 | M33: 46379.68 | N33: 47271.64 | O33: 47689.75 | P33: 47689.75 | Q33: 48882.43 | R33: 49887.7 | S33: 50839.03 | T33: 51761.8 | U33: 52601.28 | V33: 53049.22 | W33: 53049.22 | X33: 54218.4 | Y33: 55235.63 | Z33: 56227.29 | AA33: 57193.07 | AB33: 58087.18 | AC33: 58087.18 | AD33: 58087.18 | AE33: 59613.06 | AF33: 60665.69 | AG33: 61550.68 | AH33: 62364.23 | AI33: 62776 | AJ33: =AI33-D33 -> 22967.67
A34: 2 | B34: 3F | C34: AHU2 - BTU | D34: 39039.43 | E34: 40011.29 | F34: 40707.58 | G34: 41355.74 | H34: 41673.19 | I34: 41673.19 | J34: 42584.56 | K34: 43444.33 | L34: 44406.91 | M34: 45373.01 | N34: 46278.07 | O34: 46702.92 | P34: 46702.92 | Q34: 47791.44 | R34: 48823.62 | S34: 49685.21 | T34: 50511.93 | U34: 51384.4 | V34: 51844.09 | W34: 51844.09 | X34: 53106.22 | Y34: 54088.33 | Z34: 55133.66 | AA34: 56040.25 | AB34: 57035.63 | AC34: 57035.63 | AD34: 57035.63 | AE34: 58367.6 | AF34: 59509.96 | AG34: 60564.32 | AH34: 61617.73 | AI34: 62028 | AJ34: =AI34-D34 -> 22988.57
A35: 3 | B35: 3F | C35: AHU3 - BTU | D35: 34466.31 | E35: 35393.85 | F35: 36282.87 | G35: 36977.18 | H35: 37332.32 | I35: 37332.32 | J35: 38473.21 | K35: 39518.46 | L35: 40611.79 | M35: 41664.29 | N35: 42556.38 | O35: 42981.82 | P35: 42981.82 | Q35: 44183.84 | R35: 45360.7 | S35: 46420.36 | T35: 47396.84 | U35: 48367.81 | V35: 48970.9 | W35: 48970.9 | X35: 50278.82 | Y35: 51264.83 | Z35: 52289.15 | AA35: 53158.33 | AB35: 54071.12 | AC35: 54071.12 | AD35: 54071.12 | AE35: 55480.6 | AF35: 56735.68 | AG35: 57867.99 | AH35: 59125.33 | AI35: 59574 | AJ35: =AI35-D35 -> 25107.69
A36: 4 | B36: 3F | C36: AHU4 - BTU | D36: 48593.12 | E36: 49926.47 | F36: 50835.05 | G36: 51496.28 | H36: 51944.19 | I36: 51944.19 | J36: 53331.66 | K36: 54608.03 | L36: 55899.29 | M36: 57002.08 | N36: 58195.11 | O36: 58725.28 | P36: 58725.28 | Q36: 60242.6 | R36: 61701.04 | S36: 63006.1 | T36: 64142.44 | U36: 65039.01 | V36: 65593.76 | W36: 65593.76 | X36: 67007.79 | Y36: 68291.96 | Z36: 69574.21 | AA36: 70699.45 | AB36: 71782.99 | AC36: 71782.99 | AD36: 71782.99 | AE36: 73417.79 | AF36: 74799.6 | AG36: 75826.22 | AH36: 76962.14 | AI36: 77455 | AJ36: =AI36-D36 -> 28861.88
B39: Daily Energy Report
B40: Electricity Consumption
A41: Sr.No | B41: Location | C41: Meter | E41: =E3 -> 45413 | F41: =F3 -> 45414 | G41: =G3 -> 45415 | H41: =H3 -> 45416 | I41: =I3 -> 45417 | J41: =J3 -> 45418 | K41: =K3 -> 45419 | L41: =L3 -> 45420 | ... AI41: =AI3 -> 45443 | AJ41: Consumption
E42: =E4 -> Thu | F42: =F4 -> Fri | G42: =G4 -> Sat | H42: =H4 -> Sun | I42: =I4 -> Mon | J42: =J4 -> Tue | K42: =K4 -> Wed | L42: =L4 -> Thu | ... AI42: =AI4 -> Sat
E43: Time | F43: Time | G43: Time | H43: Time | I43: Time | J43: Time | K43: Time | L43: Time | M43: Time | N43: Time | O43: Time | P43: Time | Q43: Time | R43: Time | S43: Time | T43: Time | U43: Time | V43: Time | W43: Time | X43: Time | Y43: Time | Z43: Time | AA43: Time | AB43: Time | AC43: Time | AD43: Time | AE43: Time | AF43: Time | AG43: Time | AH43: Time | AI43: Time
E44: 0.33333333 | F44: 0.33333333 | G44: 0.33333333 | H44: 0.33333333 | I44: 0.33333333 | J44: 0.33333333 | K44: 0.33333333 | L44: 0.33333333 | M44: 0.33333333 | N44: 0.33333333 | O44: 0.33333333 | P44: 0.33333333 | Q44: 0.33333333 | R44: 0.33333333 | S44: 0.33333333 | T44: 0.33333333 | U44: 0.33333333 | V44: 0.33333333 | W44: 0.33333333 | X44: 0.33333333 | Y44: 0.33333333 | Z44: 0.33333333 | AA44: 0.33333333 | AB44: 0.33333333 | AC44: 0.33333333 | AD44: 0.33333333 | AE44: 0.33333333 | AF44: 0.33333333 | AG44: 0.33333333 | AH44: 0.33333333 | AI44: 0.33333333
A45: 1 | B45: 3F | C45: SL No 540430038840 (EB Unit) | E45: =E7-D7 -> 362 | F45: =F7-E7 -> 253 | G45: =G7-F7 -> 242 | H45: =H7-G7 -> 205 | I45: =I7-H7 -> 220 | J45: =J7-I7 -> 202 | K45: =K7-J7 -> 239 | L45: =L7-K7 -> 197 | ... AI45: =AI7-AH7 -> 90 | AJ45: =SUM(E45:AI45) -> 6766
...

Sheet June-24
E2: June - 2024
A3: Sr.No | B3: Location | C3: Meter | D3: Previous Reading | E3: 45444 | F3: 45445 | G3: 45446 | H3: 45447 | I3: 45448 | J3: 45449 | K3: 45450 | L3: 45451 | M3: 45452 | N3: 45453 | O3: 45454 | P3: 45455 | Q3: 45456 | R3: 45457 | S3: 45458 | T3: 45459 | U3: 45460 | V3: 45461 | W3: 45462 | X3: 45463 | Y3: 45464 | Z3: 45465 | AA3: 45466 | AB3: 45467 | AC3: 45468 | AD3: 45469 | AE3: 45470 | AF3: 45471 | AG3: 45472 | AH3: 45473 | AI3: Consumption
E4: Sat | F4: Sun | G4: Mon | H4: Tue | I4: Wed | J4: Thu | K4: Fri | L4: Sat | M4: Sun | N4: Mon | O4: Tue | P4: Wed | Q4: Thu | R4: Fri | S4: Sat | T4: Sun | U4: Mon | V4: Tue | W4: Wed | X4: Thu | Y4: Fri | Z4: Sat | AA4: Sun | AB4: Mon | AC4: Tue | AD4: Wed | AE4: Thu | AF4: Fri | AG4: Sat | AH4: Sun
E5: Time | F5: Time | G5: Time | H5: Time | I5: Time | J5: Time | K5: Time | L5: Time | M5: Time | N5: Time | O5: Time | P5: Time | Q5: Time | R5: Time | S5: Time | T5: Time | U5: Time | V5: Time | W5: Time | X5: Time | Y5: Time | Z5: Time | AA5: Time | AB5: Time | AC5: Time | AD5: Time | AE5: Time | AF5: Time | AG5: Time | AH5: Time
E6: 0.33333333 | F6: 0.33333333 | G6: 0.33333333 | H6: 0.33333333 | I6: 0.33333333 | J6: 0.33333333 | K6: 0.33333333 | L6: 0.33333333 | M6: 0.33333333 | N6: 0.33333333 | O6: 0.33333333 | P6: 0.33333333 | Q6: 0.33333333 | R6: 0.33333333 | S6: 0.33333333 | T6: 0.33333333 | U6: 0.33333333 | V6: 0.33333333 | W6: 0.33333333 | X6: 0.33333333 | Y6: 0.33333333 | Z6: 0.33333333 | AA6: 0.33333333 | AB6: 0.33333333 | AC6: 0.33333333 | AD6: 0.33333333 | AE6: 0.33333333 | AF6: 0.33333333 | AG6: 0.33333333 | AH6: 0.33333333
A7: 1 | B7: 3F | C7: SL No 540430038840 (EB Unit) | D7: 27418 | E7: 27721 | F7: 27934 | G7: 28120 | H7: 28377 | I7: 28592 | J7: 28856 | K7: 29126 | L7: 29326 | M7: 29543 | N7: 29775 | O7: 29902 | P7: 30131 | Q7: 30315 | R7: 30478 | S7: 30690 | T7: 30905 | U7: 31102 | V7: 31284 | W7: 31479 | X7: 31744 | Y7: 31999 | Z7: 32217 | AA7: 32437 | AB7: 32667 | AC7: 32929 | AD7: 33190 | AE7: 33458 | AF7: 33658 | AG7: 33879 | AH7: 33984 | AI7: =AH7-D7 -> 6566
C8: DG | D8: 1040 | E8: 1078 | F8: 1079 | G8: 1155 | H8: 1155 | I8: 1197 | J8: 1200 | K8: 1207 | L8: 1207 | M8: 1230 | N8: 1230 | O8: 1365 | P8: 1388 | Q8: 1465 | R8: 1540 | S8: 1540 | T8: 1547 | U8: 1575 | V8: 1647 | W8: 1700 | X8: 1700 | Y8: 1700 | Z8: 1700 | AA8: 1700 | AB8: 1708 | AC8: 1708 | AD8: 1708 | AE8: 1708 | AF8: 1745 | AG8: 1751 | AH8: 1753 | AI8: =AH8-D8 -> 713
A9: 2 | B9: 3F | C9: SL No 540430038845 (EB Unit) | D9: 1956 | E9: 1956 | F9: 1956 | G9: 1956 | H9: 1956 | I9: 1956 | J9: 1956 | K9: 1956 | L9: 1956 | M9: 1956 | N9: 1956 | O9: 1956 | P9: 1956 | Q9: 1956 | R9: 1956 | S9: 1956 | T9: 1956 | U9: 1956 | V9: 1956 | W9: 1956 | X9: 1956 | Y9: 1956 | Z9: 1956 | AA9: 1956 | AB9: 1956 | AC9: 1956 | AD9: 1956 | AE9: 1956 | AF9: 1956 | AG9: 1956 | AH9: 1956 | AI9: =AH9-D9 -> 0
C10: DG | D10: 28 | E10: 28 | F10: 28 | G10: 28 | H10: 28 | I10: 28 | J10: 28 | K10: 28 | L10: 28 | M10: 28 | N10: 28 | O10: 28 | P10: 28 | Q10: 28 | R10: 28 | S10: 28 | T10: 28 | U10: 28 | V10: 28 | W10: 28 | X10: 28 | Y10: 28 | Z10: 28 | AA10: 28 | AB10: 28 | AC10: 28 | AD10: 28 | AE10: 28 | AF10: 28 | AG10: 28 | AH10: 28 | AI10: =AH10-D10 -> 0
A11: 3 | B11: 3F | C11: SL No 540430038844 (EB Unit) | D11: 45249 | E11: 45659 | F11: 45937 | G11: 46190 | H11: 46554 | I11: 46857 | J11: 47224 | K11: 47560 | L11: 47822 | M11: 48099 | N11: 48444 | O11: 48610 | P11: 48936 | Q11: 49185 | R11: 49405 | S11: 49691 | T11: 49960 | U11: 50224 | V11: 50483 | W11: 50770 | X11: 51135 | Y11: 51492 | Z11: 51774 | AA11: 52068 | AB11: 52408 | AC11: 52771 | AD11: 53138 | AE11: 53521 | AF11: 53797 | AG11: 54090 | AH11: 54227 | AI11: =AH11-D11 -> 8978
C12: DG | D12: 1649 | E12: 1702 | F12: 1702 | G12: 1821 | H12: 1821 | I12: 1885 | J12: 1885 | K12: 1898 | L12: 1898 | M12: 1928 | N12: 1928 | O12: 2127 | P12: 2163 | Q12: 2280 | R12: 2392 | S12: 2393 | T12: 2402 | U12: 2439 | V12: 2548 | W12: 2630 | X12: 2630 | Y12: 2630 | Z12: 2630 | AA12: 2630 | AB12: 2642 | AC12: 2642 | AD12: 2642 | AE12: 2642 | AF12: 2690 | AG12: 2699 | AH12: 2701 | AI12: =AH12-D12 -> 1052
A13: 4 | B13: 3F | C13: SL No 540430038821 (EB Unit) | D13: 0 | E13: 0 | F13: 0 | G13: 0 | H13: 0 | I13: 0 | J13: 0 | K13: 0 | L13: 0 | M13: 0 | N13: 0 | O13: 0 | P13: 0 | Q13: 0 | R13: 0 | S13: 0 | T13: 0 | U13: 0 | V13: 0 | W13: 0 | X13: 0 | Y13: 0 | Z13: 0 | AA13: 0 | AB13: 0 | AC13: 0 | AD13: 0 | AE13: 0 | AF13: 0 | AG13: 0 | AH13: 0 | AI13: =AH13-D13 -> 0
C14: DG | D14: 0 | E14: 0 | F14: 0 | G14: 0 | H14: 0 | I14: 0 | J14: 0 | K14: 0 | L14: 0 | M14: 0 | N14: 0 | O14: 0 | P14: 0 | Q14: 0 | R14: 0 | S14: 0 | T14: 0 | U14: 0 | V14: 0 | W14: 0 | X14: 0 | Y14: 0 | Z14: 0 | AA14: 0 | AB14: 0 | AC14: 0 | AD14: 0 | AE14: 0 | AF14: 0 | AG14: 0 | AH14: 0 | AI14: =AH14-D14 -> 0
A15: 5 | B15: 3F | C15: SL No 540430038849 (EB Unit) | D15: 15905 | E15: 16093 | F15: 16220 | G15: 16350 | H15: 16538 | I15: 16695 | J15: 16889 | K15: 17062 | L15: 17186 | M15: 17308 | N15: 17492 | O15: 17582 | P15: 17758 | Q15: 17891 | R15: 18002 | S15: 18126 | T15: 18248 | U15: 18357 | V15: 18492 | W15: 18644 | X15: 18838 | Y15: 19028 | Z15: 19149 | AA15: 19281 | AB15: 19453 | AC15: 19612 | AD15: 19874 | AE15: 20029 | AF15: 20170 | AG15: 20286 | AH15: 20339 | AI15: =AH15-D15 -> 4434
C16: DG | D16: 746 | E16: 778 | F16: 779 | G16: 840 | H16: 840 | I16: 878 | J16: 878 | K16: 884 | L16: 884 | M16: 897 | N16: 897 | O16: 1003 | P16: 1021 | Q16: 1086 | R16: 1150 | S16: 1150 | T16: 1154 | U16: 1169 | V16: 1229 | W16: 1274 | X16: 1274 | Y16: 1274 | Z16: 1274 | AA16: 1274 | AB16: 1280 | AC16: 1280 | AD16: 1280 | AE16: 1280 | AF16: 1306 | AG16: 1310 | AH16: 1311 | AI16: =AH16-D16 -> 565
A17: 6 | B17: 3F | C17: SL No 540430038696 (EB Unit) | D17: 26115 | E17: 26384 | F17: 26500 | G17: 26639 | H17: 26918 | I17: 27154 | J17: 27410 | K17: 27656 | L17: 27794 | M17: 27913 | N17: 28193 | O17: 28316 | P17: 28575 | Q17: 28764 | R17: 28921 | S17: 29072 | T17: 29219 | U17: 29363 | V17: 29534 | W17: 29756 | X17: 29993 | Y17: 30229 | Z17: 30340 | AA17: 30479 | AB17: 30679 | AC17: 30924 | AD17: 31175 | AE17: 31411 | AF17: 31599 | AG17: 31714 | AH17: 31779 | AI17: =AH17-D17 -> 5664
C18: DG | D18: 1209 | E18: 1253 | F18: 1253 | G18: 1385 | H18: 1385 | I18: 1381 | J18: 1381 | K18: 1387 | L18: 1387 | M18: 1402 | N18: 1402 | O18: 1567 | P18: 1595 | Q18: 1699 | R18: 1795 | S18: 1796 | T18: 1798 | U18: 1814 | V18: 1880 | W18: 1954 | X18: 1954 | Y18: 1954 | Z18: 1954 | AA18: 1954 | AB18: 1962 | AC18: 1962 | AD18: 1962 | AE18: 1962 | AF18: 1997 | AG18: 1998 | AH18: 1999 | AI18: =AH18-D18 -> 790
