Workbook

Sheet 📊 Dashboard
B1: 🏢 CBRE FACILITY MANAGEMENT — EQUIPMENT BREAKDOWN & DOWNTIME DASHBOARD
B2: Real-Time Asset Reliability, Complete vs. Partial Breakdown Analysis & Maintenance MTTR KPI Overview (2026)
B4: 📋 TOTAL BREAKDOWNS | D4: 🔴 COMPLETE BREAKDOWNS | F4: 🟡 PARTIAL BREAKDOWNS | H4: 🎯 RESOLUTION RATE
B5: =COUNT('🛠️ Breakdown Tracker 2026'!$A$3:$A$200) -> 166 | D5: =COUNTIF('🛠️ Breakdown Tracker 2026'!$H$3:$H$200, "*Complete*") -> 44 | F5: =COUNTIF('🛠️ Breakdown Tracker 2026'!$H$3:$H$200, "*Partial*") -> 122 | H5: =IFERROR(COUNTIF('🛠️ Breakdown Tracker 2026'!$L$3:$L$200, "Closed*") / COUNT('🛠️ Breakdown Tracker 2026'!$A$3:$A$200), 1) -> 0.96987952
B6: Equipment breakdowns in 2026 | D6: Full equipment shutdown | F6: Operational with issue (0 Downtime) | H6: Breakdowns resolved & restored
B8: ⏱️ TOTAL DOWNTIME | D8: ⏳ AVERAGE MTTR (HRS) | F8: 🚨 ACTIVE WIP / OPEN | H8: 🛡️ FLEET RELIABILITY
B9: =SUM('🛠️ Breakdown Tracker 2026'!$O$3:$O$200) -> 6084.8 | D9: =IFERROR(AVERAGEIF('🛠️ Breakdown Tracker 2026'!$H$3:$H$200, "*Complete*", '🛠️ Breakdown Tracker 2026'!$O$3:$O$200), 0) -> 138.29091 | F9: =COUNTIF('🛠️ Breakdown Tracker 2026'!$L$3:$L$200, "*Progress*") + COUNTIF('🛠️ Breakdown Tracker 2026'!$L$3:$L$200, "Open*") + COUNTIF('🛠️ Breakdown Tracker 2026'!$L$3:$L$200, "*Spare*") -> 5 | H9: =1 - IFERROR(D5/B5, 0) -> 0.73493976
B10: Total machine downtime hours | D10: Mean Time to Resolve Breakdowns | F10: Breakdowns pending resolution | H10: Breakdown resistance rate
B12: 📊 TABLE 1: SIMPLE CATEGORY BREAKDOWN & DOWNTIME SUMMARY (2026)
B13: Equipment Category | C13: Total Breakdowns | D13: 🔴 Complete Down | E13: 🟡 Partial Issues | F13: Total Downtime (Hrs) | G13: Avg MTTR (Hrs) | H13: Active WIP / Open | I13: % Share
B14: 🚰 Water & Plumbing | C14: =COUNTIF('🛠️ Breakdown Tracker 2026'!$E$3:$E$200, "Water & Plumbing*") -> 91 | D14: =COUNTIFS('🛠️ Breakdown Tracker 2026'!$E$3:$E$200, "Water & Plumbing*", '🛠️ Breakdown Tracker 2026'!$H$3:$H$200, "*Complete*") -> 24 | E14: =COUNTIFS('🛠️ Breakdown Tracker 2026'!$E$3:$E$200, "Water & Plumbing*", '🛠️ Breakdown Tracker 2026'!$H$3:$H$200, "*Partial*") -> 67 | F14: =SUMIFS('🛠️ Breakdown Tracker 2026'!$O$3:$O$200, '🛠️ Breakdown Tracker 2026'!$E$3:$E$200, "Water & Plumbing*") -> 420.7 | G14: =IFERROR(AVERAGEIFS('🛠️ Breakdown Tracker 2026'!$O$3:$O$200, '🛠️ Breakdown Tracker 2026'!$E$3:$E$200, "Water & Plumbing*", '🛠️ Breakdown Tracker 2026'!$H$3:$H$200, "*Complete*"), 0) -> 17.529167 | H14: =COUNTIFS('🛠️ Breakdown Tracker 2026'!$E$3:$E$200, "Water & Plumbing*", '🛠️ Breakdown Tracker 2026'!$L$3:$L$200, "<>Closed*") -> 0 | I14: =IFERROR(C14/SUM($C$14:$C$19), 0) -> 0.54819277
B15: ❄️ HVAC & Cooling | C15: =COUNTIF('🛠️ Breakdown Tracker 2026'!$E$3:$E$200, "HVAC & Cooling*") -> 10 | D15: =COUNTIFS('🛠️ Breakdown Tracker 2026'!$E$3:$E$200, "HVAC & Cooling*", '🛠️ Breakdown Tracker 2026'!$H$3:$H$200, "*Complete*") -> 3 | E15: =COUNTIFS('🛠️ Breakdown Tracker 2026'!$E$3:$E$200, "HVAC & Cooling*", '🛠️ Breakdown Tracker 2026'!$H$3:$H$200, "*Partial*") -> 7 | F15: =SUMIFS('🛠️ Breakdown Tracker 2026'!$O$3:$O$200, '🛠️ Breakdown Tracker 2026'!$E$3:$E$200, "HVAC & Cooling*") -> 154 | G15: =IFERROR(AVERAGEIFS('🛠️ Breakdown Tracker 2026'!$O$3:$O$200, '🛠️ Breakdown Tracker 2026'!$E$3:$E$200, "HVAC & Cooling*", '🛠️ Breakdown Tracker 2026'!$H$3:$H$200, "*Complete*"), 0) -> 51.333333 | H15: =COUNTIFS('🛠️ Breakdown Tracker 2026'!$E$3:$E$200, "HVAC & Cooling*", '🛠️ Breakdown Tracker 2026'!$L$3:$L$200, "<>Closed*") -> 1 | I15: =IFERROR(C15/SUM($C$14:$C$19), 0) -> 0.060240964
B16: ⚡ Electrical & Power | C16: =COUNTIF('🛠️ Breakdown Tracker 2026'!$E$3:$E$200, "Electrical & Power*") -> 24 | D16: =COUNTIFS('🛠️ Breakdown Tracker 2026'!$E$3:$E$200, "Electrical & Power*", '🛠️ Breakdown Tracker 2026'!$H$3:$H$200, "*Complete*") -> 8 | E16: =COUNTIFS('🛠️ Breakdown Tracker 2026'!$E$3:$E$200, "Electrical & Power*", '🛠️ Breakdown Tracker 2026'!$H$3:$H$200, "*Partial*") -> 16 | F16: =SUMIFS('🛠️ Breakdown Tracker 2026'!$O$3:$O$200, '🛠️ Breakdown Tracker 2026'!$E$3:$E$200, "Electrical & Power*") -> 684.7 | G16: =IFERROR(AVERAGEIFS('🛠️ Breakdown Tracker 2026'!$O$3:$O$200, '🛠️ Breakdown Tracker 2026'!$E$3:$E$200, "Electrical & Power*", '🛠️ Breakdown Tracker 2026'!$H$3:$H$200, "*Complete*"), 0) -> 85.5875 | H16: =COUNTIFS('🛠️ Breakdown Tracker 2026'!$E$3:$E$200, "Electrical & Power*", '🛠️ Breakdown Tracker 2026'!$L$3:$L$200, "<>Closed*") -> 2 | I16: =IFERROR(C16/SUM($C$14:$C$19), 0) -> 0.14457831
B17: 🍽️ Cafeteria Equipment | C17: =COUNTIF('🛠️ Breakdown Tracker 2026'!$E$3:$E$200, "Cafeteria Equipment*") -> 15 | D17: =COUNTIFS('🛠️ Breakdown Tracker 2026'!$E$3:$E$200, "Cafeteria Equipment*", '🛠️ Breakdown Tracker 2026'!$H$3:$H$200, "*Complete*") -> 6 | E17: =COUNTIFS('🛠️ Breakdown Tracker 2026'!$E$3:$E$200, "Cafeteria Equipment*", '🛠️ Breakdown Tracker 2026'!$H$3:$H$200, "*Partial*") -> 9 | F17: =SUMIFS('🛠️ Breakdown Tracker 2026'!$O$3:$O$200, '🛠️ Breakdown Tracker 2026'!$E$3:$E$200, "Cafeteria Equipment*") -> 4472.2 | G17: =IFERROR(AVERAGEIFS('🛠️ Breakdown Tracker 2026'!$O$3:$O$200, '🛠️ Breakdown Tracker 2026'!$E$3:$E$200, "Cafeteria Equipment*", '🛠️ Breakdown Tracker 2026'!$H$3:$H$200, "*Complete*"), 0) -> 745.36667 | H17: =COUNTIFS('🛠️ Breakdown Tracker 2026'!$E$3:$E$200, "Cafeteria Equipment*", '🛠️ Breakdown Tracker 2026'!$L$3:$L$200, "<>Closed*") -> 2 | I17: =IFERROR(C17/SUM($C$14:$C$19), 0) -> 0.090361446
B18: 🚪 Doors & Access Gates | C18: =COUNTIF('🛠️ Breakdown Tracker 2026'!$E$3:$E$200, "Doors & Access Gates*") -> 12 | D18: =COUNTIFS('🛠️ Breakdown Tracker 2026'!$E$3:$E$200, "Doors & Access Gates*", '🛠️ Breakdown Tracker 2026'!$H$3:$H$200, "*Complete*") -> 1 | E18: =COUNTIFS('🛠️ Breakdown Tracker 2026'!$E$3:$E$200, "Doors & Access Gates*", '🛠️ Breakdown Tracker 2026'!$H$3:$H$200, "*Partial*") -> 11 | F18: =SUMIFS('🛠️ Breakdown Tracker 2026'!$O$3:$O$200, '🛠️ Breakdown Tracker 2026'!$E$3:$E$200, "Doors & Access Gates*") -> 273.5 | G18: =IFERROR(AVERAGEIFS('🛠️ Breakdown Tracker 2026'!$O$3:$O$200, '🛠️ Breakdown Tracker 2026'!$E$3:$E$200, "Doors & Access Gates*", '🛠️ Breakdown Tracker 2026'!$H$3:$H$200, "*Complete*"), 0) -> 273.5 | H18: =COUNTIFS('🛠️ Breakdown Tracker 2026'!$E$3:$E$200, "Doors & Access Gates*", '🛠️ Breakdown Tracker 2026'!$L$3:$L$200, "<>Closed*") -> 0 | I18: =IFERROR(C18/SUM($C$14:$C$19), 0) -> 0.072289157
B19: 🚨 Fire, Safety & BMS | C19: =COUNTIF('🛠️ Breakdown Tracker 2026'!$E$3:$E$200, "Fire, Safety & BMS*") -> 14 | D19: =COUNTIFS('🛠️ Breakdown Tracker 2026'!$E$3:$E$200, "Fire, Safety & BMS*", '🛠️ Breakdown Tracker 2026'!$H$3:$H$200, "*Complete*") -> 2 | E19: =COUNTIFS('🛠️ Breakdown Tracker 2026'!$E$3:$E$200, "Fire, Safety & BMS*", '🛠️ Breakdown Tracker 2026'!$H$3:$H$200, "*Partial*") -> 12 | F19: =SUMIFS('🛠️ Breakdown Tracker 2026'!$O$3:$O$200, '🛠️ Breakdown Tracker 2026'!$E$3:$E$200, "Fire, Safety & BMS*") -> 79.7 | G19: =IFERROR(AVERAGEIFS('🛠️ Breakdown Tracker 2026'!$O$3:$O$200, '🛠️ Breakdown Tracker 2026'!$E$3:$E$200, "Fire, Safety & BMS*", '🛠️ Breakdown Tracker 2026'!$H$3:$H$200, "*Complete*"), 0) -> 39.85 | H19: =COUNTIFS('🛠️ Breakdown Tracker 2026'!$E$3:$E$200, "Fire, Safety & BMS*", '🛠️ Breakdown Tracker 2026'!$L$3:$L$200, "<>Closed*") -> 0 | I19: =IFERROR(C19/SUM($C$14:$C$19), 0) -> 0.084337349
B20: TOTAL / FLEET BREAKDOWNS | C20: =SUM(C14:C19) -> 166 | D20: =SUM(D14:D19) -> 44 | E20: =SUM(E14:E19) -> 122 | F20: =SUM(F14:F19) -> 6084.8 | G20: =IFERROR(AVERAGEIF('🛠️ Breakdown Tracker 2026'!$H$3:$H$200, "*Complete*", '🛠️ Breakdown Tracker 2026'!$O$3:$O$200), 0) -> 138.29091 | H20: =SUM(H14:H19) -> 5 | I20: =SUM(I14:I19) -> 1
B22: ⚙️ TABLE 2: OPERATIONAL BREAKDOWN SEVERITY & DOWNTIME TRACKING RULES
B23: Operational Severity Level | C23: Total Breakdowns | D23: Closed | E23: In Progress (WIP) | F23: Open / Pending | G23: Total Downtime (Hrs) | H23: % Share | I23: Downtime Calculation Rule / Policy Applied
B24: 🔴 Complete Breakdown (Full Downtime) | C24: =COUNTIF('🛠️ Breakdown Tracker 2026'!$H$3:$H$200, "*Complete*") -> 44 | D24: =COUNTIFS('🛠️ Breakdown Tracker 2026'!$H$3:$H$200, "*Complete*", '🛠️ Breakdown Tracker 2026'!$L$3:$L$200, "Closed*") -> 43 | E24: =COUNTIFS('🛠️ Breakdown Tracker 2026'!$H$3:$H$200, "*Complete*", '🛠️ Breakdown Tracker 2026'!$L$3:$L$200, "*Progress*") -> 1 | F24: =COUNTIFS('🛠️ Breakdown Tracker 2026'!$H$3:$H$200, "*Complete*", '🛠️ Breakdown Tracker 2026'!$L$3:$L$200, "Open*") + COUNTIFS('🛠️ Breakdown Tracker 2026'!$H$3:$H$200, "*Complete*", '🛠️ Breakdown Tracker 2026'!$L$3:$L$200, "*Spare*") -> 0 | G24: =SUMIFS('🛠️ Breakdown Tracker 2026'!$O$3:$O$200, '🛠️ Breakdown Tracker 2026'!$H$3:$H$200, "*Complete*") -> 6084.8 | H24: =IFERROR(C24/$C$20, 0) -> 0.26506024 | I24: 🔴 100% Breakdown Downtime Counted (Start to Resolution)
B25: 🟡 Partial Breakdown (Machine Operational) | C25: =COUNTIF('🛠️ Breakdown Tracker 2026'!$H$3:$H$200, "*Partial*") -> 122 | D25: =COUNTIFS('🛠️ Breakdown Tracker 2026'!$H$3:$H$200, "*Partial*", '🛠️ Breakdown Tracker 2026'!$L$3:$L$200, "Closed*") -> 118 | E25: =COUNTIFS('🛠️ Breakdown Tracker 2026'!$H$3:$H$200, "*Partial*", '🛠️ Breakdown Tracker 2026'!$L$3:$L$200, "*Progress*") -> 3 | F25: =COUNTIFS('🛠️ Breakdown Tracker 2026'!$H$3:$H$200, "*Partial*", '🛠️ Breakdown Tracker 2026'!$L$3:$L$200, "Open*") + COUNTIFS('🛠️ Breakdown Tracker 2026'!$H$3:$H$200, "*Partial*", '🛠️ Breakdown Tracker 2026'!$L$3:$L$200, "*Spare*") -> 1 | G25: =SUMIFS('🛠️ Breakdown Tracker 2026'!$O$3:$O$200, '🛠️ Breakdown Tracker 2026'!$H$3:$H$200, "*Partial*") -> 0 | H25: =IFERROR(C25/$C$20, 0) -> 0.73493976 | I25: 🟡 Machine Operational - 0.0 Hrs Downtime (Not Counted)
B26: TOTAL | C26: =SUM(C24:C25) -> 166 | D26: =SUM(D24:D25) -> 161 | E26: =SUM(E24:E25) -> 4 | F26: =SUM(F24:F25) -> 1 | G26: =SUM(G24:G25) -> 6084.8 | H26: =SUM(H24:H25) -> 1 | I26: Fleet Downtime Accounting Standard
B28: 🏆 TABLE 3: TOP 10 CRITICAL ASSETS BY BREAKDOWN DOWNTIME (2026)
B29: Rank | C29: Equipment / Asset Name | D29: Primary Category | E29: Total Breakdowns | F29: 🔴 Complete Down | G29: Total Downtime (Hrs) | H29: Downtime (Days) | I29: Avg MTTR (Hrs)
B30: #1 | C30: RO Water System | D30: Water & Plumbing | E30: =COUNTIF('🛠️ Breakdown Tracker 2026'!$D$3:$D$200, "RO Water System*") -> 32 | F30: =COUNTIFS('🛠️ Breakdown Tracker 2026'!$D$3:$D$200, "RO Water System*", '🛠️ Breakdown Tracker 2026'!$H$3:$H$200, "*Complete*") -> 0 | G30: =SUMIFS('🛠️ Breakdown Tracker 2026'!$O$3:$O$200, '🛠️ Breakdown Tracker 2026'!$D$3:$D$200, "RO Water System*") -> 0 | H30: =ROUND(G30/24, 2) -> 0 | I30: =IFERROR(AVERAGEIFS('🛠️ Breakdown Tracker 2026'!$O$3:$O$200, '🛠️ Breakdown Tracker 2026'!$D$3:$D$200, "RO Water System*", '🛠️ Breakdown Tracker 2026'!$H$3:$H$200, "*Complete*"), 0) -> 0
B31: #2 | C31: Zip Tap | D31: Water & Plumbing | E31: =COUNTIF('🛠️ Breakdown Tracker 2026'!$D$3:$D$200, "Zip Tap*") -> 26 | F31: =COUNTIFS('🛠️ Breakdown Tracker 2026'!$D$3:$D$200, "Zip Tap*", '🛠️ Breakdown Tracker 2026'!$H$3:$H$200, "*Complete*") -> 7 | G31: =SUMIFS('🛠️ Breakdown Tracker 2026'!$O$3:$O$200, '🛠️ Breakdown Tracker 2026'!$D$3:$D$200, "Zip Tap*") -> 260.9 | H31: =ROUND(G31/24, 2) -> 10.87 | I31: =IFERROR(AVERAGEIFS('🛠️ Breakdown Tracker 2026'!$O$3:$O$200, '🛠️ Breakdown Tracker 2026'!$D$3:$D$200, "Zip Tap*", '🛠️ Breakdown Tracker 2026'!$H$3:$H$200, "*Complete*"), 0) -> 37.271429
B32: #3 | C32: CSU (Ceiling Suspended Unit) | D32: HVAC & Cooling | E32: =COUNTIF('🛠️ Breakdown Tracker 2026'!$D$3:$D$200, "CSU (Ceiling Suspended Unit)*") -> 5 | F32: =COUNTIFS('🛠️ Breakdown Tracker 2026'!$D$3:$D$200, "CSU (Ceiling Suspended Unit)*", '🛠️ Breakdown Tracker 2026'!$H$3:$H$200, "*Complete*") -> 1 | G32: =SUMIFS('🛠️ Breakdown Tracker 2026'!$O$3:$O$200, '🛠️ Breakdown Tracker 2026'!$D$3:$D$200, "CSU (Ceiling Suspended Unit)*") -> 24.8 | H32: =ROUND(G32/24, 2) -> 1.03 | I32: =IFERROR(AVERAGEIFS('🛠️ Breakdown Tracker 2026'!$O$3:$O$200, '🛠️ Breakdown Tracker 2026'!$D$3:$D$200, "CSU (Ceiling Suspended Unit)*", '🛠️ Breakdown Tracker 2026'!$H$3:$H$200, "*Complete*"), 0) -> 24.8
B33: #4 | C33: VAV (Variable Air Volume) | D33: HVAC & Cooling | E33: =COUNTIF('🛠️ Breakdown Tracker 2026'!$D$3:$D$200, "VAV (Variable Air Volume)*") -> 4 | F33: =COUNTIFS('🛠️ Breakdown Tracker 2026'!$D$3:$D$200, "VAV (Variable Air Volume)*", '🛠️ Breakdown Tracker 2026'!$H$3:$H$200, "*Complete*") -> 1 | G33: =SUMIFS('🛠️ Breakdown Tracker 2026'!$O$3:$O$200, '🛠️ Breakdown Tracker 2026'!$D$3:$D$200, "VAV (Variable Air Volume)*") -> 27.8 | H33: =ROUND(G33/24, 2) -> 1.16 | I33: =IFERROR(AVERAGEIFS('🛠️ Breakdown Tracker 2026'!$O$3:$O$200, '🛠️ Breakdown Tracker 2026'!$D$3:$D$200, "VAV (Variable Air Volume)*", '🛠️ Breakdown Tracker 2026'!$H$3:$H$200, "*Complete*"), 0) -> 27.8
B34: #5 | C34: Speedstile Gate | D34: Doors & Access Gates | E34: =COUNTIF('🛠️ Breakdown Tracker 2026'!$D$3:$D$200, "Speedstile Gate*") -> 0 | F34: =COUNTIFS('🛠️ Breakdown Tracker 2026'!$D$3:$D$200, "Speedstile Gate*", '🛠️ Breakdown Tracker 2026'!$H$3:$H$200, "*Complete*") -> 0 | G34: =SUMIFS('🛠️ Breakdown Tracker 2026'!$O$3:$O$200, '🛠️ Breakdown Tracker 2026'!$D$3:$D$200, "Speedstile Gate*") -> 0 | H34: =ROUND(G34/24, 2) -> 0 | I34: =IFERROR(AVERAGEIFS('🛠️ Breakdown Tracker 2026'!$O$3:$O$200, '🛠️ Breakdown Tracker 2026'!$D$3:$D$200, "Speedstile Gate*", '🛠️ Breakdown Tracker 2026'!$H$3:$H$200, "*Complete*"), 0) -> 0
B35: #6 | C35: BMS System | D35: Fire, Safety & BMS | E35: =COUNTIF('🛠️ Breakdown Tracker 2026'!$D$3:$D$200, "BMS System*") -> 5 | F35: =COUNTIFS('🛠️ Breakdown Tracker 2026'!$D$3:$D$200, "BMS System*", '🛠️ Breakdown Tracker 2026'!$H$3:$H$200, "*Complete*") -> 0 | G35: =SUMIFS('🛠️ Breakdown Tracker 2026'!$O$3:$O$200, '🛠️ Breakdown Tracker 2026'!$D$3:$D$200, "BMS System*") -> 0 | H35: =ROUND(G35/24, 2) -> 0 | I35: =IFERROR(AVERAGEIFS('🛠️ Breakdown Tracker 2026'!$O$3:$O$200, '🛠️ Breakdown Tracker 2026'!$D$3:$D$200, "BMS System*", '🛠️ Breakdown Tracker 2026'!$H$3:$H$200, "*Complete*"), 0) -> 0
B36: #7 | C36: UPS & Battery System | D36: Electrical & Power | E36: =COUNTIF('🛠️ Breakdown Tracker 2026'!$D$3:$D$200, "UPS & Battery System*") -> 2 | F36: =COUNTIFS('🛠️ Breakdown Tracker 2026'!$D$3:$D$200, "UPS & Battery System*", '🛠️ Breakdown Tracker 2026'!$H$3:$H$200, "*Complete*") -> 1 | G36: =SUMIFS('🛠️ Breakdown Tracker 2026'!$O$3:$O$200, '🛠️ Breakdown Tracker 2026'!$D$3:$D$200, "UPS & Battery System*") -> 34 | H36: =ROUND(G36/24, 2) -> 1.42 | I36: =IFERROR(AVERAGEIFS('🛠️ Breakdown Tracker 2026'!$O$3:$O$200, '🛠️ Breakdown Tracker 2026'!$D$3:$D$200, "UPS & Battery System*", '🛠️ Breakdown Tracker 2026'!$H$3:$H$200, "*Complete*"), 0) -> 34
B37: #8 | C37: Toaster Machine | D37: Cafeteria Equipment | E37: =COUNTIF('🛠️ Breakdown Tracker 2026'!$D$3:$D$200, "Toaster Machine*") -> 0 | F37: =COUNTIFS('🛠️ Breakdown Tracker 2026'!$D$3:$D$200, "Toaster Machine*", '🛠️ Breakdown Tracker 2026'!$H$3:$H$200, "*Complete*") -> 0 | G37: =SUMIFS('🛠️ Breakdown Tracker 2026'!$O$3:$O$200, '🛠️ Breakdown Tracker 2026'!$D$3:$D$200, "Toaster Machine*") -> 0 | H37: =ROUND(G37/24, 2) -> 0 | I37: =IFERROR(AVERAGEIFS('🛠️ Breakdown Tracker 2026'!$O$3:$O$200, '🛠️ Breakdown Tracker 2026'!$D$3:$D$200, "Toaster Machine*", '🛠️ Breakdown Tracker 2026'!$H$3:$H$200, "*Complete*"), 0) -> 0
B38: #9 | C38: Ice Maker Machine | D38: Cafeteria Equipment | E38: =COUNTIF('🛠️ Breakdown Tracker 2026'!$D$3:$D$200, "Ice Maker Machine*") -> 2 | F38: =COUNTIFS('🛠️ Breakdown Tracker 2026'!$D$3:$D$200, "Ice Maker Machine*", '🛠️ Breakdown Tracker 2026'!$H$3:$H$200, "*Complete*") -> 0 | G38: =SUMIFS('🛠️ Breakdown Tracker 2026'!$O$3:$O$200, '🛠️ Breakdown Tracker 2026'!$D$3:$D$200, "Ice Maker Machine*") -> 0 | H38: =ROUND(G38/24, 2) -> 0 | I38: =IFERROR(AVERAGEIFS('🛠️ Breakdown Tracker 2026'!$O$3:$O$200, '🛠️ Breakdown Tracker 2026'!$D$3:$D$200, "Ice Maker Machine*", '🛠️ Breakdown Tracker 2026'!$H$3:$H$200, "*Complete*"), 0) -> 0
B39: #10 | C39: Dishwashing Machine | D39: Cafeteria Equipment | E39: =COUNTIF('🛠️ Breakdown Tracker 2026'!$D$3:$D$200, "Dishwashing Machine*") -> 2 | F39: =COUNTIFS('🛠️ Breakdown Tracker 2026'!$D$3:$D$200, "Dishwashing Machine*", '🛠️ Breakdown Tracker 2026'!$H$3:$H$200, "*Complete*") -> 0 | G39: =SUMIFS('🛠️ Breakdown Tracker 2026'!$O$3:$O$200, '🛠️ Breakdown Tracker 2026'!$D$3:$D$200, "Dishwashing Machine*") -> 0 | H39: =ROUND(G39/24, 2) -> 0 | I39: =IFERROR(AVERAGEIFS('🛠️ Breakdown Tracker 2026'!$O$3:$O$200, '🛠️ Breakdown Tracker 2026'!$D$3:$D$200, "Dishwashing Machine*", '🛠️ Breakdown Tracker 2026'!$H$3:$H$200, "*Complete*"), 0) -> 0
B41: 🛠️ SERVICE PROVIDER RESOLUTION MATRIX | F41: 📅 2026 MONTHLY BREAKDOWN & RESOLUTION TREND
B42: Handled By | C42: Total Jobs | D42: Breakdowns | E42: Closed Rate | F42: Month (2026) | G42: Breakdowns | H42: Downtime (Hrs) | I42: Closure %
B43: In-House Team | C43: =COUNTIF('🛠️ Breakdown Tracker 2026'!$K$3:$K$200, "In-House Team*") -> 87 | D43: =COUNTIFS('🛠️ Breakdown Tracker 2026'!$K$3:$K$200, "In-House Team*", '🛠️ Breakdown Tracker 2026'!$H$3:$H$200, "*Complete*") -> 25 | E43: =IFERROR(COUNTIFS('🛠️ Breakdown Tracker 2026'!$K$3:$K$200, "In-House Team*", '🛠️ Breakdown Tracker 2026'!$L$3:$L$200, "Closed*") / C43, 1) -> 0.95402299 | F43: Jan 2026 | G43: =COUNTIFS('🛠️ Breakdown Tracker 2026'!$B$3:$B$200, ">="&DATE(2026,1,1), '🛠️ Breakdown Tracker 2026'!$B$3:$B$200, "<="&DATE(2026,1,31)) -> 30 | H43: =SUMIFS('🛠️ Breakdown Tracker 2026'!$O$3:$O$200, '🛠️ Breakdown Tracker 2026'!$B$3:$B$200, ">="&DATE(2026,1,1), '🛠️ Breakdown Tracker 2026'!$B$3:$B$200, "<="&DATE(2026,1,31)) -> 406.2 | I43: =IFERROR(COUNTIFS('🛠️ Breakdown Tracker 2026'!$B$3:$B$200, ">="&DATE(2026,1,1), '🛠️ Breakdown Tracker 2026'!$B$3:$B$200, "<="&DATE(2026,1,31), '🛠️ Breakdown Tracker 2026'!$L$3:$L$200, "Closed*") / G43, 1) -> 1
B44: Vendor / OEM | C44: =COUNTIF('🛠️ Breakdown Tracker 2026'!$K$3:$K$200, "Vendor / OEM*") -> 76 | D44: =COUNTIFS('🛠️ Breakdown Tracker 2026'!$K$3:$K$200, "Vendor / OEM*", '🛠️ Breakdown Tracker 2026'!$H$3:$H$200, "*Complete*") -> 18 | E44: =IFERROR(COUNTIFS('🛠️ Breakdown Tracker 2026'!$K$3:$K$200, "Vendor / OEM*", '🛠️ Breakdown Tracker 2026'!$L$3:$L$200, "Closed*") / C44, 1) -> 0.98684211 | F44: Feb 2026 | G44: =COUNTIFS('🛠️ Breakdown Tracker 2026'!$B$3:$B$200, ">="&DATE(2026,2,1), '🛠️ Breakdown Tracker 2026'!$B$3:$B$200, "<="&DATE(2026,2,28)) -> 40 | H44: =SUMIFS('🛠️ Breakdown Tracker 2026'!$O$3:$O$200, '🛠️ Breakdown Tracker 2026'!$B$3:$B$200, ">="&DATE(2026,2,1), '🛠️ Breakdown Tracker 2026'!$B$3:$B$200, "<="&DATE(2026,2,28)) -> 4442.3 | I44: =IFERROR(COUNTIFS('🛠️ Breakdown Tracker 2026'!$B$3:$B$200, ">="&DATE(2026,2,1), '🛠️ Breakdown Tracker 2026'!$B$3:$B$200, "<="&DATE(2026,2,28), '🛠️ Breakdown Tracker 2026'!$L$3:$L$200, "Closed*") / G44, 1) -> 0.975
B45: DLF / Landlord Team | C45: =COUNTIF('🛠️ Breakdown Tracker 2026'!$K$3:$K$200, "DLF / Landlord Team*") -> 3 | D45: =COUNTIFS('🛠️ Breakdown Tracker 2026'!$K$3:$K$200, "DLF / Landlord Team*", '🛠️ Breakdown Tracker 2026'!$H$3:$H$200, "*Complete*") -> 1 | E45: =IFERROR(COUNTIFS('🛠️ Breakdown Tracker 2026'!$K$3:$K$200, "DLF / Landlord Team*", '🛠️ Breakdown Tracker 2026'!$L$3:$L$200, "Closed*") / C45, 1) -> 1 | F45: Mar 2026 | G45: =COUNTIFS('🛠️ Breakdown Tracker 2026'!$B$3:$B$200, ">="&DATE(2026,3,1), '🛠️ Breakdown Tracker 2026'!$B$3:$B$200, "<="&DATE(2026,3,31)) -> 41 | H45: =SUMIFS('🛠️ Breakdown Tracker 2026'!$O$3:$O$200, '🛠️ Breakdown Tracker 2026'!$B$3:$B$200, ">="&DATE(2026,3,1), '🛠️ Breakdown Tracker 2026'!$B$3:$B$200, "<="&DATE(2026,3,31)) -> 80.1 | I45: =IFERROR(COUNTIFS('🛠️ Breakdown Tracker 2026'!$B$3:$B$200, ">="&DATE(2026,3,1), '🛠️ Breakdown Tracker 2026'!$B$3:$B$200, "<="&DATE(2026,3,31), '🛠️ Breakdown Tracker 2026'!$L$3:$L$200, "Closed*") / G45, 1) -> 0.95121951
B46: Project Team | C46: =COUNTIF('🛠️ Breakdown Tracker 2026'!$K$3:$K$200, "Project Team*") -> 0 | D46: =COUNTIFS('🛠️ Breakdown Tracker 2026'!$K$3:$K$200, "Project Team*", '🛠️ Breakdown Tracker 2026'!$H$3:$H$200, "*Complete*") -> 0 | E46: =IFERROR(COUNTIFS('🛠️ Breakdown Tracker 2026'!$K$3:$K$200, "Project Team*", '🛠️ Breakdown Tracker 2026'!$L$3:$L$200, "Closed*") / C46, 1) -> 1 | F46: Apr 2026 | G46: =COUNTIFS('🛠️ Breakdown Tracker 2026'!$B$3:$B$200, ">="&DATE(2026,4,1), '🛠️ Breakdown Tracker 2026'!$B$3:$B$200, "<="&DATE(2026,4,30)) -> 25 | H46: =SUMIFS('🛠️ Breakdown Tracker 2026'!$O$3:$O$200, '🛠️ Breakdown Tracker 2026'!$B$3:$B$200, ">="&DATE(2026,4,1), '🛠️ Breakdown Tracker 2026'!$B$3:$B$200, "<="&DATE(2026,4,30)) -> 642.3 | I46: =IFERROR(COUNTIFS('🛠️ Breakdown Tracker 2026'!$B$3:$B$200, ">="&DATE(2026,4,1), '🛠️ Breakdown Tracker 2026'!$B$3:$B$200, "<="&DATE(2026,4,30), '🛠️ Breakdown Tracker 2026'!$L$3:$L$200, "Closed*") / G46, 1) -> 1
...

Sheet 🛠️ Breakdown Tracker 2026
A1: 🏢 CBRE— EQUIPMENT BREAKDOWN TRACKER (2026)
A2: Sr. No. | B2: Start Date | C2: Start Time | D2: Equipment / Asset | E2: Category | F2: Location / Zone | G2: Nature of Breakdown / Malfunction | H2: Operational Impact | I2: Ticket No. | J2: Action Taken / Resolution Summary | K2: Handled By | L2: Status | M2: Closing Date | N2: Closing Time | O2: Breakdown Downtime (Hrs) | P2: Breakdown Downtime (Days) | Q2: Total Lead Time (Hrs) | R2: Complete Breakdown Flag | S2: Remarks / Vendor Details
A3: 1 | B3: 46027 | C3: 0.48055556 | D3: RO Water System | E3: Water & Plumbing | F3: Main Facility Floor | G3: Water Pressure issue | H3: 🟡 Partial Breakdown (Machine Operational) | I3: 104989 | J3: Inspected, serviced and restored to normal operation by In-House Team | K3: In-House Team | L3: Closed | M3: 46027 | N3: 0.75 | O3: =IF(ISBLANK(B3), 0, IF(ISNUMBER(SEARCH("Complete", H3)), IF(ISBLANK(M3), IF(L3="Closed", 4, ROUND(MAX(0, (NOW() - (B3 + IF(ISBLANK(C3), TIME(9,0,0), C3))) * 24), 1)), ROUND(MAX(0, ((M3 + IF(ISBLANK(N3), TIME(18,0,0), N3)) - (B3 + IF(ISBLANK(C3), TIME(9,0,0), C3))) * 24), 1)), 0)) -> 0 | P3: =ROUND(O3 / 24, 2) -> 0 | Q3: =IF(ISBLANK(B3), 0, IF(ISBLANK(M3), IF(L3="Closed", 4, ROUND(MAX(0, (NOW() - (B3 + IF(ISBLANK(C3), TIME(9,0,0), C3))) * 24), 1)), ROUND(MAX(0, ((M3 + IF(ISBLANK(N3), TIME(18,0,0), N3)) - (B3 + IF(ISBLANK(C3), TIME(9,0,0), C3))) * 24), 1))) -> 6.5 | R3: =IF(ISNUMBER(SEARCH("Complete", H3)), 1, 0) -> 0 | S3: Standard Resolution
A4: 2 | B4: 46028 | C4: 0.40138889 | D4: RO Water System | E4: Water & Plumbing | F4: Zone F Floor | G4: Zone - F, RO Water TDS issue | H4: 🟡 Partial Breakdown (Machine Operational) | I4: 105158 | J4: Inspected, serviced and restored to normal operation by In-House Team | K4: In-House Team | L4: Closed | M4: 46028 | N4: 0.75 | O4: =IF(ISBLANK(B4), 0, IF(ISNUMBER(SEARCH("Complete", H4)), IF(ISBLANK(M4), IF(L4="Closed", 4, ROUND(MAX(0, (NOW() - (B4 + IF(ISBLANK(C4), TIME(9,0,0), C4))) * 24), 1)), ROUND(MAX(0, ((M4 + IF(ISBLANK(N4), TIME(18,0,0), N4)) - (B4 + IF(ISBLANK(C4), TIME(9,0,0), C4))) * 24), 1)), 0)) -> 0 | P4: =ROUND(O4 / 24, 2) -> 0 | Q4: =IF(ISBLANK(B4), 0, IF(ISBLANK(M4), IF(L4="Closed", 4, ROUND(MAX(0, (NOW() - (B4 + IF(ISBLANK(C4), TIME(9,0,0), C4))) * 24), 1)), ROUND(MAX(0, ((M4 + IF(ISBLANK(N4), TIME(18,0,0), N4)) - (B4 + IF(ISBLANK(C4), TIME(9,0,0), C4))) * 24), 1))) -> 8.4 | R4: =IF(ISNUMBER(SEARCH("Complete", H4)), 1, 0) -> 0 | S4: Standard Resolution
A5: 3 | B5: 46031 | C5: 0.43611111 | D5: RO Water System | E5: Water & Plumbing | F5: Zone A - Social Hub | G5: Zone A, Social hub Water Leakage issue | H5: 🟡 Partial Breakdown (Machine Operational) | I5: 106282 | J5: Inspected, serviced and restored to normal operation by In-House Team | K5: In-House Team | L5: Closed | M5: 46031 | N5: 0.75 | O5: =IF(ISBLANK(B5), 0, IF(ISNUMBER(SEARCH("Complete", H5)), IF(ISBLANK(M5), IF(L5="Closed", 4, ROUND(MAX(0, (NOW() - (B5 + IF(ISBLANK(C5), TIME(9,0,0), C5))) * 24), 1)), ROUND(MAX(0, ((M5 + IF(ISBLANK(N5), TIME(18,0,0), N5)) - (B5 + IF(ISBLANK(C5), TIME(9,0,0), C5))) * 24), 1)), 0)) -> 0 | P5: =ROUND(O5 / 24, 2) -> 0 | Q5: =IF(ISBLANK(B5), 0, IF(ISBLANK(M5), IF(L5="Closed", 4, ROUND(MAX(0, (NOW() - (B5 + IF(ISBLANK(C5), TIME(9,0,0), C5))) * 24), 1)), ROUND(MAX(0, ((M5 + IF(ISBLANK(N5), TIME(18,0,0), N5)) - (B5 + IF(ISBLANK(C5), TIME(9,0,0), C5))) * 24), 1))) -> 7.5 | R5: =IF(ISNUMBER(SEARCH("Complete", H5)), 1, 0) -> 0 | S5: Standard Resolution
A6: 4 | B6: 46031 | C6: 0.43611111 | D6: Zip Tap | E6: Water & Plumbing | F6: Mother's Room | G6: Mother Room, Zip Tap Display Sensor issue | H6: 🟡 Partial Breakdown (Machine Operational) | I6: 106283 | J6: Inspected, serviced and restored to normal operation by In-House Team | K6: In-House Team | L6: Closed | M6: 46031 | N6: 0.75 | O6: =IF(ISBLANK(B6), 0, IF(ISNUMBER(SEARCH("Complete", H6)), IF(ISBLANK(M6), IF(L6="Closed", 4, ROUND(MAX(0, (NOW() - (B6 + IF(ISBLANK(C6), TIME(9,0,0), C6))) * 24), 1)), ROUND(MAX(0, ((M6 + IF(ISBLANK(N6), TIME(18,0,0), N6)) - (B6 + IF(ISBLANK(C6), TIME(9,0,0), C6))) * 24), 1)), 0)) -> 0 | P6: =ROUND(O6 / 24, 2) -> 0 | Q6: =IF(ISBLANK(B6), 0, IF(ISBLANK(M6), IF(L6="Closed", 4, ROUND(MAX(0, (NOW() - (B6 + IF(ISBLANK(C6), TIME(9,0,0), C6))) * 24), 1)), ROUND(MAX(0, ((M6 + IF(ISBLANK(N6), TIME(18,0,0), N6)) - (B6 + IF(ISBLANK(C6), TIME(9,0,0), C6))) * 24), 1))) -> 7.5 | R6: =IF(ISNUMBER(SEARCH("Complete", H6)), 1, 0) -> 0 | S6: Standard Resolution
A7: 5 | B7: 46034 | C7: 0.4625 | D7: RO Water System | E7: Water & Plumbing | F7: Zone F Floor | G7: Zone -F, RO Water TDS issue | H7: 🟡 Partial Breakdown (Machine Operational) | I7: 106572 | J7: Inspected, serviced and restored to normal operation by In-House Team | K7: In-House Team | L7: Closed | M7: 46034 | N7: 0.75 | O7: =IF(ISBLANK(B7), 0, IF(ISNUMBER(SEARCH("Complete", H7)), IF(ISBLANK(M7), IF(L7="Closed", 4, ROUND(MAX(0, (NOW() - (B7 + IF(ISBLANK(C7), TIME(9,0,0), C7))) * 24), 1)), ROUND(MAX(0, ((M7 + IF(ISBLANK(N7), TIME(18,0,0), N7)) - (B7 + IF(ISBLANK(C7), TIME(9,0,0), C7))) * 24), 1)), 0)) -> 0 | P7: =ROUND(O7 / 24, 2) -> 0 | Q7: =IF(ISBLANK(B7), 0, IF(ISBLANK(M7), IF(L7="Closed", 4, ROUND(MAX(0, (NOW() - (B7 + IF(ISBLANK(C7), TIME(9,0,0), C7))) * 24), 1)), ROUND(MAX(0, ((M7 + IF(ISBLANK(N7), TIME(18,0,0), N7)) - (B7 + IF(ISBLANK(C7), TIME(9,0,0), C7))) * 24), 1))) -> 6.9 | R7: =IF(ISNUMBER(SEARCH("Complete", H7)), 1, 0) -> 0 | S7: Standard Resolution
A8: 6 | B8: 46035 | C8: 0.33333333 | D8: UPS & Battery System | E8: Electrical & Power | F8: Main Facility Floor | G8: Light not working needs to be checked | H8: 🔴 Complete Breakdown (Full Downtime) | I8: N/A | J8: Inspected, serviced and restored to normal operation by In-House Team | K8: In-House Team | L8: Closed | M8: 46036 | N8: 0.75 | O8: =IF(ISBLANK(B8), 0, IF(ISNUMBER(SEARCH("Complete", H8)), IF(ISBLANK(M8), IF(L8="Closed", 4, ROUND(MAX(0, (NOW() - (B8 + IF(ISBLANK(C8), TIME(9,0,0), C8))) * 24), 1)), ROUND(MAX(0, ((M8 + IF(ISBLANK(N8), TIME(18,0,0), N8)) - (B8 + IF(ISBLANK(C8), TIME(9,0,0), C8))) * 24), 1)), 0)) -> 34 | P8: =ROUND(O8 / 24, 2) -> 1.42 | Q8: =IF(ISBLANK(B8), 0, IF(ISBLANK(M8), IF(L8="Closed", 4, ROUND(MAX(0, (NOW() - (B8 + IF(ISBLANK(C8), TIME(9,0,0), C8))) * 24), 1)), ROUND(MAX(0, ((M8 + IF(ISBLANK(N8), TIME(18,0,0), N8)) - (B8 + IF(ISBLANK(C8), TIME(9,0,0), C8))) * 24), 1))) -> 34 | R8: =IF(ISNUMBER(SEARCH("Complete", H8)), 1, 0) -> 1 | S8: Standard Resolution
A9: 7 | B9: 46035 | C9: 0.64583333 | D9: Washroom Door | E9: Doors & Access Gates | F9: Zone E - Male Washroom | G9: Zone - E, Male washroom door not properly close | H9: 🟡 Partial Breakdown (Machine Operational) | I9: N/A | J9: Inspected, serviced and restored to normal operation by In-House Team | K9: In-House Team | L9: Closed | M9: 46036 | N9: 0.75 | O9: =IF(ISBLANK(B9), 0, IF(ISNUMBER(SEARCH("Complete", H9)), IF(ISBLANK(M9), IF(L9="Closed", 4, ROUND(MAX(0, (NOW() - (B9 + IF(ISBLANK(C9), TIME(9,0,0), C9))) * 24), 1)), ROUND(MAX(0, ((M9 + IF(ISBLANK(N9), TIME(18,0,0), N9)) - (B9 + IF(ISBLANK(C9), TIME(9,0,0), C9))) * 24), 1)), 0)) -> 0 | P9: =ROUND(O9 / 24, 2) -> 0 | Q9: =IF(ISBLANK(B9), 0, IF(ISBLANK(M9), IF(L9="Closed", 4, ROUND(MAX(0, (NOW() - (B9 + IF(ISBLANK(C9), TIME(9,0,0), C9))) * 24), 1)), ROUND(MAX(0, ((M9 + IF(ISBLANK(N9), TIME(18,0,0), N9)) - (B9 + IF(ISBLANK(C9), TIME(9,0,0), C9))) * 24), 1))) -> 26.5 | R9: =IF(ISNUMBER(SEARCH("Complete", H9)), 1, 0) -> 0 | S9: Repaired by inhouse team
A10: 8 | B10: 46035 | C10: 0.76388889 | D10: Cafeteria | E10: Electrical & Power | F10: Cafeteria / Pantry | G10: Tuck shop DB earthing needs to be connected | H10: 🟡 Partial Breakdown (Machine Operational) | I10: N/A | J10: Inspected, serviced and restored to normal operation by In-House Team | K10: In-House Team | L10: Closed | M10: 46036 | N10: 0.75 | O10: =IF(ISBLANK(B10), 0, IF(ISNUMBER(SEARCH("Complete", H10)), IF(ISBLANK(M10), IF(L10="Closed", 4, ROUND(MAX(0, (NOW() - (B10 + IF(ISBLANK(C10), TIME(9,0,0), C10))) * 24), 1)), ROUND(MAX(0, ((M10 + IF(ISBLANK(N10), TIME(18,0,0), N10)) - (B10 + IF(ISBLANK(C10), TIME(9,0,0), C10))) * 24), 1)), 0)) -> 0 | P10: =ROUND(O10 / 24, 2) -> 0 | Q10: =IF(ISBLANK(B10), 0, IF(ISBLANK(M10), IF(L10="Closed", 4, ROUND(MAX(0, (NOW() - (B10 + IF(ISBLANK(C10), TIME(9,0,0), C10))) * 24), 1)), ROUND(MAX(0, ((M10 + IF(ISBLANK(N10), TIME(18,0,0), N10)) - (B10 + IF(ISBLANK(C10), TIME(9,0,0), C10))) * 24), 1))) -> 23.7 | R10: =IF(ISNUMBER(SEARCH("Complete", H10)), 1, 0) -> 0 | S10: Repaired by inhouse team
A11: 9 | B11: 46037 | C11: 0.375 | D11: RO Water System | E11: Water & Plumbing | F11: Social Hub 1 | G11: Social hub 1, RO Water TDS issue | H11: 🟡 Partial Breakdown (Machine Operational) | I11: 107240 | J11: OEM Vendor technician aligned, issue diagnosed & rectified | K11: Vendor / OEM | L11: Closed | M11: 46037 | N11: 0.75 | O11: =IF(ISBLANK(B11), 0, IF(ISNUMBER(SEARCH("Complete", H11)), IF(ISBLANK(M11), IF(L11="Closed", 4, ROUND(MAX(0, (NOW() - (B11 + IF(ISBLANK(C11), TIME(9,0,0), C11))) * 24), 1)), ROUND(MAX(0, ((M11 + IF(ISBLANK(N11), TIME(18,0,0), N11)) - (B11 + IF(ISBLANK(C11), TIME(9,0,0), C11))) * 24), 1)), 0)) -> 0 | P11: =ROUND(O11 / 24, 2) -> 0 | Q11: =IF(ISBLANK(B11), 0, IF(ISBLANK(M11), IF(L11="Closed", 4, ROUND(MAX(0, (NOW() - (B11 + IF(ISBLANK(C11), TIME(9,0,0), C11))) * 24), 1)), ROUND(MAX(0, ((M11 + IF(ISBLANK(N11), TIME(18,0,0), N11)) - (B11 + IF(ISBLANK(C11), TIME(9,0,0), C11))) * 24), 1))) -> 9 | R11: =IF(ISNUMBER(SEARCH("Complete", H11)), 1, 0) -> 0 | S11: Vendor
A12: 10 | B12: 46037 | C12: 0.375 | D12: RO Water System | E12: Water & Plumbing | F12: Zone 2 Floor | G12: Zone -2, RO Water TDS issue | H12: 🟡 Partial Breakdown (Machine Operational) | I12: 107342 | J12: OEM Vendor technician aligned, issue diagnosed & rectified | K12: Vendor / OEM | L12: Closed | M12: 46037 | N12: 0.75 | O12: =IF(ISBLANK(B12), 0, IF(ISNUMBER(SEARCH("Complete", H12)), IF(ISBLANK(M12), IF(L12="Closed", 4, ROUND(MAX(0, (NOW() - (B12 + IF(ISBLANK(C12), TIME(9,0,0), C12))) * 24), 1)), ROUND(MAX(0, ((M12 + IF(ISBLANK(N12), TIME(18,0,0), N12)) - (B12 + IF(ISBLANK(C12), TIME(9,0,0), C12))) * 24), 1)), 0)) -> 0 | P12: =ROUND(O12 / 24, 2) -> 0 | Q12: =IF(ISBLANK(B12), 0, IF(ISBLANK(M12), IF(L12="Closed", 4, ROUND(MAX(0, (NOW() - (B12 + IF(ISBLANK(C12), TIME(9,0,0), C12))) * 24), 1)), ROUND(MAX(0, ((M12 + IF(ISBLANK(N12), TIME(18,0,0), N12)) - (B12 + IF(ISBLANK(C12), TIME(9,0,0), C12))) * 24), 1))) -> 9 | R12: =IF(ISNUMBER(SEARCH("Complete", H12)), 1, 0) -> 0 | S12: Vendor
A13: 11 | B13: 46039 | C13: 0.44444444 | D13: Hydraulic Table Motor | E13: Electrical & Power | F13: Zone A - Workstation Floor | G13: Zone A, W/S 033 Hydraulic Table Remote issue | H13: 🟡 Partial Breakdown (Machine Operational) | I13: N/A | J13: Inspected, serviced and restored to normal operation by In-House Team | K13: In-House Team | L13: Closed | M13: 46039 | N13: 0.75 | O13: =IF(ISBLANK(B13), 0, IF(ISNUMBER(SEARCH("Complete", H13)), IF(ISBLANK(M13), IF(L13="Closed", 4, ROUND(MAX(0, (NOW() - (B13 + IF(ISBLANK(C13), TIME(9,0,0), C13))) * 24), 1)), ROUND(MAX(0, ((M13 + IF(ISBLANK(N13), TIME(18,0,0), N13)) - (B13 + IF(ISBLANK(C13), TIME(9,0,0), C13))) * 24), 1)), 0)) -> 0 | P13: =ROUND(O13 / 24, 2) -> 0 | Q13: =IF(ISBLANK(B13), 0, IF(ISBLANK(M13), IF(L13="Closed", 4, ROUND(MAX(0, (NOW() - (B13 + IF(ISBLANK(C13), TIME(9,0,0), C13))) * 24), 1)), ROUND(MAX(0, ((M13 + IF(ISBLANK(N13), TIME(18,0,0), N13)) - (B13 + IF(ISBLANK(C13), TIME(9,0,0), C13))) * 24), 1))) -> 7.3 | R13: =IF(ISNUMBER(SEARCH("Complete", H13)), 1, 0) -> 0 | S13: Standard Resolution
A14: 12 | B14: 46039 | C14: 0.475 | D14: Geyser / Water Heater | E14: Water & Plumbing | F14: Zone E - Male Washroom | G14: Zone - E, male Washroom Leakage issue | H14: 🟡 Partial Breakdown (Machine Operational) | I14: N/A | J14: Inspected, serviced and restored to normal operation by In-House Team | K14: In-House Team | L14: Closed | M14: 46039 | N14: 0.75 | O14: =IF(ISBLANK(B14), 0, IF(ISNUMBER(SEARCH("Complete", H14)), IF(ISBLANK(M14), IF(L14="Closed", 4, ROUND(MAX(0, (NOW() - (B14 + IF(ISBLANK(C14), TIME(9,0,0), C14))) * 24), 1)), ROUND(MAX(0, ((M14 + IF(ISBLANK(N14), TIME(18,0,0), N14)) - (B14 + IF(ISBLANK(C14), TIME(9,0,0), C14))) * 24), 1)), 0)) -> 0 | P14: =ROUND(O14 / 24, 2) -> 0 | Q14: =IF(ISBLANK(B14), 0, IF(ISBLANK(M14), IF(L14="Closed", 4, ROUND(MAX(0, (NOW() - (B14 + IF(ISBLANK(C14), TIME(9,0,0), C14))) * 24), 1)), ROUND(MAX(0, ((M14 + IF(ISBLANK(N14), TIME(18,0,0), N14)) - (B14 + IF(ISBLANK(C14), TIME(9,0,0), C14))) * 24), 1))) -> 6.6 | R14: =IF(ISNUMBER(SEARCH("Complete", H14)), 1, 0) -> 0 | S14: Repaired by inhouse team
... A57: 55 | B57: 46069 | C57: 0.75 | D57: Lighting Circuit / Fixture | E57: Electrical & Power | F57: Main Facility Floor | G57: Nab Logo Smps DB Cleaning And 1nos connector change | H57: 🟡 Partial Breakdown (Machine Operational) | I57: N/A | J57: Inspected, serviced and restored to normal operation by In-House Team | K57: In-House Team | L57: Closed | M57: 46069 | N57: 0.75 | O57: =IF(ISBLANK(B57), 0, IF(ISNUMBER(SEARCH("Complete", H57)), IF(ISBLANK(M57), IF(L57="Closed", 4, ROUND(MAX(0, (NOW() - (B57 + IF(ISBLANK(C57), TIME(9,0,0), C57))) * 24), 1)), ROUND(MAX(0, ((M57 + IF(ISBLANK(N57), TIME(18,0,0), N57)) - (B57 + IF(ISBLANK(C57), TIME(9,0,0), C57))) * 24), 1)), 0)) -> 0 | P57: =ROUND(O57 / 24, 2) -> 0 | Q57: =IF(ISBLANK(B57), 0, IF(ISBLANK(M57), IF(L57="Closed", 4, ROUND(MAX(0, (NOW() - (B57 + IF(ISBLANK(C57), TIME(9,0,0), C57))) * 24), 1)), ROUND(MAX(0, ((M57 + IF(ISBLANK(N57), TIME(18,0,0), N57)) - (B57 + IF(ISBLANK(C57), TIME(9,0,0), C57))) * 24), 1))) -> 0 | R57: =IF(ISNUMBER(SEARCH("Complete", H57)), 1, 0) -> 0 | S57: Repaired by inhouse team
A58: 56 | B58: 46071 | C58: 0.57777778 | D58: Microwave Oven | E58: Cafeteria Equipment | F58: Cafeteria / Pantry | G58: Cafeteria microwave not working needs to be checked | H58: 🔴 Complete Breakdown (Full Downtime) | I58: N/A | J58: Investigation in progress; technician / spare parts aligned | K58: In-House Team | L58: In Progress (WIP) | O58: =IF(ISBLANK(B58), 0, IF(ISNUMBER(SEARCH("Complete", H58)), IF(ISBLANK(M58), IF(L58="Closed", 4, ROUND(MAX(0, (NOW() - (B58 + IF(ISBLANK(C58), TIME(9,0,0), C58))) * 24), 1)), ROUND(MAX(0, ((M58 + IF(ISBLANK(N58), TIME(18,0,0), N58)) - (B58 + IF(ISBLANK(C58), TIME(9,0,0), C58))) * 24), 1)), 0)) -> 4372.1 | P58: =ROUND(O58 / 24, 2) -> 182.17 | Q58: =IF(ISBLANK(B58), 0, IF(ISBLANK(M58), IF(L58="Closed", 4, ROUND(MAX(0, (NOW() - (B58 + IF(ISBLANK(C58), TIME(9,0,0), C58))) * 24), 1)), ROUND(MAX(0, ((M58 + IF(ISBLANK(N58), TIME(18,0,0), N58)) - (B58 + IF(ISBLANK(C58), TIME(9,0,0), C58))) * 24), 1))) -> 4372.1 | R58: =IF(ISNUMBER(SEARCH("Complete", H58)), 1, 0) -> 1 | S58: Standard Resolution
A59: 57 | B59: 46072 | C59: 0.8125 | D59: Coffee / Tea Dispenser | E59: Cafeteria Equipment | F59: Cafeteria / Pantry | G59: Cafeteria ccd machine not working needs to be checked | H59: 🔴 Complete Breakdown (Full Downtime) | I59: N/A | J59: OEM Vendor technician aligned, issue diagnosed & rectified | K59: Vendor / OEM | L59: Closed | M59: 46072 | N59: 0.75 | O59: =IF(ISBLANK(B59), 0, IF(ISNUMBER(SEARCH("Complete", H59)), IF(ISBLANK(M59), IF(L59="Closed", 4, ROUND(MAX(0, (NOW() - (B59 + IF(ISBLANK(C59), TIME(9,0,0), C59))) * 24), 1)), ROUND(MAX(0, ((M59 + IF(ISBLANK(N59), TIME(18,0,0), N59)) - (B59 + IF(ISBLANK(C59), TIME(9,0,0), C59))) * 24), 1)), 0)) -> 0 | P59: =ROUND(O59 / 24, 2) -> 0 | Q59: =IF(ISBLANK(B59), 0, IF(ISBLANK(M59), IF(L59="Closed", 4, ROUND(MAX(0, (NOW() - (B59 + IF(ISBLANK(C59), TIME(9,0,0), C59))) * 24), 1)), ROUND(MAX(0, ((M59 + IF(ISBLANK(N59), TIME(18,0,0), N59)) - (B59 + IF(ISBLANK(C59), TIME(9,0,0), C59))) * 24), 1))) -> 0 | R59: =IF(ISNUMBER(SEARCH("Complete", H59)), 1, 0) -> 1 | S59: Vendor
A60: 58 | B60: 46073 | C60: 0.056944444 | D60: Drainage / Sump Pump | E60: Water & Plumbing | F60: Cafeteria / Pantry | G60: Cafeteria Island , sum pump issue | H60: 🟡 Partial Breakdown (Machine Operational) | I60: N\A | J60: Inspected, serviced and restored to normal operation by In-House Team | K60: In-House Team | L60: Closed | M60: 46086 | N60: 0.75 | O60: =IF(ISBLANK(B60), 0, IF(ISNUMBER(SEARCH("Complete", H60)), IF(ISBLANK(M60), IF(L60="Closed", 4, ROUND(MAX(0, (NOW() - (B60 + IF(ISBLANK(C60), TIME(9,0,0), C60))) * 24), 1)), ROUND(MAX(0, ((M60 + IF(ISBLANK(N60), TIME(18,0,0), N60)) - (B60 + IF(ISBLANK(C60), TIME(9,0,0), C60))) * 24), 1)), 0)) -> 0 | P60: =ROUND(O60 / 24, 2) -> 0 | Q60: =IF(ISBLANK(B60), 0, IF(ISBLANK(M60), IF(L60="Closed", 4, ROUND(MAX(0, (NOW() - (B60 + IF(ISBLANK(C60), TIME(9,0,0), C60))) * 24), 1)), ROUND(MAX(0, ((M60 + IF(ISBLANK(N60), TIME(18,0,0), N60)) - (B60 + IF(ISBLANK(C60), TIME(9,0,0), C60))) * 24), 1))) -> 328.6 | R60: =IF(ISNUMBER(SEARCH("Complete", H60)), 1, 0) -> 0 | S60: Standard Resolution
A61: 59 | B61: 46073 | C61: 0.73263889 | D61: CSU (Ceiling Suspended Unit) | E61: Cafeteria Equipment | F61: Cafeteria / Pantry | G61: Dishwash, CSU Drain line Blockage issue | H61: 🟡 Partial Breakdown (Machine Operational) | I61: N\A | J61: OEM Vendor technician aligned, issue diagnosed & rectified | K61: Vendor / OEM | L61: Closed | M61: 46075 | N61: 0.75 | O61: =IF(ISBLANK(B61), 0, IF(ISNUMBER(SEARCH("Complete", H61)), IF(ISBLANK(M61), IF(L61="Closed", 4, ROUND(MAX(0, (NOW() - (B61 + IF(ISBLANK(C61), TIME(9,0,0), C61))) * 24), 1)), ROUND(MAX(0, ((M61 + IF(ISBLANK(N61), TIME(18,0,0), N61)) - (B61 + IF(ISBLANK(C61), TIME(9,0,0), C61))) * 24), 1)), 0)) -> 0 | P61: =ROUND(O61 / 24, 2) -> 0 | Q61: =IF(ISBLANK(B61), 0, IF(ISBLANK(M61), IF(L61="Closed", 4, ROUND(MAX(0, (NOW() - (B61 + IF(ISBLANK(C61), TIME(9,0,0), C61))) * 24), 1)), ROUND(MAX(0, ((M61 + IF(ISBLANK(N61), TIME(18,0,0), N61)) - (B61 + IF(ISBLANK(C61), TIME(9,0,0), C61))) * 24), 1))) -> 48.4 | R61: =IF(ISNUMBER(SEARCH("Complete", H61)), 1, 0) -> 0 | S61: Resolved By Vendor
A62: 60 | B62: 46074 | C62: 0.29166667 | D62: Zip Tap | E62: Water & Plumbing | F62: Cafeteria / Pantry | G62: Cafeteria, Pantry Zip Tap display issue | H62: 🟡 Partial Breakdown (Machine Operational) | I62: N\A | J62: OEM Vendor technician aligned, issue diagnosed & rectified | K62: Vendor / OEM | L62: Closed | M62: 46074 | N62: 0.75 | O62: =IF(ISBLANK(B62), 0, IF(ISNUMBER(SEARCH("Complete", H62)), IF(ISBLANK(M62), IF(L62="Closed", 4, ROUND(MAX(0, (NOW() - (B62 + IF(ISBLANK(C62), TIME(9,0,0), C62))) * 24), 1)), ROUND(MAX(0, ((M62 + IF(ISBLANK(N62), TIME(18,0,0), N62)) - (B62 + IF(ISBLANK(C62), TIME(9,0,0), C62))) * 24), 1)), 0)) -> 0 | P62: =ROUND(O62 / 24, 2) -> 0 | Q62: =IF(ISBLANK(B62), 0, IF(ISBLANK(M62), IF(L62="Closed", 4, ROUND(MAX(0, (NOW() - (B62 + IF(ISBLANK(C62), TIME(9,0,0), C62))) * 24), 1)), ROUND(MAX(0, ((M62 + IF(ISBLANK(N62), TIME(18,0,0), N62)) - (B62 + IF(ISBLANK(C62), TIME(9,0,0), C62))) * 24), 1))) -> 11 | R62: =IF(ISNUMBER(SEARCH("Complete", H62)), 1, 0) -> 0 | S62: Resolved By Vendor
A63: 61 | B63: 46074 | C63: 0.48333333 | D63: Fire / Heat Detector | E63: Fire, Safety & BMS | F63: Main Facility Floor | G63: Heat Detector issue | H63: 🟡 Partial Breakdown (Machine Operational) | I63: N\A | J63: OEM Vendor technician aligned, issue diagnosed & rectified | K63: Vendor / OEM | L63: Closed | M63: 46075 | N63: 0.75 | O63: =IF(ISBLANK(B63), 0, IF(ISNUMBER(SEARCH("Complete", H63)), IF(ISBLANK(M63), IF(L63="Closed", 4, ROUND(MAX(0, (NOW() - (B63 + IF(ISBLANK(C63), TIME(9,0,0), C63))) * 24), 1)), ROUND(MAX(0, ((M63 + IF(ISBLANK(N63), TIME(18,0,0), N63)) - (B63 + IF(ISBLANK(C63), TIME(9,0,0), C63))) * 24), 1)), 0)) -> 0 | P63: =ROUND(O63 / 24, 2) -> 0 | Q63: =IF(ISBLANK(B63), 0, IF(ISBLANK(M63), IF(L63="Closed", 4, ROUND(MAX(0, (NOW() - (B63 + IF(ISBLANK(C63), TIME(9,0,0), C63))) * 24), 1)), ROUND(MAX(0, ((M63 + IF(ISBLANK(N63), TIME(18,0,0), N63)) - (B63 + IF(ISBLANK(C63), TIME(9,0,0), C63))) * 24), 1))) -> 30.4 | R63: =IF(ISNUMBER(SEARCH("Complete", H63)), 1, 0) -> 0 | S63: Resolved By Vendor
A64: 62 | B64: 46076 | C64: 0.65347222 | D64: Soap Dispenser | E64: Water & Plumbing | F64: Zone E - Male Washroom | G64: Zone -E, Female washroom nos-1, soap dispenser issue | H64: 🟡 Partial Breakdown (Machine Operational) | I64: N/A | J64: Inspected, serviced and restored to normal operation by In-House Team | K64: In-House Team | L64: Closed | M64: 46076 | N64: 0.75 | O64: =IF(ISBLANK(B64), 0, IF(ISNUMBER(SEARCH("Complete", H64)), IF(ISBLANK(M64), IF(L64="Closed", 4, ROUND(MAX(0, (NOW() - (B64 + IF(ISBLANK(C64), TIME(9,0,0), C64))) * 24), 1)), ROUND(MAX(0, ((M64 + IF(ISBLANK(N64), TIME(18,0,0), N64)) - (B64 + IF(ISBLANK(C64), TIME(9,0,0), C64))) * 24), 1)), 0)) -> 0 | P64: =ROUND(O64 / 24, 2) -> 0 | Q64: =IF(ISBLANK(B64), 0, IF(ISBLANK(M64), IF(L64="Closed", 4, ROUND(MAX(0, (NOW() - (B64 + IF(ISBLANK(C64), TIME(9,0,0), C64))) * 24), 1)), ROUND(MAX(0, ((M64 + IF(ISBLANK(N64), TIME(18,0,0), N64)) - (B64 + IF(ISBLANK(C64), TIME(9,0,0), C64))) * 24), 1))) -> 2.3 | R64: =IF(ISNUMBER(SEARCH("Complete", H64)), 1, 0) -> 0 | S64: Repaired by inhouse team
A65: 63 | B65: 46076 | C65: 0.84375 | D65: Exhaust / Inline Fan | E65: HVAC & Cooling | F65: Cafeteria / Pantry | G65: Cafeteria, Dish wash Fan noise issue | H65: 🟡 Partial Breakdown (Machine Operational) | I65: N/A | J65: Inspected, serviced and restored to normal operation by In-House Team | K65: In-House Team | L65: Closed | M65: 46076 | N65: 0.75 | O65: =IF(ISBLANK(B65), 0, IF(ISNUMBER(SEARCH("Complete", H65)), IF(ISBLANK(M65), IF(L65="Closed", 4, ROUND(MAX(0, (NOW() - (B65 + IF(ISBLANK(C65), TIME(9,0,0), C65))) * 24), 1)), ROUND(MAX(0, ((M65 + IF(ISBLANK(N65), TIME(18,0,0), N65)) - (B65 + IF(ISBLANK(C65), TIME(9,0,0), C65))) * 24), 1)), 0)) -> 0 | P65: =ROUND(O65 / 24, 2) -> 0 | Q65: =IF(ISBLANK(B65), 0, IF(ISBLANK(M65), IF(L65="Closed", 4, ROUND(MAX(0, (NOW() - (B65 + IF(ISBLANK(C65), TIME(9,0,0), C65))) * 24), 1)), ROUND(MAX(0, ((M65 + IF(ISBLANK(N65), TIME(18,0,0), N65)) - (B65 + IF(ISBLANK(C65), TIME(9,0,0), C65))) * 24), 1))) -> 0 | R65: =IF(ISNUMBER(SEARCH("Complete", H65)), 1, 0) -> 0 | S65: Repaired by inhouse team
A66: 64 | B66: 46077 | C66: 0.32847222 | D66: Door Closer / Auto Mechanism | E66: Doors & Access Gates | F66: Zone B - Male Washroom | G66: Zone - B, Male washroom Door Need to repair | H66: 🟡 Partial Breakdown (Machine Operational) | I66: N/A | J66: Door closer Change by inhouse team | K66: In-House Team | L66: Closed | M66: 46077 | N66: 0.75 | O66: =IF(ISBLANK(B66), 0, IF(ISNUMBER(SEARCH("Complete", H66)), IF(ISBLANK(M66), IF(L66="Closed", 4, ROUND(MAX(0, (NOW() - (B66 + IF(ISBLANK(C66), TIME(9,0,0), C66))) * 24), 1)), ROUND(MAX(0, ((M66 + IF(ISBLANK(N66), TIME(18,0,0), N66)) - (B66 + IF(ISBLANK(C66), TIME(9,0,0), C66))) * 24), 1)), 0)) -> 0 | P66: =ROUND(O66 / 24, 2) -> 0 | Q66: =IF(ISBLANK(B66), 0, IF(ISBLANK(M66), IF(L66="Closed", 4, ROUND(MAX(0, (NOW() - (B66 + IF(ISBLANK(C66), TIME(9,0,0), C66))) * 24), 1)), ROUND(MAX(0, ((M66 + IF(ISBLANK(N66), TIME(18,0,0), N66)) - (B66 + IF(ISBLANK(C66), TIME(9,0,0), C66))) * 24), 1))) -> 10.1 | R66: =IF(ISNUMBER(SEARCH("Complete", H66)), 1, 0) -> 0 | S66: Door closer Change by inhouse team
A67: 65 | B67: 46077 | C67: 0.42361111 | D67: VAV (Variable Air Volume) | E67: HVAC & Cooling | F67: Main Facility Floor | G67: IT Build room VAV issue | H67: 🟡 Partial Breakdown (Machine Operational) | I67: N/A | J67: Resolved inhouse team | K67: In-House Team | L67: Closed | M67: 46077 | N67: 0.75 | O67: =IF(ISBLANK(B67), 0, IF(ISNUMBER(SEARCH("Complete", H67)), IF(ISBLANK(M67), IF(L67="Closed", 4, ROUND(MAX(0, (NOW() - (B67 + IF(ISBLANK(C67), TIME(9,0,0), C67))) * 24), 1)), ROUND(MAX(0, ((M67 + IF(ISBLANK(N67), TIME(18,0,0), N67)) - (B67 + IF(ISBLANK(C67), TIME(9,0,0), C67))) * 24), 1)), 0)) -> 0 | P67: =ROUND(O67 / 24, 2) -> 0 | Q67: =IF(ISBLANK(B67), 0, IF(ISBLANK(M67), IF(L67="Closed", 4, ROUND(MAX(0, (NOW() - (B67 + IF(ISBLANK(C67), TIME(9,0,0), C67))) * 24), 1)), ROUND(MAX(0, ((M67 + IF(ISBLANK(N67), TIME(18,0,0), N67)) - (B67 + IF(ISBLANK(C67), TIME(9,0,0), C67))) * 24), 1))) -> 7.8 | R67: =IF(ISNUMBER(SEARCH("Complete", H67)), 1, 0) -> 0 | S67: Resolved inhouse team
A68: 66 | B68: 46077 | C68: 0.57777778 | D68: Zip Tap | E68: Water & Plumbing | F68: Cafeteria / Pantry | G68: Cafeteria, Pantry Zip Tap display issue | H68: 🟡 Partial Breakdown (Machine Operational) | I68: 121483 | J68: OEM Vendor technician aligned, issue diagnosed & rectified | K68: Vendor / OEM | L68: Closed | M68: 46078 | N68: 0.75 | O68: =IF(ISBLANK(B68), 0, IF(ISNUMBER(SEARCH("Complete", H68)), IF(ISBLANK(M68), IF(L68="Closed", 4, ROUND(MAX(0, (NOW() - (B68 + IF(ISBLANK(C68), TIME(9,0,0), C68))) * 24), 1)), ROUND(MAX(0, ((M68 + IF(ISBLANK(N68), TIME(18,0,0), N68)) - (B68 + IF(ISBLANK(C68), TIME(9,0,0), C68))) * 24), 1)), 0)) -> 0 | P68: =ROUND(O68 / 24, 2) -> 0 | Q68: =IF(ISBLANK(B68), 0, IF(ISBLANK(M68), IF(L68="Closed", 4, ROUND(MAX(0, (NOW() - (B68 + IF(ISBLANK(C68), TIME(9,0,0), C68))) * 24), 1)), ROUND(MAX(0, ((M68 + IF(ISBLANK(N68), TIME(18,0,0), N68)) - (B68 + IF(ISBLANK(C68), TIME(9,0,0), C68))) * 24), 1))) -> 28.1 | R68: =IF(ISNUMBER(SEARCH("Complete", H68)), 1, 0) -> 0 | S68: Resolved By Vendor
A69: 67 | B69: 46078 | C69: 0.72013889 | D69: HRT Paper Dispenser | E69: Water & Plumbing | F69: Zone B - Male Washroom | G69: Zone B , female washroom HRT Dispenser issue | H69: 🟡 Partial Breakdown (Machine Operational) | I69: N/A | J69: Inspected, serviced and restored to normal operation by In-House Team | K69: In-House Team | L69: Closed | M69: 46078 | N69: 0.75 | O69: =IF(ISBLANK(B69), 0, IF(ISNUMBER(SEARCH("Complete", H69)), IF(ISBLANK(M69), IF(L69="Closed", 4, ROUND(MAX(0, (NOW() - (B69 + IF(ISBLANK(C69), TIME(9,0,0), C69))) * 24), 1)), ROUND(MAX(0, ((M69 + IF(ISBLANK(N69), TIME(18,0,0), N69)) - (B69 + IF(ISBLANK(C69), TIME(9,0,0), C69))) * 24), 1)), 0)) -> 0 | P69: =ROUND(O69 / 24, 2) -> 0 | Q69: =IF(ISBLANK(B69), 0, IF(ISBLANK(M69), IF(L69="Closed", 4, ROUND(MAX(0, (NOW() - (B69 + IF(ISBLANK(C69), TIME(9,0,0), C69))) * 24), 1)), ROUND(MAX(0, ((M69 + IF(ISBLANK(N69), TIME(18,0,0), N69)) - (B69 + IF(ISBLANK(C69), TIME(9,0,0), C69))) * 24), 1))) -> 0.7 | R69: =IF(ISNUMBER(SEARCH("Complete", H69)), 1, 0) -> 0 | S69: Repaired by inhouse team
A70: 68 | B70: 46078 | C70: 0.76666667 | D70: Door Closer / Auto Mechanism | E70: Doors & Access Gates | F70: Zone E - Male Washroom | G70: Zone - E, Male washroom Door Need to repair | H70: 🟡 Partial Breakdown (Machine Operational) | I70: N/A | J70: Door closer Change by inhouse team | K70: In-House Team | L70: Closed | M70: 46078 | N70: 0.75 | O70: =IF(ISBLANK(B70), 0, IF(ISNUMBER(SEARCH("Complete", H70)), IF(ISBLANK(M70), IF(L70="Closed", 4, ROUND(MAX(0, (NOW() - (B70 + IF(ISBLANK(C70), TIME(9,0,0), C70))) * 24), 1)), ROUND(MAX(0, ((M70 + IF(ISBLANK(N70), TIME(18,0,0), N70)) - (B70 + IF(ISBLANK(C70), TIME(9,0,0), C70))) * 24), 1)), 0)) -> 0 | P70: =ROUND(O70 / 24, 2) -> 0 | Q70: =IF(ISBLANK(B70), 0, IF(ISBLANK(M70), IF(L70="Closed", 4, ROUND(MAX(0, (NOW() - (B70 + IF(ISBLANK(C70), TIME(9,0,0), C70))) * 24), 1)), ROUND(MAX(0, ((M70 + IF(ISBLANK(N70), TIME(18,0,0), N70)) - (B70 + IF(ISBLANK(C70), TIME(9,0,0), C70))) * 24), 1))) -> 0 | R70: =IF(ISNUMBER(SEARCH("Complete", H70)), 1, 0) -> 0 | S70: Door closer Change by inhouse team
... A77: 75 | B77: 46084 | C77: 0.76388889 | D77: Drainage / Sump Pump | E77: Water & Plumbing | F77: Cafeteria / Pantry | G77: Cafeteria, pantry store drain line blockage issue | H77: 🟡 Partial Breakdown (Machine Operational) | I77: N/A | J77: Inspected, serviced and restored to normal operation by In-House Team | K77: In-House Team | L77: Closed | M77: 46086 | N77: 0.75 | O77: =IF(ISBLANK(B77), 0, IF(ISNUMBER(SEARCH("Complete", H77)), IF(ISBLANK(M77), IF(L77="Closed", 4, ROUND(MAX(0, (NOW() - (B77 + IF(ISBLANK(C77), TIME(9,0,0), C77))) * 24), 1)), ROUND(MAX(0, ((M77 + IF(ISBLANK(N77), TIME(18,0,0), N77)) - (B77 + IF(ISBLANK(C77), TIME(9,0,0), C77))) * 24), 1)), 0)) -> 0 | P77: =ROUND(O77 / 24, 2) -> 0 | Q77: =IF(ISBLANK(B77), 0, IF(ISBLANK(M77), IF(L77="Closed", 4, ROUND(MAX(0, (NOW() - (B77 + IF(ISBLANK(C77), TIME(9,0,0), C77))) * 24), 1)), ROUND(MAX(0, ((M77 + IF(ISBLANK(N77), TIME(18,0,0), N77)) - (B77 + IF(ISBLANK(C77), TIME(9,0,0), C77))) * 24), 1))) -> 47.7 | R77: =IF(ISNUMBER(SEARCH("Complete", H77)), 1, 0) -> 0 | S77: Repaired by inhouse team
A78: 76 | B78: 46086 | C78: 0.57638889 | D78: Framery / Phone Booth Pod | E78: Electrical & Power | F78: Zone E - Workstation Floor | G78: Zone - E, Near W/s 599, POD Hydraulic Table issue | H78: 🟡 Partial Breakdown (Machine Operational) | I78: N/A | J78: Investigation in progress; technician / spare parts aligned | K78: In-House Team | L78: In Progress (WIP) | O78: =IF(ISBLANK(B78), 0, IF(ISNUMBER(SEARCH("Complete", H78)), IF(ISBLANK(M78), IF(L78="Closed", 4, ROUND(MAX(0, (NOW() - (B78 + IF(ISBLANK(C78), TIME(9,0,0), C78))) * 24), 1)), ROUND(MAX(0, ((M78 + IF(ISBLANK(N78), TIME(18,0,0), N78)) - (B78 + IF(ISBLANK(C78), TIME(9,0,0), C78))) * 24), 1)), 0)) -> 0 | P78: =ROUND(O78 / 24, 2) -> 0 | Q78: =IF(ISBLANK(B78), 0, IF(ISBLANK(M78), IF(L78="Closed", 4, ROUND(MAX(0, (NOW() - (B78 + IF(ISBLANK(C78), TIME(9,0,0), C78))) * 24), 1)), ROUND(MAX(0, ((M78 + IF(ISBLANK(N78), TIME(18,0,0), N78)) - (B78 + IF(ISBLANK(C78), TIME(9,0,0), C78))) * 24), 1))) -> 4012.1 | R78: =IF(ISNUMBER(SEARCH("Complete", H78)), 1, 0) -> 0 | S78: Standard Resolution
A79: 77 | B79: 46087 | C79: 0.84652778 | D79: Zip Tap | E79: Water & Plumbing | F79: Cafeteria / Pantry | G79: Cafeteria Zip tap joint flexible drain pipe leakege issue | H79: 🟡 Partial Breakdown (Machine Operational) | I79: N/A | J79: OEM Vendor technician aligned, issue diagnosed & rectified | K79: Vendor / OEM | L79: Closed | M79: 46087 | N79: 0.75 | O79: =IF(ISBLANK(B79), 0, IF(ISNUMBER(SEARCH("Complete", H79)), IF(ISBLANK(M79), IF(L79="Closed", 4, ROUND(MAX(0, (NOW() - (B79 + IF(ISBLANK(C79), TIME(9,0,0), C79))) * 24), 1)), ROUND(MAX(0, ((M79 + IF(ISBLANK(N79), TIME(18,0,0), N79)) - (B79 + IF(ISBLANK(C79), TIME(9,0,0), C79))) * 24), 1)), 0)) -> 0 | P79: =ROUND(O79 / 24, 2) -> 0 | Q79: =IF(ISBLANK(B79), 0, IF(ISBLANK(M79), IF(L79="Closed", 4, ROUND(MAX(0, (NOW() - (B79 + IF(ISBLANK(C79), TIME(9,0,0), C79))) * 24), 1)), ROUND(MAX(0, ((M79 + IF(ISBLANK(N79), TIME(18,0,0), N79)) - (B79 + IF(ISBLANK(C79), TIME(9,0,0), C79))) * 24), 1))) -> 0 | R79: =IF(ISNUMBER(SEARCH("Complete", H79)), 1, 0) -> 0 | S79: Vendor
A80: 78 | B80: 46088 | C80: 0.41805556 | D80: RO Water System | E80: Water & Plumbing | F80: Reception Area | G80: Reception, RO sound issue | H80: 🟡 Partial Breakdown (Machine Operational) | I80: N/A | J80: OEM Vendor technician aligned, issue diagnosed & rectified | K80: Vendor / OEM | L80: Closed | M80: 46090 | N80: 0.75 | O80: =IF(ISBLANK(B80), 0, IF(ISNUMBER(SEARCH("Complete", H80)), IF(ISBLANK(M80), IF(L80="Closed", 4, ROUND(MAX(0, (NOW() - (B80 + IF(ISBLANK(C80), TIME(9,0,0), C80))) * 24), 1)), ROUND(MAX(0, ((M80 + IF(ISBLANK(N80), TIME(18,0,0), N80)) - (B80 + IF(ISBLANK(C80), TIME(9,0,0), C80))) * 24), 1)), 0)) -> 0 | P80: =ROUND(O80 / 24, 2) -> 0 | Q80: =IF(ISBLANK(B80), 0, IF(ISBLANK(M80), IF(L80="Closed", 4, ROUND(MAX(0, (NOW() - (B80 + IF(ISBLANK(C80), TIME(9,0,0), C80))) * 24), 1)), ROUND(MAX(0, ((M80 + IF(ISBLANK(N80), TIME(18,0,0), N80)) - (B80 + IF(ISBLANK(C80), TIME(9,0,0), C80))) * 24), 1))) -> 56 | R80: =IF(ISNUMBER(SEARCH("Complete", H80)), 1, 0) -> 0 | S80: Vendor
A81: 79 | B81: 46088 | C81: 0.59583333 | D81: Sanitary Fixture & WC Flush | E81: Water & Plumbing | F81: Zone B - Male Washroom | G81: Zone - B, Male washroom WC Flush plate change work | H81: 🟡 Partial Breakdown (Machine Operational) | I81: N/A | J81: Inspected, serviced and restored to normal operation by In-House Team | K81: In-House Team | L81: Closed | M81: 46088 | N81: 0.75 | O81: =IF(ISBLANK(B81), 0, IF(ISNUMBER(SEARCH("Complete", H81)), IF(ISBLANK(M81), IF(L81="Closed", 4, ROUND(MAX(0, (NOW() - (B81 + IF(ISBLANK(C81), TIME(9,0,0), C81))) * 24), 1)), ROUND(MAX(0, ((M81 + IF(ISBLANK(N81), TIME(18,0,0), N81)) - (B81 + IF(ISBLANK(C81), TIME(9,0,0), C81))) * 24), 1)), 0)) -> 0 | P81: =ROUND(O81 / 24, 2) -> 0 | Q81: =IF(ISBLANK(B81), 0, IF(ISBLANK(M81), IF(L81="Closed", 4, ROUND(MAX(0, (NOW() - (B81 + IF(ISBLANK(C81), TIME(9,0,0), C81))) * 24), 1)), ROUND(MAX(0, ((M81 + IF(ISBLANK(N81), TIME(18,0,0), N81)) - (B81 + IF(ISBLANK(C81), TIME(9,0,0), C81))) * 24), 1))) -> 3.7 | R81: =IF(ISNUMBER(SEARCH("Complete", H81)), 1, 0) -> 0 | S81: Repaired by inhouse team
A82: 80 | B82: 46090 | C82: 0.44236111 | D82: RO Water System | E82: Water & Plumbing | F82: Cafeteria / Pantry | G82: Cafeteria, pantry RO Sound issue | H82: 🟡 Partial Breakdown (Machine Operational) | I82: 124052 | J82: OEM Vendor technician aligned, issue diagnosed & rectified | K82: Vendor / OEM | L82: Closed | M82: 46090 | N82: 0.75 | O82: =IF(ISBLANK(B82), 0, IF(ISNUMBER(SEARCH("Complete", H82)), IF(ISBLANK(M82), IF(L82="Closed", 4, ROUND(MAX(0, (NOW() - (B82 + IF(ISBLANK(C82), TIME(9,0,0), C82))) * 24), 1)), ROUND(MAX(0, ((M82 + IF(ISBLANK(N82), TIME(18,0,0), N82)) - (B82 + IF(ISBLANK(C82), TIME(9,0,0), C82))) * 24), 1)), 0)) -> 0 | P82: =ROUND(O82 / 24, 2) -> 0 | Q82: =IF(ISBLANK(B82), 0, IF(ISBLANK(M82), IF(L82="Closed", 4, ROUND(MAX(0, (NOW() - (B82 + IF(ISBLANK(C82), TIME(9,0,0), C82))) * 24), 1)), ROUND(MAX(0, ((M82 + IF(ISBLANK(N82), TIME(18,0,0), N82)) - (B82 + IF(ISBLANK(C82), TIME(9,0,0), C82))) * 24), 1))) -> 7.4 | R82: =IF(ISNUMBER(SEARCH("Complete", H82)), 1, 0) -> 0 | S82: Vendor
A83: 81 | B83: 46090 | C83: 0.44236111 | D83: Zip Tap | E83: Water & Plumbing | F83: Zone A - Social Hub | G83: Zone - A Social hub, RO Sound issue | H83: 🟡 Partial Breakdown (Machine Operational) | I83: 124055 | J83: OEM Vendor technician aligned, issue diagnosed & rectified | K83: Vendor / OEM | L83: Closed | M83: 46090 | N83: 0.75 | O83: =IF(ISBLANK(B83), 0, IF(ISNUMBER(SEARCH("Complete", H83)), IF(ISBLANK(M83), IF(L83="Closed", 4, ROUND(MAX(0, (NOW() - (B83 + IF(ISBLANK(C83), TIME(9,0,0), C83))) * 24), 1)), ROUND(MAX(0, ((M83 + IF(ISBLANK(N83), TIME(18,0,0), N83)) - (B83 + IF(ISBLANK(C83), TIME(9,0,0), C83))) * 24), 1)), 0)) -> 0 | P83: =ROUND(O83 / 24, 2) -> 0 | Q83: =IF(ISBLANK(B83), 0, IF(ISBLANK(M83), IF(L83="Closed", 4, ROUND(MAX(0, (NOW() - (B83 + IF(ISBLANK(C83), TIME(9,0,0), C83))) * 24), 1)), ROUND(MAX(0, ((M83 + IF(ISBLANK(N83), TIME(18,0,0), N83)) - (B83 + IF(ISBLANK(C83), TIME(9,0,0), C83))) * 24), 1))) -> 7.4 | R83: =IF(ISNUMBER(SEARCH("Complete", H83)), 1, 0) -> 0 | S83: Vendor
A84: 82 | B84: 46090 | C84: 0.44236111 | D84: Zip Tap | E84: Water & Plumbing | F84: Zone F - Social Hub | G84: Zone - F Social hub, RO Sound issue | H84: 🟡 Partial Breakdown (Machine Operational) | I84: 124056 | J84: OEM Vendor technician aligned, issue diagnosed & rectified | K84: Vendor / OEM | L84: Closed | M84: 46090 | N84: 0.75 | O84: =IF(ISBLANK(B84), 0, IF(ISNUMBER(SEARCH("Complete", H84)), IF(ISBLANK(M84), IF(L84="Closed", 4, ROUND(MAX(0, (NOW() - (B84 + IF(ISBLANK(C84), TIME(9,0,0), C84))) * 24), 1)), ROUND(MAX(0, ((M84 + IF(ISBLANK(N84), TIME(18,0,0), N84)) - (B84 + IF(ISBLANK(C84), TIME(9,0,0), C84))) * 24), 1)), 0)) -> 0 | P84: =ROUND(O84 / 24, 2) -> 0 | Q84: =IF(ISBLANK(B84), 0, IF(ISBLANK(M84), IF(L84="Closed", 4, ROUND(MAX(0, (NOW() - (B84 + IF(ISBLANK(C84), TIME(9,0,0), C84))) * 24), 1)), ROUND(MAX(0, ((M84 + IF(ISBLANK(N84), TIME(18,0,0), N84)) - (B84 + IF(ISBLANK(C84), TIME(9,0,0), C84))) * 24), 1))) -> 7.4 | R84: =IF(ISNUMBER(SEARCH("Complete", H84)), 1, 0) -> 0 | S84: Vendor
A85: 83 | B85: 46091 | C85: 0.25902778 | D85: Zip Tap | E85: Water & Plumbing | F85: Zone A - Social Hub | G85: Zone - A Social hub, RO Sensor issue | H85: 🟡 Partial Breakdown (Machine Operational) | I85: N/A | J85: Inspected, serviced and restored to normal operation by In-House Team | K85: In-House Team | L85: Closed | M85: 46091 | N85: 0.75 | O85: =IF(ISBLANK(B85), 0, IF(ISNUMBER(SEARCH("Complete", H85)), IF(ISBLANK(M85), IF(L85="Closed", 4, ROUND(MAX(0, (NOW() - (B85 + IF(ISBLANK(C85), TIME(9,0,0), C85))) * 24), 1)), ROUND(MAX(0, ((M85 + IF(ISBLANK(N85), TIME(18,0,0), N85)) - (B85 + IF(ISBLANK(C85), TIME(9,0,0), C85))) * 24), 1)), 0)) -> 0 | P85: =ROUND(O85 / 24, 2) -> 0 | Q85: =IF(ISBLANK(B85), 0, IF(ISBLANK(M85), IF(L85="Closed", 4, ROUND(MAX(0, (NOW() - (B85 + IF(ISBLANK(C85), TIME(9,0,0), C85))) * 24), 1)), ROUND(MAX(0, ((M85 + IF(ISBLANK(N85), TIME(18,0,0), N85)) - (B85 + IF(ISBLANK(C85), TIME(9,0,0), C85))) * 24), 1))) -> 11.8 | R85: =IF(ISNUMBER(SEARCH("Complete", H85)), 1, 0) -> 0 | S85: Repaired by inhouse team
A86: 84 | B86: 46091 | C86: 0.5 | D86: Zip Tap | E86: Water & Plumbing | F86: Cafeteria / Pantry | G86: Cafeteria, pantry Zip Tap Sensor issue | H86: 🟡 Partial Breakdown (Machine Operational) | I86: 123280 | J86: OEM Vendor technician aligned, issue diagnosed & rectified | K86: Vendor / OEM | L86: Closed | M86: 46091 | N86: 0.75 | O86: =IF(ISBLANK(B86), 0, IF(ISNUMBER(SEARCH("Complete", H86)), IF(ISBLANK(M86), IF(L86="Closed", 4, ROUND(MAX(0, (NOW() - (B86 + IF(ISBLANK(C86), TIME(9,0,0), C86))) * 24), 1)), ROUND(MAX(0, ((M86 + IF(ISBLANK(N86), TIME(18,0,0), N86)) - (B86 + IF(ISBLANK(C86), TIME(9,0,0), C86))) * 24), 1)), 0)) -> 0 | P86: =ROUND(O86 / 24, 2) -> 0 | Q86: =IF(ISBLANK(B86), 0, IF(ISBLANK(M86), IF(L86="Closed", 4, ROUND(MAX(0, (NOW() - (B86 + IF(ISBLANK(C86), TIME(9,0,0), C86))) * 24), 1)), ROUND(MAX(0, ((M86 + IF(ISBLANK(N86), TIME(18,0,0), N86)) - (B86 + IF(ISBLANK(C86), TIME(9,0,0), C86))) * 24), 1))) -> 6 | R86: =IF(ISNUMBER(SEARCH("Complete", H86)), 1, 0) -> 0 | S86: Vendor
A87: 85 | B87: 46092 | C87: 0.42291667 | D87: Refrigerator | E87: Cafeteria Equipment | F87: Cafeteria / Pantry | G87: Tuck Shop Fridge Sound issue | H87: 🟡 Partial Breakdown (Machine Operational) | I87: N/A | J87: Vendor By Fan moter change | K87: Vendor / OEM | L87: Closed | M87: 46092 | N87: 0.75 | O87: =IF(ISBLANK(B87), 0, IF(ISNUMBER(SEARCH("Complete", H87)), IF(ISBLANK(M87), IF(L87="Closed", 4, ROUND(MAX(0, (NOW() - (B87 + IF(ISBLANK(C87), TIME(9,0,0), C87))) * 24), 1)), ROUND(MAX(0, ((M87 + IF(ISBLANK(N87), TIME(18,0,0), N87)) - (B87 + IF(ISBLANK(C87), TIME(9,0,0), C87))) * 24), 1)), 0)) -> 0 | P87: =ROUND(O87 / 24, 2) -> 0 | Q87: =IF(ISBLANK(B87), 0, IF(ISBLANK(M87), IF(L87="Closed", 4, ROUND(MAX(0, (NOW() - (B87 + IF(ISBLANK(C87), TIME(9,0,0), C87))) * 24), 1)), ROUND(MAX(0, ((M87 + IF(ISBLANK(N87), TIME(18,0,0), N87)) - (B87 + IF(ISBLANK(C87), TIME(9,0,0), C87))) * 24), 1))) -> 7.8 | R87: =IF(ISNUMBER(SEARCH("Complete", H87)), 1, 0) -> 0 | S87: Vendor By Fan moter change
